Workbook

Sheet OnePlusSixGift
A1: Id | B1: Group | C1: Type | D1: ItemIDgp | E1: ItemIDiap | F1: Money | G1: Sort | H1: rewardType_3_0 | I1: rewardId_3_0 | J1: rewardNum_3_0 | K1: rewardType_3_1 | L1: rewardId_3_1 | M1: rewardNum_3_1 | N1: rewardType_3_2 | O1: rewardId_3_2 | P1: rewardNum_3_2
A2: int_key | B2: int | C2: int | D2: string | E2: string | F2: int | G2: int | H2: int | I2: int | J2: int | K2: int | L2: int | M2: int | N2: int | O2: int | P2: int
A3: s | B3: s | C3: s | D3: s | E3: s | F3: s | G3: s | H3: s | I3: s | J3: s | K3: s | L3: s | M3: s | N3: s | O3: s | P3: s
A4: 唯一索引 | B4: 分组定价 | C4: 1.free 2.购买项 | D4: 谷歌订单号 | E4: 苹果订单号 | F4: 价格 (以PayDiamond为准) | G4: 排序 | H4: 奖励类型 1金币 2钻石 3道具 4卡包 9美金(查表) 17美金金币 | I4: 奖励物品ID1 1金币 2钻石 3物品id | J4: 奖励数量1 | K4: 奖励类型 1金币 2钻石 3道具 4卡包 9美金(查表) 17美金金币 | L4: 奖励物品ID1 1金币 2钻石 3物品id | M4: 奖励数量1 | N4: 奖励类型 1金币 2钻石 3道具 4卡包 9美金(查表) 17美金金币 | O4: 奖励物品ID1 1金币 2钻石 3物品id | P4: 奖励数量1
A5: 1001 | B5: 1 | C5: 2 | F5: 999 | G5: 1 | H5: 17 | I5: 1 | J5: 900 | K5: 4 | L5: 100004 | M5: 1 | N5: 3 | O5: 160001 | P5: 3
A6: 1002 | B6: 1 | C6: 1 | G6: 2 | H6: 3 | I6: 170001 | J6: 1 | K6: 0 | L6: 0 | M6: 0 | N6: 0 | O6: 0 | P6: 0
A7: 1003 | B7: 1 | C7: 1 | G7: 3 | H7: 3 | I7: 192001 | J7: 20 | K7: 0 | L7: 0 | M7: 0 | N7: 0 | O7: 0 | P7: 0
A8: 1004 | B8: 1 | C8: 1 | G8: 4 | H8: 3 | I8: 160001 | J8: 10 | K8: 0 | L8: 0 | M8: 0 | N8: 0 | O8: 0 | P8: 0
A9: 1005 | B9: 1 | C9: 1 | G9: 5 | H9: 3 | I9: 100003 | J9: 1 | K9: 0 | L9: 0 | M9: 0 | N9: 0 | O9: 0 | P9: 0
A10: 1006 | B10: 1 | C10: 1 | G10: 6 | H10: 17 | I10: 1 | J10: 450 | K10: 0 | L10: 0 | M10: 0 | N10: 0 | O10: 0 | P10: 0
A11: 1007 | B11: 1 | C11: 1 | G11: 7 | H11: 4 | I11: 100005 | J11: 1 | K11: 0 | L11: 0 | M11: 0 | N11: 0 | O11: 0 | P11: 0
A12: 1008 | B12: 2 | C12: 2 | F12: 1999 | G12: 1 | H12: 17 | I12: 1 | J12: 2100 | K12: 4 | L12: 100004 | M12: 3 | N12: 3 | O12: 160001 | P12: 15
A13: 1009 | B13: 2 | C13: 1 | G13: 2 | H13: 3 | I13: 170001 | J13: 10 | K13: 0 | L13: 0 | M13: 0 | N13: 0 | O13: 0 | P13: 0
A14: 1010 | B14: 2 | C14: 1 | G14: 3 | H14: 3 | I14: 192001 | J14: 100 | K14: 0 | L14: 0 | M14: 0 | N14: 0 | O14: 0 | P14: 0
A15: 1011 | B15: 2 | C15: 1 | G15: 4 | H15: 3 | I15: 160001 | J15: 15 | K15: 0 | L15: 0 | M15: 0 | N15: 0 | O15: 0 | P15: 0
A16: 1012 | B16: 2 | C16: 1 | G16: 5 | H16: 3 | I16: 100003 | J16: 4 | K16: 0 | L16: 0 | M16: 0 | N16: 0 | O16: 0 | P16: 0
A17: 1013 | B17: 2 | C17: 1 | G17: 6 | H17: 17 | I17: 1 | J17: 1100 | K17: 0 | L17: 0 | M17: 0 | N17: 0 | O17: 0 | P17: 0
A18: 1014 | B18: 2 | C18: 1 | G18: 7 | H18: 4 | I18: 100005 | J18: 2 | K18: 0 | L18: 0 | M18: 0 | N18: 0 | O18: 0 | P18: 0

Sheet frenzy
Q1: 价格 | R1: 14.98 | T1: id | U1: 类型 | V1: 数量 | W1: 等价美金 | Y1: 单位金币 | Z1: 单位钻石 | AA1: 商店折扣
Q2: 等价美金 | R2: =SUM(W:W) -> 54.176471 | T2: 1 | U2: 金币 | V2: 7200000000 | W2: =V2/$Y$2 -> 21.719457 | Y2: 331500000 | Z2: 100 | AA2: 3.3
Q3: 折扣 | R3: =R2/R1 -> 3.6165868 | T3: 2 | U3: 免费金币奖励buff | V3: 1500000000 | W3: =V3/$Y$2 -> 4.5248869
Q4: 相对折扣 | R4: =R3/AA2 -> 1.0959354 | T4: 3 | U4: 钻石 | V4: 500 | W4: =V4/Z2 -> 5
T5: 4 | U5: 道具 | V5: 1 | W5: =1500000*100*0.05*V5/Y2 -> 0.022624434
T6: 5 | U6: 免费金币加速buff | V6: 3 | W6: =1*V6 -> 3
T7: 6 | U7: 金币 | V7: 3600000000 | W7: =V7/$Y$2 -> 10.859729
T8: 7 | U8: 道具 | V8: 2 | W8: =300000000*100*0.05*V8/Y2 -> 9.0497738

Sheet 数值体验表
A1: 分组定价 | B1: id | C1: 奖励类型 1金币 2钻石 3道具 4卡包 9美金(查表) 17美金金币 | D1: 奖励物品ID1 1金币 2钻石 3物品id | E1: 奖励数量1 | F1: 奖励类型 1金币 2钻石 3道具 4卡包 9美金(查表) 17美金金币 | G1: 奖励物品ID1 1金币 2钻石 3物品id | H1: 奖励数量1 | I1: 奖励类型 1金币 2钻石 3道具 4卡包 9美金(查表) 17美金金币 | J1: 奖励物品ID1 1金币 2钻石 3物品id | K1: 奖励数量1 | L1: 等价美金 | M1: 定价 | N1: 档位膨胀 | O1: 折扣 | P1: 美金膨胀 | S1: 档位 | T1: 膨胀
A2: =OnePlusSixGift!B5 -> 1 | B2: 1 | C2: =OnePlusSixGift!H5 -> 17 | D2: =OnePlusSixGift!I5 -> 1 | E2: =OnePlusSixGift!J5 -> 900 | F2: =OnePlusSixGift!K5 -> 4 | G2: =OnePlusSixGift!L5 -> 100004 | H2: =OnePlusSixGift!M5 -> 1 | I2: =OnePlusSixGift!N5 -> 3 | J2: =OnePlusSixGift!O5 -> 160001 | K2: =OnePlusSixGift!P5 -> 3 | L2: =_xlfn.IFNA(IF(C2=9,E2/100,IF(C2=17,E2/100,VLOOKUP(D2,道具id表!$C:$D,2,FALSE)*E2)),0)+_xlfn.IFNA(IF(F2=9,H2/100,IF(F2=17,H2/100,VLOOKUP(G2,道具id表!$C:$D,2,FALSE)*H2)),0)+_xlfn.IFNA(IF(I2=9,K2/100,IF(I2=17,K2/100,VLOOKUP(J2,道具id表!$C:$D,2,FALSE)*K2)),0) -> 9.7 | M2: =OnePlusSixGift!F5/100 -> 9.99 | N2: =VLOOKUP(M2,S:T,2,FALSE) -> 1.4 | O2: =SUMIF(A:A,"="&A2,L:L)/M2/N2 -> 1.2655513 | P2: =(E2+E7)/100/M2 -> 1.3513514 | S2: 0.99 | T2: 1
A3: =OnePlusSixGift!B6 -> 1 | B3: 2 | C3: =OnePlusSixGift!H6 -> 3 | D3: =OnePlusSixGift!I6 -> 170001 | E3: =OnePlusSixGift!J6 -> 1 | L3: =_xlfn.IFNA(IF(C3=9,E3/100,IF(C3=17,E3/100,VLOOKUP(D3,道具id表!$C:$D,2,FALSE)*E3)),0)+_xlfn.IFNA(IF(F3=9,H3/100,IF(F3=17,H3/100,VLOOKUP(G3,道具id表!$C:$D,2,FALSE)*H3)),0)+_xlfn.IFNA(IF(I3=9,K3/100,IF(I3=17,K3/100,VLOOKUP(J3,道具id表!$C:$D,2,FALSE)*K3)),0) -> 0 | S3: 1.99 | T3: 1.05
A4: =OnePlusSixGift!B7 -> 1 | B4: 3 | C4: =OnePlusSixGift!H7 -> 3 | D4: =OnePlusSixGift!I7 -> 192001 | E4: =OnePlusSixGift!J7 -> 20 | L4: =_xlfn.IFNA(IF(C4=9,E4/100,IF(C4=17,E4/100,VLOOKUP(D4,道具id表!$C:$D,2,FALSE)*E4)),0)+_xlfn.IFNA(IF(F4=9,H4/100,IF(F4=17,H4/100,VLOOKUP(G4,道具id表!$C:$D,2,FALSE)*H4)),0)+_xlfn.IFNA(IF(I4=9,K4/100,IF(I4=17,K4/100,VLOOKUP(J4,道具id表!$C:$D,2,FALSE)*K4)),0) -> 0.2 | S4: 2.99 | T4: 1.1
A5: =OnePlusSixGift!B8 -> 1 | B5: 4 | C5: =OnePlusSixGift!H8 -> 3 | D5: =OnePlusSixGift!I8 -> 160001 | E5: =OnePlusSixGift!J8 -> 10 | L5: =_xlfn.IFNA(IF(C5=9,E5/100,IF(C5=17,E5/100,VLOOKUP(D5,道具id表!$C:$D,2,FALSE)*E5)),0)+_xlfn.IFNA(IF(F5=9,H5/100,IF(F5=17,H5/100,VLOOKUP(G5,道具id表!$C:$D,2,FALSE)*H5)),0)+_xlfn.IFNA(IF(I5=9,K5/100,IF(I5=17,K5/100,VLOOKUP(J5,道具id表!$C:$D,2,FALSE)*K5)),0) -> 1 | S5: 3.99 | T5: 1.15
A6: =OnePlusSixGift!B9 -> 1 | B6: 5 | C6: =OnePlusSixGift!H9 -> 3 | D6: =OnePlusSixGift!I9 -> 100003 | E6: =OnePlusSixGift!J9 -> 1 | L6: =_xlfn.IFNA(IF(C6=9,E6/100,IF(C6=17,E6/100,VLOOKUP(D6,道具id表!$C:$D,2,FALSE)*E6)),0)+_xlfn.IFNA(IF(F6=9,H6/100,IF(F6=17,H6/100,VLOOKUP(G6,道具id表!$C:$D,2,FALSE)*H6)),0)+_xlfn.IFNA(IF(I6=9,K6/100,IF(I6=17,K6/100,VLOOKUP(J6,道具id表!$C:$D,2,FALSE)*K6)),0) -> 0.3 | S6: 4.99 | T6: 1.2
A7: =OnePlusSixGift!B10 -> 1 | B7: 6 | C7: =OnePlusSixGift!H10 -> 17 | D7: =OnePlusSixGift!I10 -> 1 | E7: =OnePlusSixGift!J10 -> 450 | L7: =_xlfn.IFNA(IF(C7=9,E7/100,IF(C7=17,E7/100,VLOOKUP(D7,道具id表!$C:$D,2,FALSE)*E7)),0)+_xlfn.IFNA(IF(F7=9,H7/100,IF(F7=17,H7/100,VLOOKUP(G7,道具id表!$C:$D,2,FALSE)*H7)),0)+_xlfn.IFNA(IF(I7=9,K7/100,IF(I7=17,K7/100,VLOOKUP(J7,道具id表!$C:$D,2,FALSE)*K7)),0) -> 4.5 | S7: 5.99 | T7: 1.2
A8: =OnePlusSixGift!B11 -> 1 | B8: 7 | C8: =OnePlusSixGift!H11 -> 4 | D8: =OnePlusSixGift!I11 -> 100005 | E8: =OnePlusSixGift!J11 -> 1 | L8: 2 | S8: 6.99 | T8: 1.25
A9: =OnePlusSixGift!B12 -> 2 | B9: 1 | C9: =OnePlusSixGift!H12 -> 17 | D9: =OnePlusSixGift!I12 -> 1 | E9: =OnePlusSixGift!J12 -> 2100 | F9: =OnePlusSixGift!K12 -> 4 | G9: =OnePlusSixGift!L12 -> 100004 | H9: =OnePlusSixGift!M12 -> 3 | I9: =OnePlusSixGift!N12 -> 3 | J9: =OnePlusSixGift!O12 -> 160001 | K9: =OnePlusSixGift!P12 -> 15 | L9: =_xlfn.IFNA(IF(C9=9,E9/100,IF(C9=17,E9/100,VLOOKUP(D9,道具id表!$C:$D,2,FALSE)*E9)),0)+_xlfn.IFNA(IF(F9=9,H9/100,IF(F9=17,H9/100,VLOOKUP(G9,道具id表!$C:$D,2,FALSE)*H9)),0)+_xlfn.IFNA(IF(I9=9,K9/100,IF(I9=17,K9/100,VLOOKUP(J9,道具id表!$C:$D,2,FALSE)*K9)),0) -> 23.7 | M9: =OnePlusSixGift!F12/100 -> 19.99 | N9: =VLOOKUP(M9,S:T,2,FALSE) -> 1.6 | O9: =SUMIF(A:A,"="&A9,L:L)/M9/N9 -> 1.2631316 | P9: =(E9+E14)/100/M9 -> 1.6008004 | S9: 7.99 | T9: 1.3
A10: =OnePlusSixGift!B13 -> 2 | B10: 2 | C10: =OnePlusSixGift!H13 -> 3 | D10: =OnePlusSixGift!I13 -> 170001 | E10: =OnePlusSixGift!J13 -> 10 | L10: =_xlfn.IFNA(IF(C10=9,E10/100,IF(C10=17,E10/100,VLOOKUP(D10,道具id表!$C:$D,2,FALSE)*E10)),0)+_xlfn.IFNA(IF(F10=9,H10/100,IF(F10=17,H10/100,VLOOKUP(G10,道具id表!$C:$D,2,FALSE)*H10)),0)+_xlfn.IFNA(IF(I10=9,K10/100,IF(I10=17,K10/100,VLOOKUP(J10,道具id表!$C:$D,2,FALSE)*K10)),0) -> 0 | S10: 8.99 | T10: 1.35
A11: =OnePlusSixGift!B14 -> 2 | B11: 3 | C11: =OnePlusSixGift!H14 -> 3 | D11: =OnePlusSixGift!I14 -> 192001 | E11: =OnePlusSixGift!J14 -> 100 | L11: =_xlfn.IFNA(IF(C11=9,E11/100,IF(C11=17,E11/100,VLOOKUP(D11,道具id表!$C:$D,2,FALSE)*E11)),0)+_xlfn.IFNA(IF(F11=9,H11/100,IF(F11=17,H11/100,VLOOKUP(G11,道具id表!$C:$D,2,FALSE)*H11)),0)+_xlfn.IFNA(IF(I11=9,K11/100,IF(I11=17,K11/100,VLOOKUP(J11,道具id表!$C:$D,2,FALSE)*K11)),0) -> 1 | S11: 9.99 | T11: 1.4
A12: =OnePlusSixGift!B15 -> 2 | B12: 4 | C12: =OnePlusSixGift!H15 -> 3 | D12: =OnePlusSixGift!I15 -> 160001 | E12: =OnePlusSixGift!J15 -> 15 | L12: =_xlfn.IFNA(IF(C12=9,E12/100,IF(C12=17,E12/100,VLOOKUP(D12,道具id表!$C:$D,2,FALSE)*E12)),0)+_xlfn.IFNA(IF(F12=9,H12/100,IF(F12=17,H12/100,VLOOKUP(G12,道具id表!$C:$D,2,FALSE)*H12)),0)+_xlfn.IFNA(IF(I12=9,K12/100,IF(I12=17,K12/100,VLOOKUP(J12,道具id表!$C:$D,2,FALSE)*K12)),0) -> 1.5 | S12: 12.99 | T12: 1.5
A13: =OnePlusSixGift!B16 -> 2 | B13: 5 | C13: =OnePlusSixGift!H16 -> 3 | D13: =OnePlusSixGift!I16 -> 100003 | E13: =OnePlusSixGift!J16 -> 4 | L13: =_xlfn.IFNA(IF(C13=9,E13/100,IF(C13=17,E13/100,VLOOKUP(D13,道具id表!$C:$D,2,FALSE)*E13)),0)+_xlfn.IFNA(IF(F13=9,H13/100,IF(F13=17,H13/100,VLOOKUP(G13,道具id表!$C:$D,2,FALSE)*H13)),0)+_xlfn.IFNA(IF(I13=9,K13/100,IF(I13=17,K13/100,VLOOKUP(J13,道具id表!$C:$D,2,FALSE)*K13)),0) -> 1.2 | S13: 14.99 | T13: 1.55
A14: =OnePlusSixGift!B17 -> 2 | B14: 6 | C14: =OnePlusSixGift!H17 -> 17 | D14: =OnePlusSixGift!I17 -> 1 | E14: =OnePlusSixGift!J17 -> 1100 | L14: =_xlfn.IFNA(IF(C14=9,E14/100,IF(C14=17,E14/100,VLOOKUP(D14,道具id表!$C:$D,2,FALSE)*E14)),0)+_xlfn.IFNA(IF(F14=9,H14/100,IF(F14=17,H14/100,VLOOKUP(G14,道具id表!$C:$D,2,FALSE)*H14)),0)+_xlfn.IFNA(IF(I14=9,K14/100,IF(I14=17,K14/100,VLOOKUP(J14,道具id表!$C:$D,2,FALSE)*K14)),0) -> 11 | S14: 17.99 | T14: 1.6
A15: =OnePlusSixGift!B18 -> 2 | B15: 7 | C15: =OnePlusSixGift!H18 -> 4 | D15: =OnePlusSixGift!I18 -> 100005 | E15: =OnePlusSixGift!J18 -> 2 | L15: 2 | S15: 19.99 | T15: 1.6
S16: 24.99 | T16: 1.65
S17: 29.99 | T17: 1.65
S18: 34.99 | T18: 1.7
S19: 39.99 | T19: 1.75
S20: 44.99 | T20: 1.8
S21: 49.99 | T21: 1.8
S22: 54.99 | T22: 1.8
S23: 59.99 | T23: 1.85
S24: 69.99 | T24: 1.85
S25: 74.99 | T25: 1.9
S26: 79.99 | T26: 1.9
S27: 89.99 | T27: 1.95
S28: 99.99 | T28: 2

Sheet 道具id表
A1: name | B1: _comm | C1: itemID | D1: 价值
A2: string_lan | B2: string | C2: uint_key
A3: cs | B3: skip | C3: cs
A4: //名字 | B4: //注释 | C4: //物品的ID
A5: cake | B5: 蛋糕 | C5: 1001
A6: heart | B6: 心 | C6: 1002
A7: Roadster | B7: 跑车 | C7: 1003
A8: Houseboat | B8: 游艇 | C8: 1004
A9: Castle | B9: 城堡 | C9: 1005
A10: Necklace | B10: 项链 | C10: 130001
A11: Flower | B11: 玫瑰 | C11: 130002
A12: bombs | B12: 炸弹 | C12: 130003
A13: like | B13: 赞 | C13: 130004
A14: Punch | B14: 击拳 | C14: 130005
A15: Bucket | B15: 水桶 | C15: 130006
A16: Juicy 3 | B16: 果汁3 | C16: 130007
... A45: Remaining Card | B45: 记牌器3分钟 | C45: 150001
A46: Remaining Card | B46: 记牌器1个 | C46: 160001 | D46: 0.1
A47: FunEmoji-Heart | B47: 心-表情道具 | C47: 170001
A48: FunEmoji-Turtle | B48: 乌龟-表情道具 | C48: 170002
A49: FunEmoji-Like | B49: 赞-表情道具 | C49: 170003
A50: FunEmoji-Poo | B50: 便便-表情道具 | C50: 170004
A51: FunEmoji-Flower | B51: 花-表情道具 | C51: 170005
A52: FunEmoji-Candy | B52: 糖果-表情道具 | C52: 170006
A53: FunEmoji-Pumpkin | B53: 南瓜-表情道具 | C53: 170007
A54: Revive Ticket | B54: 大奖赛复活券 | C54: 171001 | D54: 0.1
A55: Register Ticket | B55: 大奖赛报名券 | C55: 171002 | D55: 0.1
A56: RaffleTicket | B56: pass抽奖券 | C56: 191001
A57: League xp +10% | B57: 联赛经验加成 | C57: 201001
A58: League xp +10% | B58: 联赛经验加成 | C58: 201002
A59: League xp +30% | B59: 联赛经验加成 | C59: 201003
A60: League xp +40% | B60: 联赛经验加成 | C60: 201004
A61: League xp +50% | B61: 联赛经验加成 | C61: 201005
A62: SlotTicket | B62: 老虎机抽奖券 | C62: 192001 | D62: 0.01
A63: 1 Star Pack | B63: 卡包1星 | C63: 100001 | D63: 0.1
A64: 2 Stars Pack | B64: 卡包2星 | C64: 100002 | D64: 0.2
A65: 3 Stars Pack | B65: 卡包3星 | C65: 100003 | D65: 0.3
A66: 4 Stars Pack | B66: 卡包4星 | C66: 100004 | D66: 0.4
A67: 5 Stars Pack | B67: 卡包5星 | C67: 100005 | D67: 0.5
A68: Ordinary Joker | B68: Joker Card1 | C68: 210006
...
