Workbook

Sheet 膨胀后
A1: 基础金币/美金 | C1: 章节 | D1: 金币 | E1: 美金 | H1: 章节 | I1: 金币 | J1: 美金 | K1: 最大星级 | M1: 基础金币/美金 | O1: 底注 | P1: //筹码下限 | Q1: 一局消耗 | R1: 消耗美金 | S1: //卡包id1 | T1: //概率 | U1: 产出卡包 | V1: //卡包id2 | W1: //概率 | Y1: //卡包id3 | Z1: //概率 | AB1: 单局上限 | AC1: 平均小轮数 | AF1: set/star | AG1: 1 | AH1: 2 | AI1: 3 | AJ1: 4 | AK1: 5 | AL1: 6 | AM1: gold4 | AN1: gold5 | AO1: gold6 | AP1: 合计
A2: 250000 | C2: 1 | D2: 100000 | E2: =D2/$A$2 -> 0.4 | H2: 1 | I2: =J2*$M$2 -> 2500000 | J2: 2.5 | K2: 1 | M2: 1000000 | O2: 1000 | P2: 5000 | Q2: =O2*$M$4*$M$6 -> 7000 | R2: =Q2/$M$2 -> 0.007 | AB2: 1 | AC2: 13 | AF2: 1 | AG2: 8 | AH2: 0 | AI2: 0 | AJ2: 0 | AK2: 0 | AL2: 0 | AM2: 0 | AN2: 0 | AO2: 0 | AP2: 8
C3: 2 | D3: 150000 | E3: =D3/$A$2 -> 0.6 | H3: 2 | I3: =J3*$M$2 -> 2700000 | J3: 2.7 | K3: 2 | M3: 平均倍率 | O3: 3000 | P3: 210000 | Q3: =O3*$M$4*$M$6 -> 21000 | R3: =Q3/$M$2 -> 0.021 | AB3: 1 | AC3: 13 | AF3: 2 | AG3: 7 | AH3: 1 | AI3: 0 | AJ3: 0 | AK3: 0 | AL3: 0 | AM3: 0 | AN3: 0 | AO3: 0 | AP3: 8
C4: 3 | D4: 300000 | E4: =D4/$A$2 -> 1.2 | H4: 3 | I4: =J4*$M$2 -> 3000000 | J4: 3 | K4: 2 | M4: 70 | O4: 10000 | P4: 700000 | Q4: =O4*$M$4*$M$6 -> 70000 | R4: =Q4/$M$2 -> 0.07 | S4: 1 | T4: 750 | U4: =T4*$AC4/10000 -> 0.975 | AB4: 1 | AC4: 13 | AD4: =SUM(T4+W4+Z4) -> 750 | AF4: 3 | AG4: 6 | AH4: 2 | AI4: 0 | AJ4: 0 | AK4: 0 | AL4: 0 | AM4: 0 | AN4: 0 | AO4: 0 | AP4: 8
C5: 4 | D5: 500000 | E5: =D5/$A$2 -> 2 | H5: 4 | I5: =J5*$M$2 -> 3200000 | J5: 3.2 | K5: 2 | M5: 抽水 | O5: 20000 | P5: 1400000 | Q5: =O5*$M$4*$M$6 -> 140000 | R5: =Q5/$M$2 -> 0.14 | S5: 1 | T5: 400 | U5: =T5*$AC5/10000 -> 0.52 | V5: 2 | W5: 300 | X5: =W5*$AC5/10000 -> 0.39 | AB5: 1 | AC5: 13 | AD5: =SUM(T5+W5+Z5) -> 700 | AF5: 4 | AG5: 4 | AH5: 4 | AI5: 0 | AJ5: 0 | AK5: 0 | AL5: 0 | AM5: 0 | AN5: 0 | AO5: 0 | AP5: 8
C6: 5 | D6: 1000000 | E6: =D6/$A$2 -> 4 | H6: 5 | I6: =J6*$M$2 -> 3400000 | J6: 3.4 | K6: 2 | M6: 0.1 | O6: 50000 | P6: 3500000 | Q6: =O6*$M$4*$M$6 -> 350000 | R6: =Q6/$M$2 -> 0.35 | S6: 2 | T6: 400 | U6: =T6*$AC6/10000 -> 0.52 | V6: 3 | W6: 400 | X6: =W6*$AC6/10000 -> 0.52 | Y6: 4 | Z6: 300 | AA6: =Z6*$AC6/10000 -> 0.39 | AB6: 1 | AC6: 13 | AD6: =SUM(T6+W6+Z6) -> 1100 | AF6: 5 | AG6: 3 | AH6: 5 | AI6: 0 | AJ6: 0 | AK6: 0 | AL6: 0 | AM6: 0 | AN6: 0 | AO6: 0 | AP6: 8
C7: 6 | D7: 1200000 | E7: =D7/$A$2 -> 4.8 | H7: 6 | I7: =J7*$M$2 -> 3500000 | J7: 3.5 | K7: 3 | O7: 100000 | P7: 7000000 | Q7: =O7*$M$4*$M$6 -> 700000 | R7: =Q7/$M$2 -> 0.7 | S7: 3 | T7: 300 | U7: =T7*$AC7/10000 -> 0.39 | V7: 4 | W7: 250 | X7: =W7*$AC7/10000 -> 0.325 | Y7: 5 | Z7: 200 | AA7: =Z7*$AC7/10000 -> 0.26 | AB7: 1 | AC7: 13 | AD7: =SUM(T7+W7+Z7) -> 750 | AF7: 6 | AG7: 2 | AH7: 5 | AI7: 1 | AJ7: 0 | AK7: 0 | AL7: 0 | AM7: 0 | AN7: 0 | AO7: 0 | AP7: 8
C8: 7 | D8: 1500000 | E8: =D8/$A$2 -> 6 | H8: 7 | I8: =J8*$M$2 -> 3600000 | J8: 3.6 | K8: 3 | O8: 200000 | P8: 14000000 | Q8: =O8*$M$4*$M$6 -> 1400000 | R8: =Q8/$M$2 -> 1.4 | S8: 4 | T8: 300 | U8: =T8*$AC8/10000 -> 0.39 | V8: 5 | W8: 250 | X8: =W8*$AC8/10000 -> 0.325 | Y8: 6 | Z8: 200 | AA8: =Z8*$AC8/10000 -> 0.26 | AB8: 2 | AC8: 13 | AD8: =SUM(T8+W8+Z8) -> 750 | AF8: 7 | AG8: 1 | AH8: 4 | AI8: 3 | AJ8: 0 | AK8: 0 | AL8: 0 | AM8: 0 | AN8: 0 | AO8: 0 | AP8: 8
C9: 8 | D9: 1800000 | E9: =D9/$A$2 -> 7.2 | H9: 8 | I9: =J9*$M$2 -> 3700000 | J9: 3.7 | K9: 3 | O9: 500000 | P9: 35000000 | Q9: =O9*$M$4*$M$6 -> 3500000 | R9: =Q9/$M$2 -> 3.5 | S9: 4 | T9: 350 | U9: =T9*$AC9/10000 -> 0.455 | V9: 5 | W9: 300 | X9: =W9*$AC9/10000 -> 0.39 | Y9: 6 | Z9: 250 | AA9: =Z9*$AC9/10000 -> 0.325 | AB9: 3 | AC9: 13 | AD9: =SUM(T9+W9+Z9) -> 900 | AF9: 8 | AG9: 0 | AH9: 4 | AI9: 4 | AJ9: 0 | AK9: 0 | AL9: 0 | AM9: 0 | AN9: 0 | AO9: 0 | AP9: 8
C10: 9 | D10: 2000000 | E10: =D10/$A$2 -> 8 | H10: 9 | I10: =J10*$M$2 -> 20000000 | J10: 20 | K10: 4 | O10: 1000000 | P10: 70000000 | Q10: =O10*$M$4*$M$6 -> 7000000 | R10: =Q10/$M$2 -> 7 | S10: 4 | T10: 400 | U10: =T10*$AC10/10000 -> 0.52 | V10: 5 | W10: 350 | X10: =W10*$AC10/10000 -> 0.455 | Y10: 6 | Z10: 300 | AA10: =Z10*$AC10/10000 -> 0.39 | AB10: 4 | AC10: 13 | AD10: =SUM(T10+W10+Z10) -> 1050 | AF10: 9 | AG10: 0 | AH10: 3 | AI10: 4 | AJ10: 1 | AK10: 0 | AL10: 0 | AM10: 0 | AN10: 0 | AO10: 0 | AP10: 8
C11: 10 | D11: 2500000 | E11: =D11/$A$2 -> 10 | H11: 10 | I11: =J11*$M$2 -> 25000000 | J11: 25 | K11: 4 | AF11: 10 | AG11: 0 | AH11: 3 | AI11: 3 | AJ11: 2 | AK11: 0 | AL11: 0 | AM11: 0 | AN11: 0 | AO11: 0 | AP11: 8
C12: 11 | D12: 3000000 | E12: =D12/$A$2 -> 12 | H12: 11 | I12: =J12*$M$2 -> 27000000 | J12: 27 | K12: 5 | M12: 单局产出卡包 | O12: 卡包数量 | P12: 1 | Q12: 2 | R12: 3 | S12: 4 | T12: 5 | U12: 6 | AF12: 11 | AG12: 0 | AH12: 1 | AI12: 4 | AJ12: 2 | AK12: 0 | AL12: 0 | AM12: 1 | AN12: 0 | AO12: 0 | AP12: 8
C13: 12 | D13: 3500000 | E13: =D13/$A$2 -> 14 | H13: 12 | I13: =J13*$M$2 -> 29000000 | J13: 29 | K13: 5 | O13: 1000 | P13: =IF($S2=P$12,$U2,0)+IF($V2=P$12,$X2,0)+IF($Y2=P$12,$AA2,0) -> 0 | Q13: =IF($S2=Q$12,$U2,0)+IF($V2=Q$12,$X2,0)+IF($Y2=Q$12,$AA2,0) -> 0 | R13: =IF($S2=R$12,$U2,0)+IF($V2=R$12,$X2,0)+IF($Y2=R$12,$AA2,0) -> 0 | S13: =IF($S2=S$12,$U2,0)+IF($V2=S$12,$X2,0)+IF($Y2=S$12,$AA2,0) -> 0 | T13: =IF($S2=T$12,$U2,0)+IF($V2=T$12,$X2,0)+IF($Y2=T$12,$AA2,0) -> 0 | U13: =IF($S2=U$12,$U2,0)+IF($V2=U$12,$X2,0)+IF($Y2=U$12,$AA2,0) -> 0 | AF13: 12 | AG13: 0 | AH13: 1 | AI13: 3 | AJ13: 2 | AK13: 1 | AL13: 0 | AM13: 1 | AN13: 0 | AO13: 0 | AP13: 8
C14: 13 | D14: 5000000 | E14: =D14/$A$2 -> 20 | H14: 13 | I14: =J14*$M$2 -> 31000000 | J14: 31 | K14: 5 | O14: 3000 | P14: =IF($S3=P$12,$U3,0)+IF($V3=P$12,$X3,0)+IF($Y3=P$12,$AA3,0) -> 0 | Q14: =IF($S3=Q$12,$U3,0)+IF($V3=Q$12,$X3,0)+IF($Y3=Q$12,$AA3,0) -> 0 | R14: =IF($S3=R$12,$U3,0)+IF($V3=R$12,$X3,0)+IF($Y3=R$12,$AA3,0) -> 0 | S14: =IF($S3=S$12,$U3,0)+IF($V3=S$12,$X3,0)+IF($Y3=S$12,$AA3,0) -> 0 | T14: =IF($S3=T$12,$U3,0)+IF($V3=T$12,$X3,0)+IF($Y3=T$12,$AA3,0) -> 0 | U14: =IF($S3=U$12,$U3,0)+IF($V3=U$12,$X3,0)+IF($Y3=U$12,$AA3,0) -> 0 | AF14: 13 | AG14: 0 | AH14: 1 | AI14: 2 | AJ14: 2 | AK14: 1 | AL14: 0 | AM14: 1 | AN14: 1 | AO14: 0 | AP14: 8
C15: 14 | D15: 7500000 | E15: =D15/$A$2 -> 30 | H15: 14 | I15: =J15*$M$2 -> 35000000 | J15: 35 | K15: 5 | O15: 10000 | P15: =IF($S4=P$12,$U4,0)+IF($V4=P$12,$X4,0)+IF($Y4=P$12,$AA4,0) -> 0.975 | Q15: =IF($S4=Q$12,$U4,0)+IF($V4=Q$12,$X4,0)+IF($Y4=Q$12,$AA4,0) -> 0 | R15: =IF($S4=R$12,$U4,0)+IF($V4=R$12,$X4,0)+IF($Y4=R$12,$AA4,0) -> 0 | S15: =IF($S4=S$12,$U4,0)+IF($V4=S$12,$X4,0)+IF($Y4=S$12,$AA4,0) -> 0 | T15: =IF($S4=T$12,$U4,0)+IF($V4=T$12,$X4,0)+IF($Y4=T$12,$AA4,0) -> 0 | U15: =IF($S4=U$12,$U4,0)+IF($V4=U$12,$X4,0)+IF($Y4=U$12,$AA4,0) -> 0 | AF15: 14 | AG15: 0 | AH15: 0 | AI15: 2 | AJ15: 2 | AK15: 1 | AL15: 1 | AM15: 1 | AN15: 1 | AO15: 0 | AP15: 8
C16: 15 | D16: 10000000 | E16: =D16/$A$2 -> 40 | H16: 15 | I16: =J16*$M$2 -> 40000000 | J16: 40 | K16: 6 | O16: 20000 | P16: =IF($S5=P$12,$U5,0)+IF($V5=P$12,$X5,0)+IF($Y5=P$12,$AA5,0) -> 0.52 | Q16: =IF($S5=Q$12,$U5,0)+IF($V5=Q$12,$X5,0)+IF($Y5=Q$12,$AA5,0) -> 0.39 | R16: =IF($S5=R$12,$U5,0)+IF($V5=R$12,$X5,0)+IF($Y5=R$12,$AA5,0) -> 0 | S16: =IF($S5=S$12,$U5,0)+IF($V5=S$12,$X5,0)+IF($Y5=S$12,$AA5,0) -> 0 | T16: =IF($S5=T$12,$U5,0)+IF($V5=T$12,$X5,0)+IF($Y5=T$12,$AA5,0) -> 0 | U16: =IF($S5=U$12,$U5,0)+IF($V5=U$12,$X5,0)+IF($Y5=U$12,$AA5,0) -> 0 | AF16: 15 | AG16: 0 | AH16: 0 | AI16: 1 | AJ16: 3 | AK16: 1 | AL16: 1 | AM16: 1 | AN16: 1 | AO16: 0 | AP16: 8
C17: 16 | D17: 12500000 | E17: =D17/$A$2 -> 50 | H17: 16 | I17: =J17*$M$2 -> 42500000 | J17: 42.5 | K17: 6 | O17: 50000 | P17: =IF($S6=P$12,$U6,0)+IF($V6=P$12,$X6,0)+IF($Y6=P$12,$AA6,0) -> 0 | Q17: =IF($S6=Q$12,$U6,0)+IF($V6=Q$12,$X6,0)+IF($Y6=Q$12,$AA6,0) -> 0.52 | R17: =IF($S6=R$12,$U6,0)+IF($V6=R$12,$X6,0)+IF($Y6=R$12,$AA6,0) -> 0.52 | S17: =IF($S6=S$12,$U6,0)+IF($V6=S$12,$X6,0)+IF($Y6=S$12,$AA6,0) -> 0.39 | T17: =IF($S6=T$12,$U6,0)+IF($V6=T$12,$X6,0)+IF($Y6=T$12,$AA6,0) -> 0 | U17: =IF($S6=U$12,$U6,0)+IF($V6=U$12,$X6,0)+IF($Y6=U$12,$AA6,0) -> 0 | AF17: 16 | AG17: 0 | AH17: 0 | AI17: 1 | AJ17: 2 | AK17: 1 | AL17: 1 | AM17: 2 | AN17: 1 | AO17: 0 | AP17: 8
C18: 17 | D18: 15000000 | E18: =D18/$A$2 -> 60 | H18: 17 | I18: =J18*$M$2 -> 45000000 | J18: 45 | K18: 6 | O18: 100000 | P18: =IF($S7=P$12,$U7,0)+IF($V7=P$12,$X7,0)+IF($Y7=P$12,$AA7,0) -> 0 | Q18: =IF($S7=Q$12,$U7,0)+IF($V7=Q$12,$X7,0)+IF($Y7=Q$12,$AA7,0) -> 0 | R18: =IF($S7=R$12,$U7,0)+IF($V7=R$12,$X7,0)+IF($Y7=R$12,$AA7,0) -> 0.39 | S18: =IF($S7=S$12,$U7,0)+IF($V7=S$12,$X7,0)+IF($Y7=S$12,$AA7,0) -> 0.325 | T18: =IF($S7=T$12,$U7,0)+IF($V7=T$12,$X7,0)+IF($Y7=T$12,$AA7,0) -> 0.26 | U18: =IF($S7=U$12,$U7,0)+IF($V7=U$12,$X7,0)+IF($Y7=U$12,$AA7,0) -> 0 | AF18: 17 | AG18: 0 | AH18: 0 | AI18: 1 | AJ18: 1 | AK18: 2 | AL18: 1 | AM18: 2 | AN18: 1 | AO18: 0 | AP18: 8
C19: 18 | D19: 17500000 | E19: =D19/$A$2 -> 70 | H19: 18 | I19: =J19*$M$2 -> 50000000 | J19: 50 | K19: 6 | O19: 200000 | P19: =IF($S8=P$12,$U8,0)+IF($V8=P$12,$X8,0)+IF($Y8=P$12,$AA8,0) -> 0 | Q19: =IF($S8=Q$12,$U8,0)+IF($V8=Q$12,$X8,0)+IF($Y8=Q$12,$AA8,0) -> 0 | R19: =IF($S8=R$12,$U8,0)+IF($V8=R$12,$X8,0)+IF($Y8=R$12,$AA8,0) -> 0 | S19: =IF($S8=S$12,$U8,0)+IF($V8=S$12,$X8,0)+IF($Y8=S$12,$AA8,0) -> 0.39 | T19: =IF($S8=T$12,$U8,0)+IF($V8=T$12,$X8,0)+IF($Y8=T$12,$AA8,0) -> 0.325 | U19: =IF($S8=U$12,$U8,0)+IF($V8=U$12,$X8,0)+IF($Y8=U$12,$AA8,0) -> 0.26 | AF19: 18 | AG19: 0 | AH19: 0 | AI19: 1 | AJ19: 1 | AK19: 2 | AL19: 0 | AM19: 1 | AN19: 2 | AO19: 1 | AP19: 8
C20: 19 | D20: 20000000 | E20: =D20/$A$2 -> 80 | H20: 19 | I20: =J20*$M$2 -> 55000000 | J20: 55 | K20: 6 | O20: 500000 | P20: =IF($S9=P$12,$U9,0)+IF($V9=P$12,$X9,0)+IF($Y9=P$12,$AA9,0) -> 0 | Q20: =IF($S9=Q$12,$U9,0)+IF($V9=Q$12,$X9,0)+IF($Y9=Q$12,$AA9,0) -> 0 | R20: =IF($S9=R$12,$U9,0)+IF($V9=R$12,$X9,0)+IF($Y9=R$12,$AA9,0) -> 0 | S20: =IF($S9=S$12,$U9,0)+IF($V9=S$12,$X9,0)+IF($Y9=S$12,$AA9,0) -> 0.455 | T20: =IF($S9=T$12,$U9,0)+IF($V9=T$12,$X9,0)+IF($Y9=T$12,$AA9,0) -> 0.39 | U20: =IF($S9=U$12,$U9,0)+IF($V9=U$12,$X9,0)+IF($Y9=U$12,$AA9,0) -> 0.325 | AF20: 19 | AG20: 0 | AH20: 0 | AI20: 0 | AJ20: 1 | AK20: 2 | AL20: 0 | AM20: 2 | AN20: 2 | AO20: 1 | AP20: 8
C21: all | D21: 35000000 | E21: =D21/$A$2 -> 140 | H21: all | I21: =J21*$M$2 -> 100000000 | J21: 100 | O21: 1000000 | P21: =IF($S10=P$12,$U10,0)+IF($V10=P$12,$X10,0)+IF($Y10=P$12,$AA10,0) -> 0 | Q21: =IF($S10=Q$12,$U10,0)+IF($V10=Q$12,$X10,0)+IF($Y10=Q$12,$AA10,0) -> 0 | R21: =IF($S10=R$12,$U10,0)+IF($V10=R$12,$X10,0)+IF($Y10=R$12,$AA10,0) -> 0 | S21: =IF($S10=S$12,$U10,0)+IF($V10=S$12,$X10,0)+IF($Y10=S$12,$AA10,0) -> 0.52 | T21: =IF($S10=T$12,$U10,0)+IF($V10=T$12,$X10,0)+IF($Y10=T$12,$AA10,0) -> 0.455 | U21: =IF($S10=U$12,$U10,0)+IF($V10=U$12,$X10,0)+IF($Y10=U$12,$AA10,0) -> 0.39 | AF21: 合计 | AG21: 31 | AH21: 34 | AI21: 30 | AJ21: 19 | AK21: 11 | AL21: 4 | AM21: 12 | AN21: 9 | AO21: 2 | AP21: 152
C22: 基础 | D22: =SUM(D2:D21) -> 140050000 | E22: =SUM(E2:E21) -> 560.2 | H22: 基础 | I22: =SUM(I2:I21) -> 525100000 | J22: =SUM(J2:J21) -> 525.1
M23: 需要牌局数 | O23: 星级 | P23: 1 | Q23: 2 | R23: 3 | S23: 4 | T23: 5 | U23: 6
O24: 需要开卡次数 | P24: 25 | Q24: 50 | R24: 50 | S24: 50 | T24: 50 | U24: 40 | V24: 集满奖励 | W24: 集满美金 | X24: 最低牌局数
H25: 卡包 | I25: 需要开卡次数 | J25: 卡包价值 | O25: 1000 | P25: =IF(P13=0,0,P$24/P13) -> 0 | Q25: =IF(Q13=0,0,Q$24/Q13) -> 0 | R25: =IF(R13=0,0,R$24/R13) -> 0 | S25: =IF(S13=0,0,S$24/S13) -> 0 | T25: =IF(T13=0,0,T$24/T13) -> 0 | U25: =IF(U13=0,0,U$24/U13) -> 0 | V25: =IF(U25>0,SUMIF($K$2:$K$21,"<="&$U$23,$I$2:I20),IF(T25>0,SUMIF($K$2:$K$21,"<="&$T$23,$I$2:I20),IF(S25>0,SUMIF($K$2:$K$21,"<="&$S$23,$I$2:I20),IF(R25>0,SUMIF($K$2:$K$21,"<="&$R$23,$I$2:I20),IF(Q25>0,SUMIF($K$2:$K$21,"<="&$Q$23,$I$2:I20),IF(P25>0,SUMIF($K$2:$K$21,"<="&$P$23,$I$2:I20),0)))))) -> 0 | W25: =V25/$M$2 -> 0 | X25: =IF(U25>0,U25,IF(T25>0,T25,IF(S25>0,S25,IF(R25>0,R25,IF(Q25>0,Q25,P25))))) -> 0
H26: 1 | I26: 25 | J26: =SUMIF($K$2:$K$21,"<="&H26,$I$2:$I$22)/I26/$M$2 -> 0.1 | O26: 3000 | P26: =IF(P14=0,0,P$24/P14) -> 0 | Q26: =IF(Q14=0,0,Q$24/Q14) -> 0 | R26: =IF(R14=0,0,R$24/R14) -> 0 | S26: =IF(S14=0,0,S$24/S14) -> 0 | T26: =IF(T14=0,0,T$24/T14) -> 0 | U26: =IF(U14=0,0,U$24/U14) -> 0 | V26: =IF(U26>0,SUMIF($K$2:$K$21,"<="&$U$23,$I$2:I21),IF(T26>0,SUMIF($K$2:$K$21,"<="&$T$23,$I$2:I21),IF(S26>0,SUMIF($K$2:$K$21,"<="&$S$23,$I$2:I21),IF(R26>0,SUMIF($K$2:$K$21,"<="&$R$23,$I$2:I21),IF(Q26>0,SUMIF($K$2:$K$21,"<="&$Q$23,$I$2:I21),IF(P26>0,SUMIF($K$2:$K$21,"<="&$P$23,$I$2:I21),0)))))) -> 0 | W26: =V26/$M$2 -> 0 | X26: =IF(U26>0,U26,IF(T26>0,T26,IF(S26>0,S26,IF(R26>0,R26,IF(Q26>0,Q26,P26))))) -> 0
H27: 2 | I27: 50 | J27: =SUMIF($K$2:$K$21,"<="&H27,$I$2:$I$22)/I27/$M$2 -> 0.296 | O27: 10000 | P27: =IF(P15=0,0,P$24/P15) -> 25.641026 | Q27: =IF(Q15=0,0,Q$24/Q15) -> 0 | R27: =IF(R15=0,0,R$24/R15) -> 0 | S27: =IF(S15=0,0,S$24/S15) -> 0 | T27: =IF(T15=0,0,T$24/T15) -> 0 | U27: =IF(U15=0,0,U$24/U15) -> 0 | V27: =IF(U27>0,SUMIF($K$2:$K$21,"<="&$U$23,$I$2:I22),IF(T27>0,SUMIF($K$2:$K$21,"<="&$T$23,$I$2:I22),IF(S27>0,SUMIF($K$2:$K$21,"<="&$S$23,$I$2:I22),IF(R27>0,SUMIF($K$2:$K$21,"<="&$R$23,$I$2:I22),IF(Q27>0,SUMIF($K$2:$K$21,"<="&$Q$23,$I$2:I22),IF(P27>0,SUMIF($K$2:$K$21,"<="&$P$23,$I$2:I22),0)))))) -> 2500000 | W27: =V27/$M$2 -> 2.5 | X27: =IF(U27>0,U27,IF(T27>0,T27,IF(S27>0,S27,IF(R27>0,R27,IF(Q27>0,Q27,P27))))) -> 25.641026
H28: 3 | I28: 50 | J28: =SUMIF($K$2:$K$21,"<="&H28,$I$2:$I$22)/I28/$M$2 -> 0.512 | O28: 20000 | P28: =IF(P16=0,0,P$24/P16) -> 48.076923 | Q28: =IF(Q16=0,0,Q$24/Q16) -> 128.20513 | R28: =IF(R16=0,0,R$24/R16) -> 0 | S28: =IF(S16=0,0,S$24/S16) -> 0 | T28: =IF(T16=0,0,T$24/T16) -> 0 | U28: =IF(U16=0,0,U$24/U16) -> 0 | V28: =IF(U28>0,SUMIF($K$2:$K$21,"<="&$U$23,$I$2:I23),IF(T28>0,SUMIF($K$2:$K$21,"<="&$T$23,$I$2:I23),IF(S28>0,SUMIF($K$2:$K$21,"<="&$S$23,$I$2:I23),IF(R28>0,SUMIF($K$2:$K$21,"<="&$R$23,$I$2:I23),IF(Q28>0,SUMIF($K$2:$K$21,"<="&$Q$23,$I$2:I23),IF(P28>0,SUMIF($K$2:$K$21,"<="&$P$23,$I$2:I23),0)))))) -> 14800000 | W28: =V28/$M$2 -> 14.8 | X28: =IF(U28>0,U28,IF(T28>0,T28,IF(S28>0,S28,IF(R28>0,R28,IF(Q28>0,Q28,P28))))) -> 128.20513
H29: 4 | I29: 50 | J29: =SUMIF($K$2:$K$21,"<="&H29,$I$2:$I$22)/I29/$M$2 -> 1.412 | O29: 50000 | P29: =IF(P17=0,0,P$24/P17) -> 0 | Q29: =IF(Q17=0,0,Q$24/Q17) -> 96.153846 | R29: =IF(R17=0,0,R$24/R17) -> 96.153846 | S29: =IF(S17=0,0,S$24/S17) -> 128.20513 | T29: =IF(T17=0,0,T$24/T17) -> 0 | U29: =IF(U17=0,0,U$24/U17) -> 0 | V29: =IF(U29>0,SUMIF($K$2:$K$21,"<="&$U$23,$I$2:I24),IF(T29>0,SUMIF($K$2:$K$21,"<="&$T$23,$I$2:I24),IF(S29>0,SUMIF($K$2:$K$21,"<="&$S$23,$I$2:I24),IF(R29>0,SUMIF($K$2:$K$21,"<="&$R$23,$I$2:I24),IF(Q29>0,SUMIF($K$2:$K$21,"<="&$Q$23,$I$2:I24),IF(P29>0,SUMIF($K$2:$K$21,"<="&$P$23,$I$2:I24),0)))))) -> 70600000 | W29: =V29/$M$2 -> 70.6 | X29: =IF(U29>0,U29,IF(T29>0,T29,IF(S29>0,S29,IF(R29>0,R29,IF(Q29>0,Q29,P29))))) -> 128.20513
H30: 5 | I30: 50 | J30: =SUMIF($K$2:$K$21,"<="&H30,$I$2:$I$22)/I30/$M$2 -> 3.852 | O30: 100000 | P30: =IF(P18=0,0,P$24/P18) -> 0 | Q30: =IF(Q18=0,0,Q$24/Q18) -> 0 | R30: =IF(R18=0,0,R$24/R18) -> 128.20513 | S30: =IF(S18=0,0,S$24/S18) -> 153.84615 | T30: =IF(T18=0,0,T$24/T18) -> 192.30769 | U30: =IF(U18=0,0,U$24/U18) -> 0 | V30: =IF(U30>0,SUMIF($K$2:$K$21,"<="&$U$23,$I$2:I25),IF(T30>0,SUMIF($K$2:$K$21,"<="&$T$23,$I$2:I25),IF(S30>0,SUMIF($K$2:$K$21,"<="&$S$23,$I$2:I25),IF(R30>0,SUMIF($K$2:$K$21,"<="&$R$23,$I$2:I25),IF(Q30>0,SUMIF($K$2:$K$21,"<="&$Q$23,$I$2:I25),IF(P30>0,SUMIF($K$2:$K$21,"<="&$P$23,$I$2:I25),0)))))) -> 192600000 | W30: =V30/$M$2 -> 192.6 | X30: =IF(U30>0,U30,IF(T30>0,T30,IF(S30>0,S30,IF(R30>0,R30,IF(Q30>0,Q30,P30))))) -> 192.30769
H31: 6 | I31: 40 | J31: =SUMIF($K$2:$K$21,"="&H31,$I$2:$I$22)/I31/$M$2 -> 5.8125 | O31: 200000 | P31: =IF(P19=0,0,P$24/P19) -> 0 | Q31: =IF(Q19=0,0,Q$24/Q19) -> 0 | R31: =IF(R19=0,0,R$24/R19) -> 0 | S31: =IF(S19=0,0,S$24/S19) -> 128.20513 | T31: =IF(T19=0,0,T$24/T19) -> 153.84615 | U31: =IF(U19=0,0,U$24/U19) -> 153.84615 | V31: =IF(U31>0,SUMIF($K$2:$K$21,"<="&$U$23,$I$2:I26),IF(T31>0,SUMIF($K$2:$K$21,"<="&$T$23,$I$2:I26),IF(S31>0,SUMIF($K$2:$K$21,"<="&$S$23,$I$2:I26),IF(R31>0,SUMIF($K$2:$K$21,"<="&$R$23,$I$2:I26),IF(Q31>0,SUMIF($K$2:$K$21,"<="&$Q$23,$I$2:I26),IF(P31>0,SUMIF($K$2:$K$21,"<="&$P$23,$I$2:I26),0)))))) -> 425100000 | W31: =V31/$M$2 -> 425.1 | X31: =IF(U31>0,U31,IF(T31>0,T31,IF(S31>0,S31,IF(R31>0,R31,IF(Q31>0,Q31,P31))))) -> 153.84615
O32: 500000 | P32: =IF(P20=0,0,P$24/P20) -> 0 | Q32: =IF(Q20=0,0,Q$24/Q20) -> 0 | R32: =IF(R20=0,0,R$24/R20) -> 0 | S32: =IF(S20=0,0,S$24/S20) -> 109.89011 | T32: =IF(T20=0,0,T$24/T20) -> 128.20513 | U32: =IF(U20=0,0,U$24/U20) -> 123.07692 | V32: =IF(U32>0,SUMIF($K$2:$K$21,"<="&$U$23,$I$2:I27),IF(T32>0,SUMIF($K$2:$K$21,"<="&$T$23,$I$2:I27),IF(S32>0,SUMIF($K$2:$K$21,"<="&$S$23,$I$2:I27),IF(R32>0,SUMIF($K$2:$K$21,"<="&$R$23,$I$2:I27),IF(Q32>0,SUMIF($K$2:$K$21,"<="&$Q$23,$I$2:I27),IF(P32>0,SUMIF($K$2:$K$21,"<="&$P$23,$I$2:I27),0)))))) -> 425100000 | W32: =V32/$M$2 -> 425.1 | X32: =IF(U32>0,U32,IF(T32>0,T32,IF(S32>0,S32,IF(R32>0,R32,IF(Q32>0,Q32,P32))))) -> 123.07692
O33: 1000000 | P33: =IF(P21=0,0,P$24/P21) -> 0 | Q33: =IF(Q21=0,0,Q$24/Q21) -> 0 | R33: =IF(R21=0,0,R$24/R21) -> 0 | S33: =IF(S21=0,0,S$24/S21) -> 96.153846 | T33: =IF(T21=0,0,T$24/T21) -> 109.89011 | U33: =IF(U21=0,0,U$24/U21) -> 102.5641 | V33: =IF(U33>0,SUMIF($K$2:$K$21,"<="&$U$23,$I$2:I28),IF(T33>0,SUMIF($K$2:$K$21,"<="&$T$23,$I$2:I28),IF(S33>0,SUMIF($K$2:$K$21,"<="&$S$23,$I$2:I28),IF(R33>0,SUMIF($K$2:$K$21,"<="&$R$23,$I$2:I28),IF(Q33>0,SUMIF($K$2:$K$21,"<="&$Q$23,$I$2:I28),IF(P33>0,SUMIF($K$2:$K$21,"<="&$P$23,$I$2:I28),0)))))) -> 425100000 | W33: =V33/$M$2 -> 425.1 | X33: =IF(U33>0,U33,IF(T33>0,T33,IF(S33>0,S33,IF(R33>0,R33,IF(Q33>0,Q33,P33))))) -> 102.5641
M35: 入场花费美金 | Q35: 1000000 | R35: 1250000 | S35: 1500000 | T35: 1750000 | U35: 2000000 | V35: 2250000 | W35: 2500000 | X35: 2500000 | Y35: 2500000 | Z35: 2500000 | AA35: 2500000 | AB35: 2500000 | AC35: 2500000 | AD35: 2500000 | AE35: 2500000 | AF35: 2500000
O36: 底注 | P36: 一局金币 | Q36: 0 | R36: 1 | S36: 2 | T36: 3 | U36: 4 | V36: 5 | W36: 6 | X36: 7 | Y36: 8 | Z36: 9 | AA36: 10 | AB36: 11 | AC36: 12 | AD36: 13 | AE36: 14 | AF36: 15
O37: 1000 | P37: 70000 | Q37: 0.07 | R37: 0.056 | S37: 0.046666667 | T37: 0.04 | U37: 0.035 | V37: 0.031111111 | W37: 0.028 | X37: 0.028 | Y37: 0.028 | Z37: 0.028 | AA37: 0.028 | AB37: 0.028 | AC37: 0.028 | AD37: 0.028 | AE37: 0.028 | AF37: 0.028
O38: 3000 | P38: 210000 | Q38: 0.21 | R38: 0.168 | S38: 0.14 | T38: 0.12 | U38: 0.105 | V38: 0.093333333 | W38: 0.084 | X38: 0.084 | Y38: 0.084 | Z38: 0.084 | AA38: 0.084 | AB38: 0.084 | AC38: 0.084 | AD38: 0.084 | AE38: 0.084 | AF38: 0.084
O39: 10000 | P39: 700000 | Q39: 0.7 | R39: 0.56 | S39: 0.46666667 | T39: 0.4 | U39: 0.35 | V39: 0.31111111 | W39: 0.28 | X39: 0.28 | Y39: 0.28 | Z39: 0.28 | AA39: 0.28 | AB39: 0.28 | AC39: 0.28 | AD39: 0.28 | AE39: 0.28 | AF39: 0.28
O40: 20000 | P40: 1400000 | Q40: 1.4 | R40: 1.12 | S40: 0.93333333 | T40: 0.8 | U40: 0.7 | V40: 0.62222222 | W40: 0.56 | X40: 0.56 | Y40: 0.56 | Z40: 0.56 | AA40: 0.56 | AB40: 0.56 | AC40: 0.56 | AD40: 0.56 | AE40: 0.56 | AF40: 0.56
O41: 50000 | P41: 3500000 | Q41: 3.2741935 | R41: 2.7066667 | S41: 2.2555556 | T41: 1.9333333 | U41: 1.75 | V41: 1.5555556 | W41: 1.4 | X41: 1.4 | Y41: 1.4 | Z41: 1.4 | AA41: 1.4 | AB41: 1.4 | AC41: 1.4 | AD41: 1.4 | AE41: 1.4 | AF41: 1.4
...

Sheet 旧版
A1: 基础金币/美金 | C1: 章节 | D1: 金币 | E1: 美金 | H1: 章节 | I1: 金币 | J1: 美金 | K1: 最大星级 | M1: 基础金币/美金 | O1: 底注 | P1: //筹码下限 | Q1: 一局消耗 | R1: 消耗美金 | S1: //卡包id1 | T1: //概率 | U1: 产出卡包 | V1: //卡包id2 | W1: //概率 | Y1: //卡包id3 | Z1: //概率 | AB1: 单局上限 | AC1: 平均小轮数 | AF1: set/star | AG1: 1 | AH1: 2 | AI1: 3 | AJ1: 4 | AK1: 5 | AL1: 6 | AM1: gold4 | AN1: gold5 | AO1: gold6 | AP1: 合计
A2: 250000 | C2: 1 | D2: 100000 | E2: =D2/$A$2 -> 0.4 | H2: 1 | I2: 100000 | J2: 0.4 | K2: 1 | M2: 250000 | O2: 1000 | P2: =O2*$M$4 -> 100000 | Q2: =O2*$M$4*$M$6 -> 10000 | R2: =Q2/$M$2 -> 0.04 | AB2: 1 | AC2: 14 | AF2: 1 | AG2: 8 | AH2: 0 | AI2: 0 | AJ2: 0 | AK2: 0 | AL2: 0 | AM2: 0 | AN2: 0 | AO2: 0 | AP2: 8
C3: 2 | D3: 150000 | E3: =D3/$A$2 -> 0.6 | H3: 2 | I3: 150000 | J3: 0.6 | K3: 2 | M3: 平均倍率 | O3: 3000 | P3: =O3*$M$4 -> 300000 | Q3: =O3*$M$4*$M$6 -> 30000 | R3: =Q3/$M$2 -> 0.12 | AB3: 1 | AC3: =AC2 -> 14 | AF3: 2 | AG3: 7 | AH3: 1 | AI3: 0 | AJ3: 0 | AK3: 0 | AL3: 0 | AM3: 0 | AN3: 0 | AO3: 0 | AP3: 8
C4: 3 | D4: 300000 | E4: =D4/$A$2 -> 1.2 | H4: 3 | I4: 300000 | J4: 1.2 | K4: 2 | M4: 100 | O4: 10000 | P4: =O4*$M$4 -> 1000000 | Q4: =O4*$M$4*$M$6 -> 100000 | R4: =Q4/$M$2 -> 0.4 | S4: 1 | T4: 750 | U4: =T4*$AC4/10000 -> 1.05 | AB4: 1 | AC4: =AC3 -> 14 | AD4: =SUM(T4+W4+Z4) -> 750 | AF4: 3 | AG4: 6 | AH4: 2 | AI4: 0 | AJ4: 0 | AK4: 0 | AL4: 0 | AM4: 0 | AN4: 0 | AO4: 0 | AP4: 8
C5: 4 | D5: 500000 | E5: =D5/$A$2 -> 2 | H5: 4 | I5: 500000 | J5: 2 | K5: 2 | M5: 抽水 | O5: 20000 | P5: =O5*$M$4 -> 2000000 | Q5: =O5*$M$4*$M$6 -> 200000 | R5: =Q5/$M$2 -> 0.8 | S5: 1 | T5: 400 | U5: =T5*$AC5/10000 -> 0.56 | V5: 2 | W5: 300 | X5: =W5*$AC5/10000 -> 0.42 | AB5: 1 | AC5: =AC4 -> 14 | AD5: =SUM(T5+W5+Z5) -> 700 | AF5: 4 | AG5: 4 | AH5: 4 | AI5: 0 | AJ5: 0 | AK5: 0 | AL5: 0 | AM5: 0 | AN5: 0 | AO5: 0 | AP5: 8
C6: 5 | D6: 1000000 | E6: =D6/$A$2 -> 4 | H6: 5 | I6: 1000000 | J6: 4 | K6: 2 | M6: 0.1 | O6: 50000 | P6: =O6*$M$4 -> 5000000 | Q6: =O6*$M$4*$M$6 -> 500000 | R6: =Q6/$M$2 -> 2 | S6: 2 | T6: 400 | U6: =T6*$AC6/10000 -> 0.56 | V6: 3 | W6: 400 | X6: =W6*$AC6/10000 -> 0.56 | Y6: 4 | Z6: 300 | AA6: =Z6*$AC6/10000 -> 0.42 | AB6: 1 | AC6: =AC5 -> 14 | AD6: =SUM(T6+W6+Z6) -> 1100 | AF6: 5 | AG6: 3 | AH6: 5 | AI6: 0 | AJ6: 0 | AK6: 0 | AL6: 0 | AM6: 0 | AN6: 0 | AO6: 0 | AP6: 8
C7: 6 | D7: 1200000 | E7: =D7/$A$2 -> 4.8 | H7: 6 | I7: 1200000 | J7: 4.8 | K7: 3 | O7: 100000 | P7: =O7*$M$4 -> 10000000 | Q7: =O7*$M$4*$M$6 -> 1000000 | R7: =Q7/$M$2 -> 4 | S7: 3 | T7: 300 | U7: =T7*$AC7/10000 -> 0.42 | V7: 4 | W7: 250 | X7: =W7*$AC7/10000 -> 0.35 | Y7: 5 | Z7: 200 | AA7: =Z7*$AC7/10000 -> 0.28 | AB7: 1 | AC7: =AC6 -> 14 | AD7: =SUM(T7+W7+Z7) -> 750 | AF7: 6 | AG7: 2 | AH7: 5 | AI7: 1 | AJ7: 0 | AK7: 0 | AL7: 0 | AM7: 0 | AN7: 0 | AO7: 0 | AP7: 8
C8: 7 | D8: 1500000 | E8: =D8/$A$2 -> 6 | H8: 7 | I8: 1500000 | J8: 6 | K8: 3 | O8: 200000 | P8: =O8*$M$4 -> 20000000 | Q8: =O8*$M$4*$M$6 -> 2000000 | R8: =Q8/$M$2 -> 8 | S8: 4 | T8: 300 | U8: =T8*$AC8/10000 -> 0.42 | V8: 5 | W8: 250 | X8: =W8*$AC8/10000 -> 0.35 | Y8: 6 | Z8: 200 | AA8: =Z8*$AC8/10000 -> 0.28 | AB8: 2 | AC8: =AC7 -> 14 | AD8: =SUM(T8+W8+Z8) -> 750 | AF8: 7 | AG8: 1 | AH8: 4 | AI8: 3 | AJ8: 0 | AK8: 0 | AL8: 0 | AM8: 0 | AN8: 0 | AO8: 0 | AP8: 8
C9: 8 | D9: 1800000 | E9: =D9/$A$2 -> 7.2 | H9: 8 | I9: 1800000 | J9: 7.2 | K9: 3 | O9: 500000 | P9: =O9*$M$4 -> 50000000 | Q9: =O9*$M$4*$M$6 -> 5000000 | R9: =Q9/$M$2 -> 20 | S9: 4 | T9: 350 | U9: =T9*$AC9/10000 -> 0.49 | V9: 5 | W9: 300 | X9: =W9*$AC9/10000 -> 0.42 | Y9: 6 | Z9: 250 | AA9: =Z9*$AC9/10000 -> 0.35 | AB9: 3 | AC9: =AC8 -> 14 | AD9: =SUM(T9+W9+Z9) -> 900 | AF9: 8 | AG9: 0 | AH9: 4 | AI9: 4 | AJ9: 0 | AK9: 0 | AL9: 0 | AM9: 0 | AN9: 0 | AO9: 0 | AP9: 8
C10: 9 | D10: 2000000 | E10: =D10/$A$2 -> 8 | H10: 9 | I10: 2000000 | J10: 8 | K10: 4 | O10: 1000000 | P10: =O10*$M$4 -> 100000000 | Q10: =O10*$M$4*$M$6 -> 10000000 | R10: =Q10/$M$2 -> 40 | S10: 4 | T10: 400 | U10: =T10*$AC10/10000 -> 0.56 | V10: 5 | W10: 350 | X10: =W10*$AC10/10000 -> 0.49 | Y10: 6 | Z10: 300 | AA10: =Z10*$AC10/10000 -> 0.42 | AB10: 4 | AC10: =AC9 -> 14 | AD10: =SUM(T10+W10+Z10) -> 1050 | AF10: 9 | AG10: 0 | AH10: 3 | AI10: 4 | AJ10: 1 | AK10: 0 | AL10: 0 | AM10: 0 | AN10: 0 | AO10: 0 | AP10: 8
C11: 10 | D11: 2500000 | E11: =D11/$A$2 -> 10 | H11: 10 | I11: 2500000 | J11: 10 | K11: 4 | AF11: 10 | AG11: 0 | AH11: 3 | AI11: 3 | AJ11: 2 | AK11: 0 | AL11: 0 | AM11: 0 | AN11: 0 | AO11: 0 | AP11: 8
C12: 11 | D12: 3000000 | E12: =D12/$A$2 -> 12 | H12: 11 | I12: 3000000 | J12: 12 | K12: 5 | M12: 单局产出卡包 | O12: 卡包数量 | P12: 1 | Q12: 2 | R12: 3 | S12: 4 | T12: 5 | U12: 6 | AF12: 11 | AG12: 0 | AH12: 1 | AI12: 4 | AJ12: 2 | AK12: 0 | AL12: 0 | AM12: 1 | AN12: 0 | AO12: 0 | AP12: 8
C13: 12 | D13: 3500000 | E13: =D13/$A$2 -> 14 | H13: 12 | I13: 3500000 | J13: 14 | K13: 5 | O13: 1000 | P13: =IF($S2=P$12,$U2,0)+IF($V2=P$12,$X2,0)+IF($Y2=P$12,$AA2,0) -> 0 | Q13: =IF($S2=Q$12,$U2,0)+IF($V2=Q$12,$X2,0)+IF($Y2=Q$12,$AA2,0) -> 0 | R13: =IF($S2=R$12,$U2,0)+IF($V2=R$12,$X2,0)+IF($Y2=R$12,$AA2,0) -> 0 | S13: =IF($S2=S$12,$U2,0)+IF($V2=S$12,$X2,0)+IF($Y2=S$12,$AA2,0) -> 0 | T13: =IF($S2=T$12,$U2,0)+IF($V2=T$12,$X2,0)+IF($Y2=T$12,$AA2,0) -> 0 | U13: =IF($S2=U$12,$U2,0)+IF($V2=U$12,$X2,0)+IF($Y2=U$12,$AA2,0) -> 0 | AF13: 12 | AG13: 0 | AH13: 1 | AI13: 3 | AJ13: 2 | AK13: 1 | AL13: 0 | AM13: 1 | AN13: 0 | AO13: 0 | AP13: 8
C14: 13 | D14: 5000000 | E14: =D14/$A$2 -> 20 | H14: 13 | I14: 5000000 | J14: 20 | K14: 5 | O14: 3000 | P14: =IF($S3=P$12,$U3,0)+IF($V3=P$12,$X3,0)+IF($Y3=P$12,$AA3,0) -> 0 | Q14: =IF($S3=Q$12,$U3,0)+IF($V3=Q$12,$X3,0)+IF($Y3=Q$12,$AA3,0) -> 0 | R14: =IF($S3=R$12,$U3,0)+IF($V3=R$12,$X3,0)+IF($Y3=R$12,$AA3,0) -> 0 | S14: =IF($S3=S$12,$U3,0)+IF($V3=S$12,$X3,0)+IF($Y3=S$12,$AA3,0) -> 0 | T14: =IF($S3=T$12,$U3,0)+IF($V3=T$12,$X3,0)+IF($Y3=T$12,$AA3,0) -> 0 | U14: =IF($S3=U$12,$U3,0)+IF($V3=U$12,$X3,0)+IF($Y3=U$12,$AA3,0) -> 0 | AF14: 13 | AG14: 0 | AH14: 1 | AI14: 2 | AJ14: 2 | AK14: 1 | AL14: 0 | AM14: 1 | AN14: 1 | AO14: 0 | AP14: 8
C15: 14 | D15: 7500000 | E15: =D15/$A$2 -> 30 | H15: 14 | I15: 7500000 | J15: 30 | K15: 5 | O15: 10000 | P15: =IF($S4=P$12,$U4,0)+IF($V4=P$12,$X4,0)+IF($Y4=P$12,$AA4,0) -> 1.05 | Q15: =IF($S4=Q$12,$U4,0)+IF($V4=Q$12,$X4,0)+IF($Y4=Q$12,$AA4,0) -> 0 | R15: =IF($S4=R$12,$U4,0)+IF($V4=R$12,$X4,0)+IF($Y4=R$12,$AA4,0) -> 0 | S15: =IF($S4=S$12,$U4,0)+IF($V4=S$12,$X4,0)+IF($Y4=S$12,$AA4,0) -> 0 | T15: =IF($S4=T$12,$U4,0)+IF($V4=T$12,$X4,0)+IF($Y4=T$12,$AA4,0) -> 0 | U15: =IF($S4=U$12,$U4,0)+IF($V4=U$12,$X4,0)+IF($Y4=U$12,$AA4,0) -> 0 | AF15: 14 | AG15: 0 | AH15: 0 | AI15: 2 | AJ15: 2 | AK15: 1 | AL15: 1 | AM15: 1 | AN15: 1 | AO15: 0 | AP15: 8
C16: 15 | D16: 10000000 | E16: =D16/$A$2 -> 40 | H16: 15 | I16: 10000000 | J16: 40 | K16: 6 | O16: 20000 | P16: =IF($S5=P$12,$U5,0)+IF($V5=P$12,$X5,0)+IF($Y5=P$12,$AA5,0) -> 0.56 | Q16: =IF($S5=Q$12,$U5,0)+IF($V5=Q$12,$X5,0)+IF($Y5=Q$12,$AA5,0) -> 0.42 | R16: =IF($S5=R$12,$U5,0)+IF($V5=R$12,$X5,0)+IF($Y5=R$12,$AA5,0) -> 0 | S16: =IF($S5=S$12,$U5,0)+IF($V5=S$12,$X5,0)+IF($Y5=S$12,$AA5,0) -> 0 | T16: =IF($S5=T$12,$U5,0)+IF($V5=T$12,$X5,0)+IF($Y5=T$12,$AA5,0) -> 0 | U16: =IF($S5=U$12,$U5,0)+IF($V5=U$12,$X5,0)+IF($Y5=U$12,$AA5,0) -> 0 | AF16: 15 | AG16: 0 | AH16: 0 | AI16: 1 | AJ16: 3 | AK16: 1 | AL16: 1 | AM16: 1 | AN16: 1 | AO16: 0 | AP16: 8
C17: 16 | D17: 12500000 | E17: =D17/$A$2 -> 50 | H17: 16 | I17: 12500000 | J17: 50 | K17: 6 | O17: 50000 | P17: =IF($S6=P$12,$U6,0)+IF($V6=P$12,$X6,0)+IF($Y6=P$12,$AA6,0) -> 0 | Q17: =IF($S6=Q$12,$U6,0)+IF($V6=Q$12,$X6,0)+IF($Y6=Q$12,$AA6,0) -> 0.56 | R17: =IF($S6=R$12,$U6,0)+IF($V6=R$12,$X6,0)+IF($Y6=R$12,$AA6,0) -> 0.56 | S17: =IF($S6=S$12,$U6,0)+IF($V6=S$12,$X6,0)+IF($Y6=S$12,$AA6,0) -> 0.42 | T17: =IF($S6=T$12,$U6,0)+IF($V6=T$12,$X6,0)+IF($Y6=T$12,$AA6,0) -> 0 | U17: =IF($S6=U$12,$U6,0)+IF($V6=U$12,$X6,0)+IF($Y6=U$12,$AA6,0) -> 0 | AF17: 16 | AG17: 0 | AH17: 0 | AI17: 1 | AJ17: 2 | AK17: 1 | AL17: 1 | AM17: 2 | AN17: 1 | AO17: 0 | AP17: 8
C18: 17 | D18: 15000000 | E18: =D18/$A$2 -> 60 | H18: 17 | I18: 15000000 | J18: 60 | K18: 6 | O18: 100000 | P18: =IF($S7=P$12,$U7,0)+IF($V7=P$12,$X7,0)+IF($Y7=P$12,$AA7,0) -> 0 | Q18: =IF($S7=Q$12,$U7,0)+IF($V7=Q$12,$X7,0)+IF($Y7=Q$12,$AA7,0) -> 0 | R18: =IF($S7=R$12,$U7,0)+IF($V7=R$12,$X7,0)+IF($Y7=R$12,$AA7,0) -> 0.42 | S18: =IF($S7=S$12,$U7,0)+IF($V7=S$12,$X7,0)+IF($Y7=S$12,$AA7,0) -> 0.35 | T18: =IF($S7=T$12,$U7,0)+IF($V7=T$12,$X7,0)+IF($Y7=T$12,$AA7,0) -> 0.28 | U18: =IF($S7=U$12,$U7,0)+IF($V7=U$12,$X7,0)+IF($Y7=U$12,$AA7,0) -> 0 | AF18: 17 | AG18: 0 | AH18: 0 | AI18: 1 | AJ18: 1 | AK18: 2 | AL18: 1 | AM18: 2 | AN18: 1 | AO18: 0 | AP18: 8
C19: 18 | D19: 17500000 | E19: =D19/$A$2 -> 70 | H19: 18 | I19: 17500000 | J19: 70 | K19: 6 | O19: 200000 | P19: =IF($S8=P$12,$U8,0)+IF($V8=P$12,$X8,0)+IF($Y8=P$12,$AA8,0) -> 0 | Q19: =IF($S8=Q$12,$U8,0)+IF($V8=Q$12,$X8,0)+IF($Y8=Q$12,$AA8,0) -> 0 | R19: =IF($S8=R$12,$U8,0)+IF($V8=R$12,$X8,0)+IF($Y8=R$12,$AA8,0) -> 0 | S19: =IF($S8=S$12,$U8,0)+IF($V8=S$12,$X8,0)+IF($Y8=S$12,$AA8,0) -> 0.42 | T19: =IF($S8=T$12,$U8,0)+IF($V8=T$12,$X8,0)+IF($Y8=T$12,$AA8,0) -> 0.35 | U19: =IF($S8=U$12,$U8,0)+IF($V8=U$12,$X8,0)+IF($Y8=U$12,$AA8,0) -> 0.28 | AF19: 18 | AG19: 0 | AH19: 0 | AI19: 1 | AJ19: 1 | AK19: 2 | AL19: 0 | AM19: 1 | AN19: 2 | AO19: 1 | AP19: 8
C20: 19 | D20: 20000000 | E20: =D20/$A$2 -> 80 | H20: 19 | I20: 20000000 | J20: 80 | K20: 6 | O20: 500000 | P20: =IF($S9=P$12,$U9,0)+IF($V9=P$12,$X9,0)+IF($Y9=P$12,$AA9,0) -> 0 | Q20: =IF($S9=Q$12,$U9,0)+IF($V9=Q$12,$X9,0)+IF($Y9=Q$12,$AA9,0) -> 0 | R20: =IF($S9=R$12,$U9,0)+IF($V9=R$12,$X9,0)+IF($Y9=R$12,$AA9,0) -> 0 | S20: =IF($S9=S$12,$U9,0)+IF($V9=S$12,$X9,0)+IF($Y9=S$12,$AA9,0) -> 0.49 | T20: =IF($S9=T$12,$U9,0)+IF($V9=T$12,$X9,0)+IF($Y9=T$12,$AA9,0) -> 0.42 | U20: =IF($S9=U$12,$U9,0)+IF($V9=U$12,$X9,0)+IF($Y9=U$12,$AA9,0) -> 0.35 | AF20: 19 | AG20: 0 | AH20: 0 | AI20: 0 | AJ20: 1 | AK20: 2 | AL20: 0 | AM20: 2 | AN20: 2 | AO20: 1 | AP20: 8
C21: all | D21: 35000000 | E21: =D21/$A$2 -> 140 | H21: all | I21: 35000000 | J21: 140 | K21: 6 | O21: 1000000 | P21: =IF($S10=P$12,$U10,0)+IF($V10=P$12,$X10,0)+IF($Y10=P$12,$AA10,0) -> 0 | Q21: =IF($S10=Q$12,$U10,0)+IF($V10=Q$12,$X10,0)+IF($Y10=Q$12,$AA10,0) -> 0 | R21: =IF($S10=R$12,$U10,0)+IF($V10=R$12,$X10,0)+IF($Y10=R$12,$AA10,0) -> 0 | S21: =IF($S10=S$12,$U10,0)+IF($V10=S$12,$X10,0)+IF($Y10=S$12,$AA10,0) -> 0.56 | T21: =IF($S10=T$12,$U10,0)+IF($V10=T$12,$X10,0)+IF($Y10=T$12,$AA10,0) -> 0.49 | U21: =IF($S10=U$12,$U10,0)+IF($V10=U$12,$X10,0)+IF($Y10=U$12,$AA10,0) -> 0.42 | AF21: 合计 | AG21: 31 | AH21: 34 | AI21: 30 | AJ21: 19 | AK21: 11 | AL21: 4 | AM21: 12 | AN21: 9 | AO21: 2 | AP21: 152
C22: 基础 | D22: =SUM(D2:D21) -> 140050000 | E22: =SUM(E2:E21) -> 560.2 | H22: 基础 | I22: 140050000 | J22: 560.2
M23: 需要牌局数 | O23: 星级 | P23: 1 | Q23: 2 | R23: 3 | S23: 4 | T23: 5 | U23: 6
O24: 需要开卡次数 | P24: 25 | Q24: 50 | R24: 50 | S24: 50 | T24: 50 | U24: 40 | V24: 集满奖励 | W24: 集满美金 | X24: 最低牌局数
H25: 卡包 | I25: 需要开卡次数 | J25: 卡包价值 | O25: 1000 | P25: =IF(P13=0,0,P$24/P13) -> 0 | Q25: =IF(Q13=0,0,Q$24/Q13) -> 0 | R25: =IF(R13=0,0,R$24/R13) -> 0 | S25: =IF(S13=0,0,S$24/S13) -> 0 | T25: =IF(T13=0,0,T$24/T13) -> 0 | U25: =IF(U13=0,0,U$24/U13) -> 0 | V25: =IF(U25>0,SUMIF($K$2:$K$21,"<="&$U$23,$I$2:I20),IF(T25>0,SUMIF($K$2:$K$21,"<="&$T$23,$I$2:I20),IF(S25>0,SUMIF($K$2:$K$21,"<="&$S$23,$I$2:I20),IF(R25>0,SUMIF($K$2:$K$21,"<="&$R$23,$I$2:I20),IF(Q25>0,SUMIF($K$2:$K$21,"<="&$Q$23,$I$2:I20),IF(P25>0,SUMIF($K$2:$K$21,"<="&$P$23,$I$2:I20),0)))))) -> 0 | W25: =V25/$M$2 -> 0 | X25: =IF(U25>0,U25,IF(T25>0,T25,IF(S25>0,S25,IF(R25>0,R25,IF(Q25>0,Q25,P25))))) -> 0
H26: 1 | I26: 25 | J26: =SUMIF($K$2:$K$21,"<="&H26,$I$2:$I$22)/I26/$M$2 -> 0.016 | O26: 3000 | P26: =IF(P14=0,0,P$24/P14) -> 0 | Q26: =IF(Q14=0,0,Q$24/Q14) -> 0 | R26: =IF(R14=0,0,R$24/R14) -> 0 | S26: =IF(S14=0,0,S$24/S14) -> 0 | T26: =IF(T14=0,0,T$24/T14) -> 0 | U26: =IF(U14=0,0,U$24/U14) -> 0 | V26: =IF(U26>0,SUMIF($K$2:$K$21,"<="&$U$23,$I$2:I21),IF(T26>0,SUMIF($K$2:$K$21,"<="&$T$23,$I$2:I21),IF(S26>0,SUMIF($K$2:$K$21,"<="&$S$23,$I$2:I21),IF(R26>0,SUMIF($K$2:$K$21,"<="&$R$23,$I$2:I21),IF(Q26>0,SUMIF($K$2:$K$21,"<="&$Q$23,$I$2:I21),IF(P26>0,SUMIF($K$2:$K$21,"<="&$P$23,$I$2:I21),0)))))) -> 0 | W26: =V26/$M$2 -> 0 | X26: =IF(U26>0,U26,IF(T26>0,T26,IF(S26>0,S26,IF(R26>0,R26,IF(Q26>0,Q26,P26))))) -> 0
H27: 2 | I27: 50 | J27: =SUMIF($K$2:$K$21,"<="&H27,$I$2:$I$22)/I27/$M$2 -> 0.164 | O27: 10000 | P27: =IF(P15=0,0,P$24/P15) -> 23.809524 | Q27: =IF(Q15=0,0,Q$24/Q15) -> 0 | R27: =IF(R15=0,0,R$24/R15) -> 0 | S27: =IF(S15=0,0,S$24/S15) -> 0 | T27: =IF(T15=0,0,T$24/T15) -> 0 | U27: =IF(U15=0,0,U$24/U15) -> 0 | V27: =IF(U27>0,SUMIF($K$2:$K$21,"<="&$U$23,$I$2:$I$21),IF(T27>0,SUMIF($K$2:$K$21,"<="&$T$23,$I$2:$I$21),IF(S27>0,SUMIF($K$2:$K$21,"<="&$S$23,$I$2:$I$21),IF(R27>0,SUMIF($K$2:$K$21,"<="&$R$23,$I$2:$I$21),IF(Q27>0,SUMIF($K$2:$K$21,"<="&$Q$23,$I$2:$I$21),IF(P27>0,SUMIF($K$2:$K$21,"<="&$P$23,$I$2:$I$21),0)))))) -> 100000 | W27: =V27/$M$2 -> 0.4 | X27: =IF(U27>0,U27,IF(T27>0,T27,IF(S27>0,S27,IF(R27>0,R27,IF(Q27>0,Q27,P27))))) -> 23.809524
H28: 3 | I28: 50 | J28: =SUMIF($K$2:$K$21,"<="&H28,$I$2:$I$22)/I28/$M$2 -> 0.524 | O28: 20000 | P28: =IF(P16=0,0,P$24/P16) -> 44.642857 | Q28: =IF(Q16=0,0,Q$24/Q16) -> 119.04762 | R28: =IF(R16=0,0,R$24/R16) -> 0 | S28: =IF(S16=0,0,S$24/S16) -> 0 | T28: =IF(T16=0,0,T$24/T16) -> 0 | U28: =IF(U16=0,0,U$24/U16) -> 0 | V28: =IF(U28>0,SUMIF($K$2:$K$21,"<="&$U$23,$I$2:$I$21),IF(T28>0,SUMIF($K$2:$K$21,"<="&$T$23,$I$2:$I$21),IF(S28>0,SUMIF($K$2:$K$21,"<="&$S$23,$I$2:$I$21),IF(R28>0,SUMIF($K$2:$K$21,"<="&$R$23,$I$2:$I$21),IF(Q28>0,SUMIF($K$2:$K$21,"<="&$Q$23,$I$2:$I$21),IF(P28>0,SUMIF($K$2:$K$21,"<="&$P$23,$I$2:$I$21),0)))))) -> 2050000 | W28: =V28/$M$2 -> 8.2 | X28: =IF(U28>0,U28,IF(T28>0,T28,IF(S28>0,S28,IF(R28>0,R28,IF(Q28>0,Q28,P28))))) -> 119.04762
H29: 4 | I29: 50 | J29: =SUMIF($K$2:$K$21,"<="&H29,$I$2:$I$22)/I29/$M$2 -> 0.884 | O29: 50000 | P29: =IF(P17=0,0,P$24/P17) -> 0 | Q29: =IF(Q17=0,0,Q$24/Q17) -> 89.285714 | R29: =IF(R17=0,0,R$24/R17) -> 89.285714 | S29: =IF(S17=0,0,S$24/S17) -> 119.04762 | T29: =IF(T17=0,0,T$24/T17) -> 0 | U29: =IF(U17=0,0,U$24/U17) -> 0 | V29: =IF(U29>0,SUMIF($K$2:$K$21,"<="&$U$23,$I$2:$I$21),IF(T29>0,SUMIF($K$2:$K$21,"<="&$T$23,$I$2:$I$21),IF(S29>0,SUMIF($K$2:$K$21,"<="&$S$23,$I$2:$I$21),IF(R29>0,SUMIF($K$2:$K$21,"<="&$R$23,$I$2:$I$21),IF(Q29>0,SUMIF($K$2:$K$21,"<="&$Q$23,$I$2:$I$21),IF(P29>0,SUMIF($K$2:$K$21,"<="&$P$23,$I$2:$I$21),0)))))) -> 11050000 | W29: =V29/$M$2 -> 44.2 | X29: =IF(U29>0,U29,IF(T29>0,T29,IF(S29>0,S29,IF(R29>0,R29,IF(Q29>0,Q29,P29))))) -> 119.04762
H30: 5 | I30: 50 | J30: =SUMIF($K$2:$K$21,"<="&H30,$I$2:$I$22)/I30/$M$2 -> 2.404 | O30: 100000 | P30: =IF(P18=0,0,P$24/P18) -> 0 | Q30: =IF(Q18=0,0,Q$24/Q18) -> 0 | R30: =IF(R18=0,0,R$24/R18) -> 119.04762 | S30: =IF(S18=0,0,S$24/S18) -> 142.85714 | T30: =IF(T18=0,0,T$24/T18) -> 178.57143 | U30: =IF(U18=0,0,U$24/U18) -> 0 | V30: =IF(U30>0,SUMIF($K$2:$K$21,"<="&$U$23,$I$2:$I$21),IF(T30>0,SUMIF($K$2:$K$21,"<="&$T$23,$I$2:$I$21),IF(S30>0,SUMIF($K$2:$K$21,"<="&$S$23,$I$2:$I$21),IF(R30>0,SUMIF($K$2:$K$21,"<="&$R$23,$I$2:$I$21),IF(Q30>0,SUMIF($K$2:$K$21,"<="&$Q$23,$I$2:$I$21),IF(P30>0,SUMIF($K$2:$K$21,"<="&$P$23,$I$2:$I$21),0)))))) -> 30050000 | W30: =V30/$M$2 -> 120.2 | X30: =IF(U30>0,U30,IF(T30>0,T30,IF(S30>0,S30,IF(R30>0,R30,IF(Q30>0,Q30,P30))))) -> 178.57143
H31: 6 | I31: 40 | J31: =SUMIF($K$2:$K$21,"="&H31,$I$2:$I$22)/I31/$M$2 -> 11 | O31: 200000 | P31: =IF(P19=0,0,P$24/P19) -> 0 | Q31: =IF(Q19=0,0,Q$24/Q19) -> 0 | R31: =IF(R19=0,0,R$24/R19) -> 0 | S31: =IF(S19=0,0,S$24/S19) -> 119.04762 | T31: =IF(T19=0,0,T$24/T19) -> 142.85714 | U31: =IF(U19=0,0,U$24/U19) -> 142.85714 | V31: =IF(U31>0,SUMIF($K$2:$K$21,"<="&$U$23,$I$2:$I$21),IF(T31>0,SUMIF($K$2:$K$21,"<="&$T$23,$I$2:$I$21),IF(S31>0,SUMIF($K$2:$K$21,"<="&$S$23,$I$2:$I$21),IF(R31>0,SUMIF($K$2:$K$21,"<="&$R$23,$I$2:$I$21),IF(Q31>0,SUMIF($K$2:$K$21,"<="&$Q$23,$I$2:$I$21),IF(P31>0,SUMIF($K$2:$K$21,"<="&$P$23,$I$2:$I$21),0)))))) -> 140050000 | W31: =V31/$M$2 -> 560.2 | X31: =IF(U31>0,U31,IF(T31>0,T31,IF(S31>0,S31,IF(R31>0,R31,IF(Q31>0,Q31,P31))))) -> 142.85714
O32: 500000 | P32: =IF(P20=0,0,P$24/P20) -> 0 | Q32: =IF(Q20=0,0,Q$24/Q20) -> 0 | R32: =IF(R20=0,0,R$24/R20) -> 0 | S32: =IF(S20=0,0,S$24/S20) -> 102.04082 | T32: =IF(T20=0,0,T$24/T20) -> 119.04762 | U32: =IF(U20=0,0,U$24/U20) -> 114.28571 | V32: =IF(U32>0,SUMIF($K$2:$K$21,"<="&$U$23,$I$2:$I$21),IF(T32>0,SUMIF($K$2:$K$21,"<="&$T$23,$I$2:$I$21),IF(S32>0,SUMIF($K$2:$K$21,"<="&$S$23,$I$2:$I$21),IF(R32>0,SUMIF($K$2:$K$21,"<="&$R$23,$I$2:$I$21),IF(Q32>0,SUMIF($K$2:$K$21,"<="&$Q$23,$I$2:$I$21),IF(P32>0,SUMIF($K$2:$K$21,"<="&$P$23,$I$2:$I$21),0)))))) -> 140050000 | W32: =V32/$M$2 -> 560.2 | X32: =IF(U32>0,U32,IF(T32>0,T32,IF(S32>0,S32,IF(R32>0,R32,IF(Q32>0,Q32,P32))))) -> 114.28571
O33: 1000000 | P33: =IF(P21=0,0,P$24/P21) -> 0 | Q33: =IF(Q21=0,0,Q$24/Q21) -> 0 | R33: =IF(R21=0,0,R$24/R21) -> 0 | S33: =IF(S21=0,0,S$24/S21) -> 89.285714 | T33: =IF(T21=0,0,T$24/T21) -> 102.04082 | U33: =IF(U21=0,0,U$24/U21) -> 95.238095 | V33: =IF(U33>0,SUMIF($K$2:$K$21,"<="&$U$23,$I$2:$I$21),IF(T33>0,SUMIF($K$2:$K$21,"<="&$T$23,$I$2:$I$21),IF(S33>0,SUMIF($K$2:$K$21,"<="&$S$23,$I$2:$I$21),IF(R33>0,SUMIF($K$2:$K$21,"<="&$R$23,$I$2:$I$21),IF(Q33>0,SUMIF($K$2:$K$21,"<="&$Q$23,$I$2:$I$21),IF(P33>0,SUMIF($K$2:$K$21,"<="&$P$23,$I$2:$I$21),0)))))) -> 140050000 | W33: =V33/$M$2 -> 560.2 | X33: =IF(U33>0,U33,IF(T33>0,T33,IF(S33>0,S33,IF(R33>0,R33,IF(Q33>0,Q33,P33))))) -> 95.238095
M35: 入场花费美金 | Q35: 250000 | R35: 375000 | S35: 500000 | T35: 600000 | U35: 675000 | V35: 750000 | W35: 800000 | X35: 850000 | Y35: 900000 | Z35: 950000 | AA35: 1000000 | AB35: 1050000 | AC35: 1100000 | AD35: 1150000 | AE35: 1200000 | AF35: 1250000
O36: 底注 | P36: 一局金币 | Q36: 0 | R36: 1 | S36: 2 | T36: 3 | U36: 4 | V36: 5 | W36: 6 | X36: 7 | Y36: 8 | Z36: 9 | AA36: 10 | AB36: 11 | AC36: 12 | AD36: 13 | AE36: 14 | AF36: 15
O37: 1000 | P37: =Q2 -> 10000 | Q37: 0.07 | R37: 0.056 | S37: 0.046666667 | T37: 0.04 | U37: 0.035 | V37: 0.031111111 | W37: 0.028 | X37: 0.028 | Y37: 0.028 | Z37: 0.028 | AA37: 0.028 | AB37: 0.028 | AC37: 0.028 | AD37: 0.028 | AE37: 0.028 | AF37: 0.028
O38: 3000 | P38: =Q3 -> 30000 | Q38: 0.21 | R38: 0.168 | S38: 0.14 | T38: 0.12 | U38: 0.105 | V38: 0.093333333 | W38: 0.084 | X38: 0.084 | Y38: 0.084 | Z38: 0.084 | AA38: 0.084 | AB38: 0.084 | AC38: 0.084 | AD38: 0.084 | AE38: 0.084 | AF38: 0.084
O39: 10000 | P39: =Q4 -> 100000 | Q39: 0.7 | R39: 0.56 | S39: 0.46666667 | T39: 0.4 | U39: 0.35 | V39: 0.31111111 | W39: 0.28 | X39: 0.28 | Y39: 0.28 | Z39: 0.28 | AA39: 0.28 | AB39: 0.28 | AC39: 0.28 | AD39: 0.28 | AE39: 0.28 | AF39: 0.28
O40: 20000 | P40: =Q5 -> 200000 | Q40: 1.4 | R40: 1.12 | S40: 0.93333333 | T40: 0.8 | U40: 0.7 | V40: 0.62222222 | W40: 0.56 | X40: 0.56 | Y40: 0.56 | Z40: 0.56 | AA40: 0.56 | AB40: 0.56 | AC40: 0.56 | AD40: 0.56 | AE40: 0.56 | AF40: 0.56
O41: 50000 | P41: =Q6 -> 500000 | Q41: 3.2741935 | R41: 2.7066667 | S41: 2.2555556 | T41: 1.9333333 | U41: 1.75 | V41: 1.5555556 | W41: 1.4 | X41: 1.4 | Y41: 1.4 | Z41: 1.4 | AA41: 1.4 | AB41: 1.4 | AC41: 1.4 | AD41: 1.4 | AE41: 1.4 | AF41: 1.4
...

Sheet 膨胀后新版
A1: 章节 | B1: 金币 | C1: 美金 | D1: 最大星级 | F1: 基础金币/美金 | H1: 底注 | I1: //筹码下限 | J1: 一局消耗 | K1: 消耗美金 | L1: //卡包id1 | M1: //概率 | N1: 产出卡包 | O1: //卡包id2 | P1: //概率 | R1: //卡包id3 | S1: //概率 | U1: 单局上限 | V1: 平均小轮数 | Y1: set/star | Z1: 1 | AA1: 2 | AB1: 3 | AC1: 4 | AD1: 5 | AE1: 6 | AF1: gold4 | AG1: gold5 | AH1: gold6 | AI1: 合计
A2: 1 | B2: =C2*$F$2 -> 2500000 | C2: 2.5 | D2: 1 | F2: 1000000 | H2: 1000 | I2: 5000 | J2: =H2*$F$4*$F$6 -> 7000 | K2: =J2/$F$2 -> 0.007 | U2: 1 | V2: 13 | Y2: 1 | Z2: 8 | AA2: 0 | AB2: 0 | AC2: 0 | AD2: 0 | AE2: 0 | AF2: 0 | AG2: 0 | AH2: 0 | AI2: 8 | AJ2: =SUM($AI$2:AI2) -> 8
A3: 2 | B3: =C3*$F$2 -> 2700000 | C3: 2.7 | D3: 2 | F3: 平均倍率 | H3: 3000 | I3: 210000 | J3: =H3*$F$4*$F$6 -> 21000 | K3: =J3/$F$2 -> 0.021 | U3: 1 | V3: 13 | Y3: 2 | Z3: 7 | AA3: 1 | AB3: 0 | AC3: 0 | AD3: 0 | AE3: 0 | AF3: 0 | AG3: 0 | AH3: 0 | AI3: 8 | AJ3: =SUM($AI$2:AI3) -> 16
A4: 3 | B4: =C4*$F$2 -> 3000000 | C4: 3 | D4: 2 | F4: 70 | H4: 10000 | I4: 700000 | J4: =H4*$F$4*$F$6 -> 70000 | K4: =J4/$F$2 -> 0.07 | L4: 1 | M4: 750 | N4: =M4*$V4/10000 -> 0.975 | U4: 1 | V4: 13 | Y4: 3 | Z4: 6 | AA4: 2 | AB4: 0 | AC4: 0 | AD4: 0 | AE4: 0 | AF4: 0 | AG4: 0 | AH4: 0 | AI4: 8 | AJ4: =SUM($AI$2:AI4) -> 24
A5: 4 | B5: =C5*$F$2 -> 3200000 | C5: 3.2 | D5: 2 | F5: 抽水 | H5: 20000 | I5: 1400000 | J5: =H5*$F$4*$F$6 -> 140000 | K5: =J5/$F$2 -> 0.14 | L5: 1 | M5: =膨胀后!AD5-P5 -> 600 | N5: =M5*$V5/10000 -> 0.78 | O5: 2 | P5: 100 | Q5: =P5*$V5/10000 -> 0.13 | U5: 1 | V5: 13 | Y5: 4 | Z5: 4 | AA5: 4 | AB5: 0 | AC5: 0 | AD5: 0 | AE5: 0 | AF5: 0 | AG5: 0 | AH5: 0 | AI5: 8 | AJ5: =SUM($AI$2:AI5) -> 32
A6: 5 | B6: =C6*$F$2 -> 3400000 | C6: 3.4 | D6: 2 | F6: 0.1 | H6: 50000 | I6: 3500000 | J6: =H6*$F$4*$F$6 -> 350000 | K6: =J6/$F$2 -> 0.35 | L6: 2 | M6: =(膨胀后!AD6-S6-膨胀后!W6-膨胀后!T6)/2+膨胀后!T6 -> 525 | N6: =M6*$V6/10000 -> 0.6825 | O6: 3 | P6: =(膨胀后!AD6-S6-膨胀后!W6-膨胀后!T6)/2+膨胀后!W6 -> 525 | Q6: =P6*$V6/10000 -> 0.6825 | R6: 4 | S6: 50 | T6: =S6*$V6/10000 -> 0.065 | U6: 1 | V6: 13 | Y6: 5 | Z6: 3 | AA6: 5 | AB6: 0 | AC6: 0 | AD6: 0 | AE6: 0 | AF6: 0 | AG6: 0 | AH6: 0 | AI6: 8 | AJ6: =SUM($AI$2:AI6) -> 40
A7: 6 | B7: =C7*$F$2 -> 3500000 | C7: 3.5 | D7: 3 | H7: 100000 | I7: 7000000 | J7: =H7*$F$4*$F$6 -> 700000 | K7: =J7/$F$2 -> 0.7 | L7: 3 | M7: =(膨胀后!AD7-S7-膨胀后!W7-膨胀后!T7)/2+膨胀后!T7 -> 383 | N7: =M7*$V7/10000 -> 0.4979 | O7: 4 | P7: =(膨胀后!AD7-S7-膨胀后!W7-膨胀后!T7)/2+膨胀后!W7 -> 333 | Q7: =P7*$V7/10000 -> 0.4329 | R7: 5 | S7: 34 | T7: =S7*$V7/10000 -> 0.0442 | U7: 1 | V7: 13 | Y7: 6 | Z7: 2 | AA7: 5 | AB7: 1 | AC7: 0 | AD7: 0 | AE7: 0 | AF7: 0 | AG7: 0 | AH7: 0 | AI7: 8 | AJ7: =SUM($AI$2:AI7) -> 48
A8: 7 | B8: =C8*$F$2 -> 3600000 | C8: 3.6 | D8: 3 | H8: 200000 | I8: 14000000 | J8: =H8*$F$4*$F$6 -> 1400000 | K8: =J8/$F$2 -> 1.4 | L8: 4 | M8: =(膨胀后!AD8-S8-膨胀后!W8-膨胀后!T8)/2+膨胀后!T8 -> 388 | N8: =M8*$V8/10000 -> 0.5044 | O8: 5 | P8: =(膨胀后!AD8-S8-膨胀后!W8-膨胀后!T8)/2+膨胀后!W8 -> 338 | Q8: =P8*$V8/10000 -> 0.4394 | R8: 6 | S8: 24 | T8: =S8*$V8/10000 -> 0.0312 | U8: 2 | V8: 13 | Y8: 7 | Z8: 1 | AA8: 4 | AB8: 3 | AC8: 0 | AD8: 0 | AE8: 0 | AF8: 0 | AG8: 0 | AH8: 0 | AI8: 8 | AJ8: =SUM($AI$2:AI8) -> 56
A9: 8 | B9: =C9*$F$2 -> 3700000 | C9: 3.7 | D9: 3 | H9: 500000 | I9: 35000000 | J9: =H9*$F$4*$F$6 -> 3500000 | K9: =J9/$F$2 -> 3.5 | L9: 4 | M9: =(膨胀后!AD9-S9-膨胀后!W9-膨胀后!T9)/2+膨胀后!T9 -> 450 | N9: =M9*$V9/10000 -> 0.585 | O9: 5 | P9: =(膨胀后!AD9-S9-膨胀后!W9-膨胀后!T9)/2+膨胀后!W9 -> 400 | Q9: =P9*$V9/10000 -> 0.52 | R9: 6 | S9: 50 | T9: =S9*$V9/10000 -> 0.065 | U9: 3 | V9: 13 | Y9: 8 | Z9: 0 | AA9: 4 | AB9: 4 | AC9: 0 | AD9: 0 | AE9: 0 | AF9: 0 | AG9: 0 | AH9: 0 | AI9: 8 | AJ9: =SUM($AI$2:AI9) -> 64
A10: 9 | B10: =C10*$F$2 -> 20000000 | C10: 20 | D10: 4 | H10: 1000000 | I10: 70000000 | J10: =H10*$F$4*$F$6 -> 7000000 | K10: =J10/$F$2 -> 7 | L10: 4 | M10: =(膨胀后!AD10-S10-膨胀后!W10-膨胀后!T10)/2+膨胀后!T10 -> 500 | N10: =M10*$V10/10000 -> 0.65 | O10: 5 | P10: =(膨胀后!AD10-S10-膨胀后!W10-膨胀后!T10)/2+膨胀后!W10 -> 450 | Q10: =P10*$V10/10000 -> 0.585 | R10: 6 | S10: 100 | T10: =S10*$V10/10000 -> 0.13 | U10: 4 | V10: 13 | Y10: 9 | Z10: 0 | AA10: 3 | AB10: 4 | AC10: 1 | AD10: 0 | AE10: 0 | AF10: 0 | AG10: 0 | AH10: 0 | AI10: 8 | AJ10: =SUM($AI$2:AI10) -> 72
A11: 10 | B11: =C11*$F$2 -> 25000000 | C11: 25 | D11: 4 | Y11: 10 | Z11: 0 | AA11: 3 | AB11: 3 | AC11: 2 | AD11: 0 | AE11: 0 | AF11: 0 | AG11: 0 | AH11: 0 | AI11: 8 | AJ11: =SUM($AI$2:AI11) -> 80
A12: 11 | B12: =C12*$F$2 -> 27000000 | C12: 27 | D12: 5 | F12: 单局产出卡包 | H12: 卡包数量 | I12: 1 | J12: 2 | K12: 3 | L12: 4 | M12: 5 | N12: 6 | Y12: 11 | Z12: 0 | AA12: 1 | AB12: 4 | AC12: 2 | AD12: 0 | AE12: 0 | AF12: 1 | AG12: 0 | AH12: 0 | AI12: 8 | AJ12: =SUM($AI$2:AI12) -> 88
A13: 12 | B13: =C13*$F$2 -> 29000000 | C13: 29 | D13: 5 | H13: 1000 | I13: =IF($L2=I$12,$N2,0)+IF($O2=I$12,$Q2,0)+IF($R2=I$12,$T2,0) -> 0 | J13: =IF($L2=J$12,$N2,0)+IF($O2=J$12,$Q2,0)+IF($R2=J$12,$T2,0) -> 0 | K13: =IF($L2=K$12,$N2,0)+IF($O2=K$12,$Q2,0)+IF($R2=K$12,$T2,0) -> 0 | L13: =IF($L2=L$12,$N2,0)+IF($O2=L$12,$Q2,0)+IF($R2=L$12,$T2,0) -> 0 | M13: =IF($L2=M$12,$N2,0)+IF($O2=M$12,$Q2,0)+IF($R2=M$12,$T2,0) -> 0 | N13: =IF($L2=N$12,$N2,0)+IF($O2=N$12,$Q2,0)+IF($R2=N$12,$T2,0) -> 0 | Y13: 12 | Z13: 0 | AA13: 1 | AB13: 3 | AC13: 2 | AD13: 1 | AE13: 0 | AF13: 1 | AG13: 0 | AH13: 0 | AI13: 8 | AJ13: =SUM($AI$2:AI13) -> 96
A14: 13 | B14: =C14*$F$2 -> 31000000 | C14: 31 | D14: 5 | H14: 3000 | I14: =IF($L3=I$12,$N3,0)+IF($O3=I$12,$Q3,0)+IF($R3=I$12,$T3,0) -> 0 | J14: =IF($L3=J$12,$N3,0)+IF($O3=J$12,$Q3,0)+IF($R3=J$12,$T3,0) -> 0 | K14: =IF($L3=K$12,$N3,0)+IF($O3=K$12,$Q3,0)+IF($R3=K$12,$T3,0) -> 0 | L14: =IF($L3=L$12,$N3,0)+IF($O3=L$12,$Q3,0)+IF($R3=L$12,$T3,0) -> 0 | M14: =IF($L3=M$12,$N3,0)+IF($O3=M$12,$Q3,0)+IF($R3=M$12,$T3,0) -> 0 | N14: =IF($L3=N$12,$N3,0)+IF($O3=N$12,$Q3,0)+IF($R3=N$12,$T3,0) -> 0 | Y14: 13 | Z14: 0 | AA14: 1 | AB14: 2 | AC14: 2 | AD14: 1 | AE14: 0 | AF14: 1 | AG14: 1 | AH14: 0 | AI14: 8 | AJ14: =SUM($AI$2:AI14) -> 104
A15: 14 | B15: =C15*$F$2 -> 35000000 | C15: 35 | D15: 5 | H15: 10000 | I15: =IF($L4=I$12,$N4,0)+IF($O4=I$12,$Q4,0)+IF($R4=I$12,$T4,0) -> 0.975 | J15: =IF($L4=J$12,$N4,0)+IF($O4=J$12,$Q4,0)+IF($R4=J$12,$T4,0) -> 0 | K15: =IF($L4=K$12,$N4,0)+IF($O4=K$12,$Q4,0)+IF($R4=K$12,$T4,0) -> 0 | L15: =IF($L4=L$12,$N4,0)+IF($O4=L$12,$Q4,0)+IF($R4=L$12,$T4,0) -> 0 | M15: =IF($L4=M$12,$N4,0)+IF($O4=M$12,$Q4,0)+IF($R4=M$12,$T4,0) -> 0 | N15: =IF($L4=N$12,$N4,0)+IF($O4=N$12,$Q4,0)+IF($R4=N$12,$T4,0) -> 0 | Y15: 14 | Z15: 0 | AA15: 0 | AB15: 2 | AC15: 2 | AD15: 1 | AE15: 1 | AF15: 1 | AG15: 1 | AH15: 0 | AI15: 8 | AJ15: =SUM($AI$2:AI15) -> 112
A16: 15 | B16: =C16*$F$2 -> 40000000 | C16: 40 | D16: 6 | H16: 20000 | I16: =IF($L5=I$12,$N5,0)+IF($O5=I$12,$Q5,0)+IF($R5=I$12,$T5,0) -> 0.78 | J16: =IF($L5=J$12,$N5,0)+IF($O5=J$12,$Q5,0)+IF($R5=J$12,$T5,0) -> 0.13 | K16: =IF($L5=K$12,$N5,0)+IF($O5=K$12,$Q5,0)+IF($R5=K$12,$T5,0) -> 0 | L16: =IF($L5=L$12,$N5,0)+IF($O5=L$12,$Q5,0)+IF($R5=L$12,$T5,0) -> 0 | M16: =IF($L5=M$12,$N5,0)+IF($O5=M$12,$Q5,0)+IF($R5=M$12,$T5,0) -> 0 | N16: =IF($L5=N$12,$N5,0)+IF($O5=N$12,$Q5,0)+IF($R5=N$12,$T5,0) -> 0 | Y16: 15 | Z16: 0 | AA16: 0 | AB16: 1 | AC16: 3 | AD16: 1 | AE16: 1 | AF16: 1 | AG16: 1 | AH16: 0 | AI16: 8 | AJ16: =SUM($AI$2:AI16) -> 120
A17: 16 | B17: =C17*$F$2 -> 42500000 | C17: 42.5 | D17: 6 | H17: 50000 | I17: =IF($L6=I$12,$N6,0)+IF($O6=I$12,$Q6,0)+IF($R6=I$12,$T6,0) -> 0 | J17: =IF($L6=J$12,$N6,0)+IF($O6=J$12,$Q6,0)+IF($R6=J$12,$T6,0) -> 0.6825 | K17: =IF($L6=K$12,$N6,0)+IF($O6=K$12,$Q6,0)+IF($R6=K$12,$T6,0) -> 0.6825 | L17: =IF($L6=L$12,$N6,0)+IF($O6=L$12,$Q6,0)+IF($R6=L$12,$T6,0) -> 0.065 | M17: =IF($L6=M$12,$N6,0)+IF($O6=M$12,$Q6,0)+IF($R6=M$12,$T6,0) -> 0 | N17: =IF($L6=N$12,$N6,0)+IF($O6=N$12,$Q6,0)+IF($R6=N$12,$T6,0) -> 0 | Y17: 16 | Z17: 0 | AA17: 0 | AB17: 1 | AC17: 2 | AD17: 1 | AE17: 1 | AF17: 2 | AG17: 1 | AH17: 0 | AI17: 8 | AJ17: =SUM($AI$2:AI17) -> 128
A18: 17 | B18: =C18*$F$2 -> 45000000 | C18: 45 | D18: 6 | H18: 100000 | I18: =IF($L7=I$12,$N7,0)+IF($O7=I$12,$Q7,0)+IF($R7=I$12,$T7,0) -> 0 | J18: =IF($L7=J$12,$N7,0)+IF($O7=J$12,$Q7,0)+IF($R7=J$12,$T7,0) -> 0 | K18: =IF($L7=K$12,$N7,0)+IF($O7=K$12,$Q7,0)+IF($R7=K$12,$T7,0) -> 0.4979 | L18: =IF($L7=L$12,$N7,0)+IF($O7=L$12,$Q7,0)+IF($R7=L$12,$T7,0) -> 0.4329 | M18: =IF($L7=M$12,$N7,0)+IF($O7=M$12,$Q7,0)+IF($R7=M$12,$T7,0) -> 0.0442 | N18: =IF($L7=N$12,$N7,0)+IF($O7=N$12,$Q7,0)+IF($R7=N$12,$T7,0) -> 0 | Y18: 17 | Z18: 0 | AA18: 0 | AB18: 1 | AC18: 1 | AD18: 2 | AE18: 1 | AF18: 2 | AG18: 1 | AH18: 0 | AI18: 8 | AJ18: =SUM($AI$2:AI18) -> 136
A19: 18 | B19: =C19*$F$2 -> 50000000 | C19: 50 | D19: 6 | H19: 200000 | I19: =IF($L8=I$12,$N8,0)+IF($O8=I$12,$Q8,0)+IF($R8=I$12,$T8,0) -> 0 | J19: =IF($L8=J$12,$N8,0)+IF($O8=J$12,$Q8,0)+IF($R8=J$12,$T8,0) -> 0 | K19: =IF($L8=K$12,$N8,0)+IF($O8=K$12,$Q8,0)+IF($R8=K$12,$T8,0) -> 0 | L19: =IF($L8=L$12,$N8,0)+IF($O8=L$12,$Q8,0)+IF($R8=L$12,$T8,0) -> 0.5044 | M19: =IF($L8=M$12,$N8,0)+IF($O8=M$12,$Q8,0)+IF($R8=M$12,$T8,0) -> 0.4394 | N19: =IF($L8=N$12,$N8,0)+IF($O8=N$12,$Q8,0)+IF($R8=N$12,$T8,0) -> 0.0312 | Y19: 18 | Z19: 0 | AA19: 0 | AB19: 1 | AC19: 1 | AD19: 2 | AE19: 0 | AF19: 1 | AG19: 2 | AH19: 1 | AI19: 8 | AJ19: =SUM($AI$2:AI19) -> 144
A20: 19 | B20: =C20*$F$2 -> 55000000 | C20: 55 | D20: 6 | H20: 500000 | I20: =IF($L9=I$12,$N9,0)+IF($O9=I$12,$Q9,0)+IF($R9=I$12,$T9,0) -> 0 | J20: =IF($L9=J$12,$N9,0)+IF($O9=J$12,$Q9,0)+IF($R9=J$12,$T9,0) -> 0 | K20: =IF($L9=K$12,$N9,0)+IF($O9=K$12,$Q9,0)+IF($R9=K$12,$T9,0) -> 0 | L20: =IF($L9=L$12,$N9,0)+IF($O9=L$12,$Q9,0)+IF($R9=L$12,$T9,0) -> 0.585 | M20: =IF($L9=M$12,$N9,0)+IF($O9=M$12,$Q9,0)+IF($R9=M$12,$T9,0) -> 0.52 | N20: =IF($L9=N$12,$N9,0)+IF($O9=N$12,$Q9,0)+IF($R9=N$12,$T9,0) -> 0.065 | Y20: 19 | Z20: 0 | AA20: 0 | AB20: 0 | AC20: 1 | AD20: 2 | AE20: 0 | AF20: 2 | AG20: 2 | AH20: 1 | AI20: 8 | AJ20: =SUM($AI$2:AI20) -> 152
A21: all | B21: =C21*$F$2 -> 100000000 | C21: 100 | H21: 1000000 | I21: =IF($L10=I$12,$N10,0)+IF($O10=I$12,$Q10,0)+IF($R10=I$12,$T10,0) -> 0 | J21: =IF($L10=J$12,$N10,0)+IF($O10=J$12,$Q10,0)+IF($R10=J$12,$T10,0) -> 0 | K21: =IF($L10=K$12,$N10,0)+IF($O10=K$12,$Q10,0)+IF($R10=K$12,$T10,0) -> 0 | L21: =IF($L10=L$12,$N10,0)+IF($O10=L$12,$Q10,0)+IF($R10=L$12,$T10,0) -> 0.65 | M21: =IF($L10=M$12,$N10,0)+IF($O10=M$12,$Q10,0)+IF($R10=M$12,$T10,0) -> 0.585 | N21: =IF($L10=N$12,$N10,0)+IF($O10=N$12,$Q10,0)+IF($R10=N$12,$T10,0) -> 0.13 | Y21: 合计 | Z21: 31 | AA21: 34 | AB21: 30 | AC21: 19 | AD21: 11 | AE21: 4 | AF21: 12 | AG21: 9 | AH21: 2 | AI21: 152
A22: 基础 | B22: =SUM(B2:B21) -> 525100000 | C22: =SUM(C2:C21) -> 525.1
F23: 需要牌局数 | H23: 星级 | I23: 1 | J23: 2 | K23: 3 | L23: 4 | M23: 5 | N23: 6
H24: 需要开卡次数 | I24: 25 | J24: 50 | K24: 50 | L24: 50 | M24: 50 | N24: 40 | O24: 集满奖励 | P24: 集满美金 | Q24: 最低牌局数
A25: 卡包 | B25: 需要开卡次数 | C25: 卡包价值 | H25: 1000 | I25: =IF(I13=0,0,I$24/I13) -> 0 | J25: =IF(J13=0,0,J$24/J13) -> 0 | K25: =IF(K13=0,0,K$24/K13) -> 0 | L25: =IF(L13=0,0,L$24/L13) -> 0 | M25: =IF(M13=0,0,M$24/M13) -> 0 | N25: =IF(N13=0,0,N$24/N13) -> 0 | O25: =IF(N25>0,SUMIF($D$2:$D$21,"<="&$N$23,$B$2:B20),IF(M25>0,SUMIF($D$2:$D$21,"<="&$M$23,$B$2:B20),IF(L25>0,SUMIF($D$2:$D$21,"<="&$L$23,$B$2:B20),IF(K25>0,SUMIF($D$2:$D$21,"<="&$K$23,$B$2:B20),IF(J25>0,SUMIF($D$2:$D$21,"<="&$J$23,$B$2:B20),IF(I25>0,SUMIF($D$2:$D$21,"<="&$I$23,$B$2:B20),0)))))) -> 0 | P25: =O25/$F$2 -> 0 | Q25: =IF(N25>0,N25,IF(M25>0,M25,IF(L25>0,L25,IF(K25>0,K25,IF(J25>0,J25,I25))))) -> 0
A26: 1 | B26: 25 | C26: =SUMIF($D$2:$D$21,"<="&A26,$B$2:$B$22)/B26/$F$2 -> 0.1 | H26: 3000 | I26: =IF(I14=0,0,I$24/I14) -> 0 | J26: =IF(J14=0,0,J$24/J14) -> 0 | K26: =IF(K14=0,0,K$24/K14) -> 0 | L26: =IF(L14=0,0,L$24/L14) -> 0 | M26: =IF(M14=0,0,M$24/M14) -> 0 | N26: =IF(N14=0,0,N$24/N14) -> 0 | O26: =IF(N26>0,SUMIF($D$2:$D$21,"<="&$N$23,$B$2:B21),IF(M26>0,SUMIF($D$2:$D$21,"<="&$M$23,$B$2:B21),IF(L26>0,SUMIF($D$2:$D$21,"<="&$L$23,$B$2:B21),IF(K26>0,SUMIF($D$2:$D$21,"<="&$K$23,$B$2:B21),IF(J26>0,SUMIF($D$2:$D$21,"<="&$J$23,$B$2:B21),IF(I26>0,SUMIF($D$2:$D$21,"<="&$I$23,$B$2:B21),0)))))) -> 0 | P26: =O26/$F$2 -> 0 | Q26: =IF(N26>0,N26,IF(M26>0,M26,IF(L26>0,L26,IF(K26>0,K26,IF(J26>0,J26,I26))))) -> 0
A27: 2 | B27: 50 | C27: =SUMIF($D$2:$D$21,"<="&A27,$B$2:$B$22)/B27/$F$2 -> 0.296 | H27: 10000 | I27: =IF(I15=0,0,I$24/I15) -> 25.641026 | J27: =IF(J15=0,0,J$24/J15) -> 0 | K27: =IF(K15=0,0,K$24/K15) -> 0 | L27: =IF(L15=0,0,L$24/L15) -> 0 | M27: =IF(M15=0,0,M$24/M15) -> 0 | N27: =IF(N15=0,0,N$24/N15) -> 0 | O27: =IF(N27>0,SUMIF($D$2:$D$21,"<="&$N$23,$B$2:B22),IF(M27>0,SUMIF($D$2:$D$21,"<="&$M$23,$B$2:B22),IF(L27>0,SUMIF($D$2:$D$21,"<="&$L$23,$B$2:B22),IF(K27>0,SUMIF($D$2:$D$21,"<="&$K$23,$B$2:B22),IF(J27>0,SUMIF($D$2:$D$21,"<="&$J$23,$B$2:B22),IF(I27>0,SUMIF($D$2:$D$21,"<="&$I$23,$B$2:B22),0)))))) -> 2500000 | P27: =O27/$F$2 -> 2.5 | Q27: =IF(N27>0,N27,IF(M27>0,M27,IF(L27>0,L27,IF(K27>0,K27,IF(J27>0,J27,I27))))) -> 25.641026
A28: 3 | B28: 50 | C28: =SUMIF($D$2:$D$21,"<="&A28,$B$2:$B$22)/B28/$F$2 -> 0.512 | H28: 20000 | I28: =IF(I16=0,0,I$24/I16) -> 32.051282 | J28: =IF(J16=0,0,J$24/J16) -> 384.61538 | K28: =IF(K16=0,0,K$24/K16) -> 0 | L28: =IF(L16=0,0,L$24/L16) -> 0 | M28: =IF(M16=0,0,M$24/M16) -> 0 | N28: =IF(N16=0,0,N$24/N16) -> 0 | O28: =IF(N28>0,SUMIF($D$2:$D$21,"<="&$N$23,$B$2:B23),IF(M28>0,SUMIF($D$2:$D$21,"<="&$M$23,$B$2:B23),IF(L28>0,SUMIF($D$2:$D$21,"<="&$L$23,$B$2:B23),IF(K28>0,SUMIF($D$2:$D$21,"<="&$K$23,$B$2:B23),IF(J28>0,SUMIF($D$2:$D$21,"<="&$J$23,$B$2:B23),IF(I28>0,SUMIF($D$2:$D$21,"<="&$I$23,$B$2:B23),0)))))) -> 14800000 | P28: =O28/$F$2 -> 14.8 | Q28: =IF(N28>0,N28,IF(M28>0,M28,IF(L28>0,L28,IF(K28>0,K28,IF(J28>0,J28,I28))))) -> 384.61538
A29: 4 | B29: 50 | C29: =SUMIF($D$2:$D$21,"<="&A29,$B$2:$B$22)/B29/$F$2 -> 1.412 | H29: 50000 | I29: =IF(I17=0,0,I$24/I17) -> 0 | J29: =IF(J17=0,0,J$24/J17) -> 73.260073 | K29: =IF(K17=0,0,K$24/K17) -> 73.260073 | L29: =IF(L17=0,0,L$24/L17) -> 769.23077 | M29: =IF(M17=0,0,M$24/M17) -> 0 | N29: =IF(N17=0,0,N$24/N17) -> 0 | O29: =IF(N29>0,SUMIF($D$2:$D$21,"<="&$N$23,$B$2:B24),IF(M29>0,SUMIF($D$2:$D$21,"<="&$M$23,$B$2:B24),IF(L29>0,SUMIF($D$2:$D$21,"<="&$L$23,$B$2:B24),IF(K29>0,SUMIF($D$2:$D$21,"<="&$K$23,$B$2:B24),IF(J29>0,SUMIF($D$2:$D$21,"<="&$J$23,$B$2:B24),IF(I29>0,SUMIF($D$2:$D$21,"<="&$I$23,$B$2:B24),0)))))) -> 70600000 | P29: =O29/$F$2 -> 70.6 | Q29: =IF(N29>0,N29,IF(M29>0,M29,IF(L29>0,L29,IF(K29>0,K29,IF(J29>0,J29,I29))))) -> 769.23077
A30: 5 | B30: 50 | C30: =SUMIF($D$2:$D$21,"<="&A30,$B$2:$B$22)/B30/$F$2 -> 3.852 | H30: 100000 | I30: =IF(I18=0,0,I$24/I18) -> 0 | J30: =IF(J18=0,0,J$24/J18) -> 0 | K30: =IF(K18=0,0,K$24/K18) -> 100.42177 | L30: =IF(L18=0,0,L$24/L18) -> 115.50012 | M30: =IF(M18=0,0,M$24/M18) -> 1131.2217 | N30: =IF(N18=0,0,N$24/N18) -> 0 | O30: =IF(N30>0,SUMIF($D$2:$D$21,"<="&$N$23,$B$2:B25),IF(M30>0,SUMIF($D$2:$D$21,"<="&$M$23,$B$2:B25),IF(L30>0,SUMIF($D$2:$D$21,"<="&$L$23,$B$2:B25),IF(K30>0,SUMIF($D$2:$D$21,"<="&$K$23,$B$2:B25),IF(J30>0,SUMIF($D$2:$D$21,"<="&$J$23,$B$2:B25),IF(I30>0,SUMIF($D$2:$D$21,"<="&$I$23,$B$2:B25),0)))))) -> 192600000 | P30: =O30/$F$2 -> 192.6 | Q30: =IF(N30>0,N30,IF(M30>0,M30,IF(L30>0,L30,IF(K30>0,K30,IF(J30>0,J30,I30))))) -> 1131.2217
A31: 6 | B31: 40 | C31: =SUMIF($D$2:$D$21,"="&A31,$B$2:$B$22)/B31/$F$2 -> 5.8125 | H31: 200000 | I31: =IF(I19=0,0,I$24/I19) -> 0 | J31: =IF(J19=0,0,J$24/J19) -> 0 | K31: =IF(K19=0,0,K$24/K19) -> 0 | L31: =IF(L19=0,0,L$24/L19) -> 99.127676 | M31: =IF(M19=0,0,M$24/M19) -> 113.79153 | N31: =IF(N19=0,0,N$24/N19) -> 1282.0513 | O31: =IF(N31>0,SUMIF($D$2:$D$21,"<="&$N$23,$B$2:B26),IF(M31>0,SUMIF($D$2:$D$21,"<="&$M$23,$B$2:B26),IF(L31>0,SUMIF($D$2:$D$21,"<="&$L$23,$B$2:B26),IF(K31>0,SUMIF($D$2:$D$21,"<="&$K$23,$B$2:B26),IF(J31>0,SUMIF($D$2:$D$21,"<="&$J$23,$B$2:B26),IF(I31>0,SUMIF($D$2:$D$21,"<="&$I$23,$B$2:B26),0)))))) -> 425100000 | P31: =O31/$F$2 -> 425.1 | Q31: =IF(N31>0,N31,IF(M31>0,M31,IF(L31>0,L31,IF(K31>0,K31,IF(J31>0,J31,I31))))) -> 1282.0513
H32: 500000 | I32: =IF(I20=0,0,I$24/I20) -> 0 | J32: =IF(J20=0,0,J$24/J20) -> 0 | K32: =IF(K20=0,0,K$24/K20) -> 0 | L32: =IF(L20=0,0,L$24/L20) -> 85.470085 | M32: =IF(M20=0,0,M$24/M20) -> 96.153846 | N32: =IF(N20=0,0,N$24/N20) -> 615.38462 | O32: =IF(N32>0,SUMIF($D$2:$D$21,"<="&$N$23,$B$2:B27),IF(M32>0,SUMIF($D$2:$D$21,"<="&$M$23,$B$2:B27),IF(L32>0,SUMIF($D$2:$D$21,"<="&$L$23,$B$2:B27),IF(K32>0,SUMIF($D$2:$D$21,"<="&$K$23,$B$2:B27),IF(J32>0,SUMIF($D$2:$D$21,"<="&$J$23,$B$2:B27),IF(I32>0,SUMIF($D$2:$D$21,"<="&$I$23,$B$2:B27),0)))))) -> 425100000 | P32: =O32/$F$2 -> 425.1 | Q32: =IF(N32>0,N32,IF(M32>0,M32,IF(L32>0,L32,IF(K32>0,K32,IF(J32>0,J32,I32))))) -> 615.38462
H33: 1000000 | I33: =IF(I21=0,0,I$24/I21) -> 0 | J33: =IF(J21=0,0,J$24/J21) -> 0 | K33: =IF(K21=0,0,K$24/K21) -> 0 | L33: =IF(L21=0,0,L$24/L21) -> 76.923077 | M33: =IF(M21=0,0,M$24/M21) -> 85.470085 | N33: =IF(N21=0,0,N$24/N21) -> 307.69231 | O33: =IF(N33>0,SUMIF($D$2:$D$21,"<="&$N$23,$B$2:B28),IF(M33>0,SUMIF($D$2:$D$21,"<="&$M$23,$B$2:B28),IF(L33>0,SUMIF($D$2:$D$21,"<="&$L$23,$B$2:B28),IF(K33>0,SUMIF($D$2:$D$21,"<="&$K$23,$B$2:B28),IF(J33>0,SUMIF($D$2:$D$21,"<="&$J$23,$B$2:B28),IF(I33>0,SUMIF($D$2:$D$21,"<="&$I$23,$B$2:B28),0)))))) -> 425100000 | P33: =O33/$F$2 -> 425.1 | Q33: =IF(N33>0,N33,IF(M33>0,M33,IF(L33>0,L33,IF(K33>0,K33,IF(J33>0,J33,I33))))) -> 307.69231
F35: 入场花费美金 | J35: 1000000 | K35: 1250000 | L35: 1500000 | M35: 1750000 | N35: 2000000 | O35: 2250000 | P35: 2500000 | Q35: 2500000 | R35: 2500000 | S35: 2500000 | T35: 2500000 | U35: 2500000 | V35: 2500000 | W35: 2500000 | X35: 2500000 | Y35: 2500000
H36: 底注 | I36: 一局金币 | J36: 0 | K36: 1 | L36: 2 | M36: 3 | N36: 4 | O36: 5 | P36: 6 | Q36: 7 | R36: 8 | S36: 9 | T36: 10 | U36: 11 | V36: 12 | W36: 13 | X36: 14 | Y36: 15
H37: 1000 | I37: 70000 | J37: 0.07 | K37: 0.056 | L37: 0.046666667 | M37: 0.04 | N37: 0.035 | O37: 0.031111111 | P37: 0.028 | Q37: 0.028 | R37: 0.028 | S37: 0.028 | T37: 0.028 | U37: 0.028 | V37: 0.028 | W37: 0.028 | X37: 0.028 | Y37: 0.028
H38: 3000 | I38: 210000 | J38: 0.21 | K38: 0.168 | L38: 0.14 | M38: 0.12 | N38: 0.105 | O38: 0.093333333 | P38: 0.084 | Q38: 0.084 | R38: 0.084 | S38: 0.084 | T38: 0.084 | U38: 0.084 | V38: 0.084 | W38: 0.084 | X38: 0.084 | Y38: 0.084
H39: 10000 | I39: 700000 | J39: 0.7 | K39: 0.56 | L39: 0.46666667 | M39: 0.4 | N39: 0.35 | O39: 0.31111111 | P39: 0.28 | Q39: 0.28 | R39: 0.28 | S39: 0.28 | T39: 0.28 | U39: 0.28 | V39: 0.28 | W39: 0.28 | X39: 0.28 | Y39: 0.28
H40: 20000 | I40: 1400000 | J40: 1.4 | K40: 1.12 | L40: 0.93333333 | M40: 0.8 | N40: 0.7 | O40: 0.62222222 | P40: 0.56 | Q40: 0.56 | R40: 0.56 | S40: 0.56 | T40: 0.56 | U40: 0.56 | V40: 0.56 | W40: 0.56 | X40: 0.56 | Y40: 0.56
H41: 50000 | I41: 3500000 | J41: 3.2741935 | K41: 2.7066667 | L41: 2.2555556 | M41: 1.9333333 | N41: 1.75 | O41: 1.5555556 | P41: 1.4 | Q41: 1.4 | R41: 1.4 | S41: 1.4 | T41: 1.4 | U41: 1.4 | V41: 1.4 | W41: 1.4 | X41: 1.4 | Y41: 1.4
...

Sheet 10.24调整
A1: 基础金币/美金 | C1: 章节 | D1: 金币 | E1: 美金 | H1: 章节 | I1: 金币 | J1: 美金 | K1: 最大星级 | M1: 基础金币/美金 | O1: 底注 | P1: //筹码下限 | Q1: 一局消耗 | R1: 消耗美金 | S1: //卡包id1 | T1: //概率 | U1: 产出卡包 | V1: //卡包id2 | W1: //概率 | Y1: //卡包id3 | Z1: //概率 | AB1: 单局上限 | AC1: 平均小轮数 | AE1: 单局产出卡包 | AG1: 卡包数量 | AH1: 1 | AI1: 2 | AJ1: 3 | AK1: 4 | AL1: 5 | AM1: 6 | AO1: 需要牌局数 | AQ1: 星级 | AR1: 1 | AS1: 2 | AT1: 3 | AU1: 4 | AV1: 5 | AW1: 6 | BB1: 入场花费美金 | BF1: 1000000 | BG1: 1250000 | BH1: 1500000 | BI1: 1750000 | BJ1: 2000000 | BK1: 2250000 | BL1: 2500000 | BM1: 2500000 | BN1: 2500000 | BO1: 2500000 | BP1: 2500000 | BQ1: 2500000 | BR1: 2500000 | BS1: 2500000 | BT1: 2500000 | BU1: 2500000 | BW1: 消费返还 | CA1: 1000000 | CB1: 1250000 | CC1: 1500000 | CD1: 1750000 | CE1: 2000000 | CF1: 2250000 | CG1: 2500000 | CH1: 2500000 | CI1: 2500000 | CJ1: 2500000 | CK1: 2500000 | CL1: 2500000 | CM1: 2500000 | CN1: 2500000 | CO1: 2500000 | CP1: 2500000
A2: 1000000 | C2: 1 | D2: 100000 | E2: =D2/$A$2 -> 0.1 | H2: 1 | I2: 200000 | J2: =I2/$A$2 -> 0.2 | K2: 1 | M2: 1000000 | O2: 1000 | P2: 5000 | Q2: =O2*$M$4*$M$6 -> 7000 | R2: =Q2/$M$2 -> 0.007 | AB2: 1 | AC2: 13 | AG2: =O2 -> 1000 | AH2: =IF($S2=AH$1,$U2,0)+IF($V2=AH$1,$X2,0)+IF($Y2=AH$1,$AA2,0) -> 0 | AI2: =IF($S2=AI$1,$U2,0)+IF($V2=AI$1,$X2,0)+IF($Y2=AI$1,$AA2,0) -> 0 | AJ2: =IF($S2=AJ$1,$U2,0)+IF($V2=AJ$1,$X2,0)+IF($Y2=AJ$1,$AA2,0) -> 0 | AK2: =IF($S2=AK$1,$U2,0)+IF($V2=AK$1,$X2,0)+IF($Y2=AK$1,$AA2,0) -> 0 | AL2: =IF($S2=AL$1,$U2,0)+IF($V2=AL$1,$X2,0)+IF($Y2=AL$1,$AA2,0) -> 0 | AM2: =IF($S2=AM$1,$U2,0)+IF($V2=AM$1,$X2,0)+IF($Y2=AM$1,$AA2,0) -> 0 | AQ2: 需要开卡次数 | AR2: 25 | AS2: 50 | AT2: 50 | AU2: 50 | AV2: 50 | AW2: 40 | AX2: 集满奖励 | AY2: 集满美金 | AZ2: 最低牌局数 | BD2: 底注 | BE2: 一局金币 | BF2: 0 | BG2: 1 | BH2: 2 | BI2: 3 | BJ2: 4 | BK2: 5 | BL2: 6 | BM2: 7 | BN2: 8 | BO2: 9 | BP2: 10 | BQ2: 11 | BR2: 12 | BS2: 13 | BT2: 14 | BU2: 15 | BY2: 底注 | BZ2: 一局金币 | CA2: 0 | CB2: 1 | CC2: 2 | CD2: 3 | CE2: 4 | CF2: 5 | CG2: 6 | CH2: 7 | CI2: 8 | CJ2: 9 | CK2: 10 | CL2: 11 | CM2: 12 | CN2: 13 | CO2: 14 | CP2: 15
