Workbook

Sheet 闸门
A1: 等级 | B1: 升级消耗建设币 | C1: 游客数 | D1: 游客生成速率 (每秒) | E1: 开启闸机口数量 1/2/3/4 | F1: 排队上限 | G1: 游客产金币速率（每秒） | I1: 初始建设币
A2: 1 | B2: 20 | C2: 2 | D2: 3 | E2: 1 | F2: 3 | G2: 10 | I2: 90
A3: 2 | B3: 30 | C3: 5 | D3: 3 | E3: 2 | F3: 3 | G3: 10
A4: 3 | B4: 40 | C4: 10 | D4: 3 | E4: 3 | F4: 3 | G4: 10
A5: 4 | B5: 15 | C5: 10 | D5: 3 | E5: 4 | F5: 4 | G5: 10
A6: 5 | B6: 5 | C6: 10 | D6: 3 | E6: 4 | F6: 5 | G6: 10
A7: 6 | B7: 10 | C7: 10 | D7: 3 | E7: 4 | F7: 6 | G7: 10
A8: 7 | B8: 10 | C8: 10 | D8: 3 | E8: 4 | F8: 7 | G8: 10
A9: 8 | B9: 10 | C9: 10 | D9: 3 | E9: 4 | F9: 8 | G9: 10
A10: 9 | B10: 10 | C10: 10 | D10: 3 | E10: 4 | F10: 9 | G10: 10
A11: 10 | B11: 20 | C11: 10 | D11: 3 | E11: 4 | F11: 12 | G11: 10
A12: 11 | B12: 30 | C12: 10 | D12: 3 | E12: 4 | F12: 14 | G12: 10
A13: 12 | B13: 40 | C13: 10 | D13: 3 | E13: 4 | F13: 16 | G13: 10
A14: 13 | B14: 50 | C14: 10 | D14: 3 | E14: 4 | F14: 18 | G14: 10
... A29: 28 | B29: 7000 | C29: 35 | D29: 1 | E29: 4 | F29: 24 | G29: 10

Sheet 新手宫殿
A1: 等级 | B1: 升级消耗建设币 | C1: 排队上限
A2: 0 | B2: 0 | C2: 10
A3: 1 | B3: 170 | C3: 11
A4: 2 | B4: 74000 | C4: 25

Sheet 建筑物
A1: 建筑物 | B1: 每轮产金币 | C1: 产金币速率（秒） | D1: 上限
A2: 1 | B2: 84 | C2: 10 | D2: 33600
A3: 2 | B3: 15 | C3: 10 | D3: 6000
A4: 3 | B4: 30 | C4: 10 | D4: 4800
A5: 4 | B5: 15 | C5: 10 | D5: 6000
A6: 5 | B6: 32 | C6: 10 | D6: 22000
A7: 6 | B7: 30 | C7: 10 | D7: 12000
A8: 7 | B8: 21 | C8: 10 | D8: 8400
A9: 8 | B9: 24 | C9: 10 | D9: 9600
A10: 9 | B10: 84 | C10: 10 | D10: 33600
A11: 10 | B11: 6 | C11: 10 | D11: 2400
A12: 11 | B12: 20 | C12: 10 | D12: 2400
A13: 12 | B13: 30 | C13: 10 | D13: 3600

Sheet 翻地块
A1: 章节 | B1: 地块 | C1: 消耗建设币 | D1: 奖励金币 | E1: 奖励钞票 | F1: 消耗能量（spin） | G1: 累计消耗（spin） | H1: 花费美金 | I1: 累计花费美金 | J1: 奖励金币 | K1: 奖励能量 | L1: 其他 | M1: 升级奖励金币 | N1: 升级奖励能量 | P1: 宝箱 | Q1: 奖励钞票 | R1: 奖励金币 | T1: 单位金币/美金 | U1: 单位能量/美金
A2: 1 | B2: 1 | C2: 10 | D2: 1000 | E2: 1000 | F2: =C2/tycoonSlots!$E$18 -> 0.001037452 | G2: =SUM($F$2:F2) -> 0.001037452 | H2: =G2/$U$2 -> 2.59363e-05 | I2: =SUM($H$2:H2) -> 2.59363e-05 | P2: 1 | R2: 1600 | T2: 10000 | U2: 40
A3: 1 | B3: 2 | C3: 20 | D3: 1000 | E3: 1000 | F3: =C3/tycoonSlots!$E$18 -> 0.002074904 | G3: =SUM($F$2:F3) -> 0.0031123561 | H3: =G3/$U$2 -> 7.7808901e-05 | I3: =SUM($H$2:H3) -> 0.0001037452
A4: 1 | B4: 3 | C4: 30 | D4: 1000 | E4: 1000 | F4: =C4/tycoonSlots!$E$18 -> 0.0031123561 | G4: =SUM($F$2:F4) -> 0.0062247121 | H4: =G4/$U$2 -> 0.0001556178 | I4: =SUM($H$2:H4) -> 0.000259363 | R4: 2000
A5: 1 | B5: 4 | C5: 40 | D5: 1000 | E5: 1000 | F5: =C5/tycoonSlots!$E$18 -> 0.0041498081 | G5: =SUM($F$2:F5) -> 0.01037452 | H5: =G5/$U$2 -> 0.000259363 | I5: =SUM($H$2:H5) -> 0.00051872601 | J5: 10 | L5: 宝箱1 | P5: 2 | R5: 780
A6: 1 | B6: 5 | C6: 50 | D6: 1000 | E6: 1000 | F6: =C6/tycoonSlots!$E$18 -> 0.0051872601 | G6: =SUM($F$2:F6) -> 0.01556178 | H6: =G6/$U$2 -> 0.00038904451 | I6: =SUM($H$2:H6) -> 0.00090777052
A7: 1 | B7: 6 | C7: 60 | D7: 1000 | E7: 1000 | F7: =C7/tycoonSlots!$E$18 -> 0.0062247121 | G7: =SUM($F$2:F7) -> 0.021786492 | H7: =G7/$U$2 -> 0.00054466231 | I7: =SUM($H$2:H7) -> 0.0014524328 | R7: 1000
A8: 1 | B8: 7 | C8: 70 | D8: 1000 | E8: 1000 | F8: =C8/tycoonSlots!$E$18 -> 0.0072621641 | G8: =SUM($F$2:F8) -> 0.029048656 | H8: =G8/$U$2 -> 0.00072621641 | I8: =SUM($H$2:H8) -> 0.0021786492 | P8: 3 | R8: 890
A9: 1 | B9: 8 | C9: 80 | D9: 1000 | E9: 1000 | F9: =C9/tycoonSlots!$E$18 -> 0.0082996161 | G9: =SUM($F$2:F9) -> 0.037348273 | H9: =G9/$U$2 -> 0.00093370682 | I9: =SUM($H$2:H9) -> 0.0031123561 | J9: 30 | L9: 宝箱2
A10: 1 | B10: 9 | C10: 90 | D10: 1000 | E10: 1000 | F10: =C10/tycoonSlots!$E$18 -> 0.0093370682 | G10: =SUM($F$2:F10) -> 0.046685341 | H10: =G10/$U$2 -> 0.0011671335 | I10: =SUM($H$2:H10) -> 0.0042794896 | R10: 1000
A11: 1 | B11: 10 | C11: 100 | D11: 1000 | E11: 1000 | F11: =C11/tycoonSlots!$E$18 -> 0.01037452 | G11: =SUM($F$2:F11) -> 0.057059861 | H11: =G11/$U$2 -> 0.0014264965 | I11: =SUM($H$2:H11) -> 0.0057059861 | J11: 40
A12: 1 | B12: 11 | C12: 110 | D12: 1000 | E12: 1000 | F12: =C12/tycoonSlots!$E$18 -> 0.011411972 | G12: =SUM($F$2:F12) -> 0.068471833 | H12: =G12/$U$2 -> 0.0017117958 | I12: =SUM($H$2:H12) -> 0.0074177819
A13: 1 | B13: 12 | C13: 120 | D13: 1000 | E13: 1000 | F13: =C13/tycoonSlots!$E$18 -> 0.012449424 | G13: =SUM($F$2:F13) -> 0.080921257 | H13: =G13/$U$2 -> 0.0020230314 | I13: =SUM($H$2:H13) -> 0.0094408134 | J13: 50 | P13: =ROUND(57000/4.99,0) -> 11423 | Q13: =ROUND(3700/99.99,0) -> 37
A14: 1 | B14: 13 | C14: 130 | D14: 1000 | E14: 1000 | F14: =C14/tycoonSlots!$E$18 -> 0.013486876 | G14: =SUM($F$2:F14) -> 0.094408134 | H14: =G14/$U$2 -> 0.0023602033 | I14: =SUM($H$2:H14) -> 0.011801017
A15: 1 | B15: 14 | C15: 140 | D15: 1000 | E15: 1000 | F15: =C15/tycoonSlots!$E$18 -> 0.014524328 | G15: =SUM($F$2:F15) -> 0.10893246 | H15: =G15/$U$2 -> 0.0027233115 | I15: =SUM($H$2:H15) -> 0.014524328 | J15: 50
A16: 1 | B16: 15 | C16: 150 | D16: 1000 | E16: 1000 | F16: =C16/tycoonSlots!$E$18 -> 0.01556178 | G16: =SUM($F$2:F16) -> 0.12449424 | H16: =G16/$U$2 -> 0.0031123561 | I16: =SUM($H$2:H16) -> 0.017636684
A17: 1 | B17: 16 | C17: 160 | D17: 1000 | E17: 1000 | F17: =C17/tycoonSlots!$E$18 -> 0.016599232 | G17: =SUM($F$2:F17) -> 0.14109347 | H17: =G17/$U$2 -> 0.0035273369 | I17: =SUM($H$2:H17) -> 0.021164021
A18: 1 | B18: 17 | C18: 170 | D18: 1000 | E18: 1000 | F18: =C18/tycoonSlots!$E$18 -> 0.017636684 | G18: =SUM($F$2:F18) -> 0.15873016 | H18: =G18/$U$2 -> 0.003968254 | I18: =SUM($H$2:H18) -> 0.025132275 | J18: 50
A19: 1 | B19: 18 | C19: 180 | D19: 1000 | E19: 1000 | F19: =C19/tycoonSlots!$E$18 -> 0.018674136 | G19: =SUM($F$2:F19) -> 0.1774043 | H19: =G19/$U$2 -> 0.0044351074 | I19: =SUM($H$2:H19) -> 0.029567383
A20: 1 | B20: 19 | C20: 190 | D20: 1000 | E20: 1000 | F20: =C20/tycoonSlots!$E$18 -> 0.019711588 | G20: =SUM($F$2:F20) -> 0.19711588 | H20: =G20/$U$2 -> 0.0049278971 | I20: =SUM($H$2:H20) -> 0.03449528 | J20: 50
A21: 1 | B21: 20 | C21: 200 | D21: 1000 | E21: 1000 | F21: =C21/tycoonSlots!$E$18 -> 0.02074904 | G21: =SUM($F$2:F21) -> 0.21786492 | H21: =G21/$U$2 -> 0.0054466231 | I21: =SUM($H$2:H21) -> 0.039941903
A22: 1 | B22: 21 | C22: 210 | D22: 1000 | E22: 1000 | F22: =C22/tycoonSlots!$E$18 -> 0.021786492 | G22: =SUM($F$2:F22) -> 0.23965142 | H22: =G22/$U$2 -> 0.0059912854 | I22: =SUM($H$2:H22) -> 0.045933188
A23: 1 | B23: 22 | C23: 220 | D23: 1000 | E23: 1000 | F23: =C23/tycoonSlots!$E$18 -> 0.022823944 | G23: =SUM($F$2:F23) -> 0.26247536 | H23: =G23/$U$2 -> 0.006561884 | I23: =SUM($H$2:H23) -> 0.052495072 | J23: 50
A24: 1 | B24: 23 | C24: 230 | D24: 1000 | E24: 1000 | F24: =C24/tycoonSlots!$E$18 -> 0.023861396 | G24: =SUM($F$2:F24) -> 0.28633676 | H24: =G24/$U$2 -> 0.0071584189 | I24: =SUM($H$2:H24) -> 0.059653491
A25: 1 | B25: 24 | C25: 240 | D25: 1000 | E25: 1000 | F25: =C25/tycoonSlots!$E$18 -> 0.024898848 | G25: =SUM($F$2:F25) -> 0.31123561 | H25: =G25/$U$2 -> 0.0077808901 | I25: =SUM($H$2:H25) -> 0.067434381
A26: 1 | B26: 25 | C26: 240 | D26: 1000 | E26: 1000 | F26: =C26/tycoonSlots!$E$18 -> 0.024898848 | G26: =SUM($F$2:F26) -> 0.33613445 | H26: =G26/$U$2 -> 0.0084033613 | I26: =SUM($H$2:H26) -> 0.075837743 | J26: 50
A27: 1 | B27: 26 | C27: 250 | D27: 1000 | E27: 1000 | F27: =C27/tycoonSlots!$E$18 -> 0.0259363 | G27: =SUM($F$2:F27) -> 0.36207075 | H27: =G27/$U$2 -> 0.0090517689 | I27: =SUM($H$2:H27) -> 0.084889511 | J27: 50 | M27: 20000 | N27: 20
A28: 2 | B28: 27 | C28: 40 | D28: 1000 | E28: 1000 | F28: =C28/tycoonSlots!$E$18 -> 0.0041498081 | G28: =SUM($F$2:F28) -> 0.36622056 | H28: =G28/$U$2 -> 0.0091555141 | I28: =SUM($H$2:H28) -> 0.094045025 | J28: 10
A29: 2 | B29: 28 | C29: 40 | D29: 1000 | E29: 1000 | F29: =C29/tycoonSlots!$E$18 -> 0.0041498081 | G29: =SUM($F$2:F29) -> 0.37037037 | H29: =G29/$U$2 -> 0.0092592593 | I29: =SUM($H$2:H29) -> 0.10330428
A30: 2 | B30: 29 | C30: 80 | D30: 1000 | E30: 1000 | F30: =C30/tycoonSlots!$E$18 -> 0.0082996161 | G30: =SUM($F$2:F30) -> 0.37866999 | H30: =G30/$U$2 -> 0.0094667497 | I30: =SUM($H$2:H30) -> 0.11277103 | J30: 10
A31: 2 | B31: 30 | C31: 80 | D31: 1000 | E31: 1000 | F31: =C31/tycoonSlots!$E$18 -> 0.0082996161 | G31: =SUM($F$2:F31) -> 0.3869696 | H31: =G31/$U$2 -> 0.0096742401 | I31: =SUM($H$2:H31) -> 0.12244527
A32: 2 | B32: 31 | C32: 120 | D32: 1000 | E32: 1000 | F32: =C32/tycoonSlots!$E$18 -> 0.012449424 | G32: =SUM($F$2:F32) -> 0.39941903 | H32: =G32/$U$2 -> 0.0099854757 | I32: =SUM($H$2:H32) -> 0.13243075 | J32: 20 | K32: 1
A33: 2 | B33: 32 | C33: 200 | D33: 1000 | E33: 1000 | F33: =C33/tycoonSlots!$E$18 -> 0.02074904 | G33: =SUM($F$2:F33) -> 0.42016807 | H33: =G33/$U$2 -> 0.010504202 | I33: =SUM($H$2:H33) -> 0.14293495
A34: 2 | B34: 33 | C34: 600 | D34: 1000 | E34: 1000 | F34: =C34/tycoonSlots!$E$18 -> 0.062247121 | G34: =SUM($F$2:F34) -> 0.48241519 | H34: =G34/$U$2 -> 0.01206038 | I34: =SUM($H$2:H34) -> 0.15499533 | J34: 50
A35: 2 | B35: 34 | C35: 1000 | D35: 1000 | E35: 1000 | F35: =C35/tycoonSlots!$E$18 -> 0.1037452 | G35: =SUM($F$2:F35) -> 0.58616039 | H35: =G35/$U$2 -> 0.01465401 | I35: =SUM($H$2:H35) -> 0.16964934
A36: 2 | B36: 35 | C36: 1400 | D36: 1000 | E36: 1000 | F36: =C36/tycoonSlots!$E$18 -> 0.14524328 | G36: =SUM($F$2:F36) -> 0.73140367 | H36: =G36/$U$2 -> 0.018285092 | I36: =SUM($H$2:H36) -> 0.18793443 | K36: 1
A37: 2 | B37: 36 | C37: 2000 | D37: 1000 | E37: 1000 | F37: =C37/tycoonSlots!$E$18 -> 0.2074904 | G37: =SUM($F$2:F37) -> 0.93889408 | H37: =G37/$U$2 -> 0.023472352 | I37: =SUM($H$2:H37) -> 0.21140678 | J37: 100
A38: 2 | B38: 37 | C38: 2600 | D38: 1000 | E38: 1000 | F38: =C38/tycoonSlots!$E$18 -> 0.26973752 | G38: =SUM($F$2:F38) -> 1.2086316 | H38: =G38/$U$2 -> 0.03021579 | I38: =SUM($H$2:H38) -> 0.24162257
A39: 2 | B39: 38 | C39: 3200 | D39: 1000 | E39: 1000 | F39: =C39/tycoonSlots!$E$18 -> 0.33198465 | G39: =SUM($F$2:F39) -> 1.5406162 | H39: =G39/$U$2 -> 0.038515406 | I39: =SUM($H$2:H39) -> 0.28013798
A40: 2 | B40: 39 | C40: 3800 | D40: 1000 | E40: 1000 | F40: =C40/tycoonSlots!$E$18 -> 0.39423177 | G40: =SUM($F$2:F40) -> 1.934848 | H40: =G40/$U$2 -> 0.0483712 | I40: =SUM($H$2:H40) -> 0.32850918
...

Sheet 翻地块备份
A1: 章节 | B1: 地块 | C1: 消耗建设币 | D1: 奖励金币 | E1: 奖励钞票 | F1: 消耗能量（spin） | G1: 累计消耗（spin） | H1: 花费美金 | I1: 累计花费美金 | J1: 奖励金币 | K1: 奖励能量 | L1: 其他 | M1: 升级奖励金币 | N1: 升级奖励能量 | P1: 宝箱 | Q1: 奖励钞票 | R1: 奖励金币 | T1: 单位金币/美金 | U1: 单位能量/美金
A2: 1 | B2: 1 | C2: 10 | D2: 1000 | E2: 1000 | F2: =C2/tycoonSlots!$E$18 -> 0.001037452 | G2: =SUM($F$2:F2) -> 0.001037452 | H2: =G2/$U$2 -> 2.59363e-05 | I2: =SUM($H$2:H2) -> 2.59363e-05 | P2: 1 | R2: 1600 | T2: 10000 | U2: 40
A3: 1 | B3: 2 | C3: 20 | D3: 1000 | E3: 1000 | F3: =C3/tycoonSlots!$E$18 -> 0.002074904 | G3: =SUM($F$2:F3) -> 0.0031123561 | H3: =G3/$U$2 -> 7.7808901e-05 | I3: =SUM($H$2:H3) -> 0.0001037452
A4: 1 | B4: 3 | C4: 30 | D4: 1000 | E4: 1000 | F4: =C4/tycoonSlots!$E$18 -> 0.0031123561 | G4: =SUM($F$2:F4) -> 0.0062247121 | H4: =G4/$U$2 -> 0.0001556178 | I4: =SUM($H$2:H4) -> 0.000259363 | R4: 2000
A5: 1 | B5: 4 | C5: 40 | D5: 1000 | E5: 1000 | F5: =C5/tycoonSlots!$E$18 -> 0.0041498081 | G5: =SUM($F$2:F5) -> 0.01037452 | H5: =G5/$U$2 -> 0.000259363 | I5: =SUM($H$2:H5) -> 0.00051872601 | J5: 10 | L5: 宝箱1 | P5: 2 | R5: 780
A6: 1 | B6: 5 | C6: 50 | D6: 1000 | E6: 1000 | F6: =C6/tycoonSlots!$E$18 -> 0.0051872601 | G6: =SUM($F$2:F6) -> 0.01556178 | H6: =G6/$U$2 -> 0.00038904451 | I6: =SUM($H$2:H6) -> 0.00090777052
A7: 1 | B7: 6 | C7: 60 | D7: 1000 | E7: 1000 | F7: =C7/tycoonSlots!$E$18 -> 0.0062247121 | G7: =SUM($F$2:F7) -> 0.021786492 | H7: =G7/$U$2 -> 0.00054466231 | I7: =SUM($H$2:H7) -> 0.0014524328 | R7: 1000
A8: 1 | B8: 7 | C8: 70 | D8: 1000 | E8: 1000 | F8: =C8/tycoonSlots!$E$18 -> 0.0072621641 | G8: =SUM($F$2:F8) -> 0.029048656 | H8: =G8/$U$2 -> 0.00072621641 | I8: =SUM($H$2:H8) -> 0.0021786492 | P8: 3 | R8: 890
A9: 1 | B9: 8 | C9: 80 | D9: 1000 | E9: 1000 | F9: =C9/tycoonSlots!$E$18 -> 0.0082996161 | G9: =SUM($F$2:F9) -> 0.037348273 | H9: =G9/$U$2 -> 0.00093370682 | I9: =SUM($H$2:H9) -> 0.0031123561 | J9: 30 | L9: 宝箱2
A10: 1 | B10: 9 | C10: 90 | D10: 1000 | E10: 1000 | F10: =C10/tycoonSlots!$E$18 -> 0.0093370682 | G10: =SUM($F$2:F10) -> 0.046685341 | H10: =G10/$U$2 -> 0.0011671335 | I10: =SUM($H$2:H10) -> 0.0042794896 | R10: 1000
A11: 1 | B11: 10 | C11: 100 | D11: 1000 | E11: 1000 | F11: =C11/tycoonSlots!$E$18 -> 0.01037452 | G11: =SUM($F$2:F11) -> 0.057059861 | H11: =G11/$U$2 -> 0.0014264965 | I11: =SUM($H$2:H11) -> 0.0057059861 | J11: 40
A12: 1 | B12: 11 | C12: 110 | D12: 1000 | E12: 1000 | F12: =C12/tycoonSlots!$E$18 -> 0.011411972 | G12: =SUM($F$2:F12) -> 0.068471833 | H12: =G12/$U$2 -> 0.0017117958 | I12: =SUM($H$2:H12) -> 0.0074177819
A13: 1 | B13: 12 | C13: 120 | D13: 1000 | E13: 1000 | F13: =C13/tycoonSlots!$E$18 -> 0.012449424 | G13: =SUM($F$2:F13) -> 0.080921257 | H13: =G13/$U$2 -> 0.0020230314 | I13: =SUM($H$2:H13) -> 0.0094408134 | J13: 50 | P13: =ROUND(57000/4.99,0) -> 11423 | Q13: =ROUND(3700/99.99,0) -> 37
A14: 1 | B14: 13 | C14: 130 | D14: 1000 | E14: 1000 | F14: =C14/tycoonSlots!$E$18 -> 0.013486876 | G14: =SUM($F$2:F14) -> 0.094408134 | H14: =G14/$U$2 -> 0.0023602033 | I14: =SUM($H$2:H14) -> 0.011801017
A15: 1 | B15: 14 | C15: 140 | D15: 1000 | E15: 1000 | F15: =C15/tycoonSlots!$E$18 -> 0.014524328 | G15: =SUM($F$2:F15) -> 0.10893246 | H15: =G15/$U$2 -> 0.0027233115 | I15: =SUM($H$2:H15) -> 0.014524328 | J15: 50
A16: 1 | B16: 15 | C16: 150 | D16: 1000 | E16: 1000 | F16: =C16/tycoonSlots!$E$18 -> 0.01556178 | G16: =SUM($F$2:F16) -> 0.12449424 | H16: =G16/$U$2 -> 0.0031123561 | I16: =SUM($H$2:H16) -> 0.017636684
A17: 1 | B17: 16 | C17: 160 | D17: 1000 | E17: 1000 | F17: =C17/tycoonSlots!$E$18 -> 0.016599232 | G17: =SUM($F$2:F17) -> 0.14109347 | H17: =G17/$U$2 -> 0.0035273369 | I17: =SUM($H$2:H17) -> 0.021164021
A18: 1 | B18: 17 | C18: 170 | D18: 1000 | E18: 1000 | F18: =C18/tycoonSlots!$E$18 -> 0.017636684 | G18: =SUM($F$2:F18) -> 0.15873016 | H18: =G18/$U$2 -> 0.003968254 | I18: =SUM($H$2:H18) -> 0.025132275 | J18: 50
A19: 1 | B19: 18 | C19: 180 | D19: 1000 | E19: 1000 | F19: =C19/tycoonSlots!$E$18 -> 0.018674136 | G19: =SUM($F$2:F19) -> 0.1774043 | H19: =G19/$U$2 -> 0.0044351074 | I19: =SUM($H$2:H19) -> 0.029567383
A20: 1 | B20: 19 | C20: 190 | D20: 1000 | E20: 1000 | F20: =C20/tycoonSlots!$E$18 -> 0.019711588 | G20: =SUM($F$2:F20) -> 0.19711588 | H20: =G20/$U$2 -> 0.0049278971 | I20: =SUM($H$2:H20) -> 0.03449528 | J20: 50
A21: 1 | B21: 20 | C21: 200 | D21: 1000 | E21: 1000 | F21: =C21/tycoonSlots!$E$18 -> 0.02074904 | G21: =SUM($F$2:F21) -> 0.21786492 | H21: =G21/$U$2 -> 0.0054466231 | I21: =SUM($H$2:H21) -> 0.039941903
A22: 1 | B22: 21 | C22: 210 | D22: 1000 | E22: 1000 | F22: =C22/tycoonSlots!$E$18 -> 0.021786492 | G22: =SUM($F$2:F22) -> 0.23965142 | H22: =G22/$U$2 -> 0.0059912854 | I22: =SUM($H$2:H22) -> 0.045933188
A23: 1 | B23: 22 | C23: 220 | D23: 1000 | E23: 1000 | F23: =C23/tycoonSlots!$E$18 -> 0.022823944 | G23: =SUM($F$2:F23) -> 0.26247536 | H23: =G23/$U$2 -> 0.006561884 | I23: =SUM($H$2:H23) -> 0.052495072 | J23: 50
A24: 1 | B24: 23 | C24: 230 | D24: 1000 | E24: 1000 | F24: =C24/tycoonSlots!$E$18 -> 0.023861396 | G24: =SUM($F$2:F24) -> 0.28633676 | H24: =G24/$U$2 -> 0.0071584189 | I24: =SUM($H$2:H24) -> 0.059653491
A25: 1 | B25: 24 | C25: 240 | D25: 1000 | E25: 1000 | F25: =C25/tycoonSlots!$E$18 -> 0.024898848 | G25: =SUM($F$2:F25) -> 0.31123561 | H25: =G25/$U$2 -> 0.0077808901 | I25: =SUM($H$2:H25) -> 0.067434381
A26: 1 | B26: 25 | C26: 240 | D26: 1000 | E26: 1000 | F26: =C26/tycoonSlots!$E$18 -> 0.024898848 | G26: =SUM($F$2:F26) -> 0.33613445 | H26: =G26/$U$2 -> 0.0084033613 | I26: =SUM($H$2:H26) -> 0.075837743 | J26: 50
A27: 1 | B27: 26 | C27: 250 | D27: 1000 | E27: 1000 | F27: =C27/tycoonSlots!$E$18 -> 0.0259363 | G27: =SUM($F$2:F27) -> 0.36207075 | H27: =G27/$U$2 -> 0.0090517689 | I27: =SUM($H$2:H27) -> 0.084889511 | J27: 50 | M27: 20000 | N27: 20
A28: 2 | B28: 27 | C28: 40 | D28: 1000 | E28: 1000 | F28: =C28/tycoonSlots!$E$18 -> 0.0041498081 | G28: =SUM($F$2:F28) -> 0.36622056 | H28: =G28/$U$2 -> 0.0091555141 | I28: =SUM($H$2:H28) -> 0.094045025 | J28: 10
A29: 2 | B29: 28 | C29: 40 | D29: 1000 | E29: 1000 | F29: =C29/tycoonSlots!$E$18 -> 0.0041498081 | G29: =SUM($F$2:F29) -> 0.37037037 | H29: =G29/$U$2 -> 0.0092592593 | I29: =SUM($H$2:H29) -> 0.10330428
A30: 2 | B30: 29 | C30: 80 | D30: 1000 | E30: 1000 | F30: =C30/tycoonSlots!$E$18 -> 0.0082996161 | G30: =SUM($F$2:F30) -> 0.37866999 | H30: =G30/$U$2 -> 0.0094667497 | I30: =SUM($H$2:H30) -> 0.11277103 | J30: 10
A31: 2 | B31: 30 | C31: 80 | D31: 1000 | E31: 1000 | F31: =C31/tycoonSlots!$E$18 -> 0.0082996161 | G31: =SUM($F$2:F31) -> 0.3869696 | H31: =G31/$U$2 -> 0.0096742401 | I31: =SUM($H$2:H31) -> 0.12244527
A32: 2 | B32: 31 | C32: 120 | D32: 1000 | E32: 1000 | F32: =C32/tycoonSlots!$E$18 -> 0.012449424 | G32: =SUM($F$2:F32) -> 0.39941903 | H32: =G32/$U$2 -> 0.0099854757 | I32: =SUM($H$2:H32) -> 0.13243075 | J32: 20 | K32: 1
A33: 2 | B33: 32 | C33: 200 | D33: 1000 | E33: 1000 | F33: =C33/tycoonSlots!$E$18 -> 0.02074904 | G33: =SUM($F$2:F33) -> 0.42016807 | H33: =G33/$U$2 -> 0.010504202 | I33: =SUM($H$2:H33) -> 0.14293495
A34: 2 | B34: 33 | C34: 600 | D34: 1000 | E34: 1000 | F34: =C34/tycoonSlots!$E$18 -> 0.062247121 | G34: =SUM($F$2:F34) -> 0.48241519 | H34: =G34/$U$2 -> 0.01206038 | I34: =SUM($H$2:H34) -> 0.15499533 | J34: 50
A35: 2 | B35: 34 | C35: 1000 | D35: 1000 | E35: 1000 | F35: =C35/tycoonSlots!$E$18 -> 0.1037452 | G35: =SUM($F$2:F35) -> 0.58616039 | H35: =G35/$U$2 -> 0.01465401 | I35: =SUM($H$2:H35) -> 0.16964934
A36: 2 | B36: 35 | C36: 1400 | D36: 1000 | E36: 1000 | F36: =C36/tycoonSlots!$E$18 -> 0.14524328 | G36: =SUM($F$2:F36) -> 0.73140367 | H36: =G36/$U$2 -> 0.018285092 | I36: =SUM($H$2:H36) -> 0.18793443 | K36: 1
A37: 2 | B37: 36 | C37: 2000 | D37: 1000 | E37: 1000 | F37: =C37/tycoonSlots!$E$18 -> 0.2074904 | G37: =SUM($F$2:F37) -> 0.93889408 | H37: =G37/$U$2 -> 0.023472352 | I37: =SUM($H$2:H37) -> 0.21140678 | J37: 100
A38: 2 | B38: 37 | C38: 2600 | D38: 1000 | E38: 1000 | F38: =C38/tycoonSlots!$E$18 -> 0.26973752 | G38: =SUM($F$2:F38) -> 1.2086316 | H38: =G38/$U$2 -> 0.03021579 | I38: =SUM($H$2:H38) -> 0.24162257
A39: 2 | B39: 38 | C39: 3200 | D39: 1000 | E39: 1000 | F39: =C39/tycoonSlots!$E$18 -> 0.33198465 | G39: =SUM($F$2:F39) -> 1.5406162 | H39: =G39/$U$2 -> 0.038515406 | I39: =SUM($H$2:H39) -> 0.28013798
A40: 2 | B40: 39 | C40: 3800 | D40: 1000 | E40: 1000 | F40: =C40/tycoonSlots!$E$18 -> 0.39423177 | G40: =SUM($F$2:F40) -> 1.934848 | H40: =G40/$U$2 -> 0.0483712 | I40: =SUM($H$2:H40) -> 0.32850918
...

Sheet tycoon截图

Sheet tycoonSlots
A1: 类型 | B1: 奖励类型 | C1: 奖励数量 | D1: 概率 | E1: 期望
A2: 金币1 | B2: 1 | C2: 100 | D2: 6 | E2: =C2*D2/$D$18 -> 6
A3: 金币2 | B3: 1 | C3: 200 | D3: 6 | E3: =C3*D3/$D$18 -> 12
A4: 金币3 | B4: 1 | C4: 500 | D4: 6 | E4: =C4*D4/$D$18 -> 30
A5: 金币4 | B5: 1 | C5: 700 | D5: 6 | E5: =C5*D5/$D$18 -> 42
A6: 金币5 | B6: 1 | C6: 1000 | D6: 6 | E6: =C6*D6/$D$18 -> 60
A7: 金币6 | B7: 1 | C7: 5000 | D7: 6 | E7: =C7*D7/$D$18 -> 300
A8: 金币7 | B8: 1 | C8: 10000 | D8: 6 | E8: =C8*D8/$D$18 -> 600
A9: 攻击成功 | B9: 1 | C9: 30000 | D9: 6 | E9: =C9*D9/$D$18 -> 1800
A10: 攻击失败 | B10: 1 | C10: 3000 | D10: 6 | E10: =C10*D10/$D$18 -> 180
A11: 偷窃 | B11: 1 | C11: 60000 | D11: 6 | E11: =C11*D11/$D$18 -> 3600
A12: 能量 | B12: 2 | C12: 5 | D12: 6 | E12: =SUM(E2:E11)*C12*D12/$D$18 -> 1989
A13: 进度1 | B13: 3 | C13: 2000 | D13: 6 | E13: =C13*D13/$D$18 -> 120
A14: 进度2 | B14: 3 | C14: 5000 | D14: 6 | E14: =C14*D14/$D$18 -> 300
A15: 进度3 | B15: 3 | C15: 10000 | D15: 6 | E15: =C15*D15/$D$18 -> 600
A16: 盾牌 | D16: 6
A17: 不中 | D17: 10
D18: =SUM(D2:D17) -> 100 | E18: =SUM(E2:E17) -> 9639
