Workbook

Sheet 用户分布
A1: slots | B1: VIP等级 | C1: 每日金币净消耗 | E1: 每日金币等级美金净消耗 | F1: 活动周期内金币等级美金净消耗 | G1: 应设立目标值
B2: 9 | C2: 5234 | D2: =(C2/25) -> 209.36 | E2: =D2 -> 209.36 | F2: =ROUND(E2*3,0) -> 628 | G2: =F2*1.5 -> 942 | H2: =G2*0.05 -> 47.1
B3: 8 | C3: 2203 | D3: =(C3/25) -> 88.12 | E3: =D3 -> 88.12 | F3: =ROUND(E3*3,0) -> 264 | G3: =F3*1.5 -> 396
B4: 7 | C4: 1326 | D4: =(C4/25) -> 53.04 | E4: =D4 -> 53.04 | F4: =ROUND(E4*3,0) -> 159 | G4: =F4*1.5 -> 238.5
B5: 6 | C5: 699 | D5: =(C5/25) -> 27.96 | E5: =D5 -> 27.96 | F5: =ROUND(E5*3,0) -> 84 | G5: =F5*1.5 -> 126
B6: 5 | C6: 287 | D6: =(C6/25) -> 11.48 | E6: =D6 -> 11.48 | F6: =ROUND(E6*3,0) -> 34 | G6: =F6*1.5 -> 51
B7: 4 | C7: 150 | D7: =(C7/25) -> 6 | E7: =D7 -> 6 | F7: =ROUND(E7*3,0) -> 18 | G7: =F7*1.5 -> 27
B8: 3 | C8: 119 | D8: =(C8/25) -> 4.76 | E8: =D8 -> 4.76 | F8: =ROUND(E8*3,0) -> 14 | G8: =F8*1.5 -> 21
B9: 2 | C9: 75 | D9: =(C9/25) -> 3 | E9: =D9 -> 3 | F9: =ROUND(E9*3,0) -> 9 | G9: =F9*1.5 -> 13.5
B10: 1 | C10: 60 | D10: =(C10/25) -> 2.4 | E10: =D10 -> 2.4 | F10: =ROUND(E10*3,0) -> 7 | G10: =F10*1.5 -> 10.5
B11: 0 | C11: 26 | D11: =(C11/25) -> 1.04 | E11: =D11 -> 1.04 | F11: =ROUND(E11*3,0) -> 3 | G11: =F11*1.5 -> 4.5
A13: 打牌 | B13: VIP等级 | C13: 每日牌局消耗
B14: 9 | C14: 8683.59 | D14: =(C14/25) -> 347.3436 | E14: =D14 -> 347.3436 | F14: =ROUND(E14*3,0) -> 1042 | G14: =F14*1.5 -> 1563
B15: 8 | C15: 7533.12 | D15: =(C15/25) -> 301.3248 | E15: =D15 -> 301.3248 | F15: =ROUND(E15*3,0) -> 904 | G15: =F15*1.5 -> 1356
B16: 7 | C16: 3810.05 | D16: =(C16/25) -> 152.402 | E16: =D16 -> 152.402 | F16: =ROUND(E16*3,0) -> 457 | G16: =F16*1.5 -> 685.5
B17: 6 | C17: 1941.61 | D17: =(C17/25) -> 77.6644 | E17: =D17 -> 77.6644 | F17: =ROUND(E17*3,0) -> 233 | G17: =F17*1.5 -> 349.5
B18: 5 | C18: 816.94 | D18: =(C18/25) -> 32.6776 | E18: =D18 -> 32.6776 | F18: =ROUND(E18*3,0) -> 98 | G18: =F18*1.5 -> 147
B19: 4 | C19: 398.73 | D19: =(C19/25) -> 15.9492 | E19: =D19 -> 15.9492 | F19: =ROUND(E19*3,0) -> 48 | G19: =F19*1.5 -> 72
B20: 3 | C20: 363.06 | D20: =(C20/25) -> 14.5224 | E20: =D20 -> 14.5224 | F20: =ROUND(E20*3,0) -> 44 | G20: =F20*1.5 -> 66
B21: 2 | C21: 180.44 | D21: =(C21/25) -> 7.2176 | E21: =D21 -> 7.2176 | F21: =ROUND(E21*3,0) -> 22 | G21: =F21*1.5 -> 33
B22: 1 | C22: 116.1 | D22: =(C22/25) -> 4.644 | E22: =D22 -> 4.644 | F22: =ROUND(E22*3,0) -> 14 | G22: =F22*1.5 -> 21
B23: 0 | C23: 59.82 | D23: =(C23/25) -> 2.3928 | E23: =D23 -> 2.3928 | F23: =ROUND(E23*3,0) -> 7 | G23: =F23*1.5 -> 10.5

Sheet 竞品体验
A1: 轮次 | B1: 关卡 | C1: 通关所需点数 | D1: 通关奖励 | F1: 通关奖励（美元） | G1: 浮岛领取奖励（左） | I1: 浮岛领取奖励（右） | K1: 浮岛奖励领取次数 | L1: 浮岛击打次数 | M1: 特殊桩击打次数 | N1: 球均特殊桩击打次数 | O1: 特殊奖励 | P1: 弹球消耗 | Q1: 累计弹球消耗 | R1: 获取弹球消耗金币数（已去除膨胀） | S1: 累计消耗金币（已去除膨胀） | T1: 累计获得奖励（未去除膨胀） | V1: 阶段获得金币（去除膨胀：随动） | W1: 阶段获得等价美元 | X1: vip膨胀 | Y1: 等级膨胀 | Z1: 球均点数获取 | AA1: 弹均收益单价（美元） | AB1: 备注1 | AC1: 备注2 | AE1: 模型 | AF1: 消耗弹球 | AG1: 球均点数 | AH1: 球均美元 | AI1: 球均美元（算上大奖）
A2: 1 | B2: 1 | C2: 70 | D2: 9.072 | E2: 30 | F2: =(D2/($X$2*$Y$2))/0.5 -> 1.008 | L2: 8 | M2: 0 | N2: =M2/P2 -> 0 | P2: 5 | Q2: 5 | R2: 16.8 | S2: 16.8 | T2: =D2+G2+I2 -> 9.072 | U2: =E2+H2+J2 -> 30 | V2: =T2/(1.5*12) -> 0.504 | W2: =V2/0.5 -> 1.008 | X2: 1.5 | Y2: 12 | Z2: =C2/P2 -> 14 | AA2: =W2/P2 -> 0.2016 | AB2: 所消耗5球中，含2球为广告获得的免费球 | AC2: 含录制视频（编号202604031） | AE2: 1 | AF2: 5 | AG2: =ROUND(C2/AF2,0) -> 14 | AH2: 0.26
A3: 1 | B3: 2 | C3: 150 | D3: 13.608 | E3: 50 | F3: =(D3/($X$2*$Y$2))/0.5 -> 1.512 | H3: 5 | I3: 5.44 | K3: 2 | L3: 24 | M3: 0 | N3: =M3/P3 -> 0 | P3: 8 | Q3: =P3+Q2 -> 13 | R3: 39.2 | S3: =S2+R3 -> 56 | T3: =D3+G3+I3+T2 -> 28.12 | U3: =E3+H3+J3+U2 -> 85 | V3: =(T3-T2)/(X3*Y3) -> 1.0582222 | W3: =V3/0.5 -> 2.1164444 | X3: 1.5 | Y3: 12 | Z3: =C3/P3 -> 18.75 | AA3: =W3/P3 -> 0.26455556 | AB3: 所消耗8球中，含1球为广告获得的免费球 | AC3: 含录制视频（编号202604031） | AE3: 2 | AF3: 7 | AG3: =ROUND(C3/AF3,0) -> 21 | AH3: 0.23
A4: 1 | B4: 3 | C4: 300 | D4: 18.144 | E4: 70 | F4: =(D4/($X$2*$Y$2))/0.5 -> 2.016 | K4: 0 | L4: 15 | M4: 0 | N4: =M4/P4 -> 0 | P4: 9 | Q4: =P4+Q3 -> 22 | R4: 50.4 | S4: =S3+R4 -> 106.4 | T4: =D4+G4+I4+T3 -> 46.264 | U4: =E4+H4+J4+U3 -> 155 | V4: =(T4-T3)/(X4*Y4) -> 1.008 | W4: =V4/0.5 -> 2.016 | X4: 1.5 | Y4: 12 | Z4: =C4/P4 -> 33.333333 | AA4: =W4/P4 -> 0.224 | AC4: 含录制视频（编号202604031） | AE4: 3 | AF4: 9 | AG4: =ROUND(C4/AF4,0) -> 33 | AH4: 0.21
A5: 1 | B5: 4 | C5: 600 | D5: 27.216 | E5: 90 | F5: =(D5/($X$2*$Y$2))/0.5 -> 3.024 | K5: 0 | L5: 17 | M5: 1 | N5: =M5/P5 -> 0.076923077 | P5: 13 | Q5: =P5+Q4 -> 35 | R5: 0 | S5: =S4+R5 -> 106.4 | T5: =D5+G5+I5+T4 -> 73.48 | U5: =E5+H5+J5+U4 -> 245 | V5: =(T5-T4)/(X5*Y5) -> 1.512 | W5: =V5/0.5 -> 3.024 | X5: 1.5 | Y5: 12 | Z5: =C5/P5 -> 46.153846 | AA5: =W5/P5 -> 0.23261538 | AB5: 所消耗的13球均为抽中大奖的奖励免费球 | AC5: 含录制视频（编号202604031） | AE5: 4 | AF5: 22 | AG5: =ROUND(C5/AF5,0) -> 27 | AH5: 0.18
A6: 1 | B6: 5 | C6: 1200 | D6: 40.824 | E6: 110 | F6: =(D6/($X$2*$Y$2))/0.5 -> 4.536 | I6: 16.7 | K6: 1 | L6: =60+43 -> 103 | M6: 39 | N6: =M6/P6 -> 1.3448276 | P6: 29 | Q6: =P6+Q5 -> 64 | R6: 169.9 | S6: =S5+R6 -> 276.3 | T6: =D6+G6+I6+T5 -> 131.004 | U6: =E6+H6+J6+U5 -> 355 | V6: =(T6-T5)/(X6*Y6) -> 2.7392381 | W6: =V6/0.5 -> 5.4784762 | X6: 1.5 | Y6: 14 | Z6: =C6/P6 -> 41.37931 | AA6: =W6/P6 -> 0.18891297 | AC6: 含录制视频（编号202604031+202604032） | AE6: 5 | AF6: 40 | AG6: =ROUND(C6/AF6,0) -> 30 | AH6: 0.16
A7: 1 | B7: 6 | C7: 2500 | D7: 58.968 | E7: 130 | F7: =(D7/($X$2*$Y$2))/0.5 -> 6.552 | G7: 5.44 | H7: =60+20 -> 80 | J7: 20 | K7: 4 | L7: 338 | M7: =72+2 -> 74 | N7: =M7/P7 -> 1.2758621 | O7: 27.2 | P7: =45+12+1 -> 58 | Q7: =P7+Q6 -> 122 | R7: 247.3 | S7: =S6+R7 -> 523.6 | T7: =D7+G7+I7+T6+O7 -> 222.612 | U7: =E7+H7+J7+U6 -> 585 | V7: =(T7-T6)/(X7*Y7) -> 4.3622857 | W7: =V7/0.5 -> 8.7245714 | X7: 1.5 | Y7: 14 | Z7: =C7/P7 -> 43.103448 | AA7: =W7/P7 -> 0.15042365 | AB7: 所消耗的球中12球为抽中大奖的奖励免费球，1球为免费球 | AC7: 含录制视频（编号202604032+202404033） | AE7: 6 | AF7: 64 | AG7: =ROUND(C7/AF7,0) -> 39 | AH7: 0.13
A8: 1 | B8: 7 | C8: 4000 | D8: 81.648 | E8: 150 | F8: =(D8/($X$2*$Y$2))/0.5 -> 9.072 | G8: =16.7+16.7+16.7 -> 50.1 | H8: =60+5 -> 65 | I8: =50.8+50.8 -> 101.6 | J8: =5+20+5+20 -> 50 | K8: 11 | L8: 728 | M8: =30+60+53+20 -> 163 | N8: =M8/P8 -> 1.0866667 | P8: =17+14+54+51+14 -> 150 | Q8: =P8+Q7 -> 272 | R8: =123+264+181+51 -> 619 | S8: =S7+R8 -> 1142.6 | T8: =D8+G8+I8+T7+O8 -> 455.96 | U8: =E8+H8+J8+U7 -> 850 | V8: =(T8-T7)/(X8*Y8) -> 5.8337 | W8: =V8/0.5 -> 11.6674 | X8: 2.5 | Y8: 16 | Z8: =C8/P8 -> 26.666667 | AA8: =W8/P8 -> 0.077782667 | AB8: 所消耗的球中14球为抽中大奖的奖励免费球，2球为免费球 | AC8: 含录制视频（编号202604033+202604081/2/3） | AE8: 7 | AF8: 92 | AG8: =ROUND(C8/AF8,0) -> 43 | AH8: 0.11
A9: 1 | B9: 8 | C9: 6000 | D9: 113.4 | E9: 170 | F9: =(D9/($X$2*$Y$2))/0.5 -> 12.6 | G9: 5.44 | H9: =60+20+60+5+60+5 -> 210 | I9: =50.8+5.44+50.8 -> 107.04 | K9: 10 | L9: 705 | M9: =66+76+52 -> 194 | N9: =M9/P9 -> 1.2847682 | O9: 27.2 | P9: =37+11+57+57-11 -> 151 | Q9: =P9+Q8 -> 423 | R9: 514 | S9: =S8+R9 -> 1656.6 | T9: =D9+G9+I9+T8+O9 -> 709.04 | U9: =E9+H9+J9+U8 -> 1230 | V9: =(T9-T8)/(X9*Y9) -> 5.624 | W9: =V9/0.5 -> 11.248 | X9: 2.5 | Y9: 18 | Z9: =C9/P9 -> 39.735099 | AA9: =W9/P9 -> 0.074490066 | AB9: 所消耗的球中11球为抽中大奖的奖励免费球，15球为免费球 | AC9: 含录制视频（202604083/4/5） | AE9: 8 | AF9: 126 | AG9: =ROUND(C9/AF9,0) -> 48 | AH9: 0.08
A10: 1 | B10: FIN | D10: 272.16 | E10: 600 | F10: =(D10/($X$2*$Y$2))/0.5 -> 30.24 | P10: 0 | Q10: =P10+Q9 -> 423 | R10: 0 | S10: =S9+R10 -> 1656.6 | T10: =D10+G10+I10+T9+O10 -> 981.2 | U10: =E10+H10+J10+U9 -> 1830 | V10: =(T10-T9)/(X10*Y10) -> 6.048 | W10: =V10/0.5 -> 12.096 | X10: 2.5 | Y10: 18 | AA10: =70/Q10 -> 0.16548463
N11: {=SUMPRODUCT(N6:N9,P6:P9)/SUM(P6:P9)} -> 1.2113402 | AH11: {=SUMPRODUCT(AH2:AH9,AF2:AF9)/SUM(AF2:AF9)} -> 0.11967123 | AI11: 0.16548463

Sheet 数值体验表 
A1: 关卡 | B1: 奖励类型: 1金币2钻石3道具id4卡包5卡片9美金/除100 | C1: 道具id | D1: 点数 | E1: 奖励数量 | F1: 消耗发射 | G1: 发射均点数 | H1: 累计消耗发射 | I1: 美金 | J1: 累计美金 | K1: 消耗积分 | L1: 累计消耗积分 | M1: 发射次数单价 | N1: 关卡 | O1: 老虎机spin | AF1: 关卡 | AG1: 打牌次数
O2: 1 | P2: 2 | Q2: 3 | R2: 4 | S2: 5 | T2: 6 | U2: 7 | V2: 8 | W2: 9 | X2: 10 | Y2: 11 | Z2: 12 | AA2: 13 | AB2: 14 | AC2: 15 | AD2: 16 | AG2: 17 | AH2: 18 | AI2: 28 | AJ2: 29 | AK2: 32 | AL2: 95 | AM2: 108 | AN2: 109 | AO2: 110 | AP2: 111
O3: =SUMIF(bet对应表!$A:$A,"="&O2,bet对应表!$C:$C) -> 10000 | P3: =SUMIF(bet对应表!$A:$A,"="&P2,bet对应表!$C:$C) -> 30000 | Q3: =SUMIF(bet对应表!$A:$A,"="&Q2,bet对应表!$C:$C) -> 90000 | R3: =SUMIF(bet对应表!$A:$A,"="&R2,bet对应表!$C:$C) -> 100000 | S3: =SUMIF(bet对应表!$A:$A,"="&S2,bet对应表!$C:$C) -> 150000 | T3: =SUMIF(bet对应表!$A:$A,"="&T2,bet对应表!$C:$C) -> 200000 | U3: =SUMIF(bet对应表!$A:$A,"="&U2,bet对应表!$C:$C) -> 300000 | V3: =SUMIF(bet对应表!$A:$A,"="&V2,bet对应表!$C:$C) -> 500000 | ... AD3: =SUMIF(bet对应表!$A:$A,"="&AD2,bet对应表!$C:$C) -> 9000000 | AG3: =SUMIF(bet对应表!$A:$A,"="&AG2,bet对应表!$C:$C) -> 10000000 | AH3: =SUMIF(bet对应表!$A:$A,"="&AH2,bet对应表!$C:$C) -> 12000000 | AI3: =SUMIF(bet对应表!$A:$A,"="&AI2,bet对应表!$C:$C) -> 225000000 | AJ3: =SUMIF(bet对应表!$A:$A,"="&AJ2,bet对应表!$C:$C) -> 300000000 | AK3: =SUMIF(bet对应表!$A:$A,"="&AK2,bet对应表!$C:$C) -> 500000000 | AL3: =SUMIF(bet对应表!$A:$A,"="&AL2,bet对应表!$C:$C) -> 0 | AM3: =SUMIF(bet对应表!$A:$A,"="&AM2,bet对应表!$C:$C) -> 0 | AN3: =SUMIF(bet对应表!$A:$A,"="&AN2,bet对应表!$C:$C) -> 0 | ... AP3: =SUMIF(bet对应表!$A:$A,"="&AP2,bet对应表!$C:$C) -> 0
A4: 1 | B4: 9 | C4: 1 | D4: =70/C30 -> 70 | E4: =100/$D$30 -> 5 | F4: =ROUND(D4/G4,0) -> 3 | G4: =WeightCalculate!S3 -> 21.764706 | H4: =SUM($F$4:F4) -> 3 | I4: =IF(B4=1,E4/bet对应表!M7,IF(B4=9,E4/100,0)) -> 0.05 | J4: =SUM($I$4:I4) -> 0.05 | K4: =F4*QuestGetLevel!$D$51 -> 3000 | L4: =K4 -> 3000 | M4: =J4/H4 -> 0.016666667 | N4: 1 | O4: {=$L$4/(INDEX(bet对应表!$F:$F,MATCH(O2,bet对应表!$A:$A,0),0))} -> #N/A | P4: {=L4/(INDEX(bet对应表!$F:$F,MATCH($P$2,bet对应表!$A:$A,0),0))} -> #N/A | Q4: {=L4/(INDEX(bet对应表!$F:$F,MATCH($Q$2,bet对应表!$A:$A,0),0))} -> #N/A | R4: {=L4/(INDEX(bet对应表!$F:$F,MATCH($R$2,bet对应表!$A:$A,0),0))} -> #N/A | S4: {=L4/(INDEX(bet对应表!$F:$F,MATCH($S$2,bet对应表!$A:$A,0),0))} -> #N/A | T4: {=L4/(INDEX(bet对应表!$F:$F,MATCH($T$2,bet对应表!$A:$A,0),0))} -> #N/A | U4: {=L4/(INDEX(bet对应表!$F:$F,MATCH($U$2,bet对应表!$A:$A,0),0))} -> #N/A | V4: {=L4/(INDEX(bet对应表!$F:$F,MATCH($V$2,bet对应表!$A:$A,0),0))} -> #N/A | W4: {=L4/(INDEX(bet对应表!$F:$F,MATCH($W$2,bet对应表!$A:$A,0),0))} -> #N/A | X4: {=L4/(INDEX(bet对应表!$F:$F,MATCH($X$2,bet对应表!$A:$A,0),0))} -> #N/A | Y4: {=L4/(INDEX(bet对应表!$F:$F,MATCH($Y$2,bet对应表!$A:$A,0),0))} -> #N/A | Z4: {=L4/(INDEX(bet对应表!$F:$F,MATCH($Z$2,bet对应表!$A:$A,0),0))} -> #N/A | AA4: {=L4/(INDEX(bet对应表!$F:$F,MATCH($AA$2,bet对应表!$A:$A,0),0))} -> #N/A | AB4: {=L4/(INDEX(bet对应表!$F:$F,MATCH($AB$2,bet对应表!$A:$A,0),0))} -> #N/A | AC4: {=L4/(INDEX(bet对应表!$F:$F,MATCH($AC$2,bet对应表!$A:$A,0),0))} -> #N/A | AD4: {=L4/(INDEX(bet对应表!$F:$F,MATCH($AD$2,bet对应表!$A:$A,0),0))} -> #N/A | AF4: 1 | AG4: {=L4/(INDEX(bet对应表!$F:$F,MATCH($AG$2,bet对应表!$A:$A,0),0))} -> #N/A | AH4: {=L4/(INDEX(bet对应表!$F:$F,MATCH($AH$2,bet对应表!$A:$A,0),0))} -> #N/A | AI4: {=L4/(INDEX(bet对应表!$F:$F,MATCH($AI$2,bet对应表!$A:$A,0),0))} -> #DIV/0! | AJ4: {=L4/(INDEX(bet对应表!$F:$F,MATCH($AJ$2,bet对应表!$A:$A,0),0))} -> #DIV/0! | AK4: {=L4/(INDEX(bet对应表!$F:$F,MATCH($AK$2,bet对应表!$A:$A,0),0))} -> #DIV/0! | AL4: {=L4/(INDEX(bet对应表!$F:$F,MATCH($AL$2,bet对应表!$A:$A,0),0))} -> #N/A | AM4: {=L4/(INDEX(bet对应表!$F:$F,MATCH($AM$2,bet对应表!$A:$A,0),0))} -> #N/A | AN4: {=L4/(INDEX(bet对应表!$F:$F,MATCH($AN$2,bet对应表!$A:$A,0),0))} -> #N/A | AO4: {=L4/(INDEX(bet对应表!$F:$F,MATCH($AO$2,bet对应表!$A:$A,0),0))} -> #N/A | AP4: {=L4/(INDEX(bet对应表!$F:$F,MATCH($AP$2,bet对应表!$A:$A,0),0))} -> #N/A
A5: 2 | B5: 9 | C5: 1 | D5: =150/C30 -> 150 | E5: =150/$D$30 -> 7.5 | F5: =ROUND(D5/G5,0) -> 6 | G5: =WeightCalculate!S4 -> 24.354704 | H5: =SUM($F$4:F5) -> 9 | I5: =IF(B5=1,E5/bet对应表!M8,IF(B5=9,E5/100,0)) -> 0.075 | J5: =SUM($I$4:I5) -> 0.125 | K5: =F5*QuestGetLevel!$D$51 -> 6000 | L5: =K5+L4 -> 9000 | M5: =J5/H5 -> 0.013888889 | N5: 2 | O5: {=L5/(INDEX(bet对应表!F:F,MATCH($O$2,bet对应表!A:A,0),0))} -> #N/A | P5: {=L5/(INDEX(bet对应表!$F:$F,MATCH($P$2,bet对应表!$A:$A,0),0))} -> #N/A | Q5: {=L5/(INDEX(bet对应表!$F:$F,MATCH($Q$2,bet对应表!$A:$A,0),0))} -> #N/A | R5: {=L5/(INDEX(bet对应表!$F:$F,MATCH($R$2,bet对应表!$A:$A,0),0))} -> #N/A | S5: {=L5/(INDEX(bet对应表!$F:$F,MATCH($S$2,bet对应表!$A:$A,0),0))} -> #N/A | T5: {=L5/(INDEX(bet对应表!$F:$F,MATCH($T$2,bet对应表!$A:$A,0),0))} -> #N/A | U5: {=L5/(INDEX(bet对应表!$F:$F,MATCH($U$2,bet对应表!$A:$A,0),0))} -> #N/A | V5: {=L5/(INDEX(bet对应表!$F:$F,MATCH($V$2,bet对应表!$A:$A,0),0))} -> #N/A | W5: {=L5/(INDEX(bet对应表!$F:$F,MATCH($W$2,bet对应表!$A:$A,0),0))} -> #N/A | X5: {=L5/(INDEX(bet对应表!$F:$F,MATCH($X$2,bet对应表!$A:$A,0),0))} -> #N/A | Y5: {=L5/(INDEX(bet对应表!$F:$F,MATCH($Y$2,bet对应表!$A:$A,0),0))} -> #N/A | Z5: {=L5/(INDEX(bet对应表!$F:$F,MATCH($Z$2,bet对应表!$A:$A,0),0))} -> #N/A | AA5: {=L5/(INDEX(bet对应表!$F:$F,MATCH($AA$2,bet对应表!$A:$A,0),0))} -> #N/A | AB5: {=L5/(INDEX(bet对应表!$F:$F,MATCH($AB$2,bet对应表!$A:$A,0),0))} -> #N/A | AC5: {=L5/(INDEX(bet对应表!$F:$F,MATCH($AC$2,bet对应表!$A:$A,0),0))} -> #N/A | AD5: {=L5/(INDEX(bet对应表!$F:$F,MATCH($AD$2,bet对应表!$A:$A,0),0))} -> #N/A | AF5: 2 | AG5: {=L5/(INDEX(bet对应表!$F:$F,MATCH($AG$2,bet对应表!$A:$A,0),0))} -> #N/A | AH5: {=L5/(INDEX(bet对应表!$F:$F,MATCH($AH$2,bet对应表!$A:$A,0),0))} -> #N/A | AI5: {=L5/(INDEX(bet对应表!$F:$F,MATCH($AI$2,bet对应表!$A:$A,0),0))} -> #DIV/0! | AJ5: {=L5/(INDEX(bet对应表!$F:$F,MATCH($AJ$2,bet对应表!$A:$A,0),0))} -> #DIV/0! | AK5: {=L5/(INDEX(bet对应表!$F:$F,MATCH($AK$2,bet对应表!$A:$A,0),0))} -> #DIV/0! | AL5: {=L5/(INDEX(bet对应表!$F:$F,MATCH($AL$2,bet对应表!$A:$A,0),0))} -> #N/A | AM5: {=L5/(INDEX(bet对应表!$F:$F,MATCH($AM$2,bet对应表!$A:$A,0),0))} -> #N/A | AN5: {=L5/(INDEX(bet对应表!$F:$F,MATCH($AN$2,bet对应表!$A:$A,0),0))} -> #N/A | AO5: {=L5/(INDEX(bet对应表!$F:$F,MATCH($AO$2,bet对应表!$A:$A,0),0))} -> #N/A | AP5: {=L5/(INDEX(bet对应表!$F:$F,MATCH($AP$2,bet对应表!$A:$A,0),0))} -> #N/A
A6: 3 | B6: 9 | C6: 1 | D6: =300/C30 -> 300 | E6: =200/$D$30 -> 10 | F6: =ROUND(D6/G6,0) -> 11 | G6: =WeightCalculate!S5 -> 28.004441 | H6: =SUM($F$4:F6) -> 20 | I6: =IF(B6=1,E6/bet对应表!M9,IF(B6=9,E6/100,0)) -> 0.1 | J6: =SUM($I$4:I6) -> 0.225 | K6: =F6*QuestGetLevel!$D$51 -> 11000 | L6: =K6+L5 -> 20000 | M6: =J6/H6 -> 0.01125 | N6: 3 | O6: {=L6/(INDEX(bet对应表!F:F,MATCH($O$2,bet对应表!A:A,0),0))} -> #N/A | P6: {=L6/(INDEX(bet对应表!$F:$F,MATCH($P$2,bet对应表!$A:$A,0),0))} -> #N/A | Q6: {=L6/(INDEX(bet对应表!$F:$F,MATCH($Q$2,bet对应表!$A:$A,0),0))} -> #N/A | R6: {=L6/(INDEX(bet对应表!$F:$F,MATCH($R$2,bet对应表!$A:$A,0),0))} -> #N/A | S6: {=L6/(INDEX(bet对应表!$F:$F,MATCH($S$2,bet对应表!$A:$A,0),0))} -> #N/A | T6: {=L6/(INDEX(bet对应表!$F:$F,MATCH($T$2,bet对应表!$A:$A,0),0))} -> #N/A | U6: {=L6/(INDEX(bet对应表!$F:$F,MATCH($U$2,bet对应表!$A:$A,0),0))} -> #N/A | V6: {=L6/(INDEX(bet对应表!$F:$F,MATCH($V$2,bet对应表!$A:$A,0),0))} -> #N/A | W6: {=L6/(INDEX(bet对应表!$F:$F,MATCH($W$2,bet对应表!$A:$A,0),0))} -> #N/A | X6: {=L6/(INDEX(bet对应表!$F:$F,MATCH($X$2,bet对应表!$A:$A,0),0))} -> #N/A | Y6: {=L6/(INDEX(bet对应表!$F:$F,MATCH($Y$2,bet对应表!$A:$A,0),0))} -> #N/A | Z6: {=L6/(INDEX(bet对应表!$F:$F,MATCH($Z$2,bet对应表!$A:$A,0),0))} -> #N/A | AA6: {=L6/(INDEX(bet对应表!$F:$F,MATCH($AA$2,bet对应表!$A:$A,0),0))} -> #N/A | AB6: {=L6/(INDEX(bet对应表!$F:$F,MATCH($AB$2,bet对应表!$A:$A,0),0))} -> #N/A | AC6: {=L6/(INDEX(bet对应表!$F:$F,MATCH($AC$2,bet对应表!$A:$A,0),0))} -> #N/A | AD6: {=L6/(INDEX(bet对应表!$F:$F,MATCH($AD$2,bet对应表!$A:$A,0),0))} -> #N/A | AF6: 3 | AG6: {=L6/(INDEX(bet对应表!$F:$F,MATCH($AG$2,bet对应表!$A:$A,0),0))} -> #N/A | AH6: {=L6/(INDEX(bet对应表!$F:$F,MATCH($AH$2,bet对应表!$A:$A,0),0))} -> #N/A | AI6: {=L6/(INDEX(bet对应表!$F:$F,MATCH($AI$2,bet对应表!$A:$A,0),0))} -> #DIV/0! | AJ6: {=L6/(INDEX(bet对应表!$F:$F,MATCH($AJ$2,bet对应表!$A:$A,0),0))} -> #DIV/0! | AK6: {=L6/(INDEX(bet对应表!$F:$F,MATCH($AK$2,bet对应表!$A:$A,0),0))} -> #DIV/0! | AL6: {=L6/(INDEX(bet对应表!$F:$F,MATCH($AL$2,bet对应表!$A:$A,0),0))} -> #N/A | AM6: {=L6/(INDEX(bet对应表!$F:$F,MATCH($AM$2,bet对应表!$A:$A,0),0))} -> #N/A | AN6: {=L6/(INDEX(bet对应表!$F:$F,MATCH($AN$2,bet对应表!$A:$A,0),0))} -> #N/A | AO6: {=L6/(INDEX(bet对应表!$F:$F,MATCH($AO$2,bet对应表!$A:$A,0),0))} -> #N/A | AP6: {=L6/(INDEX(bet对应表!$F:$F,MATCH($AP$2,bet对应表!$A:$A,0),0))} -> #N/A
A7: 4 | B7: 9 | C7: 1 | D7: =600/C30 -> 600 | E7: =300/$D$30 -> 15 | F7: =ROUND(D7/G7,0) -> 18 | G7: =WeightCalculate!S8 -> 33.162309 | H7: =SUM($F$4:F7) -> 38 | I7: =IF(B7=1,E7/bet对应表!M10,IF(B7=9,E7/100,0)) -> 0.15 | J7: =SUM($I$4:I7) -> 0.375 | K7: =F7*QuestGetLevel!$D$51 -> 18000 | L7: =K7+L6 -> 38000 | M7: =J7/H7 -> 0.0098684211 | N7: 4 | O7: {=L7/(INDEX(bet对应表!F:F,MATCH($O$2,bet对应表!A:A,0),0))} -> #N/A | P7: {=L7/(INDEX(bet对应表!$F:$F,MATCH($P$2,bet对应表!$A:$A,0),0))} -> #N/A | Q7: {=L7/(INDEX(bet对应表!$F:$F,MATCH($Q$2,bet对应表!$A:$A,0),0))} -> #N/A | R7: {=L7/(INDEX(bet对应表!$F:$F,MATCH($R$2,bet对应表!$A:$A,0),0))} -> #N/A | S7: {=L7/(INDEX(bet对应表!$F:$F,MATCH($S$2,bet对应表!$A:$A,0),0))} -> #N/A | T7: {=L7/(INDEX(bet对应表!$F:$F,MATCH($T$2,bet对应表!$A:$A,0),0))} -> #N/A | U7: {=L7/(INDEX(bet对应表!$F:$F,MATCH($U$2,bet对应表!$A:$A,0),0))} -> #N/A | V7: {=L7/(INDEX(bet对应表!$F:$F,MATCH($V$2,bet对应表!$A:$A,0),0))} -> #N/A | W7: {=L7/(INDEX(bet对应表!$F:$F,MATCH($W$2,bet对应表!$A:$A,0),0))} -> #N/A | X7: {=L7/(INDEX(bet对应表!$F:$F,MATCH($X$2,bet对应表!$A:$A,0),0))} -> #N/A | Y7: {=L7/(INDEX(bet对应表!$F:$F,MATCH($Y$2,bet对应表!$A:$A,0),0))} -> #N/A | Z7: {=L7/(INDEX(bet对应表!$F:$F,MATCH($Z$2,bet对应表!$A:$A,0),0))} -> #N/A | AA7: {=L7/(INDEX(bet对应表!$F:$F,MATCH($AA$2,bet对应表!$A:$A,0),0))} -> #N/A | AB7: {=L7/(INDEX(bet对应表!$F:$F,MATCH($AB$2,bet对应表!$A:$A,0),0))} -> #N/A | AC7: {=L7/(INDEX(bet对应表!$F:$F,MATCH($AC$2,bet对应表!$A:$A,0),0))} -> #N/A | AD7: {=L7/(INDEX(bet对应表!$F:$F,MATCH($AD$2,bet对应表!$A:$A,0),0))} -> #N/A | AF7: 4 | AG7: {=L7/(INDEX(bet对应表!$F:$F,MATCH($AG$2,bet对应表!$A:$A,0),0))} -> #N/A | AH7: {=L7/(INDEX(bet对应表!$F:$F,MATCH($AH$2,bet对应表!$A:$A,0),0))} -> #N/A | AI7: {=L7/(INDEX(bet对应表!$F:$F,MATCH($AI$2,bet对应表!$A:$A,0),0))} -> #DIV/0! | AJ7: {=L7/(INDEX(bet对应表!$F:$F,MATCH($AJ$2,bet对应表!$A:$A,0),0))} -> #DIV/0! | AK7: {=L7/(INDEX(bet对应表!$F:$F,MATCH($AK$2,bet对应表!$A:$A,0),0))} -> #DIV/0! | AL7: {=L7/(INDEX(bet对应表!$F:$F,MATCH($AL$2,bet对应表!$A:$A,0),0))} -> #N/A | AM7: {=L7/(INDEX(bet对应表!$F:$F,MATCH($AM$2,bet对应表!$A:$A,0),0))} -> #N/A | AN7: {=L7/(INDEX(bet对应表!$F:$F,MATCH($AN$2,bet对应表!$A:$A,0),0))} -> #N/A | AO7: {=L7/(INDEX(bet对应表!$F:$F,MATCH($AO$2,bet对应表!$A:$A,0),0))} -> #N/A | AP7: {=L7/(INDEX(bet对应表!$F:$F,MATCH($AP$2,bet对应表!$A:$A,0),0))} -> #N/A
A8: 5 | B8: 9 | C8: 1 | D8: 1000 | E8: 20 | F8: =ROUND(D8/G8,0) -> 28 | G8: =WeightCalculate!S11 -> 36.130734 | H8: =SUM($F$4:F8) -> 66 | I8: =IF(B8=1,E8/bet对应表!M11,IF(B8=9,E8/100,0)) -> 0.2 | J8: =SUM($I$4:I8) -> 0.575 | K8: =F8*QuestGetLevel!$D$51 -> 28000 | L8: =K8+L7 -> 66000 | M8: =J8/H8 -> 0.0087121212 | N8: 5 | O8: {=L8/(INDEX(bet对应表!F:F,MATCH($O$2,bet对应表!A:A,0),0))} -> #N/A | P8: {=L8/(INDEX(bet对应表!$F:$F,MATCH($P$2,bet对应表!$A:$A,0),0))} -> #N/A | Q8: {=L8/(INDEX(bet对应表!$F:$F,MATCH($Q$2,bet对应表!$A:$A,0),0))} -> #N/A | R8: {=L8/(INDEX(bet对应表!$F:$F,MATCH($R$2,bet对应表!$A:$A,0),0))} -> #N/A | S8: {=L8/(INDEX(bet对应表!$F:$F,MATCH($S$2,bet对应表!$A:$A,0),0))} -> #N/A | T8: {=L8/(INDEX(bet对应表!$F:$F,MATCH($T$2,bet对应表!$A:$A,0),0))} -> #N/A | U8: {=L8/(INDEX(bet对应表!$F:$F,MATCH($U$2,bet对应表!$A:$A,0),0))} -> #N/A | V8: {=L8/(INDEX(bet对应表!$F:$F,MATCH($V$2,bet对应表!$A:$A,0),0))} -> #N/A | W8: {=L8/(INDEX(bet对应表!$F:$F,MATCH($W$2,bet对应表!$A:$A,0),0))} -> #N/A | X8: {=L8/(INDEX(bet对应表!$F:$F,MATCH($X$2,bet对应表!$A:$A,0),0))} -> #N/A | Y8: {=L8/(INDEX(bet对应表!$F:$F,MATCH($Y$2,bet对应表!$A:$A,0),0))} -> #N/A | Z8: {=L8/(INDEX(bet对应表!$F:$F,MATCH($Z$2,bet对应表!$A:$A,0),0))} -> #N/A | AA8: {=L8/(INDEX(bet对应表!$F:$F,MATCH($AA$2,bet对应表!$A:$A,0),0))} -> #N/A | AB8: {=L8/(INDEX(bet对应表!$F:$F,MATCH($AB$2,bet对应表!$A:$A,0),0))} -> #N/A | AC8: {=L8/(INDEX(bet对应表!$F:$F,MATCH($AC$2,bet对应表!$A:$A,0),0))} -> #N/A | AD8: {=L8/(INDEX(bet对应表!$F:$F,MATCH($AD$2,bet对应表!$A:$A,0),0))} -> #N/A | AF8: 5 | AG8: {=L8/(INDEX(bet对应表!$F:$F,MATCH($AG$2,bet对应表!$A:$A,0),0))} -> #N/A | AH8: {=L8/(INDEX(bet对应表!$F:$F,MATCH($AH$2,bet对应表!$A:$A,0),0))} -> #N/A | AI8: {=L8/(INDEX(bet对应表!$F:$F,MATCH($AI$2,bet对应表!$A:$A,0),0))} -> #DIV/0! | AJ8: {=L8/(INDEX(bet对应表!$F:$F,MATCH($AJ$2,bet对应表!$A:$A,0),0))} -> #DIV/0! | AK8: {=L8/(INDEX(bet对应表!$F:$F,MATCH($AK$2,bet对应表!$A:$A,0),0))} -> #DIV/0! | AL8: {=L8/(INDEX(bet对应表!$F:$F,MATCH($AL$2,bet对应表!$A:$A,0),0))} -> #N/A | AM8: {=L8/(INDEX(bet对应表!$F:$F,MATCH($AM$2,bet对应表!$A:$A,0),0))} -> #N/A | AN8: {=L8/(INDEX(bet对应表!$F:$F,MATCH($AN$2,bet对应表!$A:$A,0),0))} -> #N/A | AO8: {=L8/(INDEX(bet对应表!$F:$F,MATCH($AO$2,bet对应表!$A:$A,0),0))} -> #N/A | AP8: {=L8/(INDEX(bet对应表!$F:$F,MATCH($AP$2,bet对应表!$A:$A,0),0))} -> #N/A
A9: 6 | B9: 9 | C9: 1 | D9: 2000 | E9: 30 | F9: =ROUND(D9/G9,0) -> 45 | G9: =WeightCalculate!S14 -> 44.573014 | H9: =SUM($F$4:F9) -> 111 | I9: =IF(B9=1,E9/bet对应表!M12,IF(B9=9,E9/100,0)) -> 0.3 | J9: =SUM($I$4:I9) -> 0.875 | K9: =F9*QuestGetLevel!$D$51 -> 45000 | L9: =K9+L8 -> 111000 | M9: =J9/H9 -> 0.0078828829 | N9: 6 | O9: {=L9/(INDEX(bet对应表!F:F,MATCH($O$2,bet对应表!A:A,0),0))} -> #N/A | P9: {=L9/(INDEX(bet对应表!$F:$F,MATCH($P$2,bet对应表!$A:$A,0),0))} -> #N/A | Q9: {=L9/(INDEX(bet对应表!$F:$F,MATCH($Q$2,bet对应表!$A:$A,0),0))} -> #N/A | R9: {=L9/(INDEX(bet对应表!$F:$F,MATCH($R$2,bet对应表!$A:$A,0),0))} -> #N/A | S9: {=L9/(INDEX(bet对应表!$F:$F,MATCH($S$2,bet对应表!$A:$A,0),0))} -> #N/A | T9: {=L9/(INDEX(bet对应表!$F:$F,MATCH($T$2,bet对应表!$A:$A,0),0))} -> #N/A | U9: {=L9/(INDEX(bet对应表!$F:$F,MATCH($U$2,bet对应表!$A:$A,0),0))} -> #N/A | V9: {=L9/(INDEX(bet对应表!$F:$F,MATCH($V$2,bet对应表!$A:$A,0),0))} -> #N/A | W9: {=L9/(INDEX(bet对应表!$F:$F,MATCH($W$2,bet对应表!$A:$A,0),0))} -> #N/A | X9: {=L9/(INDEX(bet对应表!$F:$F,MATCH($X$2,bet对应表!$A:$A,0),0))} -> #N/A | Y9: {=L9/(INDEX(bet对应表!$F:$F,MATCH($Y$2,bet对应表!$A:$A,0),0))} -> #N/A | Z9: {=L9/(INDEX(bet对应表!$F:$F,MATCH($Z$2,bet对应表!$A:$A,0),0))} -> #N/A | AA9: {=L9/(INDEX(bet对应表!$F:$F,MATCH($AA$2,bet对应表!$A:$A,0),0))} -> #N/A | AB9: {=L9/(INDEX(bet对应表!$F:$F,MATCH($AB$2,bet对应表!$A:$A,0),0))} -> #N/A | AC9: {=L9/(INDEX(bet对应表!$F:$F,MATCH($AC$2,bet对应表!$A:$A,0),0))} -> #N/A | AD9: {=L9/(INDEX(bet对应表!$F:$F,MATCH($AD$2,bet对应表!$A:$A,0),0))} -> #N/A | AF9: 6 | AG9: {=L9/(INDEX(bet对应表!$F:$F,MATCH($AG$2,bet对应表!$A:$A,0),0))} -> #N/A | AH9: {=L9/(INDEX(bet对应表!$F:$F,MATCH($AH$2,bet对应表!$A:$A,0),0))} -> #N/A | AI9: {=L9/(INDEX(bet对应表!$F:$F,MATCH($AI$2,bet对应表!$A:$A,0),0))} -> #DIV/0! | AJ9: {=L9/(INDEX(bet对应表!$F:$F,MATCH($AJ$2,bet对应表!$A:$A,0),0))} -> #DIV/0! | AK9: {=L9/(INDEX(bet对应表!$F:$F,MATCH($AK$2,bet对应表!$A:$A,0),0))} -> #DIV/0! | AL9: {=L9/(INDEX(bet对应表!$F:$F,MATCH($AL$2,bet对应表!$A:$A,0),0))} -> #N/A | AM9: {=L9/(INDEX(bet对应表!$F:$F,MATCH($AM$2,bet对应表!$A:$A,0),0))} -> #N/A | AN9: {=L9/(INDEX(bet对应表!$F:$F,MATCH($AN$2,bet对应表!$A:$A,0),0))} -> #N/A | AO9: {=L9/(INDEX(bet对应表!$F:$F,MATCH($AO$2,bet对应表!$A:$A,0),0))} -> #N/A | AP9: {=L9/(INDEX(bet对应表!$F:$F,MATCH($AP$2,bet对应表!$A:$A,0),0))} -> #N/A
A10: 7 | B10: 9 | C10: 1 | D10: 3000 | E10: =900/$D$30 -> 45 | F10: =ROUND(D10/G10,0) -> 62 | G10: =WeightCalculate!S17 -> 48.38781 | H10: =SUM($F$4:F10) -> 173 | I10: =IF(B10=1,E10/bet对应表!M13,IF(B10=9,E10/100,0)) -> 0.45 | J10: =SUM($I$4:I10) -> 1.325 | K10: =F10*QuestGetLevel!$D$51 -> 62000 | L10: =K10+L9 -> 173000 | M10: =J10/H10 -> 0.0076589595 | N10: 7 | O10: {=L10/(INDEX(bet对应表!F:F,MATCH($O$2,bet对应表!A:A,0),0))} -> #N/A | P10: {=L10/(INDEX(bet对应表!$F:$F,MATCH($P$2,bet对应表!$A:$A,0),0))} -> #N/A | Q10: {=L10/(INDEX(bet对应表!$F:$F,MATCH($Q$2,bet对应表!$A:$A,0),0))} -> #N/A | R10: {=L10/(INDEX(bet对应表!$F:$F,MATCH($R$2,bet对应表!$A:$A,0),0))} -> #N/A | S10: {=L10/(INDEX(bet对应表!$F:$F,MATCH($S$2,bet对应表!$A:$A,0),0))} -> #N/A | T10: {=L10/(INDEX(bet对应表!$F:$F,MATCH($T$2,bet对应表!$A:$A,0),0))} -> #N/A | U10: {=L10/(INDEX(bet对应表!$F:$F,MATCH($U$2,bet对应表!$A:$A,0),0))} -> #N/A | V10: {=L10/(INDEX(bet对应表!$F:$F,MATCH($V$2,bet对应表!$A:$A,0),0))} -> #N/A | W10: {=L10/(INDEX(bet对应表!$F:$F,MATCH($W$2,bet对应表!$A:$A,0),0))} -> #N/A | X10: {=L10/(INDEX(bet对应表!$F:$F,MATCH($X$2,bet对应表!$A:$A,0),0))} -> #N/A | Y10: {=L10/(INDEX(bet对应表!$F:$F,MATCH($Y$2,bet对应表!$A:$A,0),0))} -> #N/A | Z10: {=L10/(INDEX(bet对应表!$F:$F,MATCH($Z$2,bet对应表!$A:$A,0),0))} -> #N/A | AA10: {=L10/(INDEX(bet对应表!$F:$F,MATCH($AA$2,bet对应表!$A:$A,0),0))} -> #N/A | AB10: {=L10/(INDEX(bet对应表!$F:$F,MATCH($AB$2,bet对应表!$A:$A,0),0))} -> #N/A | AC10: {=L10/(INDEX(bet对应表!$F:$F,MATCH($AC$2,bet对应表!$A:$A,0),0))} -> #N/A | AD10: {=L10/(INDEX(bet对应表!$F:$F,MATCH($AD$2,bet对应表!$A:$A,0),0))} -> #N/A | AF10: 7 | AG10: {=L10/(INDEX(bet对应表!$F:$F,MATCH($AG$2,bet对应表!$A:$A,0),0))} -> #N/A | AH10: {=L10/(INDEX(bet对应表!$F:$F,MATCH($AH$2,bet对应表!$A:$A,0),0))} -> #N/A | AI10: {=L10/(INDEX(bet对应表!$F:$F,MATCH($AI$2,bet对应表!$A:$A,0),0))} -> #DIV/0! | AJ10: {=L10/(INDEX(bet对应表!$F:$F,MATCH($AJ$2,bet对应表!$A:$A,0),0))} -> #DIV/0! | AK10: {=L10/(INDEX(bet对应表!$F:$F,MATCH($AK$2,bet对应表!$A:$A,0),0))} -> #DIV/0! | AL10: {=L10/(INDEX(bet对应表!$F:$F,MATCH($AL$2,bet对应表!$A:$A,0),0))} -> #N/A | AM10: {=L10/(INDEX(bet对应表!$F:$F,MATCH($AM$2,bet对应表!$A:$A,0),0))} -> #N/A | AN10: {=L10/(INDEX(bet对应表!$F:$F,MATCH($AN$2,bet对应表!$A:$A,0),0))} -> #N/A | AO10: {=L10/(INDEX(bet对应表!$F:$F,MATCH($AO$2,bet对应表!$A:$A,0),0))} -> #N/A | AP10: {=L10/(INDEX(bet对应表!$F:$F,MATCH($AP$2,bet对应表!$A:$A,0),0))} -> #N/A
A11: 8 | B11: 9 | C11: 1 | D11: 5000 | E11: =1200/$D$30 -> 60 | F11: =ROUND(D11/G11,0) -> 99 | G11: =WeightCalculate!S20 -> 50.543605 | H11: =SUM($F$4:F11) -> 272 | I11: =IF(B11=1,E11/bet对应表!M14,IF(B11=9,E11/100,0)) -> 0.6 | J11: =SUM($I$4:I11)+E30 -> 2.925 | K11: =F11*QuestGetLevel!$D$51 -> 99000 | L11: =K11+L10 -> 272000 | M11: =J11/H11 -> 0.010753676 | N11: 8 | O11: {=L11/(INDEX(bet对应表!F:F,MATCH($O$2,bet对应表!A:A,0),0))} -> #N/A | P11: {=L11/(INDEX(bet对应表!$F:$F,MATCH($P$2,bet对应表!$A:$A,0),0))} -> #N/A | Q11: {=L11/(INDEX(bet对应表!$F:$F,MATCH($Q$2,bet对应表!$A:$A,0),0))} -> #N/A | R11: {=L11/(INDEX(bet对应表!$F:$F,MATCH($R$2,bet对应表!$A:$A,0),0))} -> #N/A | S11: {=L11/(INDEX(bet对应表!$F:$F,MATCH($S$2,bet对应表!$A:$A,0),0))} -> #N/A | T11: {=L11/(INDEX(bet对应表!$F:$F,MATCH($T$2,bet对应表!$A:$A,0),0))} -> #N/A | U11: {=L11/(INDEX(bet对应表!$F:$F,MATCH($U$2,bet对应表!$A:$A,0),0))} -> #N/A | V11: {=L11/(INDEX(bet对应表!$F:$F,MATCH($V$2,bet对应表!$A:$A,0),0))} -> #N/A | W11: {=L11/(INDEX(bet对应表!$F:$F,MATCH($W$2,bet对应表!$A:$A,0),0))} -> #N/A | X11: {=L11/(INDEX(bet对应表!$F:$F,MATCH($X$2,bet对应表!$A:$A,0),0))} -> #N/A | Y11: {=L11/(INDEX(bet对应表!$F:$F,MATCH($Y$2,bet对应表!$A:$A,0),0))} -> #N/A | Z11: {=L11/(INDEX(bet对应表!$F:$F,MATCH($Z$2,bet对应表!$A:$A,0),0))} -> #N/A | AA11: {=L11/(INDEX(bet对应表!$F:$F,MATCH($AA$2,bet对应表!$A:$A,0),0))} -> #N/A | AB11: {=L11/(INDEX(bet对应表!$F:$F,MATCH($AB$2,bet对应表!$A:$A,0),0))} -> #N/A | AC11: {=L11/(INDEX(bet对应表!$F:$F,MATCH($AC$2,bet对应表!$A:$A,0),0))} -> #N/A | AD11: {=L11/(INDEX(bet对应表!$F:$F,MATCH($AD$2,bet对应表!$A:$A,0),0))} -> #N/A | AF11: 8 | AG11: {=L11/(INDEX(bet对应表!$F:$F,MATCH($AG$2,bet对应表!$A:$A,0),0))} -> #N/A | AH11: {=L11/(INDEX(bet对应表!$F:$F,MATCH($AH$2,bet对应表!$A:$A,0),0))} -> #N/A | AI11: {=L11/(INDEX(bet对应表!$F:$F,MATCH($AI$2,bet对应表!$A:$A,0),0))} -> #DIV/0! | AJ11: {=L11/(INDEX(bet对应表!$F:$F,MATCH($AJ$2,bet对应表!$A:$A,0),0))} -> #DIV/0! | AK11: {=L11/(INDEX(bet对应表!$F:$F,MATCH($AK$2,bet对应表!$A:$A,0),0))} -> #DIV/0! | AL11: {=L11/(INDEX(bet对应表!$F:$F,MATCH($AL$2,bet对应表!$A:$A,0),0))} -> #N/A | AM11: {=L11/(INDEX(bet对应表!$F:$F,MATCH($AM$2,bet对应表!$A:$A,0),0))} -> #N/A | AN11: {=L11/(INDEX(bet对应表!$F:$F,MATCH($AN$2,bet对应表!$A:$A,0),0))} -> #N/A | AO11: {=L11/(INDEX(bet对应表!$F:$F,MATCH($AO$2,bet对应表!$A:$A,0),0))} -> #N/A | AP11: {=L11/(INDEX(bet对应表!$F:$F,MATCH($AP$2,bet对应表!$A:$A,0),0))} -> #N/A
A12: 1 | B12: 9 | C12: 1 | D12: 70 | E12: =ROUND(E4*3,0) -> 15 | F12: =ROUND(D12/G12,0) -> 3 | G12: =WeightCalculate!S3 -> 21.764706 | H12: =F12+H11 -> 275 | I12: =IF(B12=1,E12/bet对应表!M15,IF(B12=9,E12/100,0)) -> 0.15 | J12: =I12+J11 -> 3.075 | K12: =F12*QuestGetLevel!$D$149 -> 9000 | L12: =K12+L11 -> 281000 | M12: =J12/H12 -> 0.011181818 | N12: 9 | O12: {=L12/(INDEX(bet对应表!F:F,MATCH($O$2,bet对应表!A:A,0),0))} -> #N/A | P12: {=L12/(INDEX(bet对应表!$F:$F,MATCH($P$2,bet对应表!$A:$A,0),0))} -> #N/A | Q12: {=L12/(INDEX(bet对应表!$F:$F,MATCH($Q$2,bet对应表!$A:$A,0),0))} -> #N/A | R12: {=L12/(INDEX(bet对应表!$F:$F,MATCH($R$2,bet对应表!$A:$A,0),0))} -> #N/A | S12: {=L12/(INDEX(bet对应表!$F:$F,MATCH($S$2,bet对应表!$A:$A,0),0))} -> #N/A | T12: {=L12/(INDEX(bet对应表!$F:$F,MATCH($T$2,bet对应表!$A:$A,0),0))} -> #N/A | U12: {=L12/(INDEX(bet对应表!$F:$F,MATCH($U$2,bet对应表!$A:$A,0),0))} -> #N/A | V12: {=L12/(INDEX(bet对应表!$F:$F,MATCH($V$2,bet对应表!$A:$A,0),0))} -> #N/A | W12: {=L12/(INDEX(bet对应表!$F:$F,MATCH($W$2,bet对应表!$A:$A,0),0))} -> #N/A | X12: {=L12/(INDEX(bet对应表!$F:$F,MATCH($X$2,bet对应表!$A:$A,0),0))} -> #N/A | Y12: {=L12/(INDEX(bet对应表!$F:$F,MATCH($Y$2,bet对应表!$A:$A,0),0))} -> #N/A | Z12: {=L12/(INDEX(bet对应表!$F:$F,MATCH($Z$2,bet对应表!$A:$A,0),0))} -> #N/A | AA12: {=L12/(INDEX(bet对应表!$F:$F,MATCH($AA$2,bet对应表!$A:$A,0),0))} -> #N/A | AB12: {=L12/(INDEX(bet对应表!$F:$F,MATCH($AB$2,bet对应表!$A:$A,0),0))} -> #N/A | AC12: {=L12/(INDEX(bet对应表!$F:$F,MATCH($AC$2,bet对应表!$A:$A,0),0))} -> #N/A | AD12: {=L12/(INDEX(bet对应表!$F:$F,MATCH($AD$2,bet对应表!$A:$A,0),0))} -> #N/A | AF12: 9 | AG12: {=L12/(INDEX(bet对应表!$F:$F,MATCH($AG$2,bet对应表!$A:$A,0),0))} -> #N/A | AH12: {=L12/(INDEX(bet对应表!$F:$F,MATCH($AH$2,bet对应表!$A:$A,0),0))} -> #N/A | AI12: {=L12/(INDEX(bet对应表!$F:$F,MATCH($AI$2,bet对应表!$A:$A,0),0))} -> #DIV/0! | AJ12: {=L12/(INDEX(bet对应表!$F:$F,MATCH($AJ$2,bet对应表!$A:$A,0),0))} -> #DIV/0! | AK12: {=L12/(INDEX(bet对应表!$F:$F,MATCH($AK$2,bet对应表!$A:$A,0),0))} -> #DIV/0! | AL12: {=L12/(INDEX(bet对应表!$F:$F,MATCH($AL$2,bet对应表!$A:$A,0),0))} -> #N/A | AM12: {=L12/(INDEX(bet对应表!$F:$F,MATCH($AM$2,bet对应表!$A:$A,0),0))} -> #N/A | AN12: {=L12/(INDEX(bet对应表!$F:$F,MATCH($AN$2,bet对应表!$A:$A,0),0))} -> #N/A | AO12: {=L12/(INDEX(bet对应表!$F:$F,MATCH($AO$2,bet对应表!$A:$A,0),0))} -> #N/A | AP12: {=L12/(INDEX(bet对应表!$F:$F,MATCH($AP$2,bet对应表!$A:$A,0),0))} -> #N/A
A13: 2 | B13: 9 | C13: 1 | D13: 150 | E13: =ROUND(E5*3,0) -> 23 | F13: =ROUND(D13/G13,0) -> 6 | G13: =WeightCalculate!S4 -> 24.354704 | H13: =F13+H12 -> 281 | I13: =IF(B13=1,E13/bet对应表!M16,IF(B13=9,E13/100,0)) -> 0.23 | J13: =I13+J12 -> 3.305 | K13: =F13*QuestGetLevel!$D$149 -> 18000 | L13: =K13+L12 -> 299000 | M13: =J13/H13 -> 0.011761566 | N13: 10 | O13: {=L13/(INDEX(bet对应表!F:F,MATCH($O$2,bet对应表!A:A,0),0))} -> #N/A | P13: {=L13/(INDEX(bet对应表!$F:$F,MATCH($P$2,bet对应表!$A:$A,0),0))} -> #N/A | Q13: {=L13/(INDEX(bet对应表!$F:$F,MATCH($Q$2,bet对应表!$A:$A,0),0))} -> #N/A | R13: {=L13/(INDEX(bet对应表!$F:$F,MATCH($R$2,bet对应表!$A:$A,0),0))} -> #N/A | S13: {=L13/(INDEX(bet对应表!$F:$F,MATCH($S$2,bet对应表!$A:$A,0),0))} -> #N/A | T13: {=L13/(INDEX(bet对应表!$F:$F,MATCH($T$2,bet对应表!$A:$A,0),0))} -> #N/A | U13: {=L13/(INDEX(bet对应表!$F:$F,MATCH($U$2,bet对应表!$A:$A,0),0))} -> #N/A | V13: {=L13/(INDEX(bet对应表!$F:$F,MATCH($V$2,bet对应表!$A:$A,0),0))} -> #N/A | W13: {=L13/(INDEX(bet对应表!$F:$F,MATCH($W$2,bet对应表!$A:$A,0),0))} -> #N/A | X13: {=L13/(INDEX(bet对应表!$F:$F,MATCH($X$2,bet对应表!$A:$A,0),0))} -> #N/A | Y13: {=L13/(INDEX(bet对应表!$F:$F,MATCH($Y$2,bet对应表!$A:$A,0),0))} -> #N/A | Z13: {=L13/(INDEX(bet对应表!$F:$F,MATCH($Z$2,bet对应表!$A:$A,0),0))} -> #N/A | AA13: {=L13/(INDEX(bet对应表!$F:$F,MATCH($AA$2,bet对应表!$A:$A,0),0))} -> #N/A | AB13: {=L13/(INDEX(bet对应表!$F:$F,MATCH($AB$2,bet对应表!$A:$A,0),0))} -> #N/A | AC13: {=L13/(INDEX(bet对应表!$F:$F,MATCH($AC$2,bet对应表!$A:$A,0),0))} -> #N/A | AD13: {=L13/(INDEX(bet对应表!$F:$F,MATCH($AD$2,bet对应表!$A:$A,0),0))} -> #N/A | AF13: 10 | AG13: {=L13/(INDEX(bet对应表!$F:$F,MATCH($AG$2,bet对应表!$A:$A,0),0))} -> #N/A | AH13: {=L13/(INDEX(bet对应表!$F:$F,MATCH($AH$2,bet对应表!$A:$A,0),0))} -> #N/A | AI13: {=L13/(INDEX(bet对应表!$F:$F,MATCH($AI$2,bet对应表!$A:$A,0),0))} -> #DIV/0! | AJ13: {=L13/(INDEX(bet对应表!$F:$F,MATCH($AJ$2,bet对应表!$A:$A,0),0))} -> #DIV/0! | AK13: {=L13/(INDEX(bet对应表!$F:$F,MATCH($AK$2,bet对应表!$A:$A,0),0))} -> #DIV/0! | AL13: {=L13/(INDEX(bet对应表!$F:$F,MATCH($AL$2,bet对应表!$A:$A,0),0))} -> #N/A | AM13: {=L13/(INDEX(bet对应表!$F:$F,MATCH($AM$2,bet对应表!$A:$A,0),0))} -> #N/A | AN13: {=L13/(INDEX(bet对应表!$F:$F,MATCH($AN$2,bet对应表!$A:$A,0),0))} -> #N/A | AO13: {=L13/(INDEX(bet对应表!$F:$F,MATCH($AO$2,bet对应表!$A:$A,0),0))} -> #N/A | AP13: {=L13/(INDEX(bet对应表!$F:$F,MATCH($AP$2,bet对应表!$A:$A,0),0))} -> #N/A
A14: 3 | B14: 9 | C14: 1 | D14: 300 | E14: =ROUND(E6*3,0) -> 30 | F14: =ROUND(D14/G14,0) -> 11 | G14: =WeightCalculate!S5 -> 28.004441 | H14: =F14+H13 -> 292 | I14: =IF(B14=1,E14/bet对应表!M17,IF(B14=9,E14/100,0)) -> 0.3 | J14: =I14+J13 -> 3.605 | K14: =F14*QuestGetLevel!$D$149 -> 33000 | L14: =K14+L13 -> 332000 | M14: =J14/H14 -> 0.01234589 | N14: 11 | O14: {=L14/(INDEX(bet对应表!F:F,MATCH($O$2,bet对应表!A:A,0),0))} -> #N/A | P14: {=L14/(INDEX(bet对应表!$F:$F,MATCH($P$2,bet对应表!$A:$A,0),0))} -> #N/A | Q14: {=L14/(INDEX(bet对应表!$F:$F,MATCH($Q$2,bet对应表!$A:$A,0),0))} -> #N/A | R14: {=L14/(INDEX(bet对应表!$F:$F,MATCH($R$2,bet对应表!$A:$A,0),0))} -> #N/A | S14: {=L14/(INDEX(bet对应表!$F:$F,MATCH($S$2,bet对应表!$A:$A,0),0))} -> #N/A | T14: {=L14/(INDEX(bet对应表!$F:$F,MATCH($T$2,bet对应表!$A:$A,0),0))} -> #N/A | U14: {=L14/(INDEX(bet对应表!$F:$F,MATCH($U$2,bet对应表!$A:$A,0),0))} -> #N/A | V14: {=L14/(INDEX(bet对应表!$F:$F,MATCH($V$2,bet对应表!$A:$A,0),0))} -> #N/A | W14: {=L14/(INDEX(bet对应表!$F:$F,MATCH($W$2,bet对应表!$A:$A,0),0))} -> #N/A | X14: {=L14/(INDEX(bet对应表!$F:$F,MATCH($X$2,bet对应表!$A:$A,0),0))} -> #N/A | Y14: {=L14/(INDEX(bet对应表!$F:$F,MATCH($Y$2,bet对应表!$A:$A,0),0))} -> #N/A | Z14: {=L14/(INDEX(bet对应表!$F:$F,MATCH($Z$2,bet对应表!$A:$A,0),0))} -> #N/A | AA14: {=L14/(INDEX(bet对应表!$F:$F,MATCH($AA$2,bet对应表!$A:$A,0),0))} -> #N/A | AB14: {=L14/(INDEX(bet对应表!$F:$F,MATCH($AB$2,bet对应表!$A:$A,0),0))} -> #N/A | AC14: {=L14/(INDEX(bet对应表!$F:$F,MATCH($AC$2,bet对应表!$A:$A,0),0))} -> #N/A | AD14: {=L14/(INDEX(bet对应表!$F:$F,MATCH($AD$2,bet对应表!$A:$A,0),0))} -> #N/A | AF14: 11 | AG14: {=L14/(INDEX(bet对应表!$F:$F,MATCH($AG$2,bet对应表!$A:$A,0),0))} -> #N/A | AH14: {=L14/(INDEX(bet对应表!$F:$F,MATCH($AH$2,bet对应表!$A:$A,0),0))} -> #N/A | AI14: {=L14/(INDEX(bet对应表!$F:$F,MATCH($AI$2,bet对应表!$A:$A,0),0))} -> #DIV/0! | AJ14: {=L14/(INDEX(bet对应表!$F:$F,MATCH($AJ$2,bet对应表!$A:$A,0),0))} -> #DIV/0! | AK14: {=L14/(INDEX(bet对应表!$F:$F,MATCH($AK$2,bet对应表!$A:$A,0),0))} -> #DIV/0! | AL14: {=L14/(INDEX(bet对应表!$F:$F,MATCH($AL$2,bet对应表!$A:$A,0),0))} -> #N/A | AM14: {=L14/(INDEX(bet对应表!$F:$F,MATCH($AM$2,bet对应表!$A:$A,0),0))} -> #N/A | AN14: {=L14/(INDEX(bet对应表!$F:$F,MATCH($AN$2,bet对应表!$A:$A,0),0))} -> #N/A | AO14: {=L14/(INDEX(bet对应表!$F:$F,MATCH($AO$2,bet对应表!$A:$A,0),0))} -> #N/A | AP14: {=L14/(INDEX(bet对应表!$F:$F,MATCH($AP$2,bet对应表!$A:$A,0),0))} -> #N/A
A15: 4 | B15: 9 | C15: 1 | D15: 600 | E15: =ROUND(E7*3,0) -> 45 | F15: =ROUND(D15/G15,0) -> 18 | G15: =WeightCalculate!S8 -> 33.162309 | H15: =F15+H14 -> 310 | I15: =IF(B15=1,E15/bet对应表!M18,IF(B15=9,E15/100,0)) -> 0.45 | J15: =I15+J14 -> 4.055 | K15: =F15*QuestGetLevel!$D$149 -> 54000 | L15: =K15+L14 -> 386000 | M15: =J15/H15 -> 0.013080645 | N15: 12 | O15: {=L15/(INDEX(bet对应表!F:F,MATCH($O$2,bet对应表!A:A,0),0))} -> #N/A | P15: {=L15/(INDEX(bet对应表!$F:$F,MATCH($P$2,bet对应表!$A:$A,0),0))} -> #N/A | Q15: {=L15/(INDEX(bet对应表!$F:$F,MATCH($Q$2,bet对应表!$A:$A,0),0))} -> #N/A | R15: {=L15/(INDEX(bet对应表!$F:$F,MATCH($R$2,bet对应表!$A:$A,0),0))} -> #N/A | S15: {=L15/(INDEX(bet对应表!$F:$F,MATCH($S$2,bet对应表!$A:$A,0),0))} -> #N/A | T15: {=L15/(INDEX(bet对应表!$F:$F,MATCH($T$2,bet对应表!$A:$A,0),0))} -> #N/A | U15: {=L15/(INDEX(bet对应表!$F:$F,MATCH($U$2,bet对应表!$A:$A,0),0))} -> #N/A | V15: {=L15/(INDEX(bet对应表!$F:$F,MATCH($V$2,bet对应表!$A:$A,0),0))} -> #N/A | W15: {=L15/(INDEX(bet对应表!$F:$F,MATCH($W$2,bet对应表!$A:$A,0),0))} -> #N/A | X15: {=L15/(INDEX(bet对应表!$F:$F,MATCH($X$2,bet对应表!$A:$A,0),0))} -> #N/A | Y15: {=L15/(INDEX(bet对应表!$F:$F,MATCH($Y$2,bet对应表!$A:$A,0),0))} -> #N/A | Z15: {=L15/(INDEX(bet对应表!$F:$F,MATCH($Z$2,bet对应表!$A:$A,0),0))} -> #N/A | AA15: {=L15/(INDEX(bet对应表!$F:$F,MATCH($AA$2,bet对应表!$A:$A,0),0))} -> #N/A | AB15: {=L15/(INDEX(bet对应表!$F:$F,MATCH($AB$2,bet对应表!$A:$A,0),0))} -> #N/A | AC15: {=L15/(INDEX(bet对应表!$F:$F,MATCH($AC$2,bet对应表!$A:$A,0),0))} -> #N/A | AD15: {=L15/(INDEX(bet对应表!$F:$F,MATCH($AD$2,bet对应表!$A:$A,0),0))} -> #N/A | AF15: 12 | AG15: {=L15/(INDEX(bet对应表!$F:$F,MATCH($AG$2,bet对应表!$A:$A,0),0))} -> #N/A | AH15: {=L15/(INDEX(bet对应表!$F:$F,MATCH($AH$2,bet对应表!$A:$A,0),0))} -> #N/A | AI15: {=L15/(INDEX(bet对应表!$F:$F,MATCH($AI$2,bet对应表!$A:$A,0),0))} -> #DIV/0! | AJ15: {=L15/(INDEX(bet对应表!$F:$F,MATCH($AJ$2,bet对应表!$A:$A,0),0))} -> #DIV/0! | AK15: {=L15/(INDEX(bet对应表!$F:$F,MATCH($AK$2,bet对应表!$A:$A,0),0))} -> #DIV/0! | AL15: {=L15/(INDEX(bet对应表!$F:$F,MATCH($AL$2,bet对应表!$A:$A,0),0))} -> #N/A | AM15: {=L15/(INDEX(bet对应表!$F:$F,MATCH($AM$2,bet对应表!$A:$A,0),0))} -> #N/A | AN15: {=L15/(INDEX(bet对应表!$F:$F,MATCH($AN$2,bet对应表!$A:$A,0),0))} -> #N/A | AO15: {=L15/(INDEX(bet对应表!$F:$F,MATCH($AO$2,bet对应表!$A:$A,0),0))} -> #N/A | AP15: {=L15/(INDEX(bet对应表!$F:$F,MATCH($AP$2,bet对应表!$A:$A,0),0))} -> #N/A
A16: 5 | B16: 9 | C16: 1 | D16: 1200 | E16: =ROUND(E8*3,0) -> 60 | F16: =ROUND(D16/G16,0) -> 33 | G16: =WeightCalculate!S11 -> 36.130734 | H16: =F16+H15 -> 343 | I16: =IF(B16=1,E16/bet对应表!M19,IF(B16=9,E16/100,0)) -> 0.6 | J16: =I16+J15 -> 4.655 | K16: =F16*QuestGetLevel!$D$149 -> 99000 | L16: =K16+L15 -> 485000 | M16: =J16/H16 -> 0.013571429 | N16: 13 | O16: {=L16/(INDEX(bet对应表!F:F,MATCH($O$2,bet对应表!A:A,0),0))} -> #N/A | P16: {=L16/(INDEX(bet对应表!$F:$F,MATCH($P$2,bet对应表!$A:$A,0),0))} -> #N/A | Q16: {=L16/(INDEX(bet对应表!$F:$F,MATCH($Q$2,bet对应表!$A:$A,0),0))} -> #N/A | R16: {=L16/(INDEX(bet对应表!$F:$F,MATCH($R$2,bet对应表!$A:$A,0),0))} -> #N/A | S16: {=L16/(INDEX(bet对应表!$F:$F,MATCH($S$2,bet对应表!$A:$A,0),0))} -> #N/A | T16: {=L16/(INDEX(bet对应表!$F:$F,MATCH($T$2,bet对应表!$A:$A,0),0))} -> #N/A | U16: {=L16/(INDEX(bet对应表!$F:$F,MATCH($U$2,bet对应表!$A:$A,0),0))} -> #N/A | V16: {=L16/(INDEX(bet对应表!$F:$F,MATCH($V$2,bet对应表!$A:$A,0),0))} -> #N/A | W16: {=L16/(INDEX(bet对应表!$F:$F,MATCH($W$2,bet对应表!$A:$A,0),0))} -> #N/A | X16: {=L16/(INDEX(bet对应表!$F:$F,MATCH($X$2,bet对应表!$A:$A,0),0))} -> #N/A | Y16: {=L16/(INDEX(bet对应表!$F:$F,MATCH($Y$2,bet对应表!$A:$A,0),0))} -> #N/A | Z16: {=L16/(INDEX(bet对应表!$F:$F,MATCH($Z$2,bet对应表!$A:$A,0),0))} -> #N/A | AA16: {=L16/(INDEX(bet对应表!$F:$F,MATCH($AA$2,bet对应表!$A:$A,0),0))} -> #N/A | AB16: {=L16/(INDEX(bet对应表!$F:$F,MATCH($AB$2,bet对应表!$A:$A,0),0))} -> #N/A | AC16: {=L16/(INDEX(bet对应表!$F:$F,MATCH($AC$2,bet对应表!$A:$A,0),0))} -> #N/A | AD16: {=L16/(INDEX(bet对应表!$F:$F,MATCH($AD$2,bet对应表!$A:$A,0),0))} -> #N/A | AF16: 13 | AG16: {=L16/(INDEX(bet对应表!$F:$F,MATCH($AG$2,bet对应表!$A:$A,0),0))} -> #N/A | AH16: {=L16/(INDEX(bet对应表!$F:$F,MATCH($AH$2,bet对应表!$A:$A,0),0))} -> #N/A | AI16: {=L16/(INDEX(bet对应表!$F:$F,MATCH($AI$2,bet对应表!$A:$A,0),0))} -> #DIV/0! | AJ16: {=L16/(INDEX(bet对应表!$F:$F,MATCH($AJ$2,bet对应表!$A:$A,0),0))} -> #DIV/0! | AK16: {=L16/(INDEX(bet对应表!$F:$F,MATCH($AK$2,bet对应表!$A:$A,0),0))} -> #DIV/0! | AL16: {=L16/(INDEX(bet对应表!$F:$F,MATCH($AL$2,bet对应表!$A:$A,0),0))} -> #N/A | AM16: {=L16/(INDEX(bet对应表!$F:$F,MATCH($AM$2,bet对应表!$A:$A,0),0))} -> #N/A | AN16: {=L16/(INDEX(bet对应表!$F:$F,MATCH($AN$2,bet对应表!$A:$A,0),0))} -> #N/A | AO16: {=L16/(INDEX(bet对应表!$F:$F,MATCH($AO$2,bet对应表!$A:$A,0),0))} -> #N/A | AP16: {=L16/(INDEX(bet对应表!$F:$F,MATCH($AP$2,bet对应表!$A:$A,0),0))} -> #N/A
A17: 6 | B17: 9 | C17: 1 | D17: 2500 | E17: =ROUND(E9*3,0) -> 90 | F17: =ROUND(D17/G17,0) -> 56 | G17: =WeightCalculate!S14 -> 44.573014 | H17: =F17+H16 -> 399 | I17: =IF(B17=1,E17/bet对应表!M20,IF(B17=9,E17/100,0)) -> 0.9 | J17: =I17+J16 -> 5.555 | K17: =F17*QuestGetLevel!$D$149 -> 168000 | L17: =K17+L16 -> 653000 | M17: =J17/H17 -> 0.013922306 | N17: 14 | O17: {=L17/(INDEX(bet对应表!F:F,MATCH($O$2,bet对应表!A:A,0),0))} -> #N/A | P17: {=L17/(INDEX(bet对应表!$F:$F,MATCH($P$2,bet对应表!$A:$A,0),0))} -> #N/A | Q17: {=L17/(INDEX(bet对应表!$F:$F,MATCH($Q$2,bet对应表!$A:$A,0),0))} -> #N/A | R17: {=L17/(INDEX(bet对应表!$F:$F,MATCH($R$2,bet对应表!$A:$A,0),0))} -> #N/A | S17: {=L17/(INDEX(bet对应表!$F:$F,MATCH($S$2,bet对应表!$A:$A,0),0))} -> #N/A | T17: {=L17/(INDEX(bet对应表!$F:$F,MATCH($T$2,bet对应表!$A:$A,0),0))} -> #N/A | U17: {=L17/(INDEX(bet对应表!$F:$F,MATCH($U$2,bet对应表!$A:$A,0),0))} -> #N/A | V17: {=L17/(INDEX(bet对应表!$F:$F,MATCH($V$2,bet对应表!$A:$A,0),0))} -> #N/A | W17: {=L17/(INDEX(bet对应表!$F:$F,MATCH($W$2,bet对应表!$A:$A,0),0))} -> #N/A | X17: {=L17/(INDEX(bet对应表!$F:$F,MATCH($X$2,bet对应表!$A:$A,0),0))} -> #N/A | Y17: {=L17/(INDEX(bet对应表!$F:$F,MATCH($Y$2,bet对应表!$A:$A,0),0))} -> #N/A | Z17: {=L17/(INDEX(bet对应表!$F:$F,MATCH($Z$2,bet对应表!$A:$A,0),0))} -> #N/A | AA17: {=L17/(INDEX(bet对应表!$F:$F,MATCH($AA$2,bet对应表!$A:$A,0),0))} -> #N/A | AB17: {=L17/(INDEX(bet对应表!$F:$F,MATCH($AB$2,bet对应表!$A:$A,0),0))} -> #N/A | AC17: {=L17/(INDEX(bet对应表!$F:$F,MATCH($AC$2,bet对应表!$A:$A,0),0))} -> #N/A | AD17: {=L17/(INDEX(bet对应表!$F:$F,MATCH($AD$2,bet对应表!$A:$A,0),0))} -> #N/A | AF17: 14 | AG17: {=L17/(INDEX(bet对应表!$F:$F,MATCH($AG$2,bet对应表!$A:$A,0),0))} -> #N/A | AH17: {=L17/(INDEX(bet对应表!$F:$F,MATCH($AH$2,bet对应表!$A:$A,0),0))} -> #N/A | AI17: {=L17/(INDEX(bet对应表!$F:$F,MATCH($AI$2,bet对应表!$A:$A,0),0))} -> #DIV/0! | AJ17: {=L17/(INDEX(bet对应表!$F:$F,MATCH($AJ$2,bet对应表!$A:$A,0),0))} -> #DIV/0! | AK17: {=L17/(INDEX(bet对应表!$F:$F,MATCH($AK$2,bet对应表!$A:$A,0),0))} -> #DIV/0! | AL17: {=L17/(INDEX(bet对应表!$F:$F,MATCH($AL$2,bet对应表!$A:$A,0),0))} -> #N/A | AM17: {=L17/(INDEX(bet对应表!$F:$F,MATCH($AM$2,bet对应表!$A:$A,0),0))} -> #N/A | AN17: {=L17/(INDEX(bet对应表!$F:$F,MATCH($AN$2,bet对应表!$A:$A,0),0))} -> #N/A | AO17: {=L17/(INDEX(bet对应表!$F:$F,MATCH($AO$2,bet对应表!$A:$A,0),0))} -> #N/A | AP17: {=L17/(INDEX(bet对应表!$F:$F,MATCH($AP$2,bet对应表!$A:$A,0),0))} -> #N/A
A18: 7 | B18: 9 | C18: 1 | D18: 4000 | E18: =ROUND(E10*3,0) -> 135 | F18: =ROUND(D18/G18,0) -> 83 | G18: =WeightCalculate!S17 -> 48.38781 | H18: =F18+H17 -> 482 | I18: =IF(B18=1,E18/bet对应表!M21,IF(B18=9,E18/100,0)) -> 1.35 | J18: =I18+J17 -> 6.905 | K18: =F18*QuestGetLevel!$D$149 -> 249000 | L18: =K18+L17 -> 902000 | M18: =J18/H18 -> 0.014325726 | N18: 15 | O18: {=L18/(INDEX(bet对应表!F:F,MATCH($O$2,bet对应表!A:A,0),0))} -> #N/A | P18: {=L18/(INDEX(bet对应表!$F:$F,MATCH($P$2,bet对应表!$A:$A,0),0))} -> #N/A | Q18: {=L18/(INDEX(bet对应表!$F:$F,MATCH($Q$2,bet对应表!$A:$A,0),0))} -> #N/A | R18: {=L18/(INDEX(bet对应表!$F:$F,MATCH($R$2,bet对应表!$A:$A,0),0))} -> #N/A | S18: {=L18/(INDEX(bet对应表!$F:$F,MATCH($S$2,bet对应表!$A:$A,0),0))} -> #N/A | T18: {=L18/(INDEX(bet对应表!$F:$F,MATCH($T$2,bet对应表!$A:$A,0),0))} -> #N/A | U18: {=L18/(INDEX(bet对应表!$F:$F,MATCH($U$2,bet对应表!$A:$A,0),0))} -> #N/A | V18: {=L18/(INDEX(bet对应表!$F:$F,MATCH($V$2,bet对应表!$A:$A,0),0))} -> #N/A | W18: {=L18/(INDEX(bet对应表!$F:$F,MATCH($W$2,bet对应表!$A:$A,0),0))} -> #N/A | X18: {=L18/(INDEX(bet对应表!$F:$F,MATCH($X$2,bet对应表!$A:$A,0),0))} -> #N/A | Y18: {=L18/(INDEX(bet对应表!$F:$F,MATCH($Y$2,bet对应表!$A:$A,0),0))} -> #N/A | Z18: {=L18/(INDEX(bet对应表!$F:$F,MATCH($Z$2,bet对应表!$A:$A,0),0))} -> #N/A | AA18: {=L18/(INDEX(bet对应表!$F:$F,MATCH($AA$2,bet对应表!$A:$A,0),0))} -> #N/A | AB18: {=L18/(INDEX(bet对应表!$F:$F,MATCH($AB$2,bet对应表!$A:$A,0),0))} -> #N/A | AC18: {=L18/(INDEX(bet对应表!$F:$F,MATCH($AC$2,bet对应表!$A:$A,0),0))} -> #N/A | AD18: {=L18/(INDEX(bet对应表!$F:$F,MATCH($AD$2,bet对应表!$A:$A,0),0))} -> #N/A | AF18: 15 | AG18: {=L18/(INDEX(bet对应表!$F:$F,MATCH($AG$2,bet对应表!$A:$A,0),0))} -> #N/A | AH18: {=L18/(INDEX(bet对应表!$F:$F,MATCH($AH$2,bet对应表!$A:$A,0),0))} -> #N/A | AI18: {=L18/(INDEX(bet对应表!$F:$F,MATCH($AI$2,bet对应表!$A:$A,0),0))} -> #DIV/0! | AJ18: {=L18/(INDEX(bet对应表!$F:$F,MATCH($AJ$2,bet对应表!$A:$A,0),0))} -> #DIV/0! | AK18: {=L18/(INDEX(bet对应表!$F:$F,MATCH($AK$2,bet对应表!$A:$A,0),0))} -> #DIV/0! | AL18: {=L18/(INDEX(bet对应表!$F:$F,MATCH($AL$2,bet对应表!$A:$A,0),0))} -> #N/A | AM18: {=L18/(INDEX(bet对应表!$F:$F,MATCH($AM$2,bet对应表!$A:$A,0),0))} -> #N/A | AN18: {=L18/(INDEX(bet对应表!$F:$F,MATCH($AN$2,bet对应表!$A:$A,0),0))} -> #N/A | AO18: {=L18/(INDEX(bet对应表!$F:$F,MATCH($AO$2,bet对应表!$A:$A,0),0))} -> #N/A | AP18: {=L18/(INDEX(bet对应表!$F:$F,MATCH($AP$2,bet对应表!$A:$A,0),0))} -> #N/A
A19: 8 | B19: 9 | C19: 1 | D19: 6000 | E19: =ROUND(E11*3,0) -> 180 | F19: =ROUND(D19/G19,0) -> 119 | G19: =WeightCalculate!S20 -> 50.543605 | H19: =F19+H18 -> 601 | I19: =IF(B19=1,E19/bet对应表!M22,IF(B19=9,E19/100,0)) -> 1.8 | J19: =I19+J18+E31 -> 11.705 | K19: =F19*QuestGetLevel!$D$149 -> 357000 | L19: =K19+L18 -> 1259000 | M19: =J19/H19 -> 0.019475874 | N19: 16 | O19: {=L19/(INDEX(bet对应表!F:F,MATCH($O$2,bet对应表!A:A,0),0))} -> #N/A | P19: {=L19/(INDEX(bet对应表!$F:$F,MATCH($P$2,bet对应表!$A:$A,0),0))} -> #N/A | Q19: {=L19/(INDEX(bet对应表!$F:$F,MATCH($Q$2,bet对应表!$A:$A,0),0))} -> #N/A | R19: {=L19/(INDEX(bet对应表!$F:$F,MATCH($R$2,bet对应表!$A:$A,0),0))} -> #N/A | S19: {=L19/(INDEX(bet对应表!$F:$F,MATCH($S$2,bet对应表!$A:$A,0),0))} -> #N/A | T19: {=L19/(INDEX(bet对应表!$F:$F,MATCH($T$2,bet对应表!$A:$A,0),0))} -> #N/A | U19: {=L19/(INDEX(bet对应表!$F:$F,MATCH($U$2,bet对应表!$A:$A,0),0))} -> #N/A | V19: {=L19/(INDEX(bet对应表!$F:$F,MATCH($V$2,bet对应表!$A:$A,0),0))} -> #N/A | W19: {=L19/(INDEX(bet对应表!$F:$F,MATCH($W$2,bet对应表!$A:$A,0),0))} -> #N/A | X19: {=L19/(INDEX(bet对应表!$F:$F,MATCH($X$2,bet对应表!$A:$A,0),0))} -> #N/A | Y19: {=L19/(INDEX(bet对应表!$F:$F,MATCH($Y$2,bet对应表!$A:$A,0),0))} -> #N/A | Z19: {=L19/(INDEX(bet对应表!$F:$F,MATCH($Z$2,bet对应表!$A:$A,0),0))} -> #N/A | AA19: {=L19/(INDEX(bet对应表!$F:$F,MATCH($AA$2,bet对应表!$A:$A,0),0))} -> #N/A | AB19: {=L19/(INDEX(bet对应表!$F:$F,MATCH($AB$2,bet对应表!$A:$A,0),0))} -> #N/A | AC19: {=L19/(INDEX(bet对应表!$F:$F,MATCH($AC$2,bet对应表!$A:$A,0),0))} -> #N/A | AD19: {=L19/(INDEX(bet对应表!$F:$F,MATCH($AD$2,bet对应表!$A:$A,0),0))} -> #N/A | AF19: 16 | AG19: {=L19/(INDEX(bet对应表!$F:$F,MATCH($AG$2,bet对应表!$A:$A,0),0))} -> #N/A | AH19: {=L19/(INDEX(bet对应表!$F:$F,MATCH($AH$2,bet对应表!$A:$A,0),0))} -> #N/A | AI19: {=L19/(INDEX(bet对应表!$F:$F,MATCH($AI$2,bet对应表!$A:$A,0),0))} -> #DIV/0! | AJ19: {=L19/(INDEX(bet对应表!$F:$F,MATCH($AJ$2,bet对应表!$A:$A,0),0))} -> #DIV/0! | AK19: {=L19/(INDEX(bet对应表!$F:$F,MATCH($AK$2,bet对应表!$A:$A,0),0))} -> #DIV/0! | AL19: {=L19/(INDEX(bet对应表!$F:$F,MATCH($AL$2,bet对应表!$A:$A,0),0))} -> #N/A | AM19: {=L19/(INDEX(bet对应表!$F:$F,MATCH($AM$2,bet对应表!$A:$A,0),0))} -> #N/A | AN19: {=L19/(INDEX(bet对应表!$F:$F,MATCH($AN$2,bet对应表!$A:$A,0),0))} -> #N/A | AO19: {=L19/(INDEX(bet对应表!$F:$F,MATCH($AO$2,bet对应表!$A:$A,0),0))} -> #N/A | AP19: {=L19/(INDEX(bet对应表!$F:$F,MATCH($AP$2,bet对应表!$A:$A,0),0))} -> #N/A
A20: 1 | B20: 9 | C20: 1 | D20: 70 | E20: =ROUND(E4*10,0) -> 50 | F20: =ROUND(D20/G20,0) -> 3 | G20: =WeightCalculate!S3 -> 21.764706 | H20: =F20+H19 -> 604 | I20: =IF(B20=1,E20/bet对应表!M23,IF(B20=9,E20/100,0)) -> 0.5 | J20: =I20+J19 -> 12.205 | K20: =F20*QuestGetLevel!$D$274 -> 45000 | L20: =K20+L19 -> 1304000 | M20: =J20/H20 -> 0.020206954 | N20: 17 | O20: {=L20/(INDEX(bet对应表!F:F,MATCH($O$2,bet对应表!A:A,0),0))} -> #N/A | P20: {=L20/(INDEX(bet对应表!$F:$F,MATCH($P$2,bet对应表!$A:$A,0),0))} -> #N/A | Q20: {=L20/(INDEX(bet对应表!$F:$F,MATCH($Q$2,bet对应表!$A:$A,0),0))} -> #N/A | R20: {=L20/(INDEX(bet对应表!$F:$F,MATCH($R$2,bet对应表!$A:$A,0),0))} -> #N/A | S20: {=L20/(INDEX(bet对应表!$F:$F,MATCH($S$2,bet对应表!$A:$A,0),0))} -> #N/A | T20: {=L20/(INDEX(bet对应表!$F:$F,MATCH($T$2,bet对应表!$A:$A,0),0))} -> #N/A | U20: {=L20/(INDEX(bet对应表!$F:$F,MATCH($U$2,bet对应表!$A:$A,0),0))} -> #N/A | V20: {=L20/(INDEX(bet对应表!$F:$F,MATCH($V$2,bet对应表!$A:$A,0),0))} -> #N/A | W20: {=L20/(INDEX(bet对应表!$F:$F,MATCH($W$2,bet对应表!$A:$A,0),0))} -> #N/A | X20: {=L20/(INDEX(bet对应表!$F:$F,MATCH($X$2,bet对应表!$A:$A,0),0))} -> #N/A | Y20: {=L20/(INDEX(bet对应表!$F:$F,MATCH($Y$2,bet对应表!$A:$A,0),0))} -> #N/A | Z20: {=L20/(INDEX(bet对应表!$F:$F,MATCH($Z$2,bet对应表!$A:$A,0),0))} -> #N/A | AA20: {=L20/(INDEX(bet对应表!$F:$F,MATCH($AA$2,bet对应表!$A:$A,0),0))} -> #N/A | AB20: {=L20/(INDEX(bet对应表!$F:$F,MATCH($AB$2,bet对应表!$A:$A,0),0))} -> #N/A | AC20: {=L20/(INDEX(bet对应表!$F:$F,MATCH($AC$2,bet对应表!$A:$A,0),0))} -> #N/A | AD20: {=L20/(INDEX(bet对应表!$F:$F,MATCH($AD$2,bet对应表!$A:$A,0),0))} -> #N/A | AF20: 17 | AG20: {=L20/(INDEX(bet对应表!$F:$F,MATCH($AG$2,bet对应表!$A:$A,0),0))} -> #N/A | AH20: {=L20/(INDEX(bet对应表!$F:$F,MATCH($AH$2,bet对应表!$A:$A,0),0))} -> #N/A | AI20: {=L20/(INDEX(bet对应表!$F:$F,MATCH($AI$2,bet对应表!$A:$A,0),0))} -> #DIV/0! | AJ20: {=L20/(INDEX(bet对应表!$F:$F,MATCH($AJ$2,bet对应表!$A:$A,0),0))} -> #DIV/0! | AK20: {=L20/(INDEX(bet对应表!$F:$F,MATCH($AK$2,bet对应表!$A:$A,0),0))} -> #DIV/0! | AL20: {=L20/(INDEX(bet对应表!$F:$F,MATCH($AL$2,bet对应表!$A:$A,0),0))} -> #N/A | AM20: {=L20/(INDEX(bet对应表!$F:$F,MATCH($AM$2,bet对应表!$A:$A,0),0))} -> #N/A | AN20: {=L20/(INDEX(bet对应表!$F:$F,MATCH($AN$2,bet对应表!$A:$A,0),0))} -> #N/A | AO20: {=L20/(INDEX(bet对应表!$F:$F,MATCH($AO$2,bet对应表!$A:$A,0),0))} -> #N/A | AP20: {=L20/(INDEX(bet对应表!$F:$F,MATCH($AP$2,bet对应表!$A:$A,0),0))} -> #N/A
A21: 2 | B21: 9 | C21: 1 | D21: 150 | E21: =ROUND(E5*10,0) -> 75 | F21: =ROUND(D21/G21,0) -> 6 | G21: =WeightCalculate!S4 -> 24.354704 | H21: =F21+H20 -> 610 | I21: =IF(B21=1,E21/bet对应表!M24,IF(B21=9,E21/100,0)) -> 0.75 | J21: =I21+J20 -> 12.955 | K21: =F21*QuestGetLevel!$D$274 -> 90000 | L21: =K21+L20 -> 1394000 | M21: =J21/H21 -> 0.021237705 | N21: 18 | O21: {=L21/(INDEX(bet对应表!F:F,MATCH($O$2,bet对应表!A:A,0),0))} -> #N/A | P21: {=L21/(INDEX(bet对应表!$F:$F,MATCH($P$2,bet对应表!$A:$A,0),0))} -> #N/A | Q21: {=L21/(INDEX(bet对应表!$F:$F,MATCH($Q$2,bet对应表!$A:$A,0),0))} -> #N/A | R21: {=L21/(INDEX(bet对应表!$F:$F,MATCH($R$2,bet对应表!$A:$A,0),0))} -> #N/A | S21: {=L21/(INDEX(bet对应表!$F:$F,MATCH($S$2,bet对应表!$A:$A,0),0))} -> #N/A | T21: {=L21/(INDEX(bet对应表!$F:$F,MATCH($T$2,bet对应表!$A:$A,0),0))} -> #N/A | U21: {=L21/(INDEX(bet对应表!$F:$F,MATCH($U$2,bet对应表!$A:$A,0),0))} -> #N/A | V21: {=L21/(INDEX(bet对应表!$F:$F,MATCH($V$2,bet对应表!$A:$A,0),0))} -> #N/A | W21: {=L21/(INDEX(bet对应表!$F:$F,MATCH($W$2,bet对应表!$A:$A,0),0))} -> #N/A | X21: {=L21/(INDEX(bet对应表!$F:$F,MATCH($X$2,bet对应表!$A:$A,0),0))} -> #N/A | Y21: {=L21/(INDEX(bet对应表!$F:$F,MATCH($Y$2,bet对应表!$A:$A,0),0))} -> #N/A | Z21: {=L21/(INDEX(bet对应表!$F:$F,MATCH($Z$2,bet对应表!$A:$A,0),0))} -> #N/A | AA21: {=L21/(INDEX(bet对应表!$F:$F,MATCH($AA$2,bet对应表!$A:$A,0),0))} -> #N/A | AB21: {=L21/(INDEX(bet对应表!$F:$F,MATCH($AB$2,bet对应表!$A:$A,0),0))} -> #N/A | AC21: {=L21/(INDEX(bet对应表!$F:$F,MATCH($AC$2,bet对应表!$A:$A,0),0))} -> #N/A | AD21: {=L21/(INDEX(bet对应表!$F:$F,MATCH($AD$2,bet对应表!$A:$A,0),0))} -> #N/A | AF21: 18 | AG21: {=L21/(INDEX(bet对应表!$F:$F,MATCH($AG$2,bet对应表!$A:$A,0),0))} -> #N/A | AH21: {=L21/(INDEX(bet对应表!$F:$F,MATCH($AH$2,bet对应表!$A:$A,0),0))} -> #N/A | AI21: {=L21/(INDEX(bet对应表!$F:$F,MATCH($AI$2,bet对应表!$A:$A,0),0))} -> #DIV/0! | AJ21: {=L21/(INDEX(bet对应表!$F:$F,MATCH($AJ$2,bet对应表!$A:$A,0),0))} -> #DIV/0! | AK21: {=L21/(INDEX(bet对应表!$F:$F,MATCH($AK$2,bet对应表!$A:$A,0),0))} -> #DIV/0! | AL21: {=L21/(INDEX(bet对应表!$F:$F,MATCH($AL$2,bet对应表!$A:$A,0),0))} -> #N/A | AM21: {=L21/(INDEX(bet对应表!$F:$F,MATCH($AM$2,bet对应表!$A:$A,0),0))} -> #N/A | AN21: {=L21/(INDEX(bet对应表!$F:$F,MATCH($AN$2,bet对应表!$A:$A,0),0))} -> #N/A | AO21: {=L21/(INDEX(bet对应表!$F:$F,MATCH($AO$2,bet对应表!$A:$A,0),0))} -> #N/A | AP21: {=L21/(INDEX(bet对应表!$F:$F,MATCH($AP$2,bet对应表!$A:$A,0),0))} -> #N/A
A22: 3 | B22: 9 | C22: 1 | D22: 300 | E22: =ROUND(E6*10,0) -> 100 | F22: =ROUND(D22/G22,0) -> 11 | G22: =WeightCalculate!S5 -> 28.004441 | H22: =F22+H21 -> 621 | I22: =IF(B22=1,E22/bet对应表!M25,IF(B22=9,E22/100,0)) -> 1 | J22: =I22+J21 -> 13.955 | K22: =F22*QuestGetLevel!$D$274 -> 165000 | L22: =K22+L21 -> 1559000 | M22: =J22/H22 -> 0.02247182 | N22: 19 | O22: {=L22/(INDEX(bet对应表!F:F,MATCH($O$2,bet对应表!A:A,0),0))} -> #N/A | P22: {=L22/(INDEX(bet对应表!$F:$F,MATCH($P$2,bet对应表!$A:$A,0),0))} -> #N/A | Q22: {=L22/(INDEX(bet对应表!$F:$F,MATCH($Q$2,bet对应表!$A:$A,0),0))} -> #N/A | R22: {=L22/(INDEX(bet对应表!$F:$F,MATCH($R$2,bet对应表!$A:$A,0),0))} -> #N/A | S22: {=L22/(INDEX(bet对应表!$F:$F,MATCH($S$2,bet对应表!$A:$A,0),0))} -> #N/A | T22: {=L22/(INDEX(bet对应表!$F:$F,MATCH($T$2,bet对应表!$A:$A,0),0))} -> #N/A | U22: {=L22/(INDEX(bet对应表!$F:$F,MATCH($U$2,bet对应表!$A:$A,0),0))} -> #N/A | V22: {=L22/(INDEX(bet对应表!$F:$F,MATCH($V$2,bet对应表!$A:$A,0),0))} -> #N/A | W22: {=L22/(INDEX(bet对应表!$F:$F,MATCH($W$2,bet对应表!$A:$A,0),0))} -> #N/A | X22: {=L22/(INDEX(bet对应表!$F:$F,MATCH($X$2,bet对应表!$A:$A,0),0))} -> #N/A | Y22: {=L22/(INDEX(bet对应表!$F:$F,MATCH($Y$2,bet对应表!$A:$A,0),0))} -> #N/A | Z22: {=L22/(INDEX(bet对应表!$F:$F,MATCH($Z$2,bet对应表!$A:$A,0),0))} -> #N/A | AA22: {=L22/(INDEX(bet对应表!$F:$F,MATCH($AA$2,bet对应表!$A:$A,0),0))} -> #N/A | AB22: {=L22/(INDEX(bet对应表!$F:$F,MATCH($AB$2,bet对应表!$A:$A,0),0))} -> #N/A | AC22: {=L22/(INDEX(bet对应表!$F:$F,MATCH($AC$2,bet对应表!$A:$A,0),0))} -> #N/A | AD22: {=L22/(INDEX(bet对应表!$F:$F,MATCH($AD$2,bet对应表!$A:$A,0),0))} -> #N/A | AF22: 19 | AG22: {=L22/(INDEX(bet对应表!$F:$F,MATCH($AG$2,bet对应表!$A:$A,0),0))} -> #N/A | AH22: {=L22/(INDEX(bet对应表!$F:$F,MATCH($AH$2,bet对应表!$A:$A,0),0))} -> #N/A | AI22: {=L22/(INDEX(bet对应表!$F:$F,MATCH($AI$2,bet对应表!$A:$A,0),0))} -> #DIV/0! | AJ22: {=L22/(INDEX(bet对应表!$F:$F,MATCH($AJ$2,bet对应表!$A:$A,0),0))} -> #DIV/0! | AK22: {=L22/(INDEX(bet对应表!$F:$F,MATCH($AK$2,bet对应表!$A:$A,0),0))} -> #DIV/0! | AL22: {=L22/(INDEX(bet对应表!$F:$F,MATCH($AL$2,bet对应表!$A:$A,0),0))} -> #N/A | AM22: {=L22/(INDEX(bet对应表!$F:$F,MATCH($AM$2,bet对应表!$A:$A,0),0))} -> #N/A | AN22: {=L22/(INDEX(bet对应表!$F:$F,MATCH($AN$2,bet对应表!$A:$A,0),0))} -> #N/A | AO22: {=L22/(INDEX(bet对应表!$F:$F,MATCH($AO$2,bet对应表!$A:$A,0),0))} -> #N/A | AP22: {=L22/(INDEX(bet对应表!$F:$F,MATCH($AP$2,bet对应表!$A:$A,0),0))} -> #N/A
A23: 4 | B23: 9 | C23: 1 | D23: 600 | E23: =ROUND(E7*10,0) -> 150 | F23: =ROUND(D23/G23,0) -> 18 | G23: =WeightCalculate!S8 -> 33.162309 | H23: =F23+H22 -> 639 | I23: =IF(B23=1,E23/bet对应表!M26,IF(B23=9,E23/100,0)) -> 1.5 | J23: =I23+J22 -> 15.455 | K23: =F23*QuestGetLevel!$D$274 -> 270000 | L23: =K23+L22 -> 1829000 | M23: =J23/H23 -> 0.024186228 | N23: 20 | O23: {=L23/(INDEX(bet对应表!F:F,MATCH($O$2,bet对应表!A:A,0),0))} -> #N/A | P23: {=L23/(INDEX(bet对应表!$F:$F,MATCH($P$2,bet对应表!$A:$A,0),0))} -> #N/A | Q23: {=L23/(INDEX(bet对应表!$F:$F,MATCH($Q$2,bet对应表!$A:$A,0),0))} -> #N/A | R23: {=L23/(INDEX(bet对应表!$F:$F,MATCH($R$2,bet对应表!$A:$A,0),0))} -> #N/A | S23: {=L23/(INDEX(bet对应表!$F:$F,MATCH($S$2,bet对应表!$A:$A,0),0))} -> #N/A | T23: {=L23/(INDEX(bet对应表!$F:$F,MATCH($T$2,bet对应表!$A:$A,0),0))} -> #N/A | U23: {=L23/(INDEX(bet对应表!$F:$F,MATCH($U$2,bet对应表!$A:$A,0),0))} -> #N/A | V23: {=L23/(INDEX(bet对应表!$F:$F,MATCH($V$2,bet对应表!$A:$A,0),0))} -> #N/A | W23: {=L23/(INDEX(bet对应表!$F:$F,MATCH($W$2,bet对应表!$A:$A,0),0))} -> #N/A | X23: {=L23/(INDEX(bet对应表!$F:$F,MATCH($X$2,bet对应表!$A:$A,0),0))} -> #N/A | Y23: {=L23/(INDEX(bet对应表!$F:$F,MATCH($Y$2,bet对应表!$A:$A,0),0))} -> #N/A | Z23: {=L23/(INDEX(bet对应表!$F:$F,MATCH($Z$2,bet对应表!$A:$A,0),0))} -> #N/A | AA23: {=L23/(INDEX(bet对应表!$F:$F,MATCH($AA$2,bet对应表!$A:$A,0),0))} -> #N/A | AB23: {=L23/(INDEX(bet对应表!$F:$F,MATCH($AB$2,bet对应表!$A:$A,0),0))} -> #N/A | AC23: {=L23/(INDEX(bet对应表!$F:$F,MATCH($AC$2,bet对应表!$A:$A,0),0))} -> #N/A | AD23: {=L23/(INDEX(bet对应表!$F:$F,MATCH($AD$2,bet对应表!$A:$A,0),0))} -> #N/A | AF23: 20 | AG23: {=L23/(INDEX(bet对应表!$F:$F,MATCH($AG$2,bet对应表!$A:$A,0),0))} -> #N/A | AH23: {=L23/(INDEX(bet对应表!$F:$F,MATCH($AH$2,bet对应表!$A:$A,0),0))} -> #N/A | AI23: {=L23/(INDEX(bet对应表!$F:$F,MATCH($AI$2,bet对应表!$A:$A,0),0))} -> #DIV/0! | AJ23: {=L23/(INDEX(bet对应表!$F:$F,MATCH($AJ$2,bet对应表!$A:$A,0),0))} -> #DIV/0! | AK23: {=L23/(INDEX(bet对应表!$F:$F,MATCH($AK$2,bet对应表!$A:$A,0),0))} -> #DIV/0! | AL23: {=L23/(INDEX(bet对应表!$F:$F,MATCH($AL$2,bet对应表!$A:$A,0),0))} -> #N/A | AM23: {=L23/(INDEX(bet对应表!$F:$F,MATCH($AM$2,bet对应表!$A:$A,0),0))} -> #N/A | AN23: {=L23/(INDEX(bet对应表!$F:$F,MATCH($AN$2,bet对应表!$A:$A,0),0))} -> #N/A | AO23: {=L23/(INDEX(bet对应表!$F:$F,MATCH($AO$2,bet对应表!$A:$A,0),0))} -> #N/A | AP23: {=L23/(INDEX(bet对应表!$F:$F,MATCH($AP$2,bet对应表!$A:$A,0),0))} -> #N/A
A24: 5 | B24: 9 | C24: 1 | D24: 1500 | E24: =ROUND(E8*10,0) -> 200 | F24: =ROUND(D24/G24,0) -> 42 | G24: =WeightCalculate!S11 -> 36.130734 | H24: =F24+H23 -> 681 | I24: =IF(B24=1,E24/bet对应表!M27,IF(B24=9,E24/100,0)) -> 2 | J24: =I24+J23 -> 17.455 | K24: =F24*QuestGetLevel!$D$274 -> 630000 | L24: =K24+L23 -> 2459000 | M24: =J24/H24 -> 0.025631424 | N24: 21 | O24: {=L24/(INDEX(bet对应表!F:F,MATCH($O$2,bet对应表!A:A,0),0))} -> #N/A | P24: {=L24/(INDEX(bet对应表!$F:$F,MATCH($P$2,bet对应表!$A:$A,0),0))} -> #N/A | Q24: {=L24/(INDEX(bet对应表!$F:$F,MATCH($Q$2,bet对应表!$A:$A,0),0))} -> #N/A | R24: {=L24/(INDEX(bet对应表!$F:$F,MATCH($R$2,bet对应表!$A:$A,0),0))} -> #N/A | S24: {=L24/(INDEX(bet对应表!$F:$F,MATCH($S$2,bet对应表!$A:$A,0),0))} -> #N/A | T24: {=L24/(INDEX(bet对应表!$F:$F,MATCH($T$2,bet对应表!$A:$A,0),0))} -> #N/A | U24: {=L24/(INDEX(bet对应表!$F:$F,MATCH($U$2,bet对应表!$A:$A,0),0))} -> #N/A | V24: {=L24/(INDEX(bet对应表!$F:$F,MATCH($V$2,bet对应表!$A:$A,0),0))} -> #N/A | W24: {=L24/(INDEX(bet对应表!$F:$F,MATCH($W$2,bet对应表!$A:$A,0),0))} -> #N/A | X24: {=L24/(INDEX(bet对应表!$F:$F,MATCH($X$2,bet对应表!$A:$A,0),0))} -> #N/A | Y24: {=L24/(INDEX(bet对应表!$F:$F,MATCH($Y$2,bet对应表!$A:$A,0),0))} -> #N/A | Z24: {=L24/(INDEX(bet对应表!$F:$F,MATCH($Z$2,bet对应表!$A:$A,0),0))} -> #N/A | AA24: {=L24/(INDEX(bet对应表!$F:$F,MATCH($AA$2,bet对应表!$A:$A,0),0))} -> #N/A | AB24: {=L24/(INDEX(bet对应表!$F:$F,MATCH($AB$2,bet对应表!$A:$A,0),0))} -> #N/A | AC24: {=L24/(INDEX(bet对应表!$F:$F,MATCH($AC$2,bet对应表!$A:$A,0),0))} -> #N/A | AD24: {=L24/(INDEX(bet对应表!$F:$F,MATCH($AD$2,bet对应表!$A:$A,0),0))} -> #N/A | AF24: 21 | AG24: {=L24/(INDEX(bet对应表!$F:$F,MATCH($AG$2,bet对应表!$A:$A,0),0))} -> #N/A | AH24: {=L24/(INDEX(bet对应表!$F:$F,MATCH($AH$2,bet对应表!$A:$A,0),0))} -> #N/A | AI24: {=L24/(INDEX(bet对应表!$F:$F,MATCH($AI$2,bet对应表!$A:$A,0),0))} -> #DIV/0! | AJ24: {=L24/(INDEX(bet对应表!$F:$F,MATCH($AJ$2,bet对应表!$A:$A,0),0))} -> #DIV/0! | AK24: {=L24/(INDEX(bet对应表!$F:$F,MATCH($AK$2,bet对应表!$A:$A,0),0))} -> #DIV/0! | AL24: {=L24/(INDEX(bet对应表!$F:$F,MATCH($AL$2,bet对应表!$A:$A,0),0))} -> #N/A | AM24: {=L24/(INDEX(bet对应表!$F:$F,MATCH($AM$2,bet对应表!$A:$A,0),0))} -> #N/A | AN24: {=L24/(INDEX(bet对应表!$F:$F,MATCH($AN$2,bet对应表!$A:$A,0),0))} -> #N/A | AO24: {=L24/(INDEX(bet对应表!$F:$F,MATCH($AO$2,bet对应表!$A:$A,0),0))} -> #N/A | AP24: {=L24/(INDEX(bet对应表!$F:$F,MATCH($AP$2,bet对应表!$A:$A,0),0))} -> #N/A
A25: 6 | B25: 9 | C25: 1 | D25: 3000 | E25: =ROUND(E9*10,0) -> 300 | F25: =ROUND(D25/G25,0) -> 67 | G25: =WeightCalculate!S14 -> 44.573014 | H25: =F25+H24 -> 748 | I25: =IF(B25=1,E25/bet对应表!M28,IF(B25=9,E25/100,0)) -> 3 | J25: =I25+J24 -> 20.455 | K25: =F25*QuestGetLevel!$D$274 -> 1005000 | L25: =K25+L24 -> 3464000 | M25: =J25/H25 -> 0.027346257 | N25: 22 | O25: {=L25/(INDEX(bet对应表!F:F,MATCH($O$2,bet对应表!A:A,0),0))} -> #N/A | P25: {=L25/(INDEX(bet对应表!$F:$F,MATCH($P$2,bet对应表!$A:$A,0),0))} -> #N/A | Q25: {=L25/(INDEX(bet对应表!$F:$F,MATCH($Q$2,bet对应表!$A:$A,0),0))} -> #N/A | R25: {=L25/(INDEX(bet对应表!$F:$F,MATCH($R$2,bet对应表!$A:$A,0),0))} -> #N/A | S25: {=L25/(INDEX(bet对应表!$F:$F,MATCH($S$2,bet对应表!$A:$A,0),0))} -> #N/A | T25: {=L25/(INDEX(bet对应表!$F:$F,MATCH($T$2,bet对应表!$A:$A,0),0))} -> #N/A | U25: {=L25/(INDEX(bet对应表!$F:$F,MATCH($U$2,bet对应表!$A:$A,0),0))} -> #N/A | V25: {=L25/(INDEX(bet对应表!$F:$F,MATCH($V$2,bet对应表!$A:$A,0),0))} -> #N/A | W25: {=L25/(INDEX(bet对应表!$F:$F,MATCH($W$2,bet对应表!$A:$A,0),0))} -> #N/A | X25: {=L25/(INDEX(bet对应表!$F:$F,MATCH($X$2,bet对应表!$A:$A,0),0))} -> #N/A | Y25: {=L25/(INDEX(bet对应表!$F:$F,MATCH($Y$2,bet对应表!$A:$A,0),0))} -> #N/A | Z25: {=L25/(INDEX(bet对应表!$F:$F,MATCH($Z$2,bet对应表!$A:$A,0),0))} -> #N/A | AA25: {=L25/(INDEX(bet对应表!$F:$F,MATCH($AA$2,bet对应表!$A:$A,0),0))} -> #N/A | AB25: {=L25/(INDEX(bet对应表!$F:$F,MATCH($AB$2,bet对应表!$A:$A,0),0))} -> #N/A | AC25: {=L25/(INDEX(bet对应表!$F:$F,MATCH($AC$2,bet对应表!$A:$A,0),0))} -> #N/A | AD25: {=L25/(INDEX(bet对应表!$F:$F,MATCH($AD$2,bet对应表!$A:$A,0),0))} -> #N/A | AF25: 22 | AG25: {=L25/(INDEX(bet对应表!$F:$F,MATCH($AG$2,bet对应表!$A:$A,0),0))} -> #N/A | AH25: {=L25/(INDEX(bet对应表!$F:$F,MATCH($AH$2,bet对应表!$A:$A,0),0))} -> #N/A | AI25: {=L25/(INDEX(bet对应表!$F:$F,MATCH($AI$2,bet对应表!$A:$A,0),0))} -> #DIV/0! | AJ25: {=L25/(INDEX(bet对应表!$F:$F,MATCH($AJ$2,bet对应表!$A:$A,0),0))} -> #DIV/0! | AK25: {=L25/(INDEX(bet对应表!$F:$F,MATCH($AK$2,bet对应表!$A:$A,0),0))} -> #DIV/0! | AL25: {=L25/(INDEX(bet对应表!$F:$F,MATCH($AL$2,bet对应表!$A:$A,0),0))} -> #N/A | AM25: {=L25/(INDEX(bet对应表!$F:$F,MATCH($AM$2,bet对应表!$A:$A,0),0))} -> #N/A | AN25: {=L25/(INDEX(bet对应表!$F:$F,MATCH($AN$2,bet对应表!$A:$A,0),0))} -> #N/A | AO25: {=L25/(INDEX(bet对应表!$F:$F,MATCH($AO$2,bet对应表!$A:$A,0),0))} -> #N/A | AP25: {=L25/(INDEX(bet对应表!$F:$F,MATCH($AP$2,bet对应表!$A:$A,0),0))} -> #N/A
