Workbook

Sheet frenzy进度
A1: 档位 | B1: 价格 | C1: 金币 | D1: 等价物 | E1: 进度金币 | F1: 进度等价物 | G1: 付费美金 | H1: 进度美金 | I1: 合计 | J1: 总折扣 | K1: 进度折扣 | M1: 价格 | N1: 金币 | O1: 单位金币 | P1: 单位钻石
A2: 1 | B2: 1.99 | C2: 172000000 | D2: 200 | E2: 86400000 | F2: 0 | G2: =C2/$O$2 -> 10.14163 | H2: =E2/$O$2+F2/$P$2 -> 5.0944 | I2: =(C2+E2)/$O$2+D2/$P$2 -> 17.23603 | J2: =I2/B2 -> 8.6613214 | K2: =H2/G2 -> 0.50232558 | M2: 1.99 | N2: 33750000 | O2: =N2/M2 -> 16959799 | P2: 100
A3: 2 | B3: 2.99 | C3: 259000000 | D3: 800 | E3: 860000000 | F3: 0 | G3: =C3/$O$2 -> 15.271407 | H3: =E3/$O$2+F3/$P$2 -> 50.708148 | I3: =(C3+E3)/$O$2+D3/$P$2 -> 73.979556 | J3: =I3/B3 -> 24.742326 | K3: =H3/G3 -> 3.3204633
A4: 3 | B4: 9.99 | C4: 648000000 | D4: 1200 | E4: 0 | F4: 5000 | G4: =C4/$O$2 -> 38.208 | H4: =E4/$O$2+F4/$P$2 -> 50 | I4: =(C4+E4)/$O$2+D4/$P$2 -> 50.208 | J4: =I4/B4 -> 5.0258258 | K4: =H4/G4 -> 1.3086265

Sheet TreasureHuntReward
A1: Id | B1: Group | C1: Type | D1: ItemIDgp | E1: ItemIDiap | F1: Money | G1: Sort | H1: exp | I1: RewardType1 | J1: RewardItem1 | K1: RewardCount1 | L1: RewardType2 | M1: RewardItem2 | N1: RewardCount2 | O1: RewardType3 | P1: RewardItem3 | Q1: RewardCount3 | R1: RewardType4 | S1: RewardItem4 | T1: RewardCount4
A2: int_key | B2: int | C2: int | D2: string | E2: string | F2: int | G2: int | H2: int | I2: int | J2: uint | K2: int | L2: int | M2: uint | N2: int | O2: int | P2: uint | Q2: int | R2: int | S2: uint | T2: int
A3: cs | B3: cs | C3: cs | D3: cs | E3: cs | F3: cs | G3: cs | H3: cs | I3: cs | J3: cs | K3: cs | L3: cs | M3: cs | N3: cs | O3: cs | P3: cs | Q3: cs | R3: cs | S3: cs | T3: cs
A4: 唯一索引 | B4: 分组定价 | C4: 1.free 2.购买项 | D4: 谷歌订单号 | E4: 苹果订单号 | F4: 价格 | G4: 排序 | H4: 经验 | I4: 奖励类型 1金币 2钻石 3道具 4卡包 9美金(查表) 17美金金币 | J4: 奖励物品ID1 1金币 2钻石 3物品id | K4: 奖励数量1 | L4: =I4 -> 奖励类型 1金币 2钻石 3道具 4卡包 9美金(查表) 17美金金币 | M4: =J4 -> 奖励物品ID1 1金币 2钻石 3物品id | N4: =K4 -> 奖励数量1 | O4: =L4 -> 奖励类型 1金币 2钻石 3道具 4卡包 9美金(查表) 17美金金币 | P4: =M4 -> 奖励物品ID1 1金币 2钻石 3物品id | Q4: =N4 -> 奖励数量1 | R4: =O4 -> 奖励类型 1金币 2钻石 3道具 4卡包 9美金(查表) 17美金金币 | S4: =P4 -> 奖励物品ID1 1金币 2钻石 3物品id | T4: =Q4 -> 奖励数量1
A5: 2001 | B5: 1 | C5: 2 | D5: =IFERROR(_xlfn.IFNA(VLOOKUP(ROUND(F5,0),道具!$B$271:$C$295,2,FALSE),""),"") -> gp_hunt_1 | E5: =IFERROR(_xlfn.IFNA(VLOOKUP(ROUND(F5,0),道具!$B$296:$C$320,2,FALSE),""),"") -> iap_hunt_1 | F5: =IF(转换!B3>0,转换!B3*100,"") -> 299 | G5: 2 | H5: ='体验表-带进度条'!R3 -> 10 | I5: =转换!I3 -> 9 | J5: =IF(I5=17,1,IF(I5=9,1,IF(转换!I3>0,VLOOKUP(转换!H3,道具!B:C,2,FALSE),""))) -> 1 | K5: =IF(转换!I3=17,ROUND(转换!J3*100/转换!$U$2,0),IF(转换!I3=9,F5,转换!J3)) -> 299
A6: 2002 | B6: 1 | C6: 2 | D6: =IFERROR(_xlfn.IFNA(VLOOKUP(ROUND(F6,0),道具!$B$271:$C$295,2,FALSE),""),"") -> gp_hunt_2 | E6: =IFERROR(_xlfn.IFNA(VLOOKUP(ROUND(F6,0),道具!$B$296:$C$320,2,FALSE),""),"") -> iap_hunt_2 | F6: =IF(转换!B9>0,转换!B9*100,"") -> 399 | G6: 8 | H6: ='体验表-带进度条'!R9 -> 25 | I6: =转换!I9 -> 9 | J6: =IF(I6=17,1,IF(I6=9,1,IF(转换!I9>0,VLOOKUP(转换!H9,道具!B:C,2,FALSE),""))) -> 1 | K6: =IF(转换!I9=17,ROUND(转换!J9*100/转换!$U$2,0),IF(转换!I9=9,F6,转换!J9)) -> 399
A7: 2003 | B7: 1 | C7: 2 | D7: =IFERROR(_xlfn.IFNA(VLOOKUP(ROUND(F7,0),道具!$B$271:$C$295,2,FALSE),""),"") -> gp_hunt_599 | E7: =IFERROR(_xlfn.IFNA(VLOOKUP(ROUND(F7,0),道具!$B$296:$C$320,2,FALSE),""),"") -> iap_hunt_599 | F7: =IF(转换!B15>0,转换!B15*100,"") -> 599 | G7: 14 | H7: ='体验表-带进度条'!R15 -> 35 | I7: =转换!I15 -> 9 | J7: =IF(I7=17,1,IF(I7=9,1,IF(转换!I15>0,VLOOKUP(转换!H15,道具!B:C,2,FALSE),""))) -> 1 | K7: =IF(转换!I15=17,ROUND(转换!J15*100/转换!$U$2,0),IF(转换!I15=9,F7,转换!J15)) -> 599
A8: 2004 | B8: 1 | C8: 2 | D8: =IFERROR(_xlfn.IFNA(VLOOKUP(ROUND(F8,0),道具!$B$271:$C$295,2,FALSE),""),"") -> gp_hunt_699 | E8: =IFERROR(_xlfn.IFNA(VLOOKUP(ROUND(F8,0),道具!$B$296:$C$320,2,FALSE),""),"") -> iap_hunt_699 | F8: =IF(转换!B21>0,转换!B21*100,"") -> 699 | G8: 20 | H8: ='体验表-带进度条'!R21 -> 0 | I8: =转换!I21 -> 9 | J8: =IF(I8=17,1,IF(I8=9,1,IF(转换!I21>0,VLOOKUP(转换!H21,道具!B:C,2,FALSE),""))) -> 1 | K8: =IF(转换!I21=17,ROUND(转换!J21*100/转换!$U$2,0),IF(转换!I21=9,F8,转换!J21)) -> 699
A9: 2005 | B9: 1 | C9: 2 | D9: =IFERROR(_xlfn.IFNA(VLOOKUP(ROUND(F9,0),道具!$B$271:$C$295,2,FALSE),""),"") -> gp_hunt_3 | E9: =IFERROR(_xlfn.IFNA(VLOOKUP(ROUND(F9,0),道具!$B$296:$C$320,2,FALSE),""),"") -> iap_hunt_3 | F9: =IF(转换!B27>0,转换!B27*100,"") -> 799 | G9: 26 | H9: ='体验表-带进度条'!R27 -> 10 | I9: =转换!I27 -> 9 | J9: =IF(I9=17,1,IF(I9=9,1,IF(转换!I27>0,VLOOKUP(转换!H27,道具!B:C,2,FALSE),""))) -> 1 | K9: =IF(转换!I27=17,ROUND(转换!J27*100/转换!$U$2,0),IF(转换!I27=9,F9,转换!J27)) -> 799
A10: 2006 | B10: 1 | C10: 2 | D10: =IFERROR(_xlfn.IFNA(VLOOKUP(ROUND(F10,0),道具!$B$271:$C$295,2,FALSE),""),"") -> gp_hunt_4 | E10: =IFERROR(_xlfn.IFNA(VLOOKUP(ROUND(F10,0),道具!$B$296:$C$320,2,FALSE),""),"") -> iap_hunt_4 | F10: =IF(转换!B33>0,转换!B33*100,"") -> 899 | G10: 32 | H10: ='体验表-带进度条'!R33 -> 25 | I10: =转换!I33 -> 9 | J10: =IF(I10=17,1,IF(I10=9,1,IF(转换!I33>0,VLOOKUP(转换!H33,道具!B:C,2,FALSE),""))) -> 1 | K10: =IF(转换!I33=17,ROUND(转换!J33*100/转换!$U$2,0),IF(转换!I33=9,F10,转换!J33)) -> 899
A11: 2007 | B11: 1 | C11: 2 | D11: =IFERROR(_xlfn.IFNA(VLOOKUP(ROUND(F11,0),道具!$B$271:$C$295,2,FALSE),""),"") -> gp_hunt_999 | E11: =IFERROR(_xlfn.IFNA(VLOOKUP(ROUND(F11,0),道具!$B$296:$C$320,2,FALSE),""),"") -> iap_hunt_999 | F11: =IF(转换!B39>0,转换!B39*100,"") -> 999 | G11: 38 | H11: ='体验表-带进度条'!R39 -> 35 | I11: =转换!I39 -> 9 | J11: =IF(I11=17,1,IF(I11=9,1,IF(转换!I39>0,VLOOKUP(转换!H39,道具!B:C,2,FALSE),""))) -> 1 | K11: =IF(转换!I39=17,ROUND(转换!J39*100/转换!$U$2,0),IF(转换!I39=9,F11,转换!J39)) -> 999
A12: 1001 | B12: 1 | C12: 1 | D12: =IFERROR(_xlfn.IFNA(VLOOKUP(ROUND(F12,0),道具!$B$271:$C$295,2,FALSE),""),"") | E12: =IFERROR(_xlfn.IFNA(VLOOKUP(ROUND(F12,0),道具!$B$296:$C$320,2,FALSE),""),"") | F12: =IF(转换!B2>0,转换!B2*100,"") | G12: 1 | H12: ='体验表-带进度条'!R2 -> 20 | I12: =转换!I2 -> 1 | J12: =IF(I12=17,1,IF(I12=9,1,IF(转换!I2>0,VLOOKUP(转换!H2,道具!B:C,2,FALSE),""))) -> 1 | K12: =IF(转换!I2=17,ROUND(转换!J2*100/转换!$U$2,0),IF(转换!I2=9,F12,转换!J2)) -> 5000
A13: 1002 | B13: 1 | C13: 1 | D13: =IFERROR(_xlfn.IFNA(VLOOKUP(ROUND(F13,0),道具!$B$271:$C$295,2,FALSE),""),"") | E13: =IFERROR(_xlfn.IFNA(VLOOKUP(ROUND(F13,0),道具!$B$296:$C$320,2,FALSE),""),"") | F13: =IF(转换!B4>0,转换!B4*100,"") | G13: 3 | H13: ='体验表-带进度条'!R4 -> 0 | I13: =转换!I4 -> 3 | J13: =IF(I13=17,1,IF(I13=9,1,IF(转换!I4>0,VLOOKUP(转换!H4,道具!B:C,2,FALSE),""))) -> 160001 | K13: =IF(转换!I4=17,ROUND(转换!J4*100/转换!$U$2,0),IF(转换!I4=9,F13,转换!J4)) -> 1
A14: 1003 | B14: 1 | C14: 1 | D14: =IFERROR(_xlfn.IFNA(VLOOKUP(ROUND(F14,0),道具!$B$271:$C$295,2,FALSE),""),"") | E14: =IFERROR(_xlfn.IFNA(VLOOKUP(ROUND(F14,0),道具!$B$296:$C$320,2,FALSE),""),"") | F14: =IF(转换!B5>0,转换!B5*100,"") | G14: 4 | H14: ='体验表-带进度条'!R5 -> 0 | I14: =转换!I5 -> 17 | J14: =IF(I14=17,1,IF(I14=9,1,IF(转换!I5>0,VLOOKUP(转换!H5,道具!B:C,2,FALSE),""))) -> 1 | K14: =IF(转换!I5=17,ROUND(转换!J5*100/转换!$U$2,0),IF(转换!I5=9,F14,转换!J5)) -> 90
A15: 1004 | B15: 1 | C15: 1 | D15: =IFERROR(_xlfn.IFNA(VLOOKUP(ROUND(F15,0),道具!$B$271:$C$295,2,FALSE),""),"") | E15: =IFERROR(_xlfn.IFNA(VLOOKUP(ROUND(F15,0),道具!$B$296:$C$320,2,FALSE),""),"") | F15: =IF(转换!B6>0,转换!B6*100,"") | G15: 5 | H15: ='体验表-带进度条'!R6 -> 10 | I15: =转换!I6 -> 4 | J15: =IF(I15=17,1,IF(I15=9,1,IF(转换!I6>0,VLOOKUP(转换!H6,道具!B:C,2,FALSE),""))) -> 100002 | K15: =IF(转换!I6=17,ROUND(转换!J6*100/转换!$U$2,0),IF(转换!I6=9,F15,转换!J6)) -> 1
A16: 1005 | B16: 1 | C16: 1 | D16: =IFERROR(_xlfn.IFNA(VLOOKUP(ROUND(F16,0),道具!$B$271:$C$295,2,FALSE),""),"") | E16: =IFERROR(_xlfn.IFNA(VLOOKUP(ROUND(F16,0),道具!$B$296:$C$320,2,FALSE),""),"") | F16: =IF(转换!B7>0,转换!B7*100,"") | G16: 6 | H16: ='体验表-带进度条'!R7 -> 0 | I16: =转换!I7 -> 3 | J16: =IF(I16=17,1,IF(I16=9,1,IF(转换!I7>0,VLOOKUP(转换!H7,道具!B:C,2,FALSE),""))) -> 192001 | K16: =IF(转换!I7=17,ROUND(转换!J7*100/转换!$U$2,0),IF(转换!I7=9,F16,转换!J7)) -> 5
A17: 1006 | B17: 1 | C17: 1 | D17: =IFERROR(_xlfn.IFNA(VLOOKUP(ROUND(F17,0),道具!$B$271:$C$295,2,FALSE),""),"") | E17: =IFERROR(_xlfn.IFNA(VLOOKUP(ROUND(F17,0),道具!$B$296:$C$320,2,FALSE),""),"") | F17: =IF(转换!B8>0,转换!B8*100,"") | G17: 7 | H17: ='体验表-带进度条'!R8 -> 0 | I17: =转换!I8 -> 3 | J17: =IF(I17=17,1,IF(I17=9,1,IF(转换!I8>0,VLOOKUP(转换!H8,道具!B:C,2,FALSE),""))) -> 171001 | K17: =IF(转换!I8=17,ROUND(转换!J8*100/转换!$U$2,0),IF(转换!I8=9,F17,转换!J8)) -> 1
A18: 1007 | B18: 1 | C18: 1 | D18: =IFERROR(_xlfn.IFNA(VLOOKUP(ROUND(F18,0),道具!$B$271:$C$295,2,FALSE),""),"") | E18: =IFERROR(_xlfn.IFNA(VLOOKUP(ROUND(F18,0),道具!$B$296:$C$320,2,FALSE),""),"") | F18: =IF(转换!B10>0,转换!B10*100,"") | G18: 9 | H18: ='体验表-带进度条'!R10 -> 0 | I18: =转换!I10 -> 3 | J18: =IF(I18=17,1,IF(I18=9,1,IF(转换!I10>0,VLOOKUP(转换!H10,道具!B:C,2,FALSE),""))) -> 160001 | K18: =IF(转换!I10=17,ROUND(转换!J10*100/转换!$U$2,0),IF(转换!I10=9,F18,转换!J10)) -> 2
A19: 1008 | B19: 1 | C19: 1 | D19: =IFERROR(_xlfn.IFNA(VLOOKUP(ROUND(F19,0),道具!$B$271:$C$295,2,FALSE),""),"") | E19: =IFERROR(_xlfn.IFNA(VLOOKUP(ROUND(F19,0),道具!$B$296:$C$320,2,FALSE),""),"") | F19: =IF(转换!B11>0,转换!B11*100,"") | G19: 10 | H19: ='体验表-带进度条'!R11 -> 0 | I19: =转换!I11 -> 17 | J19: =IF(I19=17,1,IF(I19=9,1,IF(转换!I11>0,VLOOKUP(转换!H11,道具!B:C,2,FALSE),""))) -> 1 | K19: =IF(转换!I11=17,ROUND(转换!J11*100/转换!$U$2,0),IF(转换!I11=9,F19,转换!J11)) -> 18
A20: 1009 | B20: 1 | C20: 1 | D20: =IFERROR(_xlfn.IFNA(VLOOKUP(ROUND(F20,0),道具!$B$271:$C$295,2,FALSE),""),"") | E20: =IFERROR(_xlfn.IFNA(VLOOKUP(ROUND(F20,0),道具!$B$296:$C$320,2,FALSE),""),"") | F20: =IF(转换!B12>0,转换!B12*100,"") | G20: 11 | H20: ='体验表-带进度条'!R12 -> 0 | I20: =转换!I12 -> 4 | J20: =IF(I20=17,1,IF(I20=9,1,IF(转换!I12>0,VLOOKUP(转换!H12,道具!B:C,2,FALSE),""))) -> 100003 | K20: =IF(转换!I12=17,ROUND(转换!J12*100/转换!$U$2,0),IF(转换!I12=9,F20,转换!J12)) -> 1
A21: 1010 | B21: 1 | C21: 1 | D21: =IFERROR(_xlfn.IFNA(VLOOKUP(ROUND(F21,0),道具!$B$271:$C$295,2,FALSE),""),"") | E21: =IFERROR(_xlfn.IFNA(VLOOKUP(ROUND(F21,0),道具!$B$296:$C$320,2,FALSE),""),"") | F21: =IF(转换!B13>0,转换!B13*100,"") | G21: 12 | H21: ='体验表-带进度条'!R13 -> 0 | I21: =转换!I13 -> 3 | J21: =IF(I21=17,1,IF(I21=9,1,IF(转换!I13>0,VLOOKUP(转换!H13,道具!B:C,2,FALSE),""))) -> 192001 | K21: =IF(转换!I13=17,ROUND(转换!J13*100/转换!$U$2,0),IF(转换!I13=9,F21,转换!J13)) -> 10
A22: 1011 | B22: 1 | C22: 1 | D22: =IFERROR(_xlfn.IFNA(VLOOKUP(ROUND(F22,0),道具!$B$271:$C$295,2,FALSE),""),"") | E22: =IFERROR(_xlfn.IFNA(VLOOKUP(ROUND(F22,0),道具!$B$296:$C$320,2,FALSE),""),"") | F22: =IF(转换!B14>0,转换!B14*100,"") | G22: 13 | H22: ='体验表-带进度条'!R14 -> 0 | I22: =转换!I14 -> 3 | J22: =IF(I22=17,1,IF(I22=9,1,IF(转换!I14>0,VLOOKUP(转换!H14,道具!B:C,2,FALSE),""))) -> 171002 | K22: =IF(转换!I14=17,ROUND(转换!J14*100/转换!$U$2,0),IF(转换!I14=9,F22,转换!J14)) -> 1
A23: 1012 | B23: 1 | C23: 1 | D23: =IFERROR(_xlfn.IFNA(VLOOKUP(ROUND(F23,0),道具!$B$271:$C$295,2,FALSE),""),"") | E23: =IFERROR(_xlfn.IFNA(VLOOKUP(ROUND(F23,0),道具!$B$296:$C$320,2,FALSE),""),"") | F23: =IF(转换!B16>0,转换!B16*100,"") | G23: 15 | H23: ='体验表-带进度条'!R16 -> 0 | I23: =转换!I16 -> 3 | J23: =IF(I23=17,1,IF(I23=9,1,IF(转换!I16>0,VLOOKUP(转换!H16,道具!B:C,2,FALSE),""))) -> 160001 | K23: =IF(转换!I16=17,ROUND(转换!J16*100/转换!$U$2,0),IF(转换!I16=9,F23,转换!J16)) -> 3
A24: 1013 | B24: 1 | C24: 1 | D24: =IFERROR(_xlfn.IFNA(VLOOKUP(ROUND(F24,0),道具!$B$271:$C$295,2,FALSE),""),"") | E24: =IFERROR(_xlfn.IFNA(VLOOKUP(ROUND(F24,0),道具!$B$296:$C$320,2,FALSE),""),"") | F24: =IF(转换!B17>0,转换!B17*100,"") | G24: 16 | H24: ='体验表-带进度条'!R17 -> 0 | I24: =转换!I17 -> 17 | J24: =IF(I24=17,1,IF(I24=9,1,IF(转换!I17>0,VLOOKUP(转换!H17,道具!B:C,2,FALSE),""))) -> 1 | K24: =IF(转换!I17=17,ROUND(转换!J17*100/转换!$U$2,0),IF(转换!I17=9,F24,转换!J17)) -> 45
A25: 1014 | B25: 1 | C25: 1 | D25: =IFERROR(_xlfn.IFNA(VLOOKUP(ROUND(F25,0),道具!$B$271:$C$295,2,FALSE),""),"") | E25: =IFERROR(_xlfn.IFNA(VLOOKUP(ROUND(F25,0),道具!$B$296:$C$320,2,FALSE),""),"") | F25: =IF(转换!B18>0,转换!B18*100,"") | G25: 17 | H25: ='体验表-带进度条'!R18 -> 25 | I25: =转换!I18 -> 4 | J25: =IF(I25=17,1,IF(I25=9,1,IF(转换!I18>0,VLOOKUP(转换!H18,道具!B:C,2,FALSE),""))) -> 100004 | K25: =IF(转换!I18=17,ROUND(转换!J18*100/转换!$U$2,0),IF(转换!I18=9,F25,转换!J18)) -> 1
A26: 1015 | B26: 1 | C26: 1 | D26: =IFERROR(_xlfn.IFNA(VLOOKUP(ROUND(F26,0),道具!$B$271:$C$295,2,FALSE),""),"") | E26: =IFERROR(_xlfn.IFNA(VLOOKUP(ROUND(F26,0),道具!$B$296:$C$320,2,FALSE),""),"") | F26: =IF(转换!B19>0,转换!B19*100,"") | G26: 18 | H26: ='体验表-带进度条'!R19 -> 0 | I26: =转换!I19 -> 3 | J26: =IF(I26=17,1,IF(I26=9,1,IF(转换!I19>0,VLOOKUP(转换!H19,道具!B:C,2,FALSE),""))) -> 192001 | K26: =IF(转换!I19=17,ROUND(转换!J19*100/转换!$U$2,0),IF(转换!I19=9,F26,转换!J19)) -> 15
A27: 1016 | B27: 1 | C27: 1 | D27: =IFERROR(_xlfn.IFNA(VLOOKUP(ROUND(F27,0),道具!$B$271:$C$295,2,FALSE),""),"") | E27: =IFERROR(_xlfn.IFNA(VLOOKUP(ROUND(F27,0),道具!$B$296:$C$320,2,FALSE),""),"") | F27: =IF(转换!B20>0,转换!B20*100,"") | G27: 19 | H27: ='体验表-带进度条'!R20 -> 0 | I27: =转换!I20 -> 3 | J27: =IF(I27=17,1,IF(I27=9,1,IF(转换!I20>0,VLOOKUP(转换!H20,道具!B:C,2,FALSE),""))) -> 171001 | K27: =IF(转换!I20=17,ROUND(转换!J20*100/转换!$U$2,0),IF(转换!I20=9,F27,转换!J20)) -> 1
A28: 1017 | B28: 1 | C28: 1 | D28: =IFERROR(_xlfn.IFNA(VLOOKUP(ROUND(F28,0),道具!$B$271:$C$295,2,FALSE),""),"") | E28: =IFERROR(_xlfn.IFNA(VLOOKUP(ROUND(F28,0),道具!$B$296:$C$320,2,FALSE),""),"") | F28: =IF(转换!B22>0,转换!B22*100,"") | G28: 21 | H28: ='体验表-带进度条'!R22 -> 0 | I28: =转换!I22 -> 3 | J28: =IF(I28=17,1,IF(I28=9,1,IF(转换!I22>0,VLOOKUP(转换!H22,道具!B:C,2,FALSE),""))) -> 160001 | K28: =IF(转换!I22=17,ROUND(转换!J22*100/转换!$U$2,0),IF(转换!I22=9,F28,转换!J22)) -> 4
A29: 1018 | B29: 1 | C29: 1 | D29: =IFERROR(_xlfn.IFNA(VLOOKUP(ROUND(F29,0),道具!$B$271:$C$295,2,FALSE),""),"") | E29: =IFERROR(_xlfn.IFNA(VLOOKUP(ROUND(F29,0),道具!$B$296:$C$320,2,FALSE),""),"") | F29: =IF(转换!B23>0,转换!B23*100,"") | G29: 22 | H29: ='体验表-带进度条'!R23 -> 0 | I29: =转换!I23 -> 17 | J29: =IF(I29=17,1,IF(I29=9,1,IF(转换!I23>0,VLOOKUP(转换!H23,道具!B:C,2,FALSE),""))) -> 1 | K29: =IF(转换!I23=17,ROUND(转换!J23*100/转换!$U$2,0),IF(转换!I23=9,F29,转换!J23)) -> 72
A30: 1019 | B30: 1 | C30: 1 | D30: =IFERROR(_xlfn.IFNA(VLOOKUP(ROUND(F30,0),道具!$B$271:$C$295,2,FALSE),""),"") | E30: =IFERROR(_xlfn.IFNA(VLOOKUP(ROUND(F30,0),道具!$B$296:$C$320,2,FALSE),""),"") | F30: =IF(转换!B24>0,转换!B24*100,"") | G30: 23 | H30: ='体验表-带进度条'!R24 -> 15 | I30: =转换!I24 -> 4 | J30: =IF(I30=17,1,IF(I30=9,1,IF(转换!I24>0,VLOOKUP(转换!H24,道具!B:C,2,FALSE),""))) -> 100004 | K30: =IF(转换!I24=17,ROUND(转换!J24*100/转换!$U$2,0),IF(转换!I24=9,F30,转换!J24)) -> 1
A31: 1020 | B31: 1 | C31: 1 | D31: =IFERROR(_xlfn.IFNA(VLOOKUP(ROUND(F31,0),道具!$B$271:$C$295,2,FALSE),""),"") | E31: =IFERROR(_xlfn.IFNA(VLOOKUP(ROUND(F31,0),道具!$B$296:$C$320,2,FALSE),""),"") | F31: =IF(转换!B25>0,转换!B25*100,"") | G31: 24 | H31: ='体验表-带进度条'!R25 -> 0 | I31: =转换!I25 -> 3 | J31: =IF(I31=17,1,IF(I31=9,1,IF(转换!I25>0,VLOOKUP(转换!H25,道具!B:C,2,FALSE),""))) -> 192001 | K31: =IF(转换!I25=17,ROUND(转换!J25*100/转换!$U$2,0),IF(转换!I25=9,F31,转换!J25)) -> 20
A32: 1021 | B32: 1 | C32: 1 | D32: =IFERROR(_xlfn.IFNA(VLOOKUP(ROUND(F32,0),道具!$B$271:$C$295,2,FALSE),""),"") | E32: =IFERROR(_xlfn.IFNA(VLOOKUP(ROUND(F32,0),道具!$B$296:$C$320,2,FALSE),""),"") | F32: =IF(转换!B26>0,转换!B26*100,"") | G32: 25 | H32: ='体验表-带进度条'!R26 -> 0 | I32: =转换!I26 -> 3 | J32: =IF(I32=17,1,IF(I32=9,1,IF(转换!I26>0,VLOOKUP(转换!H26,道具!B:C,2,FALSE),""))) -> 171002 | K32: =IF(转换!I26=17,ROUND(转换!J26*100/转换!$U$2,0),IF(转换!I26=9,F32,转换!J26)) -> 1
A33: 1022 | B33: 1 | C33: 1 | D33: =IFERROR(_xlfn.IFNA(VLOOKUP(ROUND(F33,0),道具!$B$271:$C$295,2,FALSE),""),"") | E33: =IFERROR(_xlfn.IFNA(VLOOKUP(ROUND(F33,0),道具!$B$296:$C$320,2,FALSE),""),"") | F33: =IF(转换!B28>0,转换!B28*100,"") | G33: 27 | H33: ='体验表-带进度条'!R28 -> 0 | I33: =转换!I28 -> 3 | J33: =IF(I33=17,1,IF(I33=9,1,IF(转换!I28>0,VLOOKUP(转换!H28,道具!B:C,2,FALSE),""))) -> 160001 | K33: =IF(转换!I28=17,ROUND(转换!J28*100/转换!$U$2,0),IF(转换!I28=9,F33,转换!J28)) -> 5
A34: 1023 | B34: 1 | C34: 1 | D34: =IFERROR(_xlfn.IFNA(VLOOKUP(ROUND(F34,0),道具!$B$271:$C$295,2,FALSE),""),"") | E34: =IFERROR(_xlfn.IFNA(VLOOKUP(ROUND(F34,0),道具!$B$296:$C$320,2,FALSE),""),"") | F34: =IF(转换!B29>0,转换!B29*100,"") | G34: 28 | H34: ='体验表-带进度条'!R29 -> 0 | I34: =转换!I29 -> 17 | J34: =IF(I34=17,1,IF(I34=9,1,IF(转换!I29>0,VLOOKUP(转换!H29,道具!B:C,2,FALSE),""))) -> 1 | K34: =IF(转换!I29=17,ROUND(转换!J29*100/转换!$U$2,0),IF(转换!I29=9,F34,转换!J29)) -> 36
A35: 1024 | B35: 1 | C35: 1 | D35: =IFERROR(_xlfn.IFNA(VLOOKUP(ROUND(F35,0),道具!$B$271:$C$295,2,FALSE),""),"") | E35: =IFERROR(_xlfn.IFNA(VLOOKUP(ROUND(F35,0),道具!$B$296:$C$320,2,FALSE),""),"") | F35: =IF(转换!B30>0,转换!B30*100,"") | G35: 29 | H35: ='体验表-带进度条'!R30 -> 25 | I35: =转换!I30 -> 4 | J35: =IF(I35=17,1,IF(I35=9,1,IF(转换!I30>0,VLOOKUP(转换!H30,道具!B:C,2,FALSE),""))) -> 100005 | K35: =IF(转换!I30=17,ROUND(转换!J30*100/转换!$U$2,0),IF(转换!I30=9,F35,转换!J30)) -> 1
A36: 1025 | B36: 1 | C36: 1 | D36: =IFERROR(_xlfn.IFNA(VLOOKUP(ROUND(F36,0),道具!$B$271:$C$295,2,FALSE),""),"") | E36: =IFERROR(_xlfn.IFNA(VLOOKUP(ROUND(F36,0),道具!$B$296:$C$320,2,FALSE),""),"") | F36: =IF(转换!B31>0,转换!B31*100,"") | G36: 30 | H36: ='体验表-带进度条'!R31 -> 0 | I36: =转换!I31 -> 3 | J36: =IF(I36=17,1,IF(I36=9,1,IF(转换!I31>0,VLOOKUP(转换!H31,道具!B:C,2,FALSE),""))) -> 192001 | K36: =IF(转换!I31=17,ROUND(转换!J31*100/转换!$U$2,0),IF(转换!I31=9,F36,转换!J31)) -> 25
A37: 1026 | B37: 1 | C37: 1 | D37: =IFERROR(_xlfn.IFNA(VLOOKUP(ROUND(F37,0),道具!$B$271:$C$295,2,FALSE),""),"") | E37: =IFERROR(_xlfn.IFNA(VLOOKUP(ROUND(F37,0),道具!$B$296:$C$320,2,FALSE),""),"") | F37: =IF(转换!B32>0,转换!B32*100,"") | G37: 31 | H37: ='体验表-带进度条'!R32 -> 0 | I37: =转换!I32 -> 3 | J37: =IF(I37=17,1,IF(I37=9,1,IF(转换!I32>0,VLOOKUP(转换!H32,道具!B:C,2,FALSE),""))) -> 171001 | K37: =IF(转换!I32=17,ROUND(转换!J32*100/转换!$U$2,0),IF(转换!I32=9,F37,转换!J32)) -> 1
A38: 1027 | B38: 1 | C38: 1 | D38: =IFERROR(_xlfn.IFNA(VLOOKUP(ROUND(F38,0),道具!$B$271:$C$295,2,FALSE),""),"") | E38: =IFERROR(_xlfn.IFNA(VLOOKUP(ROUND(F38,0),道具!$B$296:$C$320,2,FALSE),""),"") | F38: =IF(转换!B34>0,转换!B34*100,"") | G38: 33 | H38: ='体验表-带进度条'!R34 -> 0 | I38: =转换!I34 -> 3 | J38: =IF(I38=17,1,IF(I38=9,1,IF(转换!I34>0,VLOOKUP(转换!H34,道具!B:C,2,FALSE),""))) -> 160001 | K38: =IF(转换!I34=17,ROUND(转换!J34*100/转换!$U$2,0),IF(转换!I34=9,F38,转换!J34)) -> 6
A39: 1028 | B39: 1 | C39: 1 | D39: =IFERROR(_xlfn.IFNA(VLOOKUP(ROUND(F39,0),道具!$B$271:$C$295,2,FALSE),""),"") | E39: =IFERROR(_xlfn.IFNA(VLOOKUP(ROUND(F39,0),道具!$B$296:$C$320,2,FALSE),""),"") | F39: =IF(转换!B35>0,转换!B35*100,"") | G39: 34 | H39: ='体验表-带进度条'!R35 -> 0 | I39: =转换!I35 -> 17 | J39: =IF(I39=17,1,IF(I39=9,1,IF(转换!I35>0,VLOOKUP(转换!H35,道具!B:C,2,FALSE),""))) -> 1 | K39: =IF(转换!I35=17,ROUND(转换!J35*100/转换!$U$2,0),IF(转换!I35=9,F39,转换!J35)) -> 108
A40: 1029 | B40: 1 | C40: 1 | D40: =IFERROR(_xlfn.IFNA(VLOOKUP(ROUND(F40,0),道具!$B$271:$C$295,2,FALSE),""),"") | E40: =IFERROR(_xlfn.IFNA(VLOOKUP(ROUND(F40,0),道具!$B$296:$C$320,2,FALSE),""),"") | F40: =IF(转换!B36>0,转换!B36*100,"") | G40: 35 | H40: ='体验表-带进度条'!R36 -> 15 | I40: =转换!I36 -> 4 | J40: =IF(I40=17,1,IF(I40=9,1,IF(转换!I36>0,VLOOKUP(转换!H36,道具!B:C,2,FALSE),""))) -> 100005 | K40: =IF(转换!I36=17,ROUND(转换!J36*100/转换!$U$2,0),IF(转换!I36=9,F40,转换!J36)) -> 1
...

Sheet TreasureHuntLevel
A1: Group | B1: stage | C1: score | D1: RewardType1 | E1: RewardItem1 | F1: RewardCount1
A2: int | B2: int | C2: int | D2: int | E2: uint | F2: long
A3: cs | B3: cs | C3: cs | D3: cs | E3: cs | F3: cs
A4: 分组定价 | B4: // 阶段 | C4: // 升级所需积分 | D4: 奖励类型 1金币 2钻石 3道具 4卡包 9美金(查表) 17美金金币 | E4: 奖励物品ID1 1金币 2钻石 3物品id | F4: 奖励数量1
A5: ='体验表-带进度条'!AL2 -> 1 | B5: ='体验表-带进度条'!AM2 -> 1 | C5: ='体验表-带进度条'!AO2 -> 50 | D5: =IF(SUMIFS('体验表-带进度条'!U:U,'体验表-带进度条'!A:A,"="&A5,'体验表-带进度条'!P:P,"="&B5)=1,17) -> 17 | E5: =IF(D5=17,1,) -> 1 | F5: =SUMIFS('体验表-带进度条'!V:V,'体验表-带进度条'!A:A,"="&A5,'体验表-带进度条'!P:P,"="&B5) -> 110
A6: ='体验表-带进度条'!AL3 -> 1 | B6: ='体验表-带进度条'!AM3 -> 2 | C6: ='体验表-带进度条'!AO3 -> 150 | D6: =IF(SUMIFS('体验表-带进度条'!U:U,'体验表-带进度条'!A:A,"="&A6,'体验表-带进度条'!P:P,"="&B6)=1,17) -> 17 | E6: =IF(D6=17,1,) -> 1 | F6: =SUMIFS('体验表-带进度条'!V:V,'体验表-带进度条'!A:A,"="&A6,'体验表-带进度条'!P:P,"="&B6) -> 220
A7: ='体验表-带进度条'!AL4 -> 1 | B7: ='体验表-带进度条'!AM4 -> 3 | C7: ='体验表-带进度条'!AO4 -> 300 | D7: =IF(SUMIFS('体验表-带进度条'!U:U,'体验表-带进度条'!A:A,"="&A7,'体验表-带进度条'!P:P,"="&B7)=1,17) -> 17 | E7: =IF(D7=17,1,) -> 1 | F7: =SUMIFS('体验表-带进度条'!V:V,'体验表-带进度条'!A:A,"="&A7,'体验表-带进度条'!P:P,"="&B7) -> 405
A8: ='体验表-带进度条'!AL5 -> 2 | B8: ='体验表-带进度条'!AM5 -> 1 | C8: ='体验表-带进度条'!AO5 -> 50 | D8: =IF(SUMIFS('体验表-带进度条'!U:U,'体验表-带进度条'!A:A,"="&A8,'体验表-带进度条'!P:P,"="&B8)=1,17) -> 17 | E8: =IF(D8=17,1,) -> 1 | F8: =SUMIFS('体验表-带进度条'!V:V,'体验表-带进度条'!A:A,"="&A8,'体验表-带进度条'!P:P,"="&B8) -> 110
A9: ='体验表-带进度条'!AL6 -> 2 | B9: ='体验表-带进度条'!AM6 -> 2 | C9: ='体验表-带进度条'!AO6 -> 150 | D9: =IF(SUMIFS('体验表-带进度条'!U:U,'体验表-带进度条'!A:A,"="&A9,'体验表-带进度条'!P:P,"="&B9)=1,17) -> 17 | E9: =IF(D9=17,1,) -> 1 | F9: =SUMIFS('体验表-带进度条'!V:V,'体验表-带进度条'!A:A,"="&A9,'体验表-带进度条'!P:P,"="&B9) -> 220
A10: ='体验表-带进度条'!AL7 -> 2 | B10: ='体验表-带进度条'!AM7 -> 3 | C10: ='体验表-带进度条'!AO7 -> 300 | D10: =IF(SUMIFS('体验表-带进度条'!U:U,'体验表-带进度条'!A:A,"="&A10,'体验表-带进度条'!P:P,"="&B10)=1,17) -> 17 | E10: =IF(D10=17,1,) -> 1 | F10: =SUMIFS('体验表-带进度条'!V:V,'体验表-带进度条'!A:A,"="&A10,'体验表-带进度条'!P:P,"="&B10) -> 405
A11: ='体验表-带进度条'!AL8 -> 3 | B11: ='体验表-带进度条'!AM8 -> 1 | C11: ='体验表-带进度条'!AO8 -> 50 | D11: =IF(SUMIFS('体验表-带进度条'!U:U,'体验表-带进度条'!A:A,"="&A11,'体验表-带进度条'!P:P,"="&B11)=1,17) -> 17 | E11: =IF(D11=17,1,) -> 1 | F11: =SUMIFS('体验表-带进度条'!V:V,'体验表-带进度条'!A:A,"="&A11,'体验表-带进度条'!P:P,"="&B11) -> 110
A12: ='体验表-带进度条'!AL9 -> 3 | B12: ='体验表-带进度条'!AM9 -> 2 | C12: ='体验表-带进度条'!AO9 -> 150 | D12: =IF(SUMIFS('体验表-带进度条'!U:U,'体验表-带进度条'!A:A,"="&A12,'体验表-带进度条'!P:P,"="&B12)=1,17) -> 17 | E12: =IF(D12=17,1,) -> 1 | F12: =SUMIFS('体验表-带进度条'!V:V,'体验表-带进度条'!A:A,"="&A12,'体验表-带进度条'!P:P,"="&B12) -> 220
A13: ='体验表-带进度条'!AL10 -> 3 | B13: ='体验表-带进度条'!AM10 -> 3 | C13: ='体验表-带进度条'!AO10 -> 300 | D13: =IF(SUMIFS('体验表-带进度条'!U:U,'体验表-带进度条'!A:A,"="&A13,'体验表-带进度条'!P:P,"="&B13)=1,17) -> 17 | E13: =IF(D13=17,1,) -> 1 | F13: =SUMIFS('体验表-带进度条'!V:V,'体验表-带进度条'!A:A,"="&A13,'体验表-带进度条'!P:P,"="&B13) -> 405
A14: ='体验表-带进度条'!AL11 -> 4 | B14: ='体验表-带进度条'!AM11 -> 1 | C14: ='体验表-带进度条'!AO11 -> 50 | D14: =IF(SUMIFS('体验表-带进度条'!U:U,'体验表-带进度条'!A:A,"="&A14,'体验表-带进度条'!P:P,"="&B14)=1,17) -> 17 | E14: =IF(D14=17,1,) -> 1 | F14: =SUMIFS('体验表-带进度条'!V:V,'体验表-带进度条'!A:A,"="&A14,'体验表-带进度条'!P:P,"="&B14) -> 110
A15: ='体验表-带进度条'!AL12 -> 4 | B15: ='体验表-带进度条'!AM12 -> 2 | C15: ='体验表-带进度条'!AO12 -> 150 | D15: =IF(SUMIFS('体验表-带进度条'!U:U,'体验表-带进度条'!A:A,"="&A15,'体验表-带进度条'!P:P,"="&B15)=1,17) -> 17 | E15: =IF(D15=17,1,) -> 1 | F15: =SUMIFS('体验表-带进度条'!V:V,'体验表-带进度条'!A:A,"="&A15,'体验表-带进度条'!P:P,"="&B15) -> 220
A16: ='体验表-带进度条'!AL13 -> 4 | B16: ='体验表-带进度条'!AM13 -> 3 | C16: ='体验表-带进度条'!AO13 -> 300 | D16: =IF(SUMIFS('体验表-带进度条'!U:U,'体验表-带进度条'!A:A,"="&A16,'体验表-带进度条'!P:P,"="&B16)=1,17) -> 17 | E16: =IF(D16=17,1,) -> 1 | F16: =SUMIFS('体验表-带进度条'!V:V,'体验表-带进度条'!A:A,"="&A16,'体验表-带进度条'!P:P,"="&B16) -> 405
... A37: ='体验表-带进度条'!AL34 -> 11 | B37: ='体验表-带进度条'!AM34 -> 3 | C37: ='体验表-带进度条'!AO34 -> 300 | D37: =IF(SUMIFS('体验表-带进度条'!U:U,'体验表-带进度条'!A:A,"="&A37,'体验表-带进度条'!P:P,"="&B37)=1,17) -> 17 | E37: =IF(D37=17,1,) -> 1 | F37: =SUMIFS('体验表-带进度条'!V:V,'体验表-带进度条'!A:A,"="&A37,'体验表-带进度条'!P:P,"="&B37) -> 405

Sheet 道具
A1: name | B1: _comm | C1: itemID
A2: string_lan | B2: string | C2: uint_key
A3: cs | B3: skip | C3: cs
A4: //名字 | B4: //注释 | C4: //物品的ID
A5: 新手礼包 | C5: 1
A6: 老手礼包 | C6: 2
A7: 登录礼包 | C7: 3
A8: #UIAvatar42 | B8: 默认头像框 | C8: 30088
A9: #UIAvatar43 | B9: 财富榜第1名 | C9: 30089
A10: #UIAvatar44 | B10: 财富榜第2名 | C10: 30090
A11: #UIAvatar45 | B11: 财富榜第3名 | C11: 30091
A12: #UIAvatar46 | B12: 财富榜第4-20名 | C12: 30092
A13: #UIAvatar47 | B13: 财富榜第21-50名 | C13: 30093
A14: #UIAvatar48 | B14: battlePass头像框 | C14: 30094
A15: #UIAvatar49 | B15: vip1头像框 | C15: 30101
A16: #UIAvatar50 | B16: vip2头像框 | C16: 30102
A17: #UIAvatar51 | B17: vip3头像框 | C17: 30103
A18: #UIAvatar52 | B18: vip4头像框 | C18: 30104
A19: #UIAvatar53 | B19: vip5头像框 | C19: 30105
... A45: #EXCELItemName16 | B45: 初级兑换券赛门票 | C45: 10005
A46: 50里拉话费赛门票 | C46: 10006
A47: #EXCELItemName6 | B47: 100钻石赛门票 | C47: 10007
A48: #EXCELItemName7 | B48: 500钻石赛门票 | C48: 10008
A49: #EXCELItemName8 | B49: 150钻石赛门票 | C49: 10009
A50: #EXCELItemName19 | B50: 新锦标赛门票 | C50: 10010
A51: #EXCELItemName10 | B51: 20里拉电话卡兑换券 | C51: 20002
A52: #EXCELItemName11 | B52: 25里拉电话卡兑换券 | C52: 20003
A53: #EXCELItemName13 | B53: 50里拉电话卡兑换券 | C53: 20005
A54: #EXCELItemName17 | B54: 电话卡兑换券碎片 | C54: 20022
A55: #PMarket10 | B55: 奖券 | C55: 20023
A56: #PLottery49 | B56: 夺宝券 | C56: 20101
A57: #UIAvatar19 | B57: 头像框 | C57: 30001
A58: #UIAvatar19 | B58: 头像框 | C58: 30002
... A150: #PItem39 | B150: 钥匙 | C150: 70020
B151: 开斋节累计充值礼包1 | C151: 70021
B152: 开斋节累计充值礼包2 | C152: 70022
B153: 开斋节累计充值礼包3 | C153: 70023
B154: 开斋节累计充值礼包4 | C154: 70024
B155: 开斋节累计充值礼包5 | C155: 70025
B156: 开斋特等奖 | C156: 70031
...

Sheet 转换
A1: ='体验表-带进度条'!B1 -> 序列 | B1: ='体验表-带进度条'!E1 -> 0 | C1: ='体验表-带进度条'!F1 -> 档位膨胀 | D1: ='体验表-带进度条'!G1 -> 基础金币 | E1: ='体验表-带进度条'!H1 -> 合计金币 | F1: ='体验表-带进度条'!I1 -> 合计美金 | G1: ='体验表-带进度条'!J1 -> 优惠比例 | H1: ='体验表-带进度条'!K1 -> 奖励类型 | I1: ='体验表-带进度条'!L1 -> 奖励类型 1金币 2钻石 3道具 4卡包 9美金(查表) 17美金金币 | ... L1: ='体验表-带进度条'!O1 -> 档位美金 | M1: ='体验表-带进度条'!X1 -> 合计金币 | N1: ='体验表-带进度条'!AA1 -> 合计美金 | O1: ='体验表-带进度条'!AB1 -> 折扣 | Q1: 档位 | R1: 膨胀系数 | T1: VIP膨胀 | U1: 仅VIP膨胀
A2: ='体验表-带进度条'!B2 -> 1 | B2: ='体验表-带进度条'!E2 -> 0 | C2: ='体验表-带进度条'!F2 | D2: ='体验表-带进度条'!G2 -> 0 | E2: ='体验表-带进度条'!H2 -> 0 | F2: ='体验表-带进度条'!I2 -> 0 | G2: ='体验表-带进度条'!J2 -> 0 | H2: ='体验表-带进度条'!K2 -> 金币 | I2: ='体验表-带进度条'!L2 -> 1 | ... L2: ='体验表-带进度条'!O2 -> 0 | M2: ='体验表-带进度条'!X2 -> 0 | N2: ='体验表-带进度条'!AA2 -> 0 | O2: ='体验表-带进度条'!AB2 -> 0 | Q2: 99 | R2: 100 | T2: 0 | U2: 1000000
A3: ='体验表-带进度条'!B3 -> 2 | B3: ='体验表-带进度条'!E3 -> 2.99 | C3: ='体验表-带进度条'!F3 -> 109 | D3: ='体验表-带进度条'!G3 -> 3270000 | E3: ='体验表-带进度条'!H3 -> 3270000 | F3: ='体验表-带进度条'!I3 -> 2.99 | G3: ='体验表-带进度条'!J3 -> 0 | H3: ='体验表-带进度条'!K3 -> 金币 | I3: ='体验表-带进度条'!L3 -> 9 | ... L3: ='体验表-带进度条'!O3 -> 4.16895 | M3: ='体验表-带进度条'!X3 -> 4168950 | N3: ='体验表-带进度条'!AA3 -> 4.16895 | O3: ='体验表-带进度条'!AB3 -> 1.2749083 | Q3: 199 | R3: 100 | T3: 1 | U3: 1250000
A4: ='体验表-带进度条'!B4 -> 3 | B4: ='体验表-带进度条'!E4 -> 0 | C4: ='体验表-带进度条'!F4 | D4: ='体验表-带进度条'!G4 -> 0 | E4: ='体验表-带进度条'!H4 -> 0 | F4: ='体验表-带进度条'!I4 -> 0 | G4: ='体验表-带进度条'!J4 -> 0 | H4: ='体验表-带进度条'!K4 -> 记牌器1个 | I4: ='体验表-带进度条'!L4 -> 3 | ... L4: ='体验表-带进度条'!O4 -> 0 | M4: ='体验表-带进度条'!X4 -> 0 | N4: ='体验表-带进度条'!AA4 -> 0 | O4: ='体验表-带进度条'!AB4 -> 0 | Q4: 299 | R4: 109 | T4: 2 | U4: 1500000
A5: ='体验表-带进度条'!B5 -> 4 | B5: ='体验表-带进度条'!E5 -> 0 | C5: ='体验表-带进度条'!F5 | D5: ='体验表-带进度条'!G5 -> 0 | E5: ='体验表-带进度条'!H5 -> 0 | F5: ='体验表-带进度条'!I5 -> 0 | G5: ='体验表-带进度条'!J5 -> 0.1 | H5: ='体验表-带进度条'!K5 -> 金币 | I5: ='体验表-带进度条'!L5 -> 17 | ... L5: ='体验表-带进度条'!O5 -> 0 | M5: ='体验表-带进度条'!X5 -> 0 | N5: ='体验表-带进度条'!AA5 -> 0 | O5: ='体验表-带进度条'!AB5 -> 0 | Q5: 399 | R5: 114 | T5: 3 | U5: 1750000
A6: ='体验表-带进度条'!B6 -> 5 | B6: ='体验表-带进度条'!E6 -> 0 | C6: ='体验表-带进度条'!F6 | D6: ='体验表-带进度条'!G6 -> 0 | E6: ='体验表-带进度条'!H6 -> 0 | F6: ='体验表-带进度条'!I6 -> 0 | G6: ='体验表-带进度条'!J6 -> 0 | H6: ='体验表-带进度条'!K6 -> 卡包2星 | I6: ='体验表-带进度条'!L6 -> 4 | ... L6: ='体验表-带进度条'!O6 -> 0 | M6: ='体验表-带进度条'!X6 -> 0 | N6: ='体验表-带进度条'!AA6 -> 0 | O6: ='体验表-带进度条'!AB6 -> 0 | Q6: 499 | R6: 119 | T6: 4 | U6: 2000000
A7: ='体验表-带进度条'!B7 -> 6 | B7: ='体验表-带进度条'!E7 -> 0 | C7: ='体验表-带进度条'!F7 | D7: ='体验表-带进度条'!G7 -> 0 | E7: ='体验表-带进度条'!H7 -> 0 | F7: ='体验表-带进度条'!I7 -> 0 | G7: ='体验表-带进度条'!J7 -> 0 | H7: ='体验表-带进度条'!K7 -> 老虎机抽奖券 | I7: ='体验表-带进度条'!L7 -> 3 | ... L7: ='体验表-带进度条'!O7 -> 0 | M7: ='体验表-带进度条'!X7 -> 0 | N7: ='体验表-带进度条'!AA7 -> 0 | O7: ='体验表-带进度条'!AB7 -> 0 | Q7: 599 | R7: 119 | T7: 5 | U7: 2250000
A8: ='体验表-带进度条'!B8 -> 7 | B8: ='体验表-带进度条'!E8 -> 0 | C8: ='体验表-带进度条'!F8 | D8: ='体验表-带进度条'!G8 -> 0 | E8: ='体验表-带进度条'!H8 -> 0 | F8: ='体验表-带进度条'!I8 -> 0 | G8: ='体验表-带进度条'!J8 -> 0 | H8: ='体验表-带进度条'!K8 -> 大奖赛复活券 | I8: ='体验表-带进度条'!L8 -> 3 | ... L8: ='体验表-带进度条'!O8 -> 0 | M8: ='体验表-带进度条'!X8 -> 0 | N8: ='体验表-带进度条'!AA8 -> 0 | O8: ='体验表-带进度条'!AB8 -> 0 | Q8: 699 | R8: 124 | T8: 6 | U8: 2500000
A9: ='体验表-带进度条'!B9 -> 8 | B9: ='体验表-带进度条'!E9 -> 3.99 | C9: ='体验表-带进度条'!F9 -> 114 | D9: ='体验表-带进度条'!G9 -> 4560000 | E9: ='体验表-带进度条'!H9 -> 7830000 | F9: ='体验表-带进度条'!I9 -> 6.98 | G9: ='体验表-带进度条'!J9 -> 0.12 | H9: ='体验表-带进度条'!K9 -> 金币 | I9: ='体验表-带进度条'!L9 -> 9 | ... L9: ='体验表-带进度条'!O9 -> 4.73979 | M9: ='体验表-带进度条'!X9 -> 9987480 | N9: ='体验表-带进度条'!AA9 -> 9.98748 | O9: ='体验表-带进度条'!AB9 -> 1.2755402 | Q9: 799 | R9: 129 | T9: 7 | U9: 2500000
A10: ='体验表-带进度条'!B10 -> 9 | B10: ='体验表-带进度条'!E10 -> 0 | C10: ='体验表-带进度条'!F10 | D10: ='体验表-带进度条'!G10 -> 0 | E10: ='体验表-带进度条'!H10 -> 0 | F10: ='体验表-带进度条'!I10 -> 0 | G10: ='体验表-带进度条'!J10 -> 0 | H10: ='体验表-带进度条'!K10 -> 记牌器1个 | I10: ='体验表-带进度条'!L10 -> 3 | ... L10: ='体验表-带进度条'!O10 -> 0 | M10: ='体验表-带进度条'!X10 -> 0 | N10: ='体验表-带进度条'!AA10 -> 0 | O10: ='体验表-带进度条'!AB10 -> 0 | Q10: 899 | R10: 134 | T10: 8 | U10: 2500000
A11: ='体验表-带进度条'!B11 -> 10 | B11: ='体验表-带进度条'!E11 -> 0 | C11: ='体验表-带进度条'!F11 | D11: ='体验表-带进度条'!G11 -> 0 | E11: ='体验表-带进度条'!H11 -> 0 | F11: ='体验表-带进度条'!I11 -> 0 | G11: ='体验表-带进度条'!J11 -> 0.02 | H11: ='体验表-带进度条'!K11 -> 金币 | I11: ='体验表-带进度条'!L11 -> 17 | ... L11: ='体验表-带进度条'!O11 -> 0 | M11: ='体验表-带进度条'!X11 -> 0 | N11: ='体验表-带进度条'!AA11 -> 0 | O11: ='体验表-带进度条'!AB11 -> 0 | Q11: 999 | R11: 139 | T11: 9 | U11: 2500000
A12: ='体验表-带进度条'!B12 -> 11 | B12: ='体验表-带进度条'!E12 -> 0 | C12: ='体验表-带进度条'!F12 | D12: ='体验表-带进度条'!G12 -> 0 | E12: ='体验表-带进度条'!H12 -> 0 | F12: ='体验表-带进度条'!I12 -> 0 | G12: ='体验表-带进度条'!J12 -> 0 | H12: ='体验表-带进度条'!K12 -> 卡包3星 | I12: ='体验表-带进度条'!L12 -> 4 | ... L12: ='体验表-带进度条'!O12 -> 0 | M12: ='体验表-带进度条'!X12 -> 0 | N12: ='体验表-带进度条'!AA12 -> 0 | O12: ='体验表-带进度条'!AB12 -> 0 | Q12: 1099 | R12: 142 | T12: 10 | U12: 2500000
A13: ='体验表-带进度条'!B13 -> 12 | B13: ='体验表-带进度条'!E13 -> 0 | C13: ='体验表-带进度条'!F13 | D13: ='体验表-带进度条'!G13 -> 0 | E13: ='体验表-带进度条'!H13 -> 0 | F13: ='体验表-带进度条'!I13 -> 0 | G13: ='体验表-带进度条'!J13 -> 0 | H13: ='体验表-带进度条'!K13 -> 老虎机抽奖券 | I13: ='体验表-带进度条'!L13 -> 3 | ... L13: ='体验表-带进度条'!O13 -> 0 | M13: ='体验表-带进度条'!X13 -> 0 | N13: ='体验表-带进度条'!AA13 -> 0 | O13: ='体验表-带进度条'!AB13 -> 0 | Q13: 1199 | R13: 146 | T13: 11 | U13: 2500000
... A17: ='体验表-带进度条'!B17 -> 16 | B17: ='体验表-带进度条'!E17 -> 0 | C17: ='体验表-带进度条'!F17 | D17: ='体验表-带进度条'!G17 -> 0 | E17: ='体验表-带进度条'!H17 -> 0 | F17: ='体验表-带进度条'!I17 -> 0 | G17: ='体验表-带进度条'!J17 -> 0.05 | H17: ='体验表-带进度条'!K17 -> 金币 | I17: ='体验表-带进度条'!L17 -> 17 | ... L17: ='体验表-带进度条'!O17 -> 0 | M17: ='体验表-带进度条'!X17 -> 0 | N17: ='体验表-带进度条'!AA17 -> 0 | O17: ='体验表-带进度条'!AB17 -> 0 | Q17: 1799 | R17: 158 | T17: 15 | U17: 2500000
A18: ='体验表-带进度条'!B18 -> 17 | B18: ='体验表-带进度条'!E18 -> 0 | C18: ='体验表-带进度条'!F18 | D18: ='体验表-带进度条'!G18 -> 0 | E18: ='体验表-带进度条'!H18 -> 0 | F18: ='体验表-带进度条'!I18 -> 0 | G18: ='体验表-带进度条'!J18 -> 0 | H18: ='体验表-带进度条'!K18 -> 卡包4星 | I18: ='体验表-带进度条'!L18 -> 4 | ... L18: ='体验表-带进度条'!O18 -> 0 | M18: ='体验表-带进度条'!X18 -> 0 | N18: ='体验表-带进度条'!AA18 -> 0 | O18: ='体验表-带进度条'!AB18 -> 0 | Q18: 1999 | R18: 158
A19: ='体验表-带进度条'!B19 -> 18 | B19: ='体验表-带进度条'!E19 -> 0 | C19: ='体验表-带进度条'!F19 | D19: ='体验表-带进度条'!G19 -> 0 | E19: ='体验表-带进度条'!H19 -> 0 | F19: ='体验表-带进度条'!I19 -> 0 | G19: ='体验表-带进度条'!J19 -> 0 | H19: ='体验表-带进度条'!K19 -> 老虎机抽奖券 | I19: ='体验表-带进度条'!L19 -> 3 | ... L19: ='体验表-带进度条'!O19 -> 0 | M19: ='体验表-带进度条'!X19 -> 0 | N19: ='体验表-带进度条'!AA19 -> 0 | O19: ='体验表-带进度条'!AB19 -> 0 | Q19: 2499 | R19: 163
A20: ='体验表-带进度条'!B20 -> 19 | B20: ='体验表-带进度条'!E20 -> 0 | C20: ='体验表-带进度条'!F20 | D20: ='体验表-带进度条'!G20 -> 0 | E20: ='体验表-带进度条'!H20 -> 0 | F20: ='体验表-带进度条'!I20 -> 0 | G20: ='体验表-带进度条'!J20 -> 0 | H20: ='体验表-带进度条'!K20 -> 大奖赛复活券 | I20: ='体验表-带进度条'!L20 -> 3 | ... L20: ='体验表-带进度条'!O20 -> 0 | M20: ='体验表-带进度条'!X20 -> 0 | N20: ='体验表-带进度条'!AA20 -> 0 | O20: ='体验表-带进度条'!AB20 -> 0 | Q20: 2999 | R20: 163
A21: ='体验表-带进度条'!B21 -> 20 | B21: ='体验表-带进度条'!E21 -> 6.99 | C21: ='体验表-带进度条'!F21 -> 124 | D21: ='体验表-带进度条'!G21 -> 8680000 | E21: ='体验表-带进度条'!H21 -> 23650000 | F21: ='体验表-带进度条'!I21 -> 19.96 | G21: ='体验表-带进度条'!J21 -> 0.24 | H21: ='体验表-带进度条'!K21 -> 金币 | I21: ='体验表-带进度条'!L21 -> 9 | ... L21: ='体验表-带进度条'!O21 -> 9.39916 | M21: ='体验表-带进度条'!X21 -> 29133595 | N21: ='体验表-带进度条'!AA21 -> 29.133595 | O21: ='体验表-带进度条'!AB21 -> 1.2318645 | Q21: 3499 | R21: 168
A22: ='体验表-带进度条'!B22 -> 21 | B22: ='体验表-带进度条'!E22 -> 0 | C22: ='体验表-带进度条'!F22 | D22: ='体验表-带进度条'!G22 -> 0 | E22: ='体验表-带进度条'!H22 -> 0 | F22: ='体验表-带进度条'!I22 -> 0 | G22: ='体验表-带进度条'!J22 -> 0 | H22: ='体验表-带进度条'!K22 -> 记牌器1个 | I22: ='体验表-带进度条'!L22 -> 3 | ... L22: ='体验表-带进度条'!O22 -> 0 | M22: ='体验表-带进度条'!X22 -> 0 | N22: ='体验表-带进度条'!AA22 -> 0 | O22: ='体验表-带进度条'!AB22 -> 0 | Q22: 3999 | R22: 173
A23: ='体验表-带进度条'!B23 -> 22 | B23: ='体验表-带进度条'!E23 -> 0 | C23: ='体验表-带进度条'!F23 | D23: ='体验表-带进度条'!G23 -> 0 | E23: ='体验表-带进度条'!H23 -> 0 | F23: ='体验表-带进度条'!I23 -> 0 | G23: ='体验表-带进度条'!J23 -> 0.08 | H23: ='体验表-带进度条'!K23 -> 金币 | I23: ='体验表-带进度条'!L23 -> 17 | ... L23: ='体验表-带进度条'!O23 -> 0 | M23: ='体验表-带进度条'!X23 -> 0 | N23: ='体验表-带进度条'!AA23 -> 0 | O23: ='体验表-带进度条'!AB23 -> 0 | Q23: 4499 | R23: 178
A24: ='体验表-带进度条'!B24 -> 23 | B24: ='体验表-带进度条'!E24 -> 0 | C24: ='体验表-带进度条'!F24 | D24: ='体验表-带进度条'!G24 -> 0 | E24: ='体验表-带进度条'!H24 -> 0 | F24: ='体验表-带进度条'!I24 -> 0 | G24: ='体验表-带进度条'!J24 -> 0 | H24: ='体验表-带进度条'!K24 -> 卡包4星 | I24: ='体验表-带进度条'!L24 -> 4 | ... L24: ='体验表-带进度条'!O24 -> 0 | M24: ='体验表-带进度条'!X24 -> 0 | N24: ='体验表-带进度条'!AA24 -> 0 | O24: ='体验表-带进度条'!AB24 -> 0 | Q24: 4999 | R24: 178
A25: ='体验表-带进度条'!B25 -> 24 | B25: ='体验表-带进度条'!E25 -> 0 | C25: ='体验表-带进度条'!F25 | D25: ='体验表-带进度条'!G25 -> 0 | E25: ='体验表-带进度条'!H25 -> 0 | F25: ='体验表-带进度条'!I25 -> 0 | G25: ='体验表-带进度条'!J25 -> 0 | H25: ='体验表-带进度条'!K25 -> 老虎机抽奖券 | I25: ='体验表-带进度条'!L25 -> 3 | ... L25: ='体验表-带进度条'!O25 -> 0 | M25: ='体验表-带进度条'!X25 -> 0 | N25: ='体验表-带进度条'!AA25 -> 0 | O25: ='体验表-带进度条'!AB25 -> 0 | Q25: 5499 | R25: 178
A26: ='体验表-带进度条'!B26 -> 25 | B26: ='体验表-带进度条'!E26 -> 0 | C26: ='体验表-带进度条'!F26 | D26: ='体验表-带进度条'!G26 -> 0 | E26: ='体验表-带进度条'!H26 -> 0 | F26: ='体验表-带进度条'!I26 -> 0 | G26: ='体验表-带进度条'!J26 -> 0 | H26: ='体验表-带进度条'!K26 -> 大奖赛报名券 | I26: ='体验表-带进度条'!L26 -> 3 | ... L26: ='体验表-带进度条'!O26 -> 0 | M26: ='体验表-带进度条'!X26 -> 0 | N26: ='体验表-带进度条'!AA26 -> 0 | O26: ='体验表-带进度条'!AB26 -> 0 | Q26: 5999 | R26: 183
A27: ='体验表-带进度条'!B27 -> 26 | B27: ='体验表-带进度条'!E27 -> 7.99 | C27: ='体验表-带进度条'!F27 -> 129 | D27: ='体验表-带进度条'!G27 -> 10320000 | E27: ='体验表-带进度条'!H27 -> 33970000 | F27: ='体验表-带进度条'!I27 -> 27.95 | G27: ='体验表-带进度条'!J27 -> 0 | H27: ='体验表-带进度条'!K27 -> 金币 | I27: ='体验表-带进度条'!L27 -> 9 | ... L27: ='体验表-带进度条'!O27 -> 10.67958 | M27: ='体验表-带进度条'!X27 -> 39813175 | N27: ='体验表-带进度条'!AA27 -> 39.813175 | O27: ='体验表-带进度条'!AB27 -> 1.1720099 | Q27: 6999 | R27: 183
A28: ='体验表-带进度条'!B28 -> 27 | B28: ='体验表-带进度条'!E28 -> 0 | C28: ='体验表-带进度条'!F28 | D28: ='体验表-带进度条'!G28 -> 0 | E28: ='体验表-带进度条'!H28 -> 0 | F28: ='体验表-带进度条'!I28 -> 0 | G28: ='体验表-带进度条'!J28 -> 0 | H28: ='体验表-带进度条'!K28 -> 记牌器1个 | I28: ='体验表-带进度条'!L28 -> 3 | ... L28: ='体验表-带进度条'!O28 -> 0 | M28: ='体验表-带进度条'!X28 -> 0 | N28: ='体验表-带进度条'!AA28 -> 0 | O28: ='体验表-带进度条'!AB28 -> 0 | Q28: 7499 | R28: 188
A29: ='体验表-带进度条'!B29 -> 28 | B29: ='体验表-带进度条'!E29 -> 0 | C29: ='体验表-带进度条'!F29 | D29: ='体验表-带进度条'!G29 -> 0 | E29: ='体验表-带进度条'!H29 -> 0 | F29: ='体验表-带进度条'!I29 -> 0 | G29: ='体验表-带进度条'!J29 -> 0.04 | H29: ='体验表-带进度条'!K29 -> 金币 | I29: ='体验表-带进度条'!L29 -> 17 | ... L29: ='体验表-带进度条'!O29 -> 0 | M29: ='体验表-带进度条'!X29 -> 0 | N29: ='体验表-带进度条'!AA29 -> 0 | O29: ='体验表-带进度条'!AB29 -> 0 | Q29: 7999 | R29: 188
... A31: ='体验表-带进度条'!B31 -> 30 | B31: ='体验表-带进度条'!E31 -> 0 | C31: ='体验表-带进度条'!F31 | D31: ='体验表-带进度条'!G31 -> 0 | E31: ='体验表-带进度条'!H31 -> 0 | F31: ='体验表-带进度条'!I31 -> 0 | G31: ='体验表-带进度条'!J31 -> 0 | H31: ='体验表-带进度条'!K31 -> 老虎机抽奖券 | I31: ='体验表-带进度条'!L31 -> 3 | ... L31: ='体验表-带进度条'!O31 -> 0 | M31: ='体验表-带进度条'!X31 -> 0 | N31: ='体验表-带进度条'!AA31 -> 0 | O31: ='体验表-带进度条'!AB31 -> 0 | Q31: 9999 | R31: 200
A32: ='体验表-带进度条'!B32 -> 31 | B32: ='体验表-带进度条'!E32 -> 0 | C32: ='体验表-带进度条'!F32 | D32: ='体验表-带进度条'!G32 -> 0 | E32: ='体验表-带进度条'!H32 -> 0 | F32: ='体验表-带进度条'!I32 -> 0 | G32: ='体验表-带进度条'!J32 -> 0 | H32: ='体验表-带进度条'!K32 -> 大奖赛复活券 | I32: ='体验表-带进度条'!L32 -> 3 | ... L32: ='体验表-带进度条'!O32 -> 0 | M32: ='体验表-带进度条'!X32 -> 0 | N32: ='体验表-带进度条'!AA32 -> 0 | O32: ='体验表-带进度条'!AB32 -> 0
A33: ='体验表-带进度条'!B33 -> 32 | B33: ='体验表-带进度条'!E33 -> 8.99 | C33: ='体验表-带进度条'!F33 -> 134 | D33: ='体验表-带进度条'!G33 -> 12060000 | E33: ='体验表-带进度条'!H33 -> 46030000 | F33: ='体验表-带进度条'!I33 -> 36.94 | G33: ='体验表-带进度条'!J33 -> 0 | H33: ='体验表-带进度条'!K33 -> 金币 | I33: ='体验表-带进度条'!L33 -> 9 | ... L33: ='体验表-带进度条'!O33 -> 13.13874 | M33: ='体验表-带进度条'!X33 -> 52951915 | N33: ='体验表-带进度条'!AA33 -> 52.951915 | O33: ='体验表-带进度条'!AB33 -> 1.1503783
A34: ='体验表-带进度条'!B34 -> 33 | B34: ='体验表-带进度条'!E34 -> 0 | C34: ='体验表-带进度条'!F34 | D34: ='体验表-带进度条'!G34 -> 0 | E34: ='体验表-带进度条'!H34 -> 0 | F34: ='体验表-带进度条'!I34 -> 0 | G34: ='体验表-带进度条'!J34 -> 0 | H34: ='体验表-带进度条'!K34 -> 记牌器1个 | I34: ='体验表-带进度条'!L34 -> 3 | ... L34: ='体验表-带进度条'!O34 -> 0 | M34: ='体验表-带进度条'!X34 -> 0 | N34: ='体验表-带进度条'!AA34 -> 0 | O34: ='体验表-带进度条'!AB34 -> 0
A35: ='体验表-带进度条'!B35 -> 34 | B35: ='体验表-带进度条'!E35 -> 0 | C35: ='体验表-带进度条'!F35 | D35: ='体验表-带进度条'!G35 -> 0 | E35: ='体验表-带进度条'!H35 -> 0 | F35: ='体验表-带进度条'!I35 -> 0 | G35: ='体验表-带进度条'!J35 -> 0.12 | H35: ='体验表-带进度条'!K35 -> 金币 | I35: ='体验表-带进度条'!L35 -> 17 | ... L35: ='体验表-带进度条'!O35 -> 0 | M35: ='体验表-带进度条'!X35 -> 0 | N35: ='体验表-带进度条'!AA35 -> 0 | O35: ='体验表-带进度条'!AB35 -> 0
A36: ='体验表-带进度条'!B36 -> 35 | B36: ='体验表-带进度条'!E36 -> 0 | C36: ='体验表-带进度条'!F36 | D36: ='体验表-带进度条'!G36 -> 0 | E36: ='体验表-带进度条'!H36 -> 0 | F36: ='体验表-带进度条'!I36 -> 0 | G36: ='体验表-带进度条'!J36 -> 0 | H36: ='体验表-带进度条'!K36 -> 卡包5星 | I36: ='体验表-带进度条'!L36 -> 4 | ... L36: ='体验表-带进度条'!O36 -> 0 | M36: ='体验表-带进度条'!X36 -> 0 | N36: ='体验表-带进度条'!AA36 -> 0 | O36: ='体验表-带进度条'!AB36 -> 0
A37: ='体验表-带进度条'!B37 -> 36 | B37: ='体验表-带进度条'!E37 -> 0 | C37: ='体验表-带进度条'!F37 | D37: ='体验表-带进度条'!G37 -> 0 | E37: ='体验表-带进度条'!H37 -> 0 | F37: ='体验表-带进度条'!I37 -> 0 | G37: ='体验表-带进度条'!J37 -> 0 | H37: ='体验表-带进度条'!K37 -> 老虎机抽奖券 | I37: ='体验表-带进度条'!L37 -> 3 | ... L37: ='体验表-带进度条'!O37 -> 0 | M37: ='体验表-带进度条'!X37 -> 0 | N37: ='体验表-带进度条'!AA37 -> 0 | O37: ='体验表-带进度条'!AB37 -> 0
A38: ='体验表-带进度条'!B38 -> 37 | B38: ='体验表-带进度条'!E38 -> 0 | C38: ='体验表-带进度条'!F38 | D38: ='体验表-带进度条'!G38 -> 0 | E38: ='体验表-带进度条'!H38 -> 0 | F38: ='体验表-带进度条'!I38 -> 0 | G38: ='体验表-带进度条'!J38 -> 0 | H38: ='体验表-带进度条'!K38 -> 大奖赛报名券 | I38: ='体验表-带进度条'!L38 -> 3 | ... L38: ='体验表-带进度条'!O38 -> 0 | M38: ='体验表-带进度条'!X38 -> 0 | N38: ='体验表-带进度条'!AA38 -> 0 | O38: ='体验表-带进度条'!AB38 -> 0
A39: ='体验表-带进度条'!B39 -> 38 | B39: ='体验表-带进度条'!E39 -> 9.99 | C39: ='体验表-带进度条'!F39 -> 139 | D39: ='体验表-带进度条'!G39 -> 13900000 | E39: ='体验表-带进度条'!H39 -> 59930000 | F39: ='体验表-带进度条'!I39 -> 46.93 | G39: ='体验表-带进度条'!J39 -> 0.45 | H39: ='体验表-带进度条'!K39 -> 金币 | I39: ='体验表-带进度条'!L39 -> 9 | ... L39: ='体验表-带进度条'!O39 -> 14.97874 | M39: ='体验表-带进度条'!X39 -> 71975930 | N39: ='体验表-带进度条'!AA39 -> 71.97593 | O39: ='体验表-带进度条'!AB39 -> 1.201
A40: ='体验表-带进度条'!B40 -> 39 | B40: ='体验表-带进度条'!E40 -> 0 | C40: ='体验表-带进度条'!F40 | D40: ='体验表-带进度条'!G40 -> 0 | E40: ='体验表-带进度条'!H40 -> 0 | F40: ='体验表-带进度条'!I40 -> 0 | G40: ='体验表-带进度条'!J40 -> 0 | H40: ='体验表-带进度条'!K40 -> 记牌器1个 | I40: ='体验表-带进度条'!L40 -> 3 | ... L40: ='体验表-带进度条'!O40 -> 0 | M40: ='体验表-带进度条'!X40 -> 0 | N40: ='体验表-带进度条'!AA40 -> 0 | O40: ='体验表-带进度条'!AB40 -> 0
A41: ='体验表-带进度条'!B41 -> 40 | B41: ='体验表-带进度条'!E41 -> 0 | C41: ='体验表-带进度条'!F41 | D41: ='体验表-带进度条'!G41 -> 0 | E41: ='体验表-带进度条'!H41 -> 0 | F41: ='体验表-带进度条'!I41 -> 0 | G41: ='体验表-带进度条'!J41 -> 0.12 | H41: ='体验表-带进度条'!K41 -> 金币 | I41: ='体验表-带进度条'!L41 -> 17 | ... L41: ='体验表-带进度条'!O41 -> 0 | M41: ='体验表-带进度条'!X41 -> 0 | N41: ='体验表-带进度条'!AA41 -> 0 | O41: ='体验表-带进度条'!AB41 -> 0
A42: ='体验表-带进度条'!B42 -> 41 | B42: ='体验表-带进度条'!E42 -> 0 | C42: ='体验表-带进度条'!F42 | D42: ='体验表-带进度条'!G42 -> 0 | E42: ='体验表-带进度条'!H42 -> 0 | F42: ='体验表-带进度条'!I42 -> 0 | G42: ='体验表-带进度条'!J42 -> 0 | H42: ='体验表-带进度条'!K42 -> 卡包fun卡 | I42: ='体验表-带进度条'!L42 -> 4 | ... L42: ='体验表-带进度条'!O42 -> 0 | M42: ='体验表-带进度条'!X42 -> 0 | N42: ='体验表-带进度条'!AA42 -> 0 | O42: ='体验表-带进度条'!AB42 -> 0
A43: ='体验表-带进度条'!B43 -> 42 | B43: ='体验表-带进度条'!E43 -> 0 | C43: ='体验表-带进度条'!F43 | D43: ='体验表-带进度条'!G43 -> 0 | E43: ='体验表-带进度条'!H43 -> 0 | F43: ='体验表-带进度条'!I43 -> 0 | G43: ='体验表-带进度条'!J43 -> 0 | H43: ='体验表-带进度条'!K43 -> 老虎机抽奖券 | I43: ='体验表-带进度条'!L43 -> 3 | ... L43: ='体验表-带进度条'!O43 -> 0 | M43: ='体验表-带进度条'!X43 -> 0 | N43: ='体验表-带进度条'!AA43 -> 0 | O43: ='体验表-带进度条'!AB43 -> 0
... A474: ='体验表-带进度条'!B474 -> 43 | B474: ='体验表-带进度条'!E474 -> 0 | C474: ='体验表-带进度条'!F474 | D474: ='体验表-带进度条'!G474 -> 0 | E474: ='体验表-带进度条'!H474 -> 0 | F474: ='体验表-带进度条'!I474 -> 0 | G474: ='体验表-带进度条'!J474 -> 0 | H474: ='体验表-带进度条'!K474 -> 大奖赛复活券 | I474: ='体验表-带进度条'!L474 -> 3 | ... L474: ='体验表-带进度条'!O474 -> 0 | M474: ='体验表-带进度条'!X474 -> 0 | N474: ='体验表-带进度条'!AA474 -> 0 | O474: ='体验表-带进度条'!AB474 -> 0

Sheet 体验表-备份
A1: ='体验表-带进度条'!B1 -> 序列 | B1: ='体验表-带进度条'!E1 -> 0 | C1: ='体验表-带进度条'!F1 -> 档位膨胀 | D1: ='体验表-带进度条'!G1 -> 基础金币 | E1: ='体验表-带进度条'!H1 -> 合计金币 | F1: ='体验表-带进度条'!I1 -> 合计美金 | G1: ='体验表-带进度条'!J1 -> 优惠比例 | H1: ='体验表-带进度条'!K1 -> 奖励类型 | I1: ='体验表-带进度条'!L1 -> 奖励类型 1金币 2钻石 3道具 4卡包 9美金(查表) 17美金金币 | ... L1: ='体验表-带进度条'!O1 -> 档位美金 | M1: ='体验表-带进度条'!X1 -> 合计金币 | N1: ='体验表-带进度条'!AA1 -> 合计美金 | O1: ='体验表-带进度条'!AB1 -> 折扣 | Q1: ='体验表-带进度条'!AD1 -> 总计美金 | S1: 档位 | T1: 膨胀系数 | V1: VIP膨胀 | W1: 仅VIP膨胀
A2: ='体验表-带进度条'!B2 -> 1 | B2: ='体验表-带进度条'!E2 -> 0 | C2: ='体验表-带进度条'!F2 | D2: ='体验表-带进度条'!G2 -> 0 | E2: ='体验表-带进度条'!H2 -> 0 | F2: ='体验表-带进度条'!I2 -> 0 | G2: ='体验表-带进度条'!J2 -> 0 | H2: ='体验表-带进度条'!K2 -> 金币 | I2: ='体验表-带进度条'!L2 -> 1 | ... L2: ='体验表-带进度条'!O2 -> 0 | M2: ='体验表-带进度条'!X2 -> 0 | N2: ='体验表-带进度条'!AA2 -> 0 | O2: ='体验表-带进度条'!AB2 -> 0 | Q2: ='体验表-带进度条'!AD2 -> 46.93 | S2: 99 | T2: 100 | V2: 0 | W2: 1000000
A3: ='体验表-带进度条'!B3 -> 2 | B3: ='体验表-带进度条'!E3 -> 2.99 | C3: ='体验表-带进度条'!F3 -> 109 | D3: ='体验表-带进度条'!G3 -> 3270000 | E3: ='体验表-带进度条'!H3 -> 3270000 | F3: ='体验表-带进度条'!I3 -> 2.99 | G3: ='体验表-带进度条'!J3 -> 0 | H3: ='体验表-带进度条'!K3 -> 金币 | I3: ='体验表-带进度条'!L3 -> 9 | ... L3: ='体验表-带进度条'!O3 -> 4.16895 | M3: ='体验表-带进度条'!X3 -> 4168950 | N3: ='体验表-带进度条'!AA3 -> 4.16895 | O3: ='体验表-带进度条'!AB3 -> 1.2749083 | Q3: ='体验表-带进度条'!AD3 -> 总优惠比例 | S3: 199 | T3: 100 | V3: 1 | W3: 1250000
A4: ='体验表-带进度条'!B4 -> 3 | B4: ='体验表-带进度条'!E4 -> 0 | C4: ='体验表-带进度条'!F4 | D4: ='体验表-带进度条'!G4 -> 0 | E4: ='体验表-带进度条'!H4 -> 0 | F4: ='体验表-带进度条'!I4 -> 0 | G4: ='体验表-带进度条'!J4 -> 0 | H4: ='体验表-带进度条'!K4 -> 记牌器1个 | I4: ='体验表-带进度条'!L4 -> 3 | ... L4: ='体验表-带进度条'!O4 -> 0 | M4: ='体验表-带进度条'!X4 -> 0 | N4: ='体验表-带进度条'!AA4 -> 0 | O4: ='体验表-带进度条'!AB4 -> 0 | Q4: ='体验表-带进度条'!AD4 -> 1.15 | S4: 299 | T4: 109 | V4: 2 | W4: 1500000
A5: ='体验表-带进度条'!B5 -> 4 | B5: ='体验表-带进度条'!E5 -> 0 | C5: ='体验表-带进度条'!F5 | D5: ='体验表-带进度条'!G5 -> 0 | E5: ='体验表-带进度条'!H5 -> 0 | F5: ='体验表-带进度条'!I5 -> 0 | G5: ='体验表-带进度条'!J5 -> 0.1 | H5: ='体验表-带进度条'!K5 -> 金币 | I5: ='体验表-带进度条'!L5 -> 17 | ... L5: ='体验表-带进度条'!O5 -> 0 | M5: ='体验表-带进度条'!X5 -> 0 | N5: ='体验表-带进度条'!AA5 -> 0 | O5: ='体验表-带进度条'!AB5 -> 0 | Q5: ='体验表-带进度条'!AD5 -> 优惠金币 | S5: 399 | T5: 114 | V5: 3 | W5: 1750000
A6: ='体验表-带进度条'!B6 -> 5 | B6: ='体验表-带进度条'!E6 -> 0 | C6: ='体验表-带进度条'!F6 | D6: ='体验表-带进度条'!G6 -> 0 | E6: ='体验表-带进度条'!H6 -> 0 | F6: ='体验表-带进度条'!I6 -> 0 | G6: ='体验表-带进度条'!J6 -> 0 | H6: ='体验表-带进度条'!K6 -> 卡包2星 | I6: ='体验表-带进度条'!L6 -> 4 | ... L6: ='体验表-带进度条'!O6 -> 0 | M6: ='体验表-带进度条'!X6 -> 0 | N6: ='体验表-带进度条'!AA6 -> 0 | O6: ='体验表-带进度条'!AB6 -> 0 | Q6: ='体验表-带进度条'!AD6 -> 8989500 | S6: 499 | T6: 119 | V6: 4 | W6: 2000000
A7: ='体验表-带进度条'!B7 -> 6 | B7: ='体验表-带进度条'!E7 -> 0 | C7: ='体验表-带进度条'!F7 | D7: ='体验表-带进度条'!G7 -> 0 | E7: ='体验表-带进度条'!H7 -> 0 | F7: ='体验表-带进度条'!I7 -> 0 | G7: ='体验表-带进度条'!J7 -> 0 | H7: ='体验表-带进度条'!K7 -> 老虎机抽奖券 | I7: ='体验表-带进度条'!L7 -> 3 | ... L7: ='体验表-带进度条'!O7 -> 0 | M7: ='体验表-带进度条'!X7 -> 0 | N7: ='体验表-带进度条'!AA7 -> 0 | O7: ='体验表-带进度条'!AB7 -> 0 | Q7: ='体验表-带进度条'!AD7 -> 总优惠进度 | S7: 599 | T7: 119 | V7: 5 | W7: 2250000
A8: ='体验表-带进度条'!B8 -> 7 | B8: ='体验表-带进度条'!E8 -> 0 | C8: ='体验表-带进度条'!F8 | D8: ='体验表-带进度条'!G8 -> 0 | E8: ='体验表-带进度条'!H8 -> 0 | F8: ='体验表-带进度条'!I8 -> 0 | G8: ='体验表-带进度条'!J8 -> 0 | H8: ='体验表-带进度条'!K8 -> 大奖赛复活券 | I8: ='体验表-带进度条'!L8 -> 3 | ... L8: ='体验表-带进度条'!O8 -> 0 | M8: ='体验表-带进度条'!X8 -> 0 | N8: ='体验表-带进度条'!AA8 -> 0 | O8: ='体验表-带进度条'!AB8 -> 0 | Q8: ='体验表-带进度条'!AD8 -> 1.34 | S8: 699 | T8: 124 | V8: 6 | W8: 2500000
A9: ='体验表-带进度条'!B9 -> 8 | B9: ='体验表-带进度条'!E9 -> 3.99 | C9: ='体验表-带进度条'!F9 -> 114 | D9: ='体验表-带进度条'!G9 -> 4560000 | E9: ='体验表-带进度条'!H9 -> 7830000 | F9: ='体验表-带进度条'!I9 -> 6.98 | G9: ='体验表-带进度条'!J9 -> 0.12 | H9: ='体验表-带进度条'!K9 -> 金币 | I9: ='体验表-带进度条'!L9 -> 9 | ... L9: ='体验表-带进度条'!O9 -> 4.73979 | M9: ='体验表-带进度条'!X9 -> 9987480 | N9: ='体验表-带进度条'!AA9 -> 9.98748 | O9: ='体验表-带进度条'!AB9 -> 1.2755402 | S9: 799 | T9: 129 | V9: 7 | W9: 2500000
A10: ='体验表-带进度条'!B10 -> 9 | B10: ='体验表-带进度条'!E10 -> 0 | C10: ='体验表-带进度条'!F10 | D10: ='体验表-带进度条'!G10 -> 0 | E10: ='体验表-带进度条'!H10 -> 0 | F10: ='体验表-带进度条'!I10 -> 0 | G10: ='体验表-带进度条'!J10 -> 0 | H10: ='体验表-带进度条'!K10 -> 记牌器1个 | I10: ='体验表-带进度条'!L10 -> 3 | ... L10: ='体验表-带进度条'!O10 -> 0 | M10: ='体验表-带进度条'!X10 -> 0 | N10: ='体验表-带进度条'!AA10 -> 0 | O10: ='体验表-带进度条'!AB10 -> 0 | S10: 899 | T10: 134 | V10: 8 | W10: 2500000
A11: ='体验表-带进度条'!B11 -> 10 | B11: ='体验表-带进度条'!E11 -> 0 | C11: ='体验表-带进度条'!F11 | D11: ='体验表-带进度条'!G11 -> 0 | E11: ='体验表-带进度条'!H11 -> 0 | F11: ='体验表-带进度条'!I11 -> 0 | G11: ='体验表-带进度条'!J11 -> 0.02 | H11: ='体验表-带进度条'!K11 -> 金币 | I11: ='体验表-带进度条'!L11 -> 17 | ... L11: ='体验表-带进度条'!O11 -> 0 | M11: ='体验表-带进度条'!X11 -> 0 | N11: ='体验表-带进度条'!AA11 -> 0 | O11: ='体验表-带进度条'!AB11 -> 0 | S11: 999 | T11: 139 | V11: 9 | W11: 2500000
A12: ='体验表-带进度条'!B12 -> 11 | B12: ='体验表-带进度条'!E12 -> 0 | C12: ='体验表-带进度条'!F12 | D12: ='体验表-带进度条'!G12 -> 0 | E12: ='体验表-带进度条'!H12 -> 0 | F12: ='体验表-带进度条'!I12 -> 0 | G12: ='体验表-带进度条'!J12 -> 0 | H12: ='体验表-带进度条'!K12 -> 卡包3星 | I12: ='体验表-带进度条'!L12 -> 4 | ... L12: ='体验表-带进度条'!O12 -> 0 | M12: ='体验表-带进度条'!X12 -> 0 | N12: ='体验表-带进度条'!AA12 -> 0 | O12: ='体验表-带进度条'!AB12 -> 0 | S12: 1099 | T12: 142 | V12: 10 | W12: 2500000
A13: ='体验表-带进度条'!B13 -> 12 | B13: ='体验表-带进度条'!E13 -> 0 | C13: ='体验表-带进度条'!F13 | D13: ='体验表-带进度条'!G13 -> 0 | E13: ='体验表-带进度条'!H13 -> 0 | F13: ='体验表-带进度条'!I13 -> 0 | G13: ='体验表-带进度条'!J13 -> 0 | H13: ='体验表-带进度条'!K13 -> 老虎机抽奖券 | I13: ='体验表-带进度条'!L13 -> 3 | ... L13: ='体验表-带进度条'!O13 -> 0 | M13: ='体验表-带进度条'!X13 -> 0 | N13: ='体验表-带进度条'!AA13 -> 0 | O13: ='体验表-带进度条'!AB13 -> 0 | S13: 1199 | T13: 146 | V13: 11 | W13: 2500000
A14: ='体验表-带进度条'!B14 -> 13 | B14: ='体验表-带进度条'!E14 -> 0 | C14: ='体验表-带进度条'!F14 | D14: ='体验表-带进度条'!G14 -> 0 | E14: ='体验表-带进度条'!H14 -> 0 | F14: ='体验表-带进度条'!I14 -> 0 | G14: ='体验表-带进度条'!J14 -> 0 | H14: ='体验表-带进度条'!K14 -> 大奖赛报名券 | I14: ='体验表-带进度条'!L14 -> 3 | ... L14: ='体验表-带进度条'!O14 -> 0 | M14: ='体验表-带进度条'!X14 -> 0 | N14: ='体验表-带进度条'!AA14 -> 0 | O14: ='体验表-带进度条'!AB14 -> 0 | S14: 1299 | T14: 149 | V14: 12 | W14: 2500000
A15: ='体验表-带进度条'!B15 -> 14 | B15: ='体验表-带进度条'!E15 -> 5.99 | C15: ='体验表-带进度条'!F15 -> 119 | D15: ='体验表-带进度条'!G15 -> 7140000 | E15: ='体验表-带进度条'!H15 -> 14970000 | F15: ='体验表-带进度条'!I15 -> 12.97 | G15: ='体验表-带进度条'!J15 -> 0 | H15: ='体验表-带进度条'!K15 -> 金币 | I15: ='体验表-带进度条'!L15 -> 9 | ... L15: ='体验表-带进度条'!O15 -> 7.589475 | M15: ='体验表-带进度条'!X15 -> 17576955 | N15: ='体验表-带进度条'!AA15 -> 17.576955 | O15: ='体验表-带进度条'!AB15 -> 1.1741453 | S15: 1399 | T15: 151 | V15: 13 | W15: 2500000
A16: ='体验表-带进度条'!B16 -> 15 | B16: ='体验表-带进度条'!E16 -> 0 | C16: ='体验表-带进度条'!F16 | D16: ='体验表-带进度条'!G16 -> 0 | E16: ='体验表-带进度条'!H16 -> 0 | F16: ='体验表-带进度条'!I16 -> 0 | G16: ='体验表-带进度条'!J16 -> 0 | H16: ='体验表-带进度条'!K16 -> 记牌器1个 | I16: ='体验表-带进度条'!L16 -> 3 | ... L16: ='体验表-带进度条'!O16 -> 0 | M16: ='体验表-带进度条'!X16 -> 0 | N16: ='体验表-带进度条'!AA16 -> 0 | O16: ='体验表-带进度条'!AB16 -> 0 | S16: 1499 | T16: 154 | V16: 14 | W16: 2500000
A17: ='体验表-带进度条'!B17 -> 16 | B17: ='体验表-带进度条'!E17 -> 0 | C17: ='体验表-带进度条'!F17 | D17: ='体验表-带进度条'!G17 -> 0 | E17: ='体验表-带进度条'!H17 -> 0 | F17: ='体验表-带进度条'!I17 -> 0 | G17: ='体验表-带进度条'!J17 -> 0.05 | H17: ='体验表-带进度条'!K17 -> 金币 | I17: ='体验表-带进度条'!L17 -> 17 | ... L17: ='体验表-带进度条'!O17 -> 0 | M17: ='体验表-带进度条'!X17 -> 0 | N17: ='体验表-带进度条'!AA17 -> 0 | O17: ='体验表-带进度条'!AB17 -> 0 | S17: 1799 | T17: 158 | V17: 15 | W17: 2500000
A18: ='体验表-带进度条'!B18 -> 17 | B18: ='体验表-带进度条'!E18 -> 0 | C18: ='体验表-带进度条'!F18 | D18: ='体验表-带进度条'!G18 -> 0 | E18: ='体验表-带进度条'!H18 -> 0 | F18: ='体验表-带进度条'!I18 -> 0 | G18: ='体验表-带进度条'!J18 -> 0 | H18: ='体验表-带进度条'!K18 -> 卡包4星 | I18: ='体验表-带进度条'!L18 -> 4 | ... L18: ='体验表-带进度条'!O18 -> 0 | M18: ='体验表-带进度条'!X18 -> 0 | N18: ='体验表-带进度条'!AA18 -> 0 | O18: ='体验表-带进度条'!AB18 -> 0 | S18: 1999 | T18: 158
A19: ='体验表-带进度条'!B19 -> 18 | B19: ='体验表-带进度条'!E19 -> 0 | C19: ='体验表-带进度条'!F19 | D19: ='体验表-带进度条'!G19 -> 0 | E19: ='体验表-带进度条'!H19 -> 0 | F19: ='体验表-带进度条'!I19 -> 0 | G19: ='体验表-带进度条'!J19 -> 0 | H19: ='体验表-带进度条'!K19 -> 老虎机抽奖券 | I19: ='体验表-带进度条'!L19 -> 3 | ... L19: ='体验表-带进度条'!O19 -> 0 | M19: ='体验表-带进度条'!X19 -> 0 | N19: ='体验表-带进度条'!AA19 -> 0 | O19: ='体验表-带进度条'!AB19 -> 0 | S19: 2499 | T19: 163
A20: ='体验表-带进度条'!B20 -> 19 | B20: ='体验表-带进度条'!E20 -> 0 | C20: ='体验表-带进度条'!F20 | D20: ='体验表-带进度条'!G20 -> 0 | E20: ='体验表-带进度条'!H20 -> 0 | F20: ='体验表-带进度条'!I20 -> 0 | G20: ='体验表-带进度条'!J20 -> 0 | H20: ='体验表-带进度条'!K20 -> 大奖赛复活券 | I20: ='体验表-带进度条'!L20 -> 3 | ... L20: ='体验表-带进度条'!O20 -> 0 | M20: ='体验表-带进度条'!X20 -> 0 | N20: ='体验表-带进度条'!AA20 -> 0 | O20: ='体验表-带进度条'!AB20 -> 0 | S20: 2999 | T20: 163
A21: ='体验表-带进度条'!B21 -> 20 | B21: ='体验表-带进度条'!E21 -> 6.99 | C21: ='体验表-带进度条'!F21 -> 124 | D21: ='体验表-带进度条'!G21 -> 8680000 | E21: ='体验表-带进度条'!H21 -> 23650000 | F21: ='体验表-带进度条'!I21 -> 19.96 | G21: ='体验表-带进度条'!J21 -> 0.24 | H21: ='体验表-带进度条'!K21 -> 金币 | I21: ='体验表-带进度条'!L21 -> 9 | ... L21: ='体验表-带进度条'!O21 -> 9.39916 | M21: ='体验表-带进度条'!X21 -> 29133595 | N21: ='体验表-带进度条'!AA21 -> 29.133595 | O21: ='体验表-带进度条'!AB21 -> 1.2318645 | S21: 3499 | T21: 168
A22: ='体验表-带进度条'!B22 -> 21 | B22: ='体验表-带进度条'!E22 -> 0 | C22: ='体验表-带进度条'!F22 | D22: ='体验表-带进度条'!G22 -> 0 | E22: ='体验表-带进度条'!H22 -> 0 | F22: ='体验表-带进度条'!I22 -> 0 | G22: ='体验表-带进度条'!J22 -> 0 | H22: ='体验表-带进度条'!K22 -> 记牌器1个 | I22: ='体验表-带进度条'!L22 -> 3 | ... L22: ='体验表-带进度条'!O22 -> 0 | M22: ='体验表-带进度条'!X22 -> 0 | N22: ='体验表-带进度条'!AA22 -> 0 | O22: ='体验表-带进度条'!AB22 -> 0 | S22: 3999 | T22: 173
A23: ='体验表-带进度条'!B23 -> 22 | B23: ='体验表-带进度条'!E23 -> 0 | C23: ='体验表-带进度条'!F23 | D23: ='体验表-带进度条'!G23 -> 0 | E23: ='体验表-带进度条'!H23 -> 0 | F23: ='体验表-带进度条'!I23 -> 0 | G23: ='体验表-带进度条'!J23 -> 0.08 | H23: ='体验表-带进度条'!K23 -> 金币 | I23: ='体验表-带进度条'!L23 -> 17 | ... L23: ='体验表-带进度条'!O23 -> 0 | M23: ='体验表-带进度条'!X23 -> 0 | N23: ='体验表-带进度条'!AA23 -> 0 | O23: ='体验表-带进度条'!AB23 -> 0 | S23: 4499 | T23: 178
A24: ='体验表-带进度条'!B24 -> 23 | B24: ='体验表-带进度条'!E24 -> 0 | C24: ='体验表-带进度条'!F24 | D24: ='体验表-带进度条'!G24 -> 0 | E24: ='体验表-带进度条'!H24 -> 0 | F24: ='体验表-带进度条'!I24 -> 0 | G24: ='体验表-带进度条'!J24 -> 0 | H24: ='体验表-带进度条'!K24 -> 卡包4星 | I24: ='体验表-带进度条'!L24 -> 4 | ... L24: ='体验表-带进度条'!O24 -> 0 | M24: ='体验表-带进度条'!X24 -> 0 | N24: ='体验表-带进度条'!AA24 -> 0 | O24: ='体验表-带进度条'!AB24 -> 0 | S24: 4999 | T24: 178
A25: ='体验表-带进度条'!B25 -> 24 | B25: ='体验表-带进度条'!E25 -> 0 | C25: ='体验表-带进度条'!F25 | D25: ='体验表-带进度条'!G25 -> 0 | E25: ='体验表-带进度条'!H25 -> 0 | F25: ='体验表-带进度条'!I25 -> 0 | G25: ='体验表-带进度条'!J25 -> 0 | H25: ='体验表-带进度条'!K25 -> 老虎机抽奖券 | I25: ='体验表-带进度条'!L25 -> 3 | ... L25: ='体验表-带进度条'!O25 -> 0 | M25: ='体验表-带进度条'!X25 -> 0 | N25: ='体验表-带进度条'!AA25 -> 0 | O25: ='体验表-带进度条'!AB25 -> 0 | S25: 5499 | T25: 178
A26: ='体验表-带进度条'!B26 -> 25 | B26: ='体验表-带进度条'!E26 -> 0 | C26: ='体验表-带进度条'!F26 | D26: ='体验表-带进度条'!G26 -> 0 | E26: ='体验表-带进度条'!H26 -> 0 | F26: ='体验表-带进度条'!I26 -> 0 | G26: ='体验表-带进度条'!J26 -> 0 | H26: ='体验表-带进度条'!K26 -> 大奖赛报名券 | I26: ='体验表-带进度条'!L26 -> 3 | ... L26: ='体验表-带进度条'!O26 -> 0 | M26: ='体验表-带进度条'!X26 -> 0 | N26: ='体验表-带进度条'!AA26 -> 0 | O26: ='体验表-带进度条'!AB26 -> 0 | S26: 5999 | T26: 183
A27: ='体验表-带进度条'!B27 -> 26 | B27: ='体验表-带进度条'!E27 -> 7.99 | C27: ='体验表-带进度条'!F27 -> 129 | D27: ='体验表-带进度条'!G27 -> 10320000 | E27: ='体验表-带进度条'!H27 -> 33970000 | F27: ='体验表-带进度条'!I27 -> 27.95 | G27: ='体验表-带进度条'!J27 -> 0 | H27: ='体验表-带进度条'!K27 -> 金币 | I27: ='体验表-带进度条'!L27 -> 9 | ... L27: ='体验表-带进度条'!O27 -> 10.67958 | M27: ='体验表-带进度条'!X27 -> 39813175 | N27: ='体验表-带进度条'!AA27 -> 39.813175 | O27: ='体验表-带进度条'!AB27 -> 1.1720099 | S27: 6999 | T27: 183
A28: ='体验表-带进度条'!B28 -> 27 | B28: ='体验表-带进度条'!E28 -> 0 | C28: ='体验表-带进度条'!F28 | D28: ='体验表-带进度条'!G28 -> 0 | E28: ='体验表-带进度条'!H28 -> 0 | F28: ='体验表-带进度条'!I28 -> 0 | G28: ='体验表-带进度条'!J28 -> 0 | H28: ='体验表-带进度条'!K28 -> 记牌器1个 | I28: ='体验表-带进度条'!L28 -> 3 | ... L28: ='体验表-带进度条'!O28 -> 0 | M28: ='体验表-带进度条'!X28 -> 0 | N28: ='体验表-带进度条'!AA28 -> 0 | O28: ='体验表-带进度条'!AB28 -> 0 | S28: 7499 | T28: 188
A29: ='体验表-带进度条'!B29 -> 28 | B29: ='体验表-带进度条'!E29 -> 0 | C29: ='体验表-带进度条'!F29 | D29: ='体验表-带进度条'!G29 -> 0 | E29: ='体验表-带进度条'!H29 -> 0 | F29: ='体验表-带进度条'!I29 -> 0 | G29: ='体验表-带进度条'!J29 -> 0.04 | H29: ='体验表-带进度条'!K29 -> 金币 | I29: ='体验表-带进度条'!L29 -> 17 | ... L29: ='体验表-带进度条'!O29 -> 0 | M29: ='体验表-带进度条'!X29 -> 0 | N29: ='体验表-带进度条'!AA29 -> 0 | O29: ='体验表-带进度条'!AB29 -> 0 | S29: 7999 | T29: 188
... A31: ='体验表-带进度条'!B31 -> 30 | B31: ='体验表-带进度条'!E31 -> 0 | C31: ='体验表-带进度条'!F31 | D31: ='体验表-带进度条'!G31 -> 0 | E31: ='体验表-带进度条'!H31 -> 0 | F31: ='体验表-带进度条'!I31 -> 0 | G31: ='体验表-带进度条'!J31 -> 0 | H31: ='体验表-带进度条'!K31 -> 老虎机抽奖券 | I31: ='体验表-带进度条'!L31 -> 3 | ... L31: ='体验表-带进度条'!O31 -> 0 | M31: ='体验表-带进度条'!X31 -> 0 | N31: ='体验表-带进度条'!AA31 -> 0 | O31: ='体验表-带进度条'!AB31 -> 0 | S31: 9999 | T31: 200
A32: ='体验表-带进度条'!B32 -> 31 | B32: ='体验表-带进度条'!E32 -> 0 | C32: ='体验表-带进度条'!F32 | D32: ='体验表-带进度条'!G32 -> 0 | E32: ='体验表-带进度条'!H32 -> 0 | F32: ='体验表-带进度条'!I32 -> 0 | G32: ='体验表-带进度条'!J32 -> 0 | H32: ='体验表-带进度条'!K32 -> 大奖赛复活券 | I32: ='体验表-带进度条'!L32 -> 3 | ... L32: ='体验表-带进度条'!O32 -> 0 | M32: ='体验表-带进度条'!X32 -> 0 | N32: ='体验表-带进度条'!AA32 -> 0 | O32: ='体验表-带进度条'!AB32 -> 0
A33: ='体验表-带进度条'!B33 -> 32 | B33: ='体验表-带进度条'!E33 -> 8.99 | C33: ='体验表-带进度条'!F33 -> 134 | D33: ='体验表-带进度条'!G33 -> 12060000 | E33: ='体验表-带进度条'!H33 -> 46030000 | F33: ='体验表-带进度条'!I33 -> 36.94 | G33: ='体验表-带进度条'!J33 -> 0 | H33: ='体验表-带进度条'!K33 -> 金币 | I33: ='体验表-带进度条'!L33 -> 9 | ... L33: ='体验表-带进度条'!O33 -> 13.13874 | M33: ='体验表-带进度条'!X33 -> 52951915 | N33: ='体验表-带进度条'!AA33 -> 52.951915 | O33: ='体验表-带进度条'!AB33 -> 1.1503783
A34: ='体验表-带进度条'!B34 -> 33 | B34: ='体验表-带进度条'!E34 -> 0 | C34: ='体验表-带进度条'!F34 | D34: ='体验表-带进度条'!G34 -> 0 | E34: ='体验表-带进度条'!H34 -> 0 | F34: ='体验表-带进度条'!I34 -> 0 | G34: ='体验表-带进度条'!J34 -> 0 | H34: ='体验表-带进度条'!K34 -> 记牌器1个 | I34: ='体验表-带进度条'!L34 -> 3 | ... L34: ='体验表-带进度条'!O34 -> 0 | M34: ='体验表-带进度条'!X34 -> 0 | N34: ='体验表-带进度条'!AA34 -> 0 | O34: ='体验表-带进度条'!AB34 -> 0
A35: ='体验表-带进度条'!B35 -> 34 | B35: ='体验表-带进度条'!E35 -> 0 | C35: ='体验表-带进度条'!F35 | D35: ='体验表-带进度条'!G35 -> 0 | E35: ='体验表-带进度条'!H35 -> 0 | F35: ='体验表-带进度条'!I35 -> 0 | G35: ='体验表-带进度条'!J35 -> 0.12 | H35: ='体验表-带进度条'!K35 -> 金币 | I35: ='体验表-带进度条'!L35 -> 17 | ... L35: ='体验表-带进度条'!O35 -> 0 | M35: ='体验表-带进度条'!X35 -> 0 | N35: ='体验表-带进度条'!AA35 -> 0 | O35: ='体验表-带进度条'!AB35 -> 0
A36: ='体验表-带进度条'!B36 -> 35 | B36: ='体验表-带进度条'!E36 -> 0 | C36: ='体验表-带进度条'!F36 | D36: ='体验表-带进度条'!G36 -> 0 | E36: ='体验表-带进度条'!H36 -> 0 | F36: ='体验表-带进度条'!I36 -> 0 | G36: ='体验表-带进度条'!J36 -> 0 | H36: ='体验表-带进度条'!K36 -> 卡包5星 | I36: ='体验表-带进度条'!L36 -> 4 | ... L36: ='体验表-带进度条'!O36 -> 0 | M36: ='体验表-带进度条'!X36 -> 0 | N36: ='体验表-带进度条'!AA36 -> 0 | O36: ='体验表-带进度条'!AB36 -> 0
A37: ='体验表-带进度条'!B37 -> 36 | B37: ='体验表-带进度条'!E37 -> 0 | C37: ='体验表-带进度条'!F37 | D37: ='体验表-带进度条'!G37 -> 0 | E37: ='体验表-带进度条'!H37 -> 0 | F37: ='体验表-带进度条'!I37 -> 0 | G37: ='体验表-带进度条'!J37 -> 0 | H37: ='体验表-带进度条'!K37 -> 老虎机抽奖券 | I37: ='体验表-带进度条'!L37 -> 3 | ... L37: ='体验表-带进度条'!O37 -> 0 | M37: ='体验表-带进度条'!X37 -> 0 | N37: ='体验表-带进度条'!AA37 -> 0 | O37: ='体验表-带进度条'!AB37 -> 0
A38: ='体验表-带进度条'!B38 -> 37 | B38: ='体验表-带进度条'!E38 -> 0 | C38: ='体验表-带进度条'!F38 | D38: ='体验表-带进度条'!G38 -> 0 | E38: ='体验表-带进度条'!H38 -> 0 | F38: ='体验表-带进度条'!I38 -> 0 | G38: ='体验表-带进度条'!J38 -> 0 | H38: ='体验表-带进度条'!K38 -> 大奖赛报名券 | I38: ='体验表-带进度条'!L38 -> 3 | ... L38: ='体验表-带进度条'!O38 -> 0 | M38: ='体验表-带进度条'!X38 -> 0 | N38: ='体验表-带进度条'!AA38 -> 0 | O38: ='体验表-带进度条'!AB38 -> 0
A39: ='体验表-带进度条'!B39 -> 38 | B39: ='体验表-带进度条'!E39 -> 9.99 | C39: ='体验表-带进度条'!F39 -> 139 | D39: ='体验表-带进度条'!G39 -> 13900000 | E39: ='体验表-带进度条'!H39 -> 59930000 | F39: ='体验表-带进度条'!I39 -> 46.93 | G39: ='体验表-带进度条'!J39 -> 0.45 | H39: ='体验表-带进度条'!K39 -> 金币 | I39: ='体验表-带进度条'!L39 -> 9 | ... L39: ='体验表-带进度条'!O39 -> 14.97874 | M39: ='体验表-带进度条'!X39 -> 71975930 | N39: ='体验表-带进度条'!AA39 -> 71.97593 | O39: ='体验表-带进度条'!AB39 -> 1.201
A40: ='体验表-带进度条'!B40 -> 39 | B40: ='体验表-带进度条'!E40 -> 0 | C40: ='体验表-带进度条'!F40 | D40: ='体验表-带进度条'!G40 -> 0 | E40: ='体验表-带进度条'!H40 -> 0 | F40: ='体验表-带进度条'!I40 -> 0 | G40: ='体验表-带进度条'!J40 -> 0 | H40: ='体验表-带进度条'!K40 -> 记牌器1个 | I40: ='体验表-带进度条'!L40 -> 3 | ... L40: ='体验表-带进度条'!O40 -> 0 | M40: ='体验表-带进度条'!X40 -> 0 | N40: ='体验表-带进度条'!AA40 -> 0 | O40: ='体验表-带进度条'!AB40 -> 0
A41: ='体验表-带进度条'!B41 -> 40 | B41: ='体验表-带进度条'!E41 -> 0 | C41: ='体验表-带进度条'!F41 | D41: ='体验表-带进度条'!G41 -> 0 | E41: ='体验表-带进度条'!H41 -> 0 | F41: ='体验表-带进度条'!I41 -> 0 | G41: ='体验表-带进度条'!J41 -> 0.12 | H41: ='体验表-带进度条'!K41 -> 金币 | I41: ='体验表-带进度条'!L41 -> 17 | ... L41: ='体验表-带进度条'!O41 -> 0 | M41: ='体验表-带进度条'!X41 -> 0 | N41: ='体验表-带进度条'!AA41 -> 0 | O41: ='体验表-带进度条'!AB41 -> 0
...

Sheet 体验表-带进度条
A1: 分组 | B1: 序列 | D1: exp | F1: 档位膨胀 | G1: 基础金币 | H1: 合计金币 | I1: 合计美金 | J1: 优惠比例 | K1: 奖励类型 | L1: 奖励类型 1金币 2钻石 3道具 4卡包 9美金(查表) 17美金金币 | M1: 数量 | N1: 档位金币 | O1: 档位美金 | P1: 进度序号 | Q1: 奖励类型 | R1: exp | S1: 关卡进度 | T1: 累计进度 | U1: 奖励类型1金币2钻石3道具4卡包9美金(查表)17美金金币 | V1: 数量 | W1: 金币 | X1: 合计金币 | AA1: 合计美金 | AB1: 折扣 | AD1: 总计美金 | AF1: 档位 | AG1: 膨胀系数 | AI1: VIP膨胀 | AJ1: 仅VIP膨胀 | AL1: 分组 | AM1: 阶段 | AN1: 积分 | AO1: 累计积分
A2: 1 | B2: 1 | F2: =IFERROR(VLOOKUP(ROUND((E2+0.01)*100,0),AF:AG,2,FALSE),"") | K2: 金币 | L2: 1 | M2: 5000 | R2: 20 | S2: {=_xlfn.IFNA(MATCH(SUMIFS(R:R,A:A,"="&A2,B:B,"<"&(B2+1)),_xlfn._xlws.FILTER(AO:AO,AL:AL=A2),1),1)} -> 1 | T2: =SUMIFS(R:R,A:A,"="&A2,B:B,"<"&(B2+1)) -> 20 | AD2: =SUM(E2:E44) -> 46.93 | AF2: 99 | AG2: 100 | AI2: 0 | AJ2: 1000000 | AL2: 1 | AM2: 1 | AN2: 50 | AO2: =SUMIFS(AN:AN,AL:AL,"="&AL2,AM:AM,"<="&AM2) -> 50
A3: 1 | B3: 2 | E3: 2.99 | F3: =IFERROR(VLOOKUP(ROUND(E3*100,0),AF:AG,2,FALSE),"") -> 109 | G3: =(E3+0.01)*F3*$AJ$2/100 -> 3270000 | H3: =SUM(G3) -> 3270000 | I3: =SUM(E3) -> 2.99 | K3: 金币 | L3: 9 | M3: =G3 -> 3270000 | N3: =SUMIF(K3:K8,"="&"金币",M3:M8) -> 4168950 | O3: =N3/$AJ$2 -> 4.16895 | R3: 10 | S3: {=_xlfn.IFNA(MATCH(SUMIFS(R:R,A:A,"="&A3,B:B,"<"&(B3+1)),_xlfn._xlws.FILTER(AO:AO,AL:AL=A3),1),1)} -> 1 | T3: =SUMIFS(R:R,A:A,"="&A3,B:B,"<"&(B3+1)) -> 30 | U3: =_xlfn.IFNA(VLOOKUP(Q3,道具!B:C,2,FALSE),"") | V3: =IF(U3=1,CEILING(W3*100/$AJ$2,5),IF(U3=2,J3*100,0)) -> 0 | W3: =IF(U3=1,J3*$AD$6,IF(U3=2,J3*$AJ$2,0)) -> 0 | X3: =SUM(N3)+SUM(W3) -> 4168950 | Y3: =SUM(O3) -> 4.16895 | Z3: =X3 -> 4168950 | AA3: =X3/$AJ$2 -> 4.16895 | AB3: =X3/H3 -> 1.2749083 | AD3: 总优惠比例 | AF3: 199 | AG3: 100 | AI3: 1 | AJ3: 1250000 | AL3: 1 | AM3: 2 | AN3: 100 | AO3: =SUMIFS(AN:AN,AL:AL,"="&AL3,AM:AM,"<="&AM3) -> 150
A4: 1 | B4: 3 | F4: =IFERROR(VLOOKUP(ROUND(E4*100,0),AF:AG,2,FALSE),"") | K4: 记牌器1个 | L4: 3 | M4: 1 | S4: {=_xlfn.IFNA(MATCH(SUMIFS(R:R,A:A,"="&A4,B:B,"<"&(B4+1)),_xlfn._xlws.FILTER(AO:AO,AL:AL=A4),1),1)} -> 1 | T4: =SUMIFS(R:R,A:A,"="&A4,B:B,"<"&(B4+1)) -> 30 | AD4: 1.15 | AF4: 299 | AG4: 109 | AI4: 2 | AJ4: 1500000 | AL4: 1 | AM4: 3 | AN4: 150 | AO4: =SUMIFS(AN:AN,AL:AL,"="&AL4,AM:AM,"<="&AM4) -> 300
A5: 1 | B5: 4 | F5: =IFERROR(VLOOKUP(ROUND(E5*100,0),AF:AG,2,FALSE),"") | J5: 0.1 | K5: 金币 | L5: 17 | M5: =J5*$AD$6 -> 898950 | S5: {=_xlfn.IFNA(MATCH(SUMIFS(R:R,A:A,"="&A5,B:B,"<"&(B5+1)),_xlfn._xlws.FILTER(AO:AO,AL:AL=A5),1),1)} -> 1 | T5: =SUMIFS(R:R,A:A,"="&A5,B:B,"<"&(B5+1)) -> 30 | AD5: 优惠金币 | AF5: 399 | AG5: 114 | AI5: 3 | AJ5: 1750000 | AL5: =AL2+1 -> 2 | AM5: 1 | AN5: 50 | AO5: =SUMIFS(AN:AN,AL:AL,"="&AL5,AM:AM,"<="&AM5) -> 50
A6: 1 | B6: 5 | F6: =IFERROR(VLOOKUP(ROUND(E6*100,0),AF:AG,2,FALSE),"") | K6: 卡包2星 | L6: 4 | M6: 1 | R6: 10 | S6: {=_xlfn.IFNA(MATCH(SUMIFS(R:R,A:A,"="&A6,B:B,"<"&(B6+1)),_xlfn._xlws.FILTER(AO:AO,AL:AL=A6),1),1)} -> 1 | T6: =SUMIFS(R:R,A:A,"="&A6,B:B,"<"&(B6+1)) -> 40 | AD6: =SUM(G2:G44)*(AD4-1) -> 8989500 | AF6: 499 | AG6: 119 | AI6: 4 | AJ6: 2000000 | AL6: =AL3+1 -> 2 | AM6: 2 | AN6: 100 | AO6: =SUMIFS(AN:AN,AL:AL,"="&AL6,AM:AM,"<="&AM6) -> 150
A7: 1 | B7: 6 | F7: =IFERROR(VLOOKUP(ROUND(E7*100,0),AF:AG,2,FALSE),"") | K7: 老虎机抽奖券 | L7: 3 | M7: 5 | S7: {=_xlfn.IFNA(MATCH(SUMIFS(R:R,A:A,"="&A7,B:B,"<"&(B7+1)),_xlfn._xlws.FILTER(AO:AO,AL:AL=A7),1),1)} -> 1 | T7: =SUMIFS(R:R,A:A,"="&A7,B:B,"<"&(B7+1)) -> 40 | AD7: 总优惠进度 | AF7: 599 | AG7: 119 | AI7: 5 | AJ7: 2250000 | AL7: =AL4+1 -> 2 | AM7: 3 | AN7: 150 | AO7: =SUMIFS(AN:AN,AL:AL,"="&AL7,AM:AM,"<="&AM7) -> 300
