Workbook

Sheet 数值体验表
B1: 角色等级 | C1: multiplier值 | D1: 需要spin | H1: 单位spin/s | J1: 倍率期望 | K1: id | L1: 奖励倍率 | M1: 权重 | O1: 领取间隔时间(秒) | Q1: 倍率期望 | R1: id | S1: 奖励倍率 | T1: 权重 | W1: buff | X1: 倍数 | Y1: 价格 | Z1: 时场（分钟） | AA1: 折扣
A2: id | B2: playerLevel | C2: level | D2: betNeed | F2: 花费时间min | H2: 1 | J2: =SUM(N2:N10) -> 0.02 | K2: 1 | L2: 1 | M2: 0 | N2: =L2*M2/SUMIF(K:K,K2,M:M) -> 0 | O2: 900 | Q2: =SUMIF(R:R,1,U:U) -> 1.5020161 | R2: 1 | S2: 10 | T2: 100 | U2: =S2*T2/SUMIF(R:R,R2,T:T) -> 0.040322581 | W2: bonus | X2: 2 | Y2: 0.49 | Z2: 120 | AA2: =J11*Z2/(O12/60/X2)/Y2 -> 0.27210884
A3: 1 | B3: 1 | C3: 1 | D3: 0 | F3: =ROUND(D3/$H$2/60,0) -> 0 | K3: 1 | L3: 0.01 | M3: 5000 | N3: =L3*M3/SUMIF(K:K,K3,M:M) -> 0.0060240964 | O3: 900 | R3: 1 | S3: 1.5 | T3: 2500 | U3: =S3*T3/SUMIF(R:R,R3,T:T) -> 0.15120968 | W3: 免费转盘 | X3: 2 | Y3: 2 | Z3: 120 | AA3: =Q2*X3/Y3 -> 1.5020161
A4: 2 | B4: 1 | C4: 2 | D4: 50 | F4: =ROUND(D4/$H$2/60,0) -> 1 | H4: #触发转盘累积领取的mega bonus次数 | K4: 1 | L4: 0.02 | M4: 500 | N4: =L4*M4/SUMIF(K:K,K4,M:M) -> 0.0012048193 | O4: 900 | R4: 1 | S4: 1 | T4: 2000 | U4: =S4*T4/SUMIF(R:R,R4,T:T) -> 0.080645161 | W4: 付费转盘 | X4: 2 | Y4: 2 | Z4: 120 | AA4: =Q16*X4/Y4 -> 7.5100806
A5: 3 | B5: 1 | C5: 3 | D5: 200 | F5: =ROUND(D5/$H$2/60,0) -> 3 | H5: megaBonus | K5: 1 | L5: 0.02 | M5: 500 | N5: =L5*M5/SUMIF(K:K,K5,M:M) -> 0.0012048193 | O5: 900 | R5: 1 | S5: 1.5 | T5: 2000 | U5: =S5*T5/SUMIF(R:R,R5,T:T) -> 0.12096774
A6: 4 | B6: 1 | C6: 4 | D6: 500 | F6: =ROUND(D6/$H$2/60,0) -> 8 | H6: 5 | K6: 1 | L6: 0.02 | M6: 1000 | N6: =L6*M6/SUMIF(K:K,K6,M:M) -> 0.0024096386 | O6: 900 | R6: 1 | S6: 2 | T6: 2500 | U6: =S6*T6/SUMIF(R:R,R6,T:T) -> 0.2016129
A7: 5 | B7: 1 | C7: 5 | D7: 1000 | F7: =ROUND(D7/$H$2/60,0) -> 17 | K7: 1 | L7: 0.04 | M7: 500 | N7: =L7*M7/SUMIF(K:K,K7,M:M) -> 0.0024096386 | O7: 900 | R7: 1 | S7: 0.5 | T7: 2000 | U7: =S7*T7/SUMIF(R:R,R7,T:T) -> 0.040322581
A8: 6 | B8: 1 | C8: 10 | D8: 2000 | F8: =ROUND(D8/$H$2/60,0) -> 33 | H8: FreeBonusHourly | K8: 1 | L8: 0.06 | M8: 500 | N8: =L8*M8/SUMIF(K:K,K8,M:M) -> 0.0036144578 | O8: 900 | R8: 1 | S8: 2.5 | T8: 1500 | U8: =S8*T8/SUMIF(R:R,R8,T:T) -> 0.15120968
H9: FreeBonusWheel | K9: 1 | L9: 0.08 | M9: 200 | N9: =L9*M9/SUMIF(K:K,K9,M:M) -> 0.0019277108 | O9: 900 | R9: 1 | S9: 1.5 | T9: 2000 | U9: =S9*T9/SUMIF(R:R,R9,T:T) -> 0.12096774
H10: FreeBonusMultiplier | K10: 1 | L10: 0.1 | M10: 100 | N10: =L10*M10/SUMIF(K:K,K10,M:M) -> 0.0012048193 | O10: 900 | R10: 1 | S10: 2 | T10: 2500 | U10: =S10*T10/SUMIF(R:R,R10,T:T) -> 0.2016129
J11: =SUM(N11:N19) -> 0.1 | K11: 2 | L11: 5 | M11: 0 | N11: =L11*M11/SUMIF(K:K,K11,M:M) -> 0 | O11: 10800 | R11: 1 | S11: 0.5 | T11: 2000 | U11: =S11*T11/SUMIF(R:R,R11,T:T) -> 0.040322581
K12: 2 | L12: 0.05 | M12: 5000 | N12: =L12*M12/SUMIF(K:K,K12,M:M) -> 0.030120482 | O12: 10800 | R12: 1 | S12: 3 | T12: 1000 | U12: =S12*T12/SUMIF(R:R,R12,T:T) -> 0.12096774
K13: 2 | L13: 0.1 | M13: 500 | N13: =L13*M13/SUMIF(K:K,K13,M:M) -> 0.0060240964 | O13: 10800 | R13: 1 | S13: 1.5 | T13: 2500 | U13: =S13*T13/SUMIF(R:R,R13,T:T) -> 0.15120968
K14: 2 | L14: 0.1 | M14: 500 | N14: =L14*M14/SUMIF(K:K,K14,M:M) -> 0.0060240964 | O14: 10800 | R14: 1 | S14: 0.5 | T14: 2000 | U14: =S14*T14/SUMIF(R:R,R14,T:T) -> 0.040322581
K15: 2 | L15: 0.1 | M15: 1000 | N15: =L15*M15/SUMIF(K:K,K15,M:M) -> 0.012048193 | O15: 10800 | R15: 1 | S15: 5 | T15: 200 | U15: =S15*T15/SUMIF(R:R,R15,T:T) -> 0.040322581
K16: 2 | L16: 0.2 | M16: 500 | N16: =L16*M16/SUMIF(K:K,K16,M:M) -> 0.012048193 | O16: 10800 | Q16: =SUMIF(R:R,2,U:U) -> 7.5100806 | R16: 2 | S16: =S2*5 -> 50 | T16: =T2 -> 100 | U16: =S16*T16/SUMIF(R:R,R16,T:T) -> 0.2016129
K17: 2 | L17: 0.3 | M17: 500 | N17: =L17*M17/SUMIF(K:K,K17,M:M) -> 0.018072289 | O17: 10800 | R17: 2 | S17: =S3*5 -> 7.5 | T17: =T3 -> 2500 | U17: =S17*T17/SUMIF(R:R,R17,T:T) -> 0.75604839
K18: 2 | L18: 0.4 | M18: 200 | N18: =L18*M18/SUMIF(K:K,K18,M:M) -> 0.0096385542 | O18: 10800 | R18: 2 | S18: =S4*5 -> 5 | T18: =T4 -> 2000 | U18: =S18*T18/SUMIF(R:R,R18,T:T) -> 0.40322581
K19: 2 | L19: 0.5 | M19: 100 | N19: =L19*M19/SUMIF(K:K,K19,M:M) -> 0.0060240964 | O19: 10800 | R19: 2 | S19: =S5*5 -> 7.5 | T19: =T5 -> 2000 | U19: =S19*T19/SUMIF(R:R,R19,T:T) -> 0.60483871
R20: 2 | S20: =S6*5 -> 10 | T20: =T6 -> 2500 | U20: =S20*T20/SUMIF(R:R,R20,T:T) -> 1.0080645
R21: 2 | S21: =S7*5 -> 2.5 | T21: =T7 -> 2000 | U21: =S21*T21/SUMIF(R:R,R21,T:T) -> 0.2016129
R22: 2 | S22: =S8*5 -> 12.5 | T22: =T8 -> 1500 | U22: =S22*T22/SUMIF(R:R,R22,T:T) -> 0.75604839
R23: 2 | S23: =S9*5 -> 7.5 | T23: =T9 -> 2000 | U23: =S23*T23/SUMIF(R:R,R23,T:T) -> 0.60483871
R24: 2 | S24: =S10*5 -> 10 | T24: =T10 -> 2500 | U24: =S24*T24/SUMIF(R:R,R24,T:T) -> 1.0080645
R25: 2 | S25: =S11*5 -> 2.5 | T25: =T11 -> 2000 | U25: =S25*T25/SUMIF(R:R,R25,T:T) -> 0.2016129
R26: 2 | S26: =S12*5 -> 15 | T26: =T12 -> 1000 | U26: =S26*T26/SUMIF(R:R,R26,T:T) -> 0.60483871
R27: 2 | S27: =S13*5 -> 7.5 | T27: =T13 -> 2500 | U27: =S27*T27/SUMIF(R:R,R27,T:T) -> 0.75604839
R28: 2 | S28: =S14*5 -> 2.5 | T28: =T14 -> 2000 | U28: =S28*T28/SUMIF(R:R,R28,T:T) -> 0.2016129
R29: 2 | S29: =S15*5 -> 25 | T29: =T15 -> 200 | U29: =S29*T29/SUMIF(R:R,R29,T:T) -> 0.2016129

Sheet FreeBonusHourly
A1: id | B1: level | C1: moduleNameId | D1: coins | E1: weightType | F1: weight | G1: interval | H1: maxRate
A2: int | B2: int | C2: int | D2: int | E2: int | F2: int | G2: int | H2: int
A3: cs | B3: s | C3: s | D3: s | E3: s | F3: s | G3: s | H3: s
A4: 奖励类型1mini2mega | B4: 等级 | C4: 模块名索引ID | D4: 奖励美金值，千分比 | E4: 权重类型，领取次数 | F4: 权重 | G4: 领取间隔时间(秒) | H4: win up to显示
A5: 1 | B5: 1 | D5: =数值体验表!L2*100 -> 100 | E5: 1 | F5: =数值体验表!M2 -> 0 | G5: =60*16 -> 960 | H5: 10
A6: 1 | B6: 1 | D6: =数值体验表!L3*100 -> 1 | E6: 1 | F6: =数值体验表!M3 -> 5000 | G6: =60*16 -> 960 | H6: 10
A7: 1 | B7: 1 | D7: =数值体验表!L4*100 -> 2 | E7: 1 | F7: =数值体验表!M4 -> 500 | G7: =60*16 -> 960 | H7: 10
A8: 1 | B8: 1 | D8: =数值体验表!L5*100 -> 2 | E8: 1 | F8: =数值体验表!M5 -> 500 | G8: =60*16 -> 960 | H8: 10
A9: 1 | B9: 1 | D9: =数值体验表!L6*100 -> 2 | E9: 1 | F9: =数值体验表!M6 -> 1000 | G9: =60*16 -> 960 | H9: 10
A10: 1 | B10: 1 | D10: =数值体验表!L7*100 -> 4 | E10: 1 | F10: =数值体验表!M7 -> 500 | G10: =60*16 -> 960 | H10: 10
A11: 1 | B11: 1 | D11: =数值体验表!L8*100 -> 6 | E11: 1 | F11: =数值体验表!M8 -> 500 | G11: =60*16 -> 960 | H11: 10
A12: 1 | B12: 1 | D12: =数值体验表!L9*100 -> 8 | E12: 1 | F12: =数值体验表!M9 -> 200 | G12: =60*16 -> 960 | H12: 10
A13: 1 | B13: 1 | D13: =数值体验表!L10*100 -> 10 | E13: 1 | F13: =数值体验表!M10 -> 100 | G13: =60*16 -> 960 | H13: 10
A14: 2 | B14: 1 | D14: =数值体验表!L11*100 -> 500 | E14: 1 | F14: =数值体验表!M11 -> 0 | G14: =60*60*3 -> 10800 | H14: 50
A15: 2 | B15: 1 | D15: =数值体验表!L12*100 -> 5 | E15: 1 | F15: =数值体验表!M12 -> 5000 | G15: =60*60*3 -> 10800 | H15: 50
A16: 2 | B16: 1 | D16: =数值体验表!L13*100 -> 10 | E16: 1 | F16: =数值体验表!M13 -> 500 | G16: =60*60*3 -> 10800 | H16: 50
A17: 2 | B17: 1 | D17: =数值体验表!L14*100 -> 10 | E17: 1 | F17: =数值体验表!M14 -> 500 | G17: =60*60*3 -> 10800 | H17: 50
A18: 2 | B18: 1 | D18: =数值体验表!L15*100 -> 10 | E18: 1 | F18: =数值体验表!M15 -> 1000 | G18: =60*60*3 -> 10800 | H18: 50
A19: 2 | B19: 1 | D19: =数值体验表!L16*100 -> 20 | E19: 1 | F19: =数值体验表!M16 -> 500 | G19: =60*60*3 -> 10800 | H19: 50
A20: 2 | B20: 1 | D20: =数值体验表!L17*100 -> 30 | E20: 1 | F20: =数值体验表!M17 -> 500 | G20: =60*60*3 -> 10800 | H20: 50
A21: 2 | B21: 1 | D21: =数值体验表!L18*100 -> 40 | E21: 1 | F21: =数值体验表!M18 -> 200 | G21: =60*60*3 -> 10800 | H21: 50
A22: 2 | B22: 1 | D22: =数值体验表!L19*100 -> 50 | E22: 1 | F22: =数值体验表!M19 -> 100 | G22: =60*60*3 -> 10800 | H22: 50

Sheet FreeBonusWheel
A1: level | B1: payType | C1: moduleNameId | D1: multi | E1: weightType | F1: weight | G1: group | H1: ItemIDgp | I1: ItemIDiap | J1: CommonPayKey | K1: Money
A2: int | B2: int | C2: int | D2: int | E2: int | F2: int | G2: int | H2: string | I2: string | J2: string | K2: int
A3: s | B3: s | C3: s | D3: s | E3: s | F3: s | G3: s | H3: s | I3: s | J3: s | K3: s
A4: 等级 | B4: 转盘类型1免费2付费 | C4: 模块名索引ID | D4: 倍数,百分比 | E4: 权重类型，周次数 | F4: 权重 | G4: 分组定价，0不走分组 | H4: 谷歌订单号 | I4: 苹果订单号 | J4: 通用支付key | K4: 价格
A5: 1 | B5: 1 | D5: =数值体验表!S2*100 -> 1000 | E5: 0 | F5: =数值体验表!T2 -> 100 | G5: 0
A6: 1 | B6: 1 | D6: =数值体验表!S3*100 -> 150 | E6: 0 | F6: =数值体验表!T3 -> 2500 | G6: 0
A7: 1 | B7: 1 | D7: =数值体验表!S4*100 -> 100 | E7: 0 | F7: =数值体验表!T4 -> 2000 | G7: 0
A8: 1 | B8: 1 | D8: =数值体验表!S5*100 -> 150 | E8: 0 | F8: =数值体验表!T5 -> 2000 | G8: 0
A9: 1 | B9: 1 | D9: =数值体验表!S6*100 -> 200 | E9: 0 | F9: =数值体验表!T6 -> 2500 | G9: 0
A10: 1 | B10: 1 | D10: =数值体验表!S7*100 -> 50 | E10: 0 | F10: =数值体验表!T7 -> 2000 | G10: 0
A11: 1 | B11: 1 | D11: =数值体验表!S8*100 -> 250 | E11: 0 | F11: =数值体验表!T8 -> 1500 | G11: 0
A12: 1 | B12: 1 | D12: =数值体验表!S9*100 -> 150 | E12: 0 | F12: =数值体验表!T9 -> 2000 | G12: 0
A13: 1 | B13: 1 | D13: =数值体验表!S10*100 -> 200 | E13: 0 | F13: =数值体验表!T10 -> 2500 | G13: 0
A14: 1 | B14: 1 | D14: =数值体验表!S11*100 -> 50 | E14: 0 | F14: =数值体验表!T11 -> 2000 | G14: 0
A15: 1 | B15: 1 | D15: =数值体验表!S12*100 -> 300 | E15: 0 | F15: =数值体验表!T12 -> 1000 | G15: 0
A16: 1 | B16: 1 | D16: =数值体验表!S13*100 -> 150 | E16: 0 | F16: =数值体验表!T13 -> 2500 | G16: 0
... A18: 1 | B18: 1 | D18: =数值体验表!S15*100 -> 500 | E18: 0 | F18: =数值体验表!T15 -> 200 | G18: 0
A19: 1 | B19: 2 | D19: =数值体验表!S16*100 -> 5000 | E19: 0 | F19: =数值体验表!T16 -> 100 | G19: 1 | H19: gp_roulette_1 | I19: iap_roulette_1 | J19: PK_399 | K19: 399
A20: 1 | B20: 2 | D20: =数值体验表!S17*100 -> 750 | E20: 0 | F20: =数值体验表!T17 -> 2500 | G20: 1 | H20: gp_roulette_1 | I20: iap_roulette_1 | J20: PK_399 | K20: 399
A21: 1 | B21: 2 | D21: =数值体验表!S18*100 -> 500 | E21: 0 | F21: =数值体验表!T18 -> 2000 | G21: 1 | H21: gp_roulette_1 | I21: iap_roulette_1 | J21: PK_399 | K21: 399
A22: 1 | B22: 2 | D22: =数值体验表!S19*100 -> 750 | E22: 0 | F22: =数值体验表!T19 -> 2000 | G22: 1 | H22: gp_roulette_1 | I22: iap_roulette_1 | J22: PK_399 | K22: 399
A23: 1 | B23: 2 | D23: =数值体验表!S20*100 -> 1000 | E23: 0 | F23: =数值体验表!T20 -> 2500 | G23: 1 | H23: gp_roulette_1 | I23: iap_roulette_1 | J23: PK_399 | K23: 399
A24: 1 | B24: 2 | D24: =数值体验表!S21*100 -> 250 | E24: 0 | F24: =数值体验表!T21 -> 2000 | G24: 1 | H24: gp_roulette_1 | I24: iap_roulette_1 | J24: PK_399 | K24: 399
A25: 1 | B25: 2 | D25: =数值体验表!S22*100 -> 1250 | E25: 0 | F25: =数值体验表!T22 -> 1500 | G25: 1 | H25: gp_roulette_1 | I25: iap_roulette_1 | J25: PK_399 | K25: 399
A26: 1 | B26: 2 | D26: =数值体验表!S23*100 -> 750 | E26: 0 | F26: =数值体验表!T23 -> 2000 | G26: 1 | H26: gp_roulette_1 | I26: iap_roulette_1 | J26: PK_399 | K26: 399
A27: 1 | B27: 2 | D27: =数值体验表!S24*100 -> 1000 | E27: 0 | F27: =数值体验表!T24 -> 2500 | G27: 1 | H27: gp_roulette_1 | I27: iap_roulette_1 | J27: PK_399 | K27: 399
A28: 1 | B28: 2 | D28: =数值体验表!S25*100 -> 250 | E28: 0 | F28: =数值体验表!T25 -> 2000 | G28: 1 | H28: gp_roulette_1 | I28: iap_roulette_1 | J28: PK_399 | K28: 399
A29: 1 | B29: 2 | D29: =数值体验表!S26*100 -> 1500 | E29: 0 | F29: =数值体验表!T26 -> 1000 | G29: 1 | H29: gp_roulette_1 | I29: iap_roulette_1 | J29: PK_399 | K29: 399
A30: 1 | B30: 2 | D30: =数值体验表!S27*100 -> 750 | E30: 0 | F30: =数值体验表!T27 -> 2500 | G30: 1 | H30: gp_roulette_1 | I30: iap_roulette_1 | J30: PK_399 | K30: 399
A31: 1 | B31: 2 | D31: =数值体验表!S28*100 -> 250 | E31: 0 | F31: =数值体验表!T28 -> 2000 | G31: 1 | H31: gp_roulette_1 | I31: iap_roulette_1 | J31: PK_399 | K31: 399
A32: 1 | B32: 2 | D32: =数值体验表!S29 -> 25 | E32: 0 | F32: =数值体验表!T29 -> 200 | G32: 1 | H32: gp_roulette_1 | I32: iap_roulette_1 | J32: PK_399 | K32: 399
A33: 1 | B33: 2 | D33: =D19 -> 5000 | E33: 0 | F33: =F19 -> 100 | G33: 2 | H33: gp_roulette_2 | I33: iap_roulette_2 | J33: PK_599 | K33: 599
A34: 1 | B34: 2 | D34: =D20 -> 750 | E34: 0 | F34: =F20 -> 2500 | G34: 2 | H34: gp_roulette_2 | I34: iap_roulette_2 | J34: PK_599 | K34: 599
A35: 1 | B35: 2 | D35: =D21 -> 500 | E35: 0 | F35: =F21 -> 2000 | G35: 2 | H35: gp_roulette_2 | I35: iap_roulette_2 | J35: PK_599 | K35: 599
A36: 1 | B36: 2 | D36: =D22 -> 750 | E36: 0 | F36: =F22 -> 2000 | G36: 2 | H36: gp_roulette_2 | I36: iap_roulette_2 | J36: PK_599 | K36: 599
A37: 1 | B37: 2 | D37: =D23 -> 1000 | E37: 0 | F37: =F23 -> 2500 | G37: 2 | H37: gp_roulette_2 | I37: iap_roulette_2 | J37: PK_599 | K37: 599
A38: 1 | B38: 2 | D38: =D24 -> 250 | E38: 0 | F38: =F24 -> 2000 | G38: 2 | H38: gp_roulette_2 | I38: iap_roulette_2 | J38: PK_599 | K38: 599
A39: 1 | B39: 2 | D39: =D25 -> 1250 | E39: 0 | F39: =F25 -> 1500 | G39: 2 | H39: gp_roulette_2 | I39: iap_roulette_2 | J39: PK_599 | K39: 599
A40: 1 | B40: 2 | D40: =D26 -> 750 | E40: 0 | F40: =F26 -> 2000 | G40: 2 | H40: gp_roulette_2 | I40: iap_roulette_2 | J40: PK_599 | K40: 599
A41: 1 | B41: 2 | D41: =D27 -> 1000 | E41: 0 | F41: =F27 -> 2500 | G41: 2 | H41: gp_roulette_2 | I41: iap_roulette_2 | J41: PK_599 | K41: 599
...

Sheet FreeBonusMultiplier
A1: level | B1: multiplier | C1: spinNeed
A2: int | B2: int | C2: int
A3: s | B3: s | C3: s
A4: 等级 | B4: 倍数 | C4: 需要spin
A5: 1 | B5: 1 | C5: 0
A6: 1 | B6: 2 | C6: 50
A7: 1 | B7: 3 | C7: 200
A8: 1 | B8: 4 | C8: 500
A9: 1 | B9: 5 | C9: 1000
A10: 1 | B10: 10 | C10: 2000
A11: 2 | B11: 1 | C11: 0
A12: 2 | B12: 2 | C12: 25
A13: 2 | B13: 3 | C13: 100
A14: 2 | B14: 4 | C14: 250
A15: 2 | B15: 5 | C15: 500
A16: 2 | B16: 10 | C16: 1000
